Workbook

Sheet Instruções
B1: Corte ao vivo — como usar esta planilha
B2: Roteiro de corte, câmeras e gravação, escala da equipe e registro de erros para a revisão.
B4: Legenda: onde preencher
B5: Amarelo-claro | C5: Células de entrada. É aqui que você digita.
B6: Cinza | C6: Células calculadas ou fixas (rótulos, contas, avisos). Não altere.
B7: Cinza em itálico | C7: Linha de exemplo (marcada com “Ex.”) e dicas de preenchimento. Não entram nas contas.
B8: Listas suspensas | C8: Tipo de momento, fontes, transição, função, tipo e causa de erro aceitam só as opções da lista.
B9: Números e horas | C9: Duração em minutos, só o número. Horas no formato 19:00.
B10: Comentários | C10: Células com triângulo vermelho no canto trazem uma dica. Passe o mouse sobre elas.
B12: Ordem de preenchimento
B13: 1 | C13: Aba Roteiro de corte: preencha o cabeçalho, a hora de início e confira os três parâmetros no alto.
B14: 2 | C14: Aba Roteiro de corte: liste os momentos do evento na ordem, com duração, fonte principal e alternativas.
B15: 3 | C15: Aba Roteiro de corte: preencha as câmeras (posição, plano de base, operador) e os gravadores.
B16: 4 | C16: Resolva cada pendência e cada aviso. A linha fica verde quando está OK.
B17: 5 | C17: Aba Equipe: monte a escala e confira as palavras de comando com a equipe.
B18: 6 | C18: Aba Checklist: confira os doze itens antes de o evento começar.
B19: 7 | C19: Depois do evento, aba Registro de erros: anote os erros vistos na gravação e a ação de cada um.
B21: Abas da planilha
B22: Roteiro de corte | C22: Até 20 momentos, seis câmeras e dois gravadores, com hora de cada momento, ritmo sugerido, pendências e espaço de gravação.
B23: Equipe | C23: Escala de até 14 funções, com situação de cada linha, e as palavras de comando combinadas.
B24: Registro de erros | C24: Até 30 erros, com contagem por tipo e por causa e ações em aberto.
B25: Referência | C25: Ritmo por tipo de momento, transições, linguagem de comando, tally e taxas de gravação.
B26: Checklist | C26: Os doze itens do treinamento, com percentual atendido.
B27: Exemplo - Roteiro | C27: O roteiro do culto do exemplo 1 do treinamento, antes das correções.
B29: Regras e premissas do modelo
B30: Hora de cada momento | C30: Hora de início do evento mais a soma das durações dos momentos anteriores.
B31: Ritmo sugerido | C31: Vem da tabela da aba Referência, pelo tipo de momento. É ponto de partida, e não norma.
B32: Pendência | C32: Uma por linha, na ordem: duração, fonte principal, áudio da mídia, alternativa repetida, momento longo sem alternativa, câmera sem operador.
B33: Sem alternativa | C33: Só recebe alerta o momento mais longo que o limite do alto da aba (5 minutos no início). Troque se quiser.
B34: Espaço de gravação | C34: Taxa (Mbps) × (duração do roteiro + margem) × 60 ÷ 8 ÷ 1000, em GB. A taxa real depende do formato: confira o manual.
B35: Concentração | C35: Câmera principal em mais que a parcela do alto da aba (60% no início) recebe aviso para combinar um plano B.
B36: Exemplos | C36: Os dados do exemplo e das linhas “Ex.” são ilustrativos, criados para este material.

Sheet Roteiro de corte
B1: Roteiro de corte — momento a momento
B2: Preencha as células em amarelo-claro. As células cinza são calculadas e apontam o que falta resolver.
B4: Evento | I4: Momento sem alternativa: alerta acima de (min) | L4: 5 | M4: Regra prática deste material. Momento curto pode ficar só na câmera geral.
B5: Local | I5: Margem de gravação (min) | L5: 30 | M5: Tempo a mais que cada gravador deve suportar, além do roteiro.
B6: Data | I6: Concentração numa câmera: alerta acima de | L6: 0.6 | M6: Parcela do tempo como principal. Acima dela, combine um plano B.
B7: Hora de início | I7: A hora de cada momento é calculada a partir da hora de início e das durações.
B8: Diretor de imagem | I8: Fontes: Câmera 1 a 6, Mídia, Slides, Letras ou Vinheta. A pendência some quando a linha está resolvida.
B10: Roteiro de corte, na ordem do evento
B11: # | C11: Momento | D11: Tipo | E11: Duração | F11: Início | G11: Fonte principal | H11: Alternativa 1 | I11: Alternativa 2 | J11: Gráfico | K11: Transição de entrada | L11: Áudio da mídia | M11: Ritmo sugerido | N11: Pendência | O11: Observação
C12: o que acontece no palco | D12: da lista | E12: min | F12: calculado | G12: da lista | H12: da lista | I12: da lista | J12: legenda, letra, texto | K12: da lista | L12: Sim / Não | M12: da aba Referência | N12: calculada
B13: Ex. | C13: Pregação | D13: Pregação | E13: 40 | F13: 19:40 | G13: Câmera 2 | H13: Câmera 1 | I13: Câmera 3 | J13: Nome do pastor | K13: Corte seco | M13: 20 a 60 s ou mais, Corte seco | N13: OK
B14: 1 | F14: =IF(OR(E14="",$D$7=""),"",$D$7) | M14: =IF(D14="","",IFERROR(VLOOKUP(D14,Referência!$B$6:$D$16,2,FALSE())&", "&VLOOKUP(D14,Referência!$B$6:$D$16,3,FALSE()),"")) | N14: =IF(AND(C14="",G14=""),"",IF(E14="","Informe a duração",IF(G14="","Defina a fonte principal",IF(AND(OR(G14="Mídia",G14="Vinheta"),L14=""),"Defina o áudio da mídia",IF(OR(AND(H14<>"",H14=G14),AND(I14<>"",I14=G14),AND(H14<>"",H14=I14)),"Alternativa repetida",IF(AND(H14="",I14="",E14>$L$4),"Sem alternativa",IF(IFERROR(INDEX($G$38:$G$43,MATCH(G14,$C$38:$C$43,0))="",FALSE()),"Câmera sem operador",IF(OR(IFERROR(INDEX($G$38:$G$43,MATCH(H14,$C$38:$C$43,0))="",FALSE()),IFERROR(INDEX($G$38:$G$43,MATCH(I14,$C$38:$C$43,0))="",FALSE())),"Alternativa sem operador","OK"))))))))
B15: 2 | F15: =IF(OR(E15="",$D$7=""),"",$D$7+SUM($E$14:E14)/1440) | M15: =IF(D15="","",IFERROR(VLOOKUP(D15,Referência!$B$6:$D$16,2,FALSE())&", "&VLOOKUP(D15,Referência!$B$6:$D$16,3,FALSE()),"")) | N15: =IF(AND(C15="",G15=""),"",IF(E15="","Informe a duração",IF(G15="","Defina a fonte principal",IF(AND(OR(G15="Mídia",G15="Vinheta"),L15=""),"Defina o áudio da mídia",IF(OR(AND(H15<>"",H15=G15),AND(I15<>"",I15=G15),AND(H15<>"",H15=I15)),"Alternativa repetida",IF(AND(H15="",I15="",E15>$L$4),"Sem alternativa",IF(IFERROR(INDEX($G$38:$G$43,MATCH(G15,$C$38:$C$43,0))="",FALSE()),"Câmera sem operador",IF(OR(IFERROR(INDEX($G$38:$G$43,MATCH(H15,$C$38:$C$43,0))="",FALSE()),IFERROR(INDEX($G$38:$G$43,MATCH(I15,$C$38:$C$43,0))="",FALSE())),"Alternativa sem operador","OK"))))))))
B16: 3 | F16: =IF(OR(E16="",$D$7=""),"",$D$7+SUM($E$14:E15)/1440) | M16: =IF(D16="","",IFERROR(VLOOKUP(D16,Referência!$B$6:$D$16,2,FALSE())&", "&VLOOKUP(D16,Referência!$B$6:$D$16,3,FALSE()),"")) | N16: =IF(AND(C16="",G16=""),"",IF(E16="","Informe a duração",IF(G16="","Defina a fonte principal",IF(AND(OR(G16="Mídia",G16="Vinheta"),L16=""),"Defina o áudio da mídia",IF(OR(AND(H16<>"",H16=G16),AND(I16<>"",I16=G16),AND(H16<>"",H16=I16)),"Alternativa repetida",IF(AND(H16="",I16="",E16>$L$4),"Sem alternativa",IF(IFERROR(INDEX($G$38:$G$43,MATCH(G16,$C$38:$C$43,0))="",FALSE()),"Câmera sem operador",IF(OR(IFERROR(INDEX($G$38:$G$43,MATCH(H16,$C$38:$C$43,0))="",FALSE()),IFERROR(INDEX($G$38:$G$43,MATCH(I16,$C$38:$C$43,0))="",FALSE())),"Alternativa sem operador","OK"))))))))
B17: 4 | F17: =IF(OR(E17="",$D$7=""),"",$D$7+SUM($E$14:E16)/1440) | M17: =IF(D17="","",IFERROR(VLOOKUP(D17,Referência!$B$6:$D$16,2,FALSE())&", "&VLOOKUP(D17,Referência!$B$6:$D$16,3,FALSE()),"")) | N17: =IF(AND(C17="",G17=""),"",IF(E17="","Informe a duração",IF(G17="","Defina a fonte principal",IF(AND(OR(G17="Mídia",G17="Vinheta"),L17=""),"Defina o áudio da mídia",IF(OR(AND(H17<>"",H17=G17),AND(I17<>"",I17=G17),AND(H17<>"",H17=I17)),"Alternativa repetida",IF(AND(H17="",I17="",E17>$L$4),"Sem alternativa",IF(IFERROR(INDEX($G$38:$G$43,MATCH(G17,$C$38:$C$43,0))="",FALSE()),"Câmera sem operador",IF(OR(IFERROR(INDEX($G$38:$G$43,MATCH(H17,$C$38:$C$43,0))="",FALSE()),IFERROR(INDEX($G$38:$G$43,MATCH(I17,$C$38:$C$43,0))="",FALSE())),"Alternativa sem operador","OK"))))))))
B18: 5 | F18: =IF(OR(E18="",$D$7=""),"",$D$7+SUM($E$14:E17)/1440) | M18: =IF(D18="","",IFERROR(VLOOKUP(D18,Referência!$B$6:$D$16,2,FALSE())&", "&VLOOKUP(D18,Referência!$B$6:$D$16,3,FALSE()),"")) | N18: =IF(AND(C18="",G18=""),"",IF(E18="","Informe a duração",IF(G18="","Defina a fonte principal",IF(AND(OR(G18="Mídia",G18="Vinheta"),L18=""),"Defina o áudio da mídia",IF(OR(AND(H18<>"",H18=G18),AND(I18<>"",I18=G18),AND(H18<>"",H18=I18)),"Alternativa repetida",IF(AND(H18="",I18="",E18>$L$4),"Sem alternativa",IF(IFERROR(INDEX($G$38:$G$43,MATCH(G18,$C$38:$C$43,0))="",FALSE()),"Câmera sem operador",IF(OR(IFERROR(INDEX($G$38:$G$43,MATCH(H18,$C$38:$C$43,0))="",FALSE()),IFERROR(INDEX($G$38:$G$43,MATCH(I18,$C$38:$C$43,0))="",FALSE())),"Alternativa sem operador","OK"))))))))
B19: 6 | F19: =IF(OR(E19="",$D$7=""),"",$D$7+SUM($E$14:E18)/1440) | M19: =IF(D19="","",IFERROR(VLOOKUP(D19,Referência!$B$6:$D$16,2,FALSE())&", "&VLOOKUP(D19,Referência!$B$6:$D$16,3,FALSE()),"")) | N19: =IF(AND(C19="",G19=""),"",IF(E19="","Informe a duração",IF(G19="","Defina a fonte principal",IF(AND(OR(G19="Mídia",G19="Vinheta"),L19=""),"Defina o áudio da mídia",IF(OR(AND(H19<>"",H19=G19),AND(I19<>"",I19=G19),AND(H19<>"",H19=I19)),"Alternativa repetida",IF(AND(H19="",I19="",E19>$L$4),"Sem alternativa",IF(IFERROR(INDEX($G$38:$G$43,MATCH(G19,$C$38:$C$43,0))="",FALSE()),"Câmera sem operador",IF(OR(IFERROR(INDEX($G$38:$G$43,MATCH(H19,$C$38:$C$43,0))="",FALSE()),IFERROR(INDEX($G$38:$G$43,MATCH(I19,$C$38:$C$43,0))="",FALSE())),"Alternativa sem operador","OK"))))))))
B20: 7 | F20: =IF(OR(E20="",$D$7=""),"",$D$7+SUM($E$14:E19)/1440) | M20: =IF(D20="","",IFERROR(VLOOKUP(D20,Referência!$B$6:$D$16,2,FALSE())&", "&VLOOKUP(D20,Referência!$B$6:$D$16,3,FALSE()),"")) | N20: =IF(AND(C20="",G20=""),"",IF(E20="","Informe a duração",IF(G20="","Defina a fonte principal",IF(AND(OR(G20="Mídia",G20="Vinheta"),L20=""),"Defina o áudio da mídia",IF(OR(AND(H20<>"",H20=G20),AND(I20<>"",I20=G20),AND(H20<>"",H20=I20)),"Alternativa repetida",IF(AND(H20="",I20="",E20>$L$4),"Sem alternativa",IF(IFERROR(INDEX($G$38:$G$43,MATCH(G20,$C$38:$C$43,0))="",FALSE()),"Câmera sem operador",IF(OR(IFERROR(INDEX($G$38:$G$43,MATCH(H20,$C$38:$C$43,0))="",FALSE()),IFERROR(INDEX($G$38:$G$43,MATCH(I20,$C$38:$C$43,0))="",FALSE())),"Alternativa sem operador","OK"))))))))
B21: 8 | F21: =IF(OR(E21="",$D$7=""),"",$D$7+SUM($E$14:E20)/1440) | M21: =IF(D21="","",IFERROR(VLOOKUP(D21,Referência!$B$6:$D$16,2,FALSE())&", "&VLOOKUP(D21,Referência!$B$6:$D$16,3,FALSE()),"")) | N21: =IF(AND(C21="",G21=""),"",IF(E21="","Informe a duração",IF(G21="","Defina a fonte principal",IF(AND(OR(G21="Mídia",G21="Vinheta"),L21=""),"Defina o áudio da mídia",IF(OR(AND(H21<>"",H21=G21),AND(I21<>"",I21=G21),AND(H21<>"",H21=I21)),"Alternativa repetida",IF(AND(H21="",I21="",E21>$L$4),"Sem alternativa",IF(IFERROR(INDEX($G$38:$G$43,MATCH(G21,$C$38:$C$43,0))="",FALSE()),"Câmera sem operador",IF(OR(IFERROR(INDEX($G$38:$G$43,MATCH(H21,$C$38:$C$43,0))="",FALSE()),IFERROR(INDEX($G$38:$G$43,MATCH(I21,$C$38:$C$43,0))="",FALSE())),"Alternativa sem operador","OK"))))))))
B22: 9 | F22: =IF(OR(E22="",$D$7=""),"",$D$7+SUM($E$14:E21)/1440) | M22: =IF(D22="","",IFERROR(VLOOKUP(D22,Referência!$B$6:$D$16,2,FALSE())&", "&VLOOKUP(D22,Referência!$B$6:$D$16,3,FALSE()),"")) | N22: =IF(AND(C22="",G22=""),"",IF(E22="","Informe a duração",IF(G22="","Defina a fonte principal",IF(AND(OR(G22="Mídia",G22="Vinheta"),L22=""),"Defina o áudio da mídia",IF(OR(AND(H22<>"",H22=G22),AND(I22<>"",I22=G22),AND(H22<>"",H22=I22)),"Alternativa repetida",IF(AND(H22="",I22="",E22>$L$4),"Sem alternativa",IF(IFERROR(INDEX($G$38:$G$43,MATCH(G22,$C$38:$C$43,0))="",FALSE()),"Câmera sem operador",IF(OR(IFERROR(INDEX($G$38:$G$43,MATCH(H22,$C$38:$C$43,0))="",FALSE()),IFERROR(INDEX($G$38:$G$43,MATCH(I22,$C$38:$C$43,0))="",FALSE())),"Alternativa sem operador","OK"))))))))
B23: 10 | F23: =IF(OR(E23="",$D$7=""),"",$D$7+SUM($E$14:E22)/1440) | M23: =IF(D23="","",IFERROR(VLOOKUP(D23,Referência!$B$6:$D$16,2,FALSE())&", "&VLOOKUP(D23,Referência!$B$6:$D$16,3,FALSE()),"")) | N23: =IF(AND(C23="",G23=""),"",IF(E23="","Informe a duração",IF(G23="","Defina a fonte principal",IF(AND(OR(G23="Mídia",G23="Vinheta"),L23=""),"Defina o áudio da mídia",IF(OR(AND(H23<>"",H23=G23),AND(I23<>"",I23=G23),AND(H23<>"",H23=I23)),"Alternativa repetida",IF(AND(H23="",I23="",E23>$L$4),"Sem alternativa",IF(IFERROR(INDEX($G$38:$G$43,MATCH(G23,$C$38:$C$43,0))="",FALSE()),"Câmera sem operador",IF(OR(IFERROR(INDEX($G$38:$G$43,MATCH(H23,$C$38:$C$43,0))="",FALSE()),IFERROR(INDEX($G$38:$G$43,MATCH(I23,$C$38:$C$43,0))="",FALSE())),"Alternativa sem operador","OK"))))))))
B24: 11 | F24: =IF(OR(E24="",$D$7=""),"",$D$7+SUM($E$14:E23)/1440) | M24: =IF(D24="","",IFERROR(VLOOKUP(D24,Referência!$B$6:$D$16,2,FALSE())&", "&VLOOKUP(D24,Referência!$B$6:$D$16,3,FALSE()),"")) | N24: =IF(AND(C24="",G24=""),"",IF(E24="","Informe a duração",IF(G24="","Defina a fonte principal",IF(AND(OR(G24="Mídia",G24="Vinheta"),L24=""),"Defina o áudio da mídia",IF(OR(AND(H24<>"",H24=G24),AND(I24<>"",I24=G24),AND(H24<>"",H24=I24)),"Alternativa repetida",IF(AND(H24="",I24="",E24>$L$4),"Sem alternativa",IF(IFERROR(INDEX($G$38:$G$43,MATCH(G24,$C$38:$C$43,0))="",FALSE()),"Câmera sem operador",IF(OR(IFERROR(INDEX($G$38:$G$43,MATCH(H24,$C$38:$C$43,0))="",FALSE()),IFERROR(INDEX($G$38:$G$43,MATCH(I24,$C$38:$C$43,0))="",FALSE())),"Alternativa sem operador","OK"))))))))
B25: 12 | F25: =IF(OR(E25="",$D$7=""),"",$D$7+SUM($E$14:E24)/1440) | M25: =IF(D25="","",IFERROR(VLOOKUP(D25,Referência!$B$6:$D$16,2,FALSE())&", "&VLOOKUP(D25,Referência!$B$6:$D$16,3,FALSE()),"")) | N25: =IF(AND(C25="",G25=""),"",IF(E25="","Informe a duração",IF(G25="","Defina a fonte principal",IF(AND(OR(G25="Mídia",G25="Vinheta"),L25=""),"Defina o áudio da mídia",IF(OR(AND(H25<>"",H25=G25),AND(I25<>"",I25=G25),AND(H25<>"",H25=I25)),"Alternativa repetida",IF(AND(H25="",I25="",E25>$L$4),"Sem alternativa",IF(IFERROR(INDEX($G$38:$G$43,MATCH(G25,$C$38:$C$43,0))="",FALSE()),"Câmera sem operador",IF(OR(IFERROR(INDEX($G$38:$G$43,MATCH(H25,$C$38:$C$43,0))="",FALSE()),IFERROR(INDEX($G$38:$G$43,MATCH(I25,$C$38:$C$43,0))="",FALSE())),"Alternativa sem operador","OK"))))))))
B26: 13 | F26: =IF(OR(E26="",$D$7=""),"",$D$7+SUM($E$14:E25)/1440) | M26: =IF(D26="","",IFERROR(VLOOKUP(D26,Referência!$B$6:$D$16,2,FALSE())&", "&VLOOKUP(D26,Referência!$B$6:$D$16,3,FALSE()),"")) | N26: =IF(AND(C26="",G26=""),"",IF(E26="","Informe a duração",IF(G26="","Defina a fonte principal",IF(AND(OR(G26="Mídia",G26="Vinheta"),L26=""),"Defina o áudio da mídia",IF(OR(AND(H26<>"",H26=G26),AND(I26<>"",I26=G26),AND(H26<>"",H26=I26)),"Alternativa repetida",IF(AND(H26="",I26="",E26>$L$4),"Sem alternativa",IF(IFERROR(INDEX($G$38:$G$43,MATCH(G26,$C$38:$C$43,0))="",FALSE()),"Câmera sem operador",IF(OR(IFERROR(INDEX($G$38:$G$43,MATCH(H26,$C$38:$C$43,0))="",FALSE()),IFERROR(INDEX($G$38:$G$43,MATCH(I26,$C$38:$C$43,0))="",FALSE())),"Alternativa sem operador","OK"))))))))
... B33: 20 | F33: =IF(OR(E33="",$D$7=""),"",$D$7+SUM($E$14:E32)/1440) | M33: =IF(D33="","",IFERROR(VLOOKUP(D33,Referência!$B$6:$D$16,2,FALSE())&", "&VLOOKUP(D33,Referência!$B$6:$D$16,3,FALSE()),"")) | N33: =IF(AND(C33="",G33=""),"",IF(E33="","Informe a duração",IF(G33="","Defina a fonte principal",IF(AND(OR(G33="Mídia",G33="Vinheta"),L33=""),"Defina o áudio da mídia",IF(OR(AND(H33<>"",H33=G33),AND(I33<>"",I33=G33),AND(H33<>"",H33=I33)),"Alternativa repetida",IF(AND(H33="",I33="",E33>$L$4),"Sem alternativa",IF(IFERROR(INDEX($G$38:$G$43,MATCH(G33,$C$38:$C$43,0))="",FALSE()),"Câmera sem operador",IF(OR(IFERROR(INDEX($G$38:$G$43,MATCH(H33,$C$38:$C$43,0))="",FALSE()),IFERROR(INDEX($G$38:$G$43,MATCH(I33,$C$38:$C$43,0))="",FALSE())),"Alternativa sem operador","OK"))))))))
B35: Câmeras e gravação
B36: # | C36: Câmera ou gravador | D36: Posição | E36: Plano de base | G36: Operador | H36: Grava? | I36: Taxa | J36: Espaço livre | K36: Minutos como principal | L36: % do tempo | M36: Espaço necessário | N36: Gravação | O36: Uso no roteiro
D37: onde fica | E37: quadro quando livre | G37: nome | H37: Sim / Não | I37: Mbps | J37: GB | K37: min | M37: GB, com a margem
B38: 1 | C38: Câmera 1 | K38: =IF(SUM($E$14:$E$33)=0,"",SUMIF($G$14:$G$33,C38,$E$14:$E$33)) | L38: =IF(K38="","",K38/SUM($E$14:$E$33)) | M38: =IF(OR(H38<>"Sim",I38="",SUM($E$14:$E$33)=0),"",ROUND(I38*(SUM($E$14:$E$33)+$L$5)*60/8/1000,1)) | N38: =IF(H38<>"Sim","",IF(OR(I38="",J38=""),"Informe taxa e espaço",IF(M38="","",IF(M38>J38,"Falta espaço","OK")))) | O38: =IF(COUNTIF($G$14:$I$33,C38)=0,"",IF(G38="","Em uso sem operador",IF(AND(L38<>"",L38>$L$6),"Concentrada: combine plano B","OK")))
B39: 2 | C39: Câmera 2 | K39: =IF(SUM($E$14:$E$33)=0,"",SUMIF($G$14:$G$33,C39,$E$14:$E$33)) | L39: =IF(K39="","",K39/SUM($E$14:$E$33)) | M39: =IF(OR(H39<>"Sim",I39="",SUM($E$14:$E$33)=0),"",ROUND(I39*(SUM($E$14:$E$33)+$L$5)*60/8/1000,1)) | N39: =IF(H39<>"Sim","",IF(OR(I39="",J39=""),"Informe taxa e espaço",IF(M39="","",IF(M39>J39,"Falta espaço","OK")))) | O39: =IF(COUNTIF($G$14:$I$33,C39)=0,"",IF(G39="","Em uso sem operador",IF(AND(L39<>"",L39>$L$6),"Concentrada: combine plano B","OK")))
B40: 3 | C40: Câmera 3 | K40: =IF(SUM($E$14:$E$33)=0,"",SUMIF($G$14:$G$33,C40,$E$14:$E$33)) | L40: =IF(K40="","",K40/SUM($E$14:$E$33)) | M40: =IF(OR(H40<>"Sim",I40="",SUM($E$14:$E$33)=0),"",ROUND(I40*(SUM($E$14:$E$33)+$L$5)*60/8/1000,1)) | N40: =IF(H40<>"Sim","",IF(OR(I40="",J40=""),"Informe taxa e espaço",IF(M40="","",IF(M40>J40,"Falta espaço","OK")))) | O40: =IF(COUNTIF($G$14:$I$33,C40)=0,"",IF(G40="","Em uso sem operador",IF(AND(L40<>"",L40>$L$6),"Concentrada: combine plano B","OK")))
B41: 4 | C41: Câmera 4 | K41: =IF(SUM($E$14:$E$33)=0,"",SUMIF($G$14:$G$33,C41,$E$14:$E$33)) | L41: =IF(K41="","",K41/SUM($E$14:$E$33)) | M41: =IF(OR(H41<>"Sim",I41="",SUM($E$14:$E$33)=0),"",ROUND(I41*(SUM($E$14:$E$33)+$L$5)*60/8/1000,1)) | N41: =IF(H41<>"Sim","",IF(OR(I41="",J41=""),"Informe taxa e espaço",IF(M41="","",IF(M41>J41,"Falta espaço","OK")))) | O41: =IF(COUNTIF($G$14:$I$33,C41)=0,"",IF(G41="","Em uso sem operador",IF(AND(L41<>"",L41>$L$6),"Concentrada: combine plano B","OK")))
B42: 5 | C42: Câmera 5 | K42: =IF(SUM($E$14:$E$33)=0,"",SUMIF($G$14:$G$33,C42,$E$14:$E$33)) | L42: =IF(K42="","",K42/SUM($E$14:$E$33)) | M42: =IF(OR(H42<>"Sim",I42="",SUM($E$14:$E$33)=0),"",ROUND(I42*(SUM($E$14:$E$33)+$L$5)*60/8/1000,1)) | N42: =IF(H42<>"Sim","",IF(OR(I42="",J42=""),"Informe taxa e espaço",IF(M42="","",IF(M42>J42,"Falta espaço","OK")))) | O42: =IF(COUNTIF($G$14:$I$33,C42)=0,"",IF(G42="","Em uso sem operador",IF(AND(L42<>"",L42>$L$6),"Concentrada: combine plano B","OK")))
B43: 6 | C43: Câmera 6 | K43: =IF(SUM($E$14:$E$33)=0,"",SUMIF($G$14:$G$33,C43,$E$14:$E$33)) | L43: =IF(K43="","",K43/SUM($E$14:$E$33)) | M43: =IF(OR(H43<>"Sim",I43="",SUM($E$14:$E$33)=0),"",ROUND(I43*(SUM($E$14:$E$33)+$L$5)*60/8/1000,1)) | N43: =IF(H43<>"Sim","",IF(OR(I43="",J43=""),"Informe taxa e espaço",IF(M43="","",IF(M43>J43,"Falta espaço","OK")))) | O43: =IF(COUNTIF($G$14:$I$33,C43)=0,"",IF(G43="","Em uso sem operador",IF(AND(L43<>"",L43>$L$6),"Concentrada: combine plano B","OK")))
B44: 7 | C44: Programa (PGM) | E44: – | G44: – | K44: – | L44: – | M44: =IF(OR(H44<>"Sim",I44="",SUM($E$14:$E$33)=0),"",ROUND(I44*(SUM($E$14:$E$33)+$L$5)*60/8/1000,1)) | N44: =IF(H44<>"Sim","",IF(OR(I44="",J44=""),"Informe taxa e espaço",IF(M44="","",IF(M44>J44,"Falta espaço","OK")))) | O44: –
B45: 8 | C45: Programa limpo | E45: – | G45: – | K45: – | L45: – | M45: =IF(OR(H45<>"Sim",I45="",SUM($E$14:$E$33)=0),"",ROUND(I45*(SUM($E$14:$E$33)+$L$5)*60/8/1000,1)) | N45: =IF(H45<>"Sim","",IF(OR(I45="",J45=""),"Informe taxa e espaço",IF(M45="","",IF(M45>J45,"Falta espaço","OK")))) | O45: –
B47: Resumo automático
B48: Momentos registrados | G48: =COUNTA(C14:C33) -> 0
B49: Duração total (min) | G49: =SUM($E$14:$E$33) -> 0
B50: Hora de término | G50: =IF(OR($D$7="",SUM($E$14:$E$33)=0),"",$D$7+SUM($E$14:$E$33)/1440)
...

Sheet Equipe
B1: Equipe — escala e linguagem de comando
B2: Preencha as células em amarelo-claro. A situação de cada linha e o aviso são calculados.
B4: Evento | G4: Em equipe pequena, uma pessoa pode ter duas funções: registre as duas linhas com o mesmo nome.
B5: Data
B6: Diretor de imagem | G6: Diretor, corte e câmeras precisam de intercom. Sem intercom, combine sinais e planos de base fixos.
B7: Hora de chegada da equipe
B9: Escala da equipe
B10: # | C10: Função | D10: Nome | E10: Posto | F10: Intercom | G10: Substituto | H10: Chegada | I10: Situação | J10: Observação
C11: da lista | E11: onde fica | F11: Sim / Não | G11: quem cobre | H11: hh:mm | I11: calculada
B12: Ex. | C12: Câmera 2 | D12: Voluntário B | E12: Fundo, à esquerda | F12: Sim | G12: Voluntário D | H12: 17:30 | I12: OK | J12: Plano de base: médio do púlpito
B13: 1 | I13: =IF(C13="","",IF(D13="","Sem nome",IF(AND(OR(C13="Diretor de imagem",C13="Operador de corte",C13="Câmera 1",C13="Câmera 2",C13="Câmera 3",C13="Câmera 4",C13="Câmera 5",C13="Câmera 6"),F13<>"Sim"),"Sem intercom",IF(G13="","Sem substituto","OK"))))
B14: 2 | I14: =IF(C14="","",IF(D14="","Sem nome",IF(AND(OR(C14="Diretor de imagem",C14="Operador de corte",C14="Câmera 1",C14="Câmera 2",C14="Câmera 3",C14="Câmera 4",C14="Câmera 5",C14="Câmera 6"),F14<>"Sim"),"Sem intercom",IF(G14="","Sem substituto","OK"))))
B15: 3 | I15: =IF(C15="","",IF(D15="","Sem nome",IF(AND(OR(C15="Diretor de imagem",C15="Operador de corte",C15="Câmera 1",C15="Câmera 2",C15="Câmera 3",C15="Câmera 4",C15="Câmera 5",C15="Câmera 6"),F15<>"Sim"),"Sem intercom",IF(G15="","Sem substituto","OK"))))
B16: 4 | I16: =IF(C16="","",IF(D16="","Sem nome",IF(AND(OR(C16="Diretor de imagem",C16="Operador de corte",C16="Câmera 1",C16="Câmera 2",C16="Câmera 3",C16="Câmera 4",C16="Câmera 5",C16="Câmera 6"),F16<>"Sim"),"Sem intercom",IF(G16="","Sem substituto","OK"))))
B17: 5 | I17: =IF(C17="","",IF(D17="","Sem nome",IF(AND(OR(C17="Diretor de imagem",C17="Operador de corte",C17="Câmera 1",C17="Câmera 2",C17="Câmera 3",C17="Câmera 4",C17="Câmera 5",C17="Câmera 6"),F17<>"Sim"),"Sem intercom",IF(G17="","Sem substituto","OK"))))
B18: 6 | I18: =IF(C18="","",IF(D18="","Sem nome",IF(AND(OR(C18="Diretor de imagem",C18="Operador de corte",C18="Câmera 1",C18="Câmera 2",C18="Câmera 3",C18="Câmera 4",C18="Câmera 5",C18="Câmera 6"),F18<>"Sim"),"Sem intercom",IF(G18="","Sem substituto","OK"))))
B19: 7 | I19: =IF(C19="","",IF(D19="","Sem nome",IF(AND(OR(C19="Diretor de imagem",C19="Operador de corte",C19="Câmera 1",C19="Câmera 2",C19="Câmera 3",C19="Câmera 4",C19="Câmera 5",C19="Câmera 6"),F19<>"Sim"),"Sem intercom",IF(G19="","Sem substituto","OK"))))
B20: 8 | I20: =IF(C20="","",IF(D20="","Sem nome",IF(AND(OR(C20="Diretor de imagem",C20="Operador de corte",C20="Câmera 1",C20="Câmera 2",C20="Câmera 3",C20="Câmera 4",C20="Câmera 5",C20="Câmera 6"),F20<>"Sim"),"Sem intercom",IF(G20="","Sem substituto","OK"))))
B21: 9 | I21: =IF(C21="","",IF(D21="","Sem nome",IF(AND(OR(C21="Diretor de imagem",C21="Operador de corte",C21="Câmera 1",C21="Câmera 2",C21="Câmera 3",C21="Câmera 4",C21="Câmera 5",C21="Câmera 6"),F21<>"Sim"),"Sem intercom",IF(G21="","Sem substituto","OK"))))
B22: 10 | I22: =IF(C22="","",IF(D22="","Sem nome",IF(AND(OR(C22="Diretor de imagem",C22="Operador de corte",C22="Câmera 1",C22="Câmera 2",C22="Câmera 3",C22="Câmera 4",C22="Câmera 5",C22="Câmera 6"),F22<>"Sim"),"Sem intercom",IF(G22="","Sem substituto","OK"))))
B23: 11 | I23: =IF(C23="","",IF(D23="","Sem nome",IF(AND(OR(C23="Diretor de imagem",C23="Operador de corte",C23="Câmera 1",C23="Câmera 2",C23="Câmera 3",C23="Câmera 4",C23="Câmera 5",C23="Câmera 6"),F23<>"Sim"),"Sem intercom",IF(G23="","Sem substituto","OK"))))
B24: 12 | I24: =IF(C24="","",IF(D24="","Sem nome",IF(AND(OR(C24="Diretor de imagem",C24="Operador de corte",C24="Câmera 1",C24="Câmera 2",C24="Câmera 3",C24="Câmera 4",C24="Câmera 5",C24="Câmera 6"),F24<>"Sim"),"Sem intercom",IF(G24="","Sem substituto","OK"))))
... B26: 14 | I26: =IF(C26="","",IF(D26="","Sem nome",IF(AND(OR(C26="Diretor de imagem",C26="Operador de corte",C26="Câmera 1",C26="Câmera 2",C26="Câmera 3",C26="Câmera 4",C26="Câmera 5",C26="Câmera 6"),F26<>"Sim"),"Sem intercom",IF(G26="","Sem substituto","OK"))))
B28: Resumo automático
B29: Funções na escala | F29: =COUNTA(C13:C26) -> 0
B30: Diretor de imagem | F30: =COUNTIF(C13:C26,"Diretor de imagem") -> 0
B31: Operador de corte | F31: =COUNTIF(C13:C26,"Operador de corte") -> 0
B32: Câmeras com operador | F32: =COUNTIF(C13:C26,"Câmera 1")+COUNTIF(C13:C26,"Câmera 2")+COUNTIF(C13:C26,"Câmera 3")+COUNTIF(C13:C26,"Câmera 4")+COUNTIF(C13:C26,"Câmera 5")+COUNTIF(C13:C26,"Câmera 6") -> 0
B33: Linhas sem nome ou sem intercom | F33: =COUNTIF(I13:I26,"Sem nome")+COUNTIF(I13:I26,"Sem intercom") -> 0
B34: Linhas sem substituto | F34: =COUNTIF(I13:I26,"Sem substituto") -> 0
B35: Aviso | F35: =IF(F29=0,"Preencha a escala",IF(F30=0,"Falta o diretor de imagem",IF(F31=0,"Falta o operador de corte: se o diretor corta, registre as duas funções",IF(F32=0,"Nenhuma câmera com operador",IF(F33>0,"Há linha sem nome ou sem intercom",IF(F34>0,"OK, mas há funções sem substituto","OK")))))) -> Preencha a escala
B37: Palavras de comando combinadas
B38: Ação | D38: Preparo | E38: Execução | G38: Observação
B39: Corte seco | D39: Prepara 2. | E39: Corta. | G39: Sempre o número da câmera, nunca o nome da pessoa.
B40: Fusão | D40: Prepara fusão para a 1. | E40: Funde. | G40: Avise que é fusão já no preparo.
B41: Legenda ou letra | D41: Prepara legenda do pastor. | E41: Entra legenda. | G41: Todo “entra” tem um “sai legenda”.
B42: Vídeo | D42: Prepara vídeo de avisos. | E42: Roda vídeo. | G42: A mídia responde “vídeo pronto” e avisa “dez segundos”.
B43: Pedido de plano | D43: 3, congregação, plano aberto. | E43: – | G43: A câmera só se move se estiver livre.
B44: Sem tally | D44: – | E44: 2 no ar. / 2, liberada. | G44: O diretor avisa quem entrou e quem saiu do ar.
B45: Abertura e fim | D45: Prepara abertura. | E45: Sai do preto. / Vai a preto. | G45: Combine se o FTB começa ativo.
...

Sheet Registro de erros
B1: Registro de erros — para a reunião de revisão
B2: Anote cada erro com a hora em que apareceu na gravação. A situação de cada linha e o resumo são calculados.
B4: Evento | I4: Assista à gravação do programa com a equipe. Para cada erro, uma linha.
B5: Data do evento | I5: A causa diz onde agir: Comando e Roteiro são da direção; Operação e Treinamento, de quem opera; Equipamento, da manutenção.
B6: Diretor de imagem
B7: Revisão feita em | I7: O objetivo é corrigir o processo, e não achar culpados.
B9: Erros vistos na revisão
B10: # | C10: Hora | D10: Momento | E10: Tipo | F10: Fonte | G10: Causa | H10: Gravidade | I10: O que aconteceu | J10: Ação para o próximo evento | K10: Responsável | L10: Ação feita? | M10: Situação
C11: hh:mm | D11: do roteiro | E11: da lista | F11: da lista | G11: da lista | H11: da lista | L11: Sim / Não | M11: calculada
B12: Ex. | C12: 19:31 | D12: Avisos em vídeo | E12: Tela preta ou buraco | F12: Mídia | G12: Roteiro | H12: Alta | I12: Tela preta por 6 s no fim do vídeo | J12: Câmera geral no preview durante todo vídeo | K12: Diretor | L12: Sim | M12: OK
B13: 1 | M13: =IF(E13="","",IF(J13="","Defina a ação",IF(L13="Sim","OK","Em aberto")))
B14: 2 | M14: =IF(E14="","",IF(J14="","Defina a ação",IF(L14="Sim","OK","Em aberto")))
B15: 3 | M15: =IF(E15="","",IF(J15="","Defina a ação",IF(L15="Sim","OK","Em aberto")))
B16: 4 | M16: =IF(E16="","",IF(J16="","Defina a ação",IF(L16="Sim","OK","Em aberto")))
B17: 5 | M17: =IF(E17="","",IF(J17="","Defina a ação",IF(L17="Sim","OK","Em aberto")))
B18: 6 | M18: =IF(E18="","",IF(J18="","Defina a ação",IF(L18="Sim","OK","Em aberto")))
B19: 7 | M19: =IF(E19="","",IF(J19="","Defina a ação",IF(L19="Sim","OK","Em aberto")))
B20: 8 | M20: =IF(E20="","",IF(J20="","Defina a ação",IF(L20="Sim","OK","Em aberto")))
B21: 9 | M21: =IF(E21="","",IF(J21="","Defina a ação",IF(L21="Sim","OK","Em aberto")))
B22: 10 | M22: =IF(E22="","",IF(J22="","Defina a ação",IF(L22="Sim","OK","Em aberto")))
B23: 11 | M23: =IF(E23="","",IF(J23="","Defina a ação",IF(L23="Sim","OK","Em aberto")))
B24: 12 | M24: =IF(E24="","",IF(J24="","Defina a ação",IF(L24="Sim","OK","Em aberto")))
... B42: 30 | M42: =IF(E42="","",IF(J42="","Defina a ação",IF(L42="Sim","OK","Em aberto")))
B44: Resumo por tipo e por causa
B45: Tipo de erro | F45: Vezes | H45: Causa | J45: Vezes
B46: Corte atrasado | F46: =COUNTIF($E$13:$E$42,B46) -> 0 | H46: Comando | J46: =COUNTIF($G$13:$G$42,H46) -> 0
B47: Corte sem motivo | F47: =COUNTIF($E$13:$E$42,B47) -> 0 | H47: Roteiro | J47: =COUNTIF($G$13:$G$42,H47) -> 0
B48: Câmera mexendo no ar | F48: =COUNTIF($E$13:$E$42,B48) -> 0 | H48: Operação | J48: =COUNTIF($G$13:$G$42,H48) -> 0
B49: Salto | F49: =COUNTIF($E$13:$E$42,B49) -> 0 | H49: Equipamento | J49: =COUNTIF($G$13:$G$42,H49) -> 0
B50: Eixo cruzado | F50: =COUNTIF($E$13:$E$42,B50) -> 0 | H50: Treinamento | J50: =COUNTIF($G$13:$G$42,H50) -> 0
B51: Gráfico esquecido | F51: =COUNTIF($E$13:$E$42,B51) -> 0 | H51: Comunicação | J51: =COUNTIF($G$13:$G$42,H51) -> 0
B52: Gráfico errado | F52: =COUNTIF($E$13:$E$42,B52) -> 0
B53: Mídia sem som | F53: =COUNTIF($E$13:$E$42,B53) -> 0 | H53: Erros registrados | J53: =COUNTA(E13:E42) -> 0
B54: Tela preta ou buraco | F54: =COUNTIF($E$13:$E$42,B54) -> 0 | H54: Tipo mais frequente | J54: =IF(MAX(F46:F56)=0,"",INDEX(B46:B56,MATCH(MAX(F46:F56),F46:F56,0)))
B55: Fonte com defeito | F55: =COUNTIF($E$13:$E$42,B55) -> 0 | H55: Causa mais frequente | J55: =IF(MAX(J46:J51)=0,"",INDEX(H46:H51,MATCH(MAX(J46:J51),J46:J51,0)))
B56: Comunicação | F56: =COUNTIF($E$13:$E$42,B56) -> 0 | H56: Erros de gravidade alta | J56: =COUNTIF(H13:H42,"Alta") -> 0
H57: Ações em aberto ou sem definição | J57: =COUNTIF(M13:M42,"Em aberto")+COUNTIF(M13:M42,"Defina a ação") -> 0
H58: Aviso | J58: =IF(J53=0,"Nenhum erro registrado",IF(J57>0,"Há ações a definir ou a fazer antes do próximo evento","OK")) -> Nenhum erro registrado

Sheet Referência
B1: Referência — corte ao vivo
B2: Valores de referência, para servir de ponto de partida. Confira o manual do seu equipamento.
B4: Ritmo por tipo de momento
B5: Tipo de momento | C5: Duração de cada plano | D5: Transição | E5: Observação
B6: Abertura | C6: plano geral, 5 a 10 s | D6: Do preto ou fusão | E6: Logo ou vinheta, se houver. Situe quem chega à transmissão.
B7: Louvor rápido | C7: 3 a 6 s por plano | D7: Corte seco | E7: Corte no tempo forte, nas viradas das frases. Cortes fora do tempo cansam.
B8: Louvor lento | C8: 6 a 12 s por plano | D8: Fusão de 0,5 a 1 s | E8: Movimentos lentos de câmera no ar, se combinados.
B9: Oração | C9: plano longo | D9: Fusão | E9: Plano aberto e estável. Sem gráfico. Evite closes de quem ora.
B10: Leitura | C10: 10 a 30 s por plano | D10: Corte seco | E10: Texto ou referência como gráfico, sem cobrir o rosto.
B11: Pregação | C11: 20 a 60 s ou mais | D11: Corte seco | E11: Saídas de 3 a 6 s para o geral e a reação. Não corte no meio da frase.
B12: Avisos | C12: 10 a 30 s por plano | D12: Corte seco | E12: Nome e função de quem fala na legenda.
B13: Mídia | C13: o vídeo inteiro | D13: Corte seco | E13: Câmera geral no preview até o fim. Aviso de dez segundos.
B14: Oferta ou ceia | C14: 6 a 12 s por plano | D14: Fusão lenta | E14: Detalhe das mãos e dos elementos. Combine até onde chegar perto.
B15: Entrevista | C15: 5 a 15 s por plano | D15: Corte seco | E15: Corte para quem vai falar, um instante antes. Câmeras do mesmo lado do eixo.
B16: Encerramento | C16: plano geral | D16: Para o preto, 1 a 2 s | E16: Tela final, se houver. Pare as gravações depois do preto.
B18: Transições
B19: Transição | C19: O que faz | D19: Tempo para começar | E19: Quando usar
B20: Corte seco (cut) | C20: troca na hora | D20: instantâneo | E20: O padrão: fala, música com andamento, entrevista, reação.
B21: Fusão (mix) | C21: uma imagem some e a outra aparece | D21: 0,5 a 1 s entre câmeras; até 2 s entre momentos | E21: Música lenta, oração, passagem de um momento para outro.
B22: Fade para preto (FTB) | C22: escurece tudo, inclusive os gráficos | D22: 1 a 2 s | E22: Só no começo e no fim. O botão pisca enquanto está ativo.
B23: Cortina (wipe) e efeitos | C23: uma imagem empurra ou cobre a outra | D23: – | E23: Quase nunca. Só em vinheta combinada.
B25: Linguagem de comando
B26: Ação | C26: Preparo | D26: Execução | E26: Cuidado
B27: Corte seco | C27: Prepara 2. | D27: Corta. | E27: Sempre o número da câmera, nunca o nome da pessoa.
B28: Fusão | C28: Prepara fusão para a 1. | D28: Funde. | E28: Avise que é fusão já no preparo.
B29: Legenda ou letra | C29: Prepara legenda do pastor. | D29: Entra legenda. | E29: Todo “entra” tem um “sai legenda”.
B30: Vídeo | C30: Prepara vídeo de avisos. | D30: Roda vídeo. | E30: A mídia responde “vídeo pronto” e avisa “dez segundos”.
B31: Pedido de plano | C31: 3, congregação, plano aberto. | D31: – | E31: A câmera só se move se estiver livre.
B32: Sem tally | C32: – | D32: 2 no ar. / 2, liberada. | E32: O diretor avisa quem entrou e quem saiu do ar.
B33: Abertura e fim | C33: Prepara abertura. | D33: Sai do preto. / Vai a preto. | E33: Combine se o FTB começa ativo.
B35: Tally e janelas do multiview
B36: Cor | C36: Significa | D36: Operador de câmera | E36: Observação
B37: Vermelho | C37: no ar (program) | D37: segura o quadro | E37: Só se move para acompanhar a pessoa, com suavidade, ou a pedido do diretor.
B38: Verde | C38: próxima (preview) | D38: termina o ajuste e segura | E38: O corte pode vir a qualquer instante.
B39: Apagado | C39: livre | D39: volta ao plano de base | E39: Hora de acertar foco e quadro, ou de buscar o plano pedido.
B41: Taxas de gravação e espaço
B42: Formato | C42: Taxa típica | D42: Espaço por hora | E42: Observação
B43: 1080p comprimido, qualidade padrão | C43: 10 a 25 Mbps | D43: 4,5 a 11 GB | E43: Comum em celulares e em gravadores de switcher.
B44: 1080p comprimido, qualidade alta | C44: 25 a 50 Mbps | D44: 11 a 23 GB | E44: Comum em câmeras de vídeo e fotográficas.
B45: 4K comprimido | C45: 50 a 150 Mbps | D45: 23 a 68 GB | E45: Arquivos grandes. Confira o tempo máximo de gravação da câmera.
...

Sheet Checklist
B1: Checklist do corte ao vivo
B2: Confira antes de o evento começar; o último item fica para o fim. Escolha a situação de cada item na lista suspensa.
B4: # | C4: Grupo | D4: Item | E4: Situação | F4: Observação
B5: 1 | C5: Preparação | D5: O roteiro de corte está pronto, com fonte principal e alternativa em cada momento.
B6: 2 | C6: Equipe | D6: Cada função da escala tem um nome, e todos conhecem as palavras de comando.
B7: 3 | C7: Equipe | D7: Cada câmera tem um plano de base, e a câmera geral é o plano de segurança.
B8: 4 | C8: Sistema | D8: Todas as fontes aparecem no multiview, no formato do sistema e com o nome certo.
B9: 5 | C9: Sistema | D9: As câmeras foram igualadas em exposição e em cor, com a luz do evento.
B10: 6 | C10: Sistema | D10: O tally e o intercom foram testados com cada operador de câmera.
B11: 7 | C11: Gráficos e mídia | D11: As legendas, as letras e os vídeos foram testados no preview, com a grafia dos nomes conferida.
B12: 8 | C12: Gráficos e mídia | D12: O som de cada vídeo foi combinado com o operador de áudio.
B13: 9 | C13: Switcher | D13: O tempo da fusão está ajustado, e o FTB e o key final começam como combinado.
B14: 10 | C14: Switcher | D14: O telão da sala e a transmissão recebem, cada um, a saída certa.
B15: 11 | C15: Gravação | D15: As gravações foram iniciadas, com espaço conferido, e os contadores estão andando.
B16: 12 | C16: Revisão | D16: Os erros do evento foram anotados com a hora, para a reunião de revisão.
B18: Itens respondidos | E18: =COUNTA(E5:E16) -> 0
B19: Percentual atendido (Parcial vale metade) | E19: =IF(COUNTA(E5:E16)=0,"",(COUNTIF(E5:E16,"Sim")+COUNTIF(E5:E16,"Parcial")/2)/COUNTA(E5:E16))
B20: Situação | E20: =IF(COUNTA(E5:E16)<12,"Incompleto",IF(COUNTIF(E5:E16,"Não")=0,"OK","Há itens a resolver")) -> Incompleto

Sheet Exemplo - Roteiro
B1: Roteiro de corte — momento a momento
B2: Exemplo preenchido (exemplo 1 do treinamento), para consulta. Use a aba Roteiro de corte para o seu evento.
B4: Evento | D4: Culto de domingo | I4: Momento sem alternativa: alerta acima de (min) | L4: 5 | M4: Regra prática deste material. Momento curto pode ficar só na câmera geral.
B5: Local | D5: Igreja de 200 lugares | I5: Margem de gravação (min) | L5: 30 | M5: Tempo a mais que cada gravador deve suportar, além do roteiro.
B6: Data | D6: 46299 | I6: Concentração numa câmera: alerta acima de | L6: 0.6 | M6: Parcela do tempo como principal. Acima dela, combine um plano B.
B7: Hora de início | D7: 0.79166667 | I7: A hora de cada momento é calculada a partir da hora de início e das durações.
B8: Diretor de imagem | D8: Diretor de imagem da escala | I8: Fontes: Câmera 1 a 6, Mídia, Slides, Letras ou Vinheta. A pendência some quando a linha está resolvida.
B10: Roteiro de corte, na ordem do evento
B11: # | C11: Momento | D11: Tipo | E11: Duração | F11: Início | G11: Fonte principal | H11: Alternativa 1 | I11: Alternativa 2 | J11: Gráfico | K11: Transição de entrada | L11: Áudio da mídia | M11: Ritmo sugerido | N11: Pendência | O11: Observação
C12: o que acontece no palco | D12: da lista | E12: min | F12: calculado | G12: da lista | H12: da lista | I12: da lista | J12: legenda, letra, texto | K12: da lista | L12: Sim / Não | M12: da aba Referência | N12: calculada
B13: Roteiro como estava na quinta-feira, antes das correções. As colunas F, M e N são calculadas.
B14: 1 | C14: Abertura e acolhida | D14: Abertura | E14: 3 | F14: =IF(OR(E14="",$D$7=""),"",$D$7) -> 0.79166667 | G14: Câmera 1 | H14: Câmera 3 | J14: Logo da igreja | K14: Do preto | M14: =IF(D14="","",IFERROR(VLOOKUP(D14,Referência!$B$6:$D$16,2,FALSE())&", "&VLOOKUP(D14,Referência!$B$6:$D$16,3,FALSE()),"")) -> plano geral, 5 a 10 s, Do preto ou fusão | N14: =IF(AND(C14="",G14=""),"",IF(E14="","Informe a duração",IF(G14="","Defina a fonte principal",IF(AND(OR(G14="Mídia",G14="Vinheta"),L14=""),"Defina o áudio da mídia",IF(OR(AND(H14<>"",H14=G14),AND(I14<>"",I14=G14),AND(H14<>"",H14=I14)),"Alternativa repetida",IF(AND(H14="",I14="",E14>$L$4),"Sem alternativa",IF(IFERROR(INDEX($G$38:$G$43,MATCH(G14,$C$38:$C$43,0))="",FALSE()),"Câmera sem operador",IF(OR(IFERROR(INDEX($G$38:$G$43,MATCH(H14,$C$38:$C$43,0))="",FALSE()),IFERROR(INDEX($G$38:$G$43,MATCH(I14,$C$38:$C$43,0))="",FALSE())),"Alternativa sem operador","OK")))))))) -> OK
B15: 2 | C15: Louvor | D15: Louvor rápido | E15: 21 | F15: =IF(OR(E15="",$D$7=""),"",$D$7+SUM($E$14:E14)/1440) -> 0.79375 | G15: Câmera 2 | H15: Câmera 1 | I15: Câmera 3 | J15: Letra | K15: Fusão | M15: =IF(D15="","",IFERROR(VLOOKUP(D15,Referência!$B$6:$D$16,2,FALSE())&", "&VLOOKUP(D15,Referência!$B$6:$D$16,3,FALSE()),"")) -> 3 a 6 s por plano, Corte seco | N15: =IF(AND(C15="",G15=""),"",IF(E15="","Informe a duração",IF(G15="","Defina a fonte principal",IF(AND(OR(G15="Mídia",G15="Vinheta"),L15=""),"Defina o áudio da mídia",IF(OR(AND(H15<>"",H15=G15),AND(I15<>"",I15=G15),AND(H15<>"",H15=I15)),"Alternativa repetida",IF(AND(H15="",I15="",E15>$L$4),"Sem alternativa",IF(IFERROR(INDEX($G$38:$G$43,MATCH(G15,$C$38:$C$43,0))="",FALSE()),"Câmera sem operador",IF(OR(IFERROR(INDEX($G$38:$G$43,MATCH(H15,$C$38:$C$43,0))="",FALSE()),IFERROR(INDEX($G$38:$G$43,MATCH(I15,$C$38:$C$43,0))="",FALSE())),"Alternativa sem operador","OK")))))))) -> OK
B16: 3 | C16: Oração | D16: Oração | E16: 3 | F16: =IF(OR(E16="",$D$7=""),"",$D$7+SUM($E$14:E15)/1440) -> 0.80833333 | G16: Câmera 1 | H16: Câmera 3 | K16: Fusão | M16: =IF(D16="","",IFERROR(VLOOKUP(D16,Referência!$B$6:$D$16,2,FALSE())&", "&VLOOKUP(D16,Referência!$B$6:$D$16,3,FALSE()),"")) -> plano longo, Fusão | N16: =IF(AND(C16="",G16=""),"",IF(E16="","Informe a duração",IF(G16="","Defina a fonte principal",IF(AND(OR(G16="Mídia",G16="Vinheta"),L16=""),"Defina o áudio da mídia",IF(OR(AND(H16<>"",H16=G16),AND(I16<>"",I16=G16),AND(H16<>"",H16=I16)),"Alternativa repetida",IF(AND(H16="",I16="",E16>$L$4),"Sem alternativa",IF(IFERROR(INDEX($G$38:$G$43,MATCH(G16,$C$38:$C$43,0))="",FALSE()),"Câmera sem operador",IF(OR(IFERROR(INDEX($G$38:$G$43,MATCH(H16,$C$38:$C$43,0))="",FALSE()),IFERROR(INDEX($G$38:$G$43,MATCH(I16,$C$38:$C$43,0))="",FALSE())),"Alternativa sem operador","OK")))))))) -> OK
B17: 4 | C17: Avisos em vídeo | D17: Mídia | E17: 4 | F17: =IF(OR(E17="",$D$7=""),"",$D$7+SUM($E$14:E16)/1440) -> 0.81041667 | G17: Mídia | H17: Câmera 1 | K17: Corte seco | M17: =IF(D17="","",IFERROR(VLOOKUP(D17,Referência!$B$6:$D$16,2,FALSE())&", "&VLOOKUP(D17,Referência!$B$6:$D$16,3,FALSE()),"")) -> o vídeo inteiro, Corte seco | N17: =IF(AND(C17="",G17=""),"",IF(E17="","Informe a duração",IF(G17="","Defina a fonte principal",IF(AND(OR(G17="Mídia",G17="Vinheta"),L17=""),"Defina o áudio da mídia",IF(OR(AND(H17<>"",H17=G17),AND(I17<>"",I17=G17),AND(H17<>"",H17=I17)),"Alternativa repetida",IF(AND(H17="",I17="",E17>$L$4),"Sem alternativa",IF(IFERROR(INDEX($G$38:$G$43,MATCH(G17,$C$38:$C$43,0))="",FALSE()),"Câmera sem operador",IF(OR(IFERROR(INDEX($G$38:$G$43,MATCH(H17,$C$38:$C$43,0))="",FALSE()),IFERROR(INDEX($G$38:$G$43,MATCH(I17,$C$38:$C$43,0))="",FALSE())),"Alternativa sem operador","OK")))))))) -> Defina o áudio da mídia
B18: 5 | C18: Leitura bíblica | D18: Leitura | E18: 4 | F18: =IF(OR(E18="",$D$7=""),"",$D$7+SUM($E$14:E17)/1440) -> 0.81319444 | G18: Câmera 2 | H18: Câmera 2 | J18: Texto do versículo | K18: Corte seco | M18: =IF(D18="","",IFERROR(VLOOKUP(D18,Referência!$B$6:$D$16,2,FALSE())&", "&VLOOKUP(D18,Referência!$B$6:$D$16,3,FALSE()),"")) -> 10 a 30 s por plano, Corte seco | N18: =IF(AND(C18="",G18=""),"",IF(E18="","Informe a duração",IF(G18="","Defina a fonte principal",IF(AND(OR(G18="Mídia",G18="Vinheta"),L18=""),"Defina o áudio da mídia",IF(OR(AND(H18<>"",H18=G18),AND(I18<>"",I18=G18),AND(H18<>"",H18=I18)),"Alternativa repetida",IF(AND(H18="",I18="",E18>$L$4),"Sem alternativa",IF(IFERROR(INDEX($G$38:$G$43,MATCH(G18,$C$38:$C$43,0))="",FALSE()),"Câmera sem operador",IF(OR(IFERROR(INDEX($G$38:$G$43,MATCH(H18,$C$38:$C$43,0))="",FALSE()),IFERROR(INDEX($G$38:$G$43,MATCH(I18,$C$38:$C$43,0))="",FALSE())),"Alternativa sem operador","OK")))))))) -> Alternativa repetida
B19: 6 | C19: Pregação | D19: Pregação | E19: 40 | F19: =IF(OR(E19="",$D$7=""),"",$D$7+SUM($E$14:E18)/1440) -> 0.81597222 | G19: Câmera 2 | J19: Nome do pastor e versículos | K19: Corte seco | M19: =IF(D19="","",IFERROR(VLOOKUP(D19,Referência!$B$6:$D$16,2,FALSE())&", "&VLOOKUP(D19,Referência!$B$6:$D$16,3,FALSE()),"")) -> 20 a 60 s ou mais, Corte seco | N19: =IF(AND(C19="",G19=""),"",IF(E19="","Informe a duração",IF(G19="","Defina a fonte principal",IF(AND(OR(G19="Mídia",G19="Vinheta"),L19=""),"Defina o áudio da mídia",IF(OR(AND(H19<>"",H19=G19),AND(I19<>"",I19=G19),AND(H19<>"",H19=I19)),"Alternativa repetida",IF(AND(H19="",I19="",E19>$L$4),"Sem alternativa",IF(IFERROR(INDEX($G$38:$G$43,MATCH(G19,$C$38:$C$43,0))="",FALSE()),"Câmera sem operador",IF(OR(IFERROR(INDEX($G$38:$G$43,MATCH(H19,$C$38:$C$43,0))="",FALSE()),IFERROR(INDEX($G$38:$G$43,MATCH(I19,$C$38:$C$43,0))="",FALSE())),"Alternativa sem operador","OK")))))))) -> Sem alternativa
B20: 7 | C20: Oferta | D20: Oferta ou ceia | E20: 2 | F20: =IF(OR(E20="",$D$7=""),"",$D$7+SUM($E$14:E19)/1440) -> 0.84375 | G20: Câmera 3 | H20: Câmera 1 | K20: Fusão | M20: =IF(D20="","",IFERROR(VLOOKUP(D20,Referência!$B$6:$D$16,2,FALSE())&", "&VLOOKUP(D20,Referência!$B$6:$D$16,3,FALSE()),"")) -> 6 a 12 s por plano, Fusão lenta | N20: =IF(AND(C20="",G20=""),"",IF(E20="","Informe a duração",IF(G20="","Defina a fonte principal",IF(AND(OR(G20="Mídia",G20="Vinheta"),L20=""),"Defina o áudio da mídia",IF(OR(AND(H20<>"",H20=G20),AND(I20<>"",I20=G20),AND(H20<>"",H20=I20)),"Alternativa repetida",IF(AND(H20="",I20="",E20>$L$4),"Sem alternativa",IF(IFERROR(INDEX($G$38:$G$43,MATCH(G20,$C$38:$C$43,0))="",FALSE()),"Câmera sem operador",IF(OR(IFERROR(INDEX($G$38:$G$43,MATCH(H20,$C$38:$C$43,0))="",FALSE()),IFERROR(INDEX($G$38:$G$43,MATCH(I20,$C$38:$C$43,0))="",FALSE())),"Alternativa sem operador","OK")))))))) -> OK
B21: 8 | C21: Louvor final | D21: Louvor lento | E21: 5 | F21: =IF(OR(E21="",$D$7=""),"",$D$7+SUM($E$14:E20)/1440) -> 0.84513889 | G21: Câmera 4 | H21: Câmera 1 | J21: Letra | K21: Fusão | M21: =IF(D21="","",IFERROR(VLOOKUP(D21,Referência!$B$6:$D$16,2,FALSE())&", "&VLOOKUP(D21,Referência!$B$6:$D$16,3,FALSE()),"")) -> 6 a 12 s por plano, Fusão de 0,5 a 1 s | N21: =IF(AND(C21="",G21=""),"",IF(E21="","Informe a duração",IF(G21="","Defina a fonte principal",IF(AND(OR(G21="Mídia",G21="Vinheta"),L21=""),"Defina o áudio da mídia",IF(OR(AND(H21<>"",H21=G21),AND(I21<>"",I21=G21),AND(H21<>"",H21=I21)),"Alternativa repetida",IF(AND(H21="",I21="",E21>$L$4),"Sem alternativa",IF(IFERROR(INDEX($G$38:$G$43,MATCH(G21,$C$38:$C$43,0))="",FALSE()),"Câmera sem operador",IF(OR(IFERROR(INDEX($G$38:$G$43,MATCH(H21,$C$38:$C$43,0))="",FALSE()),IFERROR(INDEX($G$38:$G$43,MATCH(I21,$C$38:$C$43,0))="",FALSE())),"Alternativa sem operador","OK")))))))) -> Câmera sem operador
B22: 9 | C22: Bênção e encerramento | D22: Encerramento | E22: 2 | F22: =IF(OR(E22="",$D$7=""),"",$D$7+SUM($E$14:E21)/1440) -> 0.84861111 | G22: Câmera 1 | J22: Tela de encerramento | K22: Para o preto | M22: =IF(D22="","",IFERROR(VLOOKUP(D22,Referência!$B$6:$D$16,2,FALSE())&", "&VLOOKUP(D22,Referência!$B$6:$D$16,3,FALSE()),"")) -> plano geral, Para o preto, 1 a 2 s | N22: =IF(AND(C22="",G22=""),"",IF(E22="","Informe a duração",IF(G22="","Defina a fonte principal",IF(AND(OR(G22="Mídia",G22="Vinheta"),L22=""),"Defina o áudio da mídia",IF(OR(AND(H22<>"",H22=G22),AND(I22<>"",I22=G22),AND(H22<>"",H22=I22)),"Alternativa repetida",IF(AND(H22="",I22="",E22>$L$4),"Sem alternativa",IF(IFERROR(INDEX($G$38:$G$43,MATCH(G22,$C$38:$C$43,0))="",FALSE()),"Câmera sem operador",IF(OR(IFERROR(INDEX($G$38:$G$43,MATCH(H22,$C$38:$C$43,0))="",FALSE()),IFERROR(INDEX($G$38:$G$43,MATCH(I22,$C$38:$C$43,0))="",FALSE())),"Alternativa sem operador","OK")))))))) -> OK
B23: 10 | F23: =IF(OR(E23="",$D$7=""),"",$D$7+SUM($E$14:E22)/1440) | M23: =IF(D23="","",IFERROR(VLOOKUP(D23,Referência!$B$6:$D$16,2,FALSE())&", "&VLOOKUP(D23,Referência!$B$6:$D$16,3,FALSE()),"")) | N23: =IF(AND(C23="",G23=""),"",IF(E23="","Informe a duração",IF(G23="","Defina a fonte principal",IF(AND(OR(G23="Mídia",G23="Vinheta"),L23=""),"Defina o áudio da mídia",IF(OR(AND(H23<>"",H23=G23),AND(I23<>"",I23=G23),AND(H23<>"",H23=I23)),"Alternativa repetida",IF(AND(H23="",I23="",E23>$L$4),"Sem alternativa",IF(IFERROR(INDEX($G$38:$G$43,MATCH(G23,$C$38:$C$43,0))="",FALSE()),"Câmera sem operador",IF(OR(IFERROR(INDEX($G$38:$G$43,MATCH(H23,$C$38:$C$43,0))="",FALSE()),IFERROR(INDEX($G$38:$G$43,MATCH(I23,$C$38:$C$43,0))="",FALSE())),"Alternativa sem operador","OK"))))))))
B24: 11 | F24: =IF(OR(E24="",$D$7=""),"",$D$7+SUM($E$14:E23)/1440) | M24: =IF(D24="","",IFERROR(VLOOKUP(D24,Referência!$B$6:$D$16,2,FALSE())&", "&VLOOKUP(D24,Referência!$B$6:$D$16,3,FALSE()),"")) | N24: =IF(AND(C24="",G24=""),"",IF(E24="","Informe a duração",IF(G24="","Defina a fonte principal",IF(AND(OR(G24="Mídia",G24="Vinheta"),L24=""),"Defina o áudio da mídia",IF(OR(AND(H24<>"",H24=G24),AND(I24<>"",I24=G24),AND(H24<>"",H24=I24)),"Alternativa repetida",IF(AND(H24="",I24="",E24>$L$4),"Sem alternativa",IF(IFERROR(INDEX($G$38:$G$43,MATCH(G24,$C$38:$C$43,0))="",FALSE()),"Câmera sem operador",IF(OR(IFERROR(INDEX($G$38:$G$43,MATCH(H24,$C$38:$C$43,0))="",FALSE()),IFERROR(INDEX($G$38:$G$43,MATCH(I24,$C$38:$C$43,0))="",FALSE())),"Alternativa sem operador","OK"))))))))
B25: 12 | F25: =IF(OR(E25="",$D$7=""),"",$D$7+SUM($E$14:E24)/1440) | M25: =IF(D25="","",IFERROR(VLOOKUP(D25,Referência!$B$6:$D$16,2,FALSE())&", "&VLOOKUP(D25,Referência!$B$6:$D$16,3,FALSE()),"")) | N25: =IF(AND(C25="",G25=""),"",IF(E25="","Informe a duração",IF(G25="","Defina a fonte principal",IF(AND(OR(G25="Mídia",G25="Vinheta"),L25=""),"Defina o áudio da mídia",IF(OR(AND(H25<>"",H25=G25),AND(I25<>"",I25=G25),AND(H25<>"",H25=I25)),"Alternativa repetida",IF(AND(H25="",I25="",E25>$L$4),"Sem alternativa",IF(IFERROR(INDEX($G$38:$G$43,MATCH(G25,$C$38:$C$43,0))="",FALSE()),"Câmera sem operador",IF(OR(IFERROR(INDEX($G$38:$G$43,MATCH(H25,$C$38:$C$43,0))="",FALSE()),IFERROR(INDEX($G$38:$G$43,MATCH(I25,$C$38:$C$43,0))="",FALSE())),"Alternativa sem operador","OK"))))))))
B26: 13 | F26: =IF(OR(E26="",$D$7=""),"",$D$7+SUM($E$14:E25)/1440) | M26: =IF(D26="","",IFERROR(VLOOKUP(D26,Referência!$B$6:$D$16,2,FALSE())&", "&VLOOKUP(D26,Referência!$B$6:$D$16,3,FALSE()),"")) | N26: =IF(AND(C26="",G26=""),"",IF(E26="","Informe a duração",IF(G26="","Defina a fonte principal",IF(AND(OR(G26="Mídia",G26="Vinheta"),L26=""),"Defina o áudio da mídia",IF(OR(AND(H26<>"",H26=G26),AND(I26<>"",I26=G26),AND(H26<>"",H26=I26)),"Alternativa repetida",IF(AND(H26="",I26="",E26>$L$4),"Sem alternativa",IF(IFERROR(INDEX($G$38:$G$43,MATCH(G26,$C$38:$C$43,0))="",FALSE()),"Câmera sem operador",IF(OR(IFERROR(INDEX($G$38:$G$43,MATCH(H26,$C$38:$C$43,0))="",FALSE()),IFERROR(INDEX($G$38:$G$43,MATCH(I26,$C$38:$C$43,0))="",FALSE())),"Alternativa sem operador","OK"))))))))
B27: 14 | F27: =IF(OR(E27="",$D$7=""),"",$D$7+SUM($E$14:E26)/1440) | M27: =IF(D27="","",IFERROR(VLOOKUP(D27,Referência!$B$6:$D$16,2,FALSE())&", "&VLOOKUP(D27,Referência!$B$6:$D$16,3,FALSE()),"")) | N27: =IF(AND(C27="",G27=""),"",IF(E27="","Informe a duração",IF(G27="","Defina a fonte principal",IF(AND(OR(G27="Mídia",G27="Vinheta"),L27=""),"Defina o áudio da mídia",IF(OR(AND(H27<>"",H27=G27),AND(I27<>"",I27=G27),AND(H27<>"",H27=I27)),"Alternativa repetida",IF(AND(H27="",I27="",E27>$L$4),"Sem alternativa",IF(IFERROR(INDEX($G$38:$G$43,MATCH(G27,$C$38:$C$43,0))="",FALSE()),"Câmera sem operador",IF(OR(IFERROR(INDEX($G$38:$G$43,MATCH(H27,$C$38:$C$43,0))="",FALSE()),IFERROR(INDEX($G$38:$G$43,MATCH(I27,$C$38:$C$43,0))="",FALSE())),"Alternativa sem operador","OK"))))))))
B28: 15 | F28: =IF(OR(E28="",$D$7=""),"",$D$7+SUM($E$14:E27)/1440) | M28: =IF(D28="","",IFERROR(VLOOKUP(D28,Referência!$B$6:$D$16,2,FALSE())&", "&VLOOKUP(D28,Referência!$B$6:$D$16,3,FALSE()),"")) | N28: =IF(AND(C28="",G28=""),"",IF(E28="","Informe a duração",IF(G28="","Defina a fonte principal",IF(AND(OR(G28="Mídia",G28="Vinheta"),L28=""),"Defina o áudio da mídia",IF(OR(AND(H28<>"",H28=G28),AND(I28<>"",I28=G28),AND(H28<>"",H28=I28)),"Alternativa repetida",IF(AND(H28="",I28="",E28>$L$4),"Sem alternativa",IF(IFERROR(INDEX($G$38:$G$43,MATCH(G28,$C$38:$C$43,0))="",FALSE()),"Câmera sem operador",IF(OR(IFERROR(INDEX($G$38:$G$43,MATCH(H28,$C$38:$C$43,0))="",FALSE()),IFERROR(INDEX($G$38:$G$43,MATCH(I28,$C$38:$C$43,0))="",FALSE())),"Alternativa sem operador","OK"))))))))
B29: 16 | F29: =IF(OR(E29="",$D$7=""),"",$D$7+SUM($E$14:E28)/1440) | M29: =IF(D29="","",IFERROR(VLOOKUP(D29,Referência!$B$6:$D$16,2,FALSE())&", "&VLOOKUP(D29,Referência!$B$6:$D$16,3,FALSE()),"")) | N29: =IF(AND(C29="",G29=""),"",IF(E29="","Informe a duração",IF(G29="","Defina a fonte principal",IF(AND(OR(G29="Mídia",G29="Vinheta"),L29=""),"Defina o áudio da mídia",IF(OR(AND(H29<>"",H29=G29),AND(I29<>"",I29=G29),AND(H29<>"",H29=I29)),"Alternativa repetida",IF(AND(H29="",I29="",E29>$L$4),"Sem alternativa",IF(IFERROR(INDEX($G$38:$G$43,MATCH(G29,$C$38:$C$43,0))="",FALSE()),"Câmera sem operador",IF(OR(IFERROR(INDEX($G$38:$G$43,MATCH(H29,$C$38:$C$43,0))="",FALSE()),IFERROR(INDEX($G$38:$G$43,MATCH(I29,$C$38:$C$43,0))="",FALSE())),"Alternativa sem operador","OK"))))))))
B30: 17 | F30: =IF(OR(E30="",$D$7=""),"",$D$7+SUM($E$14:E29)/1440) | M30: =IF(D30="","",IFERROR(VLOOKUP(D30,Referência!$B$6:$D$16,2,FALSE())&", "&VLOOKUP(D30,Referência!$B$6:$D$16,3,FALSE()),"")) | N30: =IF(AND(C30="",G30=""),"",IF(E30="","Informe a duração",IF(G30="","Defina a fonte principal",IF(AND(OR(G30="Mídia",G30="Vinheta"),L30=""),"Defina o áudio da mídia",IF(OR(AND(H30<>"",H30=G30),AND(I30<>"",I30=G30),AND(H30<>"",H30=I30)),"Alternativa repetida",IF(AND(H30="",I30="",E30>$L$4),"Sem alternativa",IF(IFERROR(INDEX($G$38:$G$43,MATCH(G30,$C$38:$C$43,0))="",FALSE()),"Câmera sem operador",IF(OR(IFERROR(INDEX($G$38:$G$43,MATCH(H30,$C$38:$C$43,0))="",FALSE()),IFERROR(INDEX($G$38:$G$43,MATCH(I30,$C$38:$C$43,0))="",FALSE())),"Alternativa sem operador","OK"))))))))
B31: 18 | F31: =IF(OR(E31="",$D$7=""),"",$D$7+SUM($E$14:E30)/1440) | M31: =IF(D31="","",IFERROR(VLOOKUP(D31,Referência!$B$6:$D$16,2,FALSE())&", "&VLOOKUP(D31,Referência!$B$6:$D$16,3,FALSE()),"")) | N31: =IF(AND(C31="",G31=""),"",IF(E31="","Informe a duração",IF(G31="","Defina a fonte principal",IF(AND(OR(G31="Mídia",G31="Vinheta"),L31=""),"Defina o áudio da mídia",IF(OR(AND(H31<>"",H31=G31),AND(I31<>"",I31=G31),AND(H31<>"",H31=I31)),"Alternativa repetida",IF(AND(H31="",I31="",E31>$L$4),"Sem alternativa",IF(IFERROR(INDEX($G$38:$G$43,MATCH(G31,$C$38:$C$43,0))="",FALSE()),"Câmera sem operador",IF(OR(IFERROR(INDEX($G$38:$G$43,MATCH(H31,$C$38:$C$43,0))="",FALSE()),IFERROR(INDEX($G$38:$G$43,MATCH(I31,$C$38:$C$43,0))="",FALSE())),"Alternativa sem operador","OK"))))))))
B32: 19 | F32: =IF(OR(E32="",$D$7=""),"",$D$7+SUM($E$14:E31)/1440) | M32: =IF(D32="","",IFERROR(VLOOKUP(D32,Referência!$B$6:$D$16,2,FALSE())&", "&VLOOKUP(D32,Referência!$B$6:$D$16,3,FALSE()),"")) | N32: =IF(AND(C32="",G32=""),"",IF(E32="","Informe a duração",IF(G32="","Defina a fonte principal",IF(AND(OR(G32="Mídia",G32="Vinheta"),L32=""),"Defina o áudio da mídia",IF(OR(AND(H32<>"",H32=G32),AND(I32<>"",I32=G32),AND(H32<>"",H32=I32)),"Alternativa repetida",IF(AND(H32="",I32="",E32>$L$4),"Sem alternativa",IF(IFERROR(INDEX($G$38:$G$43,MATCH(G32,$C$38:$C$43,0))="",FALSE()),"Câmera sem operador",IF(OR(IFERROR(INDEX($G$38:$G$43,MATCH(H32,$C$38:$C$43,0))="",FALSE()),IFERROR(INDEX($G$38:$G$43,MATCH(I32,$C$38:$C$43,0))="",FALSE())),"Alternativa sem operador","OK"))))))))
B33: 20 | F33: =IF(OR(E33="",$D$7=""),"",$D$7+SUM($E$14:E32)/1440) | M33: =IF(D33="","",IFERROR(VLOOKUP(D33,Referência!$B$6:$D$16,2,FALSE())&", "&VLOOKUP(D33,Referência!$B$6:$D$16,3,FALSE()),"")) | N33: =IF(AND(C33="",G33=""),"",IF(E33="","Informe a duração",IF(G33="","Defina a fonte principal",IF(AND(OR(G33="Mídia",G33="Vinheta"),L33=""),"Defina o áudio da mídia",IF(OR(AND(H33<>"",H33=G33),AND(I33<>"",I33=G33),AND(H33<>"",H33=I33)),"Alternativa repetida",IF(AND(H33="",I33="",E33>$L$4),"Sem alternativa",IF(IFERROR(INDEX($G$38:$G$43,MATCH(G33,$C$38:$C$43,0))="",FALSE()),"Câmera sem operador",IF(OR(IFERROR(INDEX($G$38:$G$43,MATCH(H33,$C$38:$C$43,0))="",FALSE()),IFERROR(INDEX($G$38:$G$43,MATCH(I33,$C$38:$C$43,0))="",FALSE())),"Alternativa sem operador","OK"))))))))
B35: Câmeras e gravação
B36: # | C36: Câmera ou gravador | D36: Posição | E36: Plano de base | G36: Operador | H36: Grava? | I36: Taxa | J36: Espaço livre | K36: Minutos como principal | L36: % do tempo | M36: Espaço necessário | N36: Gravação | O36: Uso no roteiro
D37: onde fica | E37: quadro quando livre | G37: nome | H37: Sim / Não | I37: Mbps | J37: GB | K37: min | M37: GB, com a margem
B38: 1 | C38: Câmera 1 | D38: Fundo, centro do corredor | E38: Geral do palco | G38: Voluntário A | H38: Sim | I38: 50 | J38: 64 | K38: =IF(SUM($E$14:$E$33)=0,"",SUMIF($G$14:$G$33,C38,$E$14:$E$33)) -> 8 | L38: =IF(K38="","",K38/SUM($E$14:$E$33)) -> 0.095238095 | M38: =IF(OR(H38<>"Sim",I38="",SUM($E$14:$E$33)=0),"",ROUND(I38*(SUM($E$14:$E$33)+$L$5)*60/8/1000,1)) -> 42.8 | N38: =IF(H38<>"Sim","",IF(OR(I38="",J38=""),"Informe taxa e espaço",IF(M38="","",IF(M38>J38,"Falta espaço","OK")))) -> OK | O38: =IF(COUNTIF($G$14:$I$33,C38)=0,"",IF(G38="","Em uso sem operador",IF(AND(L38<>"",L38>$L$6),"Concentrada: combine plano B","OK"))) -> OK
B39: 2 | C39: Câmera 2 | D39: Fundo, à esquerda | E39: Médio do púlpito | G39: Voluntário B | H39: Sim | I39: 50 | J39: 32 | K39: =IF(SUM($E$14:$E$33)=0,"",SUMIF($G$14:$G$33,C39,$E$14:$E$33)) -> 65 | L39: =IF(K39="","",K39/SUM($E$14:$E$33)) -> 0.77380952 | M39: =IF(OR(H39<>"Sim",I39="",SUM($E$14:$E$33)=0),"",ROUND(I39*(SUM($E$14:$E$33)+$L$5)*60/8/1000,1)) -> 42.8 | N39: =IF(H39<>"Sim","",IF(OR(I39="",J39=""),"Informe taxa e espaço",IF(M39="","",IF(M39>J39,"Falta espaço","OK")))) -> Falta espaço | O39: =IF(COUNTIF($G$14:$I$33,C39)=0,"",IF(G39="","Em uso sem operador",IF(AND(L39<>"",L39>$L$6),"Concentrada: combine plano B","OK"))) -> Concentrada: combine plano B
B40: 3 | C40: Câmera 3 | D40: Frente, à esquerda do palco | E40: Banda e congregação | G40: Voluntário C | H40: Não | K40: =IF(SUM($E$14:$E$33)=0,"",SUMIF($G$14:$G$33,C40,$E$14:$E$33)) -> 2 | L40: =IF(K40="","",K40/SUM($E$14:$E$33)) -> 0.023809524 | M40: =IF(OR(H40<>"Sim",I40="",SUM($E$14:$E$33)=0),"",ROUND(I40*(SUM($E$14:$E$33)+$L$5)*60/8/1000,1)) | N40: =IF(H40<>"Sim","",IF(OR(I40="",J40=""),"Informe taxa e espaço",IF(M40="","",IF(M40>J40,"Falta espaço","OK")))) | O40: =IF(COUNTIF($G$14:$I$33,C40)=0,"",IF(G40="","Em uso sem operador",IF(AND(L40<>"",L40>$L$6),"Concentrada: combine plano B","OK"))) -> OK
B41: 4 | C41: Câmera 4 | D41: Frente, à direita do palco | E41: Close de quem canta | H41: Não | K41: =IF(SUM($E$14:$E$33)=0,"",SUMIF($G$14:$G$33,C41,$E$14:$E$33)) -> 5 | L41: =IF(K41="","",K41/SUM($E$14:$E$33)) -> 0.05952381 | M41: =IF(OR(H41<>"Sim",I41="",SUM($E$14:$E$33)=0),"",ROUND(I41*(SUM($E$14:$E$33)+$L$5)*60/8/1000,1)) | N41: =IF(H41<>"Sim","",IF(OR(I41="",J41=""),"Informe taxa e espaço",IF(M41="","",IF(M41>J41,"Falta espaço","OK")))) | O41: =IF(COUNTIF($G$14:$I$33,C41)=0,"",IF(G41="","Em uso sem operador",IF(AND(L41<>"",L41>$L$6),"Concentrada: combine plano B","OK"))) -> Em uso sem operador
B42: 5 | C42: Câmera 5 | K42: =IF(SUM($E$14:$E$33)=0,"",SUMIF($G$14:$G$33,C42,$E$14:$E$33)) -> 0 | L42: =IF(K42="","",K42/SUM($E$14:$E$33)) -> 0 | M42: =IF(OR(H42<>"Sim",I42="",SUM($E$14:$E$33)=0),"",ROUND(I42*(SUM($E$14:$E$33)+$L$5)*60/8/1000,1)) | N42: =IF(H42<>"Sim","",IF(OR(I42="",J42=""),"Informe taxa e espaço",IF(M42="","",IF(M42>J42,"Falta espaço","OK")))) | O42: =IF(COUNTIF($G$14:$I$33,C42)=0,"",IF(G42="","Em uso sem operador",IF(AND(L42<>"",L42>$L$6),"Concentrada: combine plano B","OK")))
B43: 6 | C43: Câmera 6 | K43: =IF(SUM($E$14:$E$33)=0,"",SUMIF($G$14:$G$33,C43,$E$14:$E$33)) -> 0 | L43: =IF(K43="","",K43/SUM($E$14:$E$33)) -> 0 | M43: =IF(OR(H43<>"Sim",I43="",SUM($E$14:$E$33)=0),"",ROUND(I43*(SUM($E$14:$E$33)+$L$5)*60/8/1000,1)) | N43: =IF(H43<>"Sim","",IF(OR(I43="",J43=""),"Informe taxa e espaço",IF(M43="","",IF(M43>J43,"Falta espaço","OK")))) | O43: =IF(COUNTIF($G$14:$I$33,C43)=0,"",IF(G43="","Em uso sem operador",IF(AND(L43<>"",L43>$L$6),"Concentrada: combine plano B","OK")))
...
