Workbook

Sheet Instruções
B1: Microfones — como usar esta planilha
B2: Inventário dos microfones, escolha do microfone de cada fonte e conferência da regra 3:1.
B4: Legenda: onde preencher
B5: Amarelo-claro | C5: Células de entrada. É aqui que você digita.
B6: Cinza | C6: Células calculadas ou fixas (rótulos, contas, avisos). Não altere.
B7: Cinza em itálico | C7: Linha de exemplo (marcada com “Ex.”) e dicas de preenchimento. Não entram nas contas.
B8: Listas suspensas | C8: Formato, tipo, padrão, ligação, teste e tipo de fonte aceitam só as opções da lista.
B9: Números | C9: Distâncias em centímetros, só o número: 30, e não “30 cm”.
B10: Comentários | C10: Células com triângulo vermelho no canto trazem uma dica. Passe o mouse sobre elas.
B12: Ordem de preenchimento
B13: 1 | C13: Aba Inventário: cadastre cada microfone, com o padrão tirado do manual do modelo, e o resultado do teste.
B14: 2 | C14: Aba Escolha por fonte: liste as fontes do evento, escolha o tipo de fonte e o número do microfone.
B15: 3 | C15: Veja a situação e o que fazer. Troque o microfone ou confira a escolha até tudo ficar OK.
B16: 4 | C16: Na montagem: posicione cada microfone pela distância e pela posição de partida, e ligue o phantom onde indicado.
B17: 5 | C17: Aba Regra 3 para 1: meça os microfones que ficam abertos juntos e corrija os pares fora da regra.
B18: 6 | C18: Aba Checklist: confira os doze itens antes do ajuste de ganho.
B20: Abas da planilha
B21: Inventário | C21: Até 30 microfones, com phantom, maior rejeição, lugar do retorno e situação calculados.
B22: Escolha por fonte | C22: Até 20 fontes, com a sugestão de microfone e a conferência do microfone escolhido.
B23: Regra 3 para 1 | C23: Até 12 pares de microfones, com razão, vazamento estimado e o que fazer.
B24: Referência | C24: Ponto de partida por fonte, padrões polares, dinâmico e condensador, distância e nível.
B25: Checklist | C25: Os doze itens do treinamento, com percentual atendido.
B26: Exemplo - Escolha | C26: O culto do exemplo 1 do treinamento: nove fontes como foram planejadas, com o inventário de dez microfones.
B28: Regras e premissas do modelo
B29: Phantom | C29: Sim para condensador com fio. Não para dinâmico e para microfone sem fio. Fita: confira o manual.
B30: Sugestão por fonte | C30: Vem da tabela da aba Referência. Ela é ponto de partida, e não regra: a decisão final é pelo ouvido.
B31: Tipo e padrão | C31: “Tipo diferente” aparece quando a fonte pede um tipo e o microfone é de outro. “Padrão diferente”, quando a fonte pede padrão direcional e o microfone é omni ou figura de 8.
B32: Repetido | C32: O mesmo número de microfone em dois canais. A marcação aparece no segundo canal em que ele foi usado.
B33: Regra 3 para 1 | C33: Razão = distância entre os microfones ÷ maior distância até a fonte. OK a partir de 3; Perto do limite de 2 a 3.
B34: Vazamento estimado | C34: Conta de campo livre (cerca de 6 dB a cada vez que a distância dobra). Em sala reverberante, o vazamento real é maior.
B35: Exemplos | C35: Os dados das abas e da linha Ex. são ilustrativos, criados para este material.

Sheet Inventário
B1: Inventário de microfones
B2: Cadastre cada microfone com o formato, o tipo e o padrão do manual. As células cinza são calculadas.
B4: Igreja ou equipe | I4: Identifique cada microfone com uma fita ou etiqueta, e use o mesmo nome aqui e na aba Escolha por fonte.
B5: Responsável
B6: Data da conferência
B8: Microfones
B9: Nº | C9: Identificação | D9: Formato | E9: Tipo | F9: Padrão polar | G9: Ligação | H9: Teste | I9: Última limpeza | J9: Phantom | K9: Maior rejeição | L9: Onde pôr o retorno | M9: Situação | N9: Observação
C10: nome ou fita | D10: lista | E10: lista | F10: do manual | G10: lista | H10: com a voz | I10: data | J10: precisa? | K10: direção
B11: Ex. | C11: Mão 3 (fita amarela) | D11: De mão | E11: Dinâmico | F11: Supercardioide | G11: Com fio | H11: OK | I11: 04/10/2026 | J11: Não | K11: cerca de 125° | L11: Em diagonal, nunca bem atrás | M11: OK
B12: Uma linha por microfone. O número da coluna B é o que você escolhe na aba Escolha por fonte.
B13: 1 | J13: =IF(E13="","",IF(G13="Sem fio","Não",IF(E13="Condensador","Sim",IF(E13="Fita","Não: veja o manual","Não")))) | K13: =IF(F13="","",IF(F13="Cardioide","180°, bem atrás",IF(F13="Supercardioide","cerca de 125°",IF(F13="Hipercardioide","cerca de 110°",IF(F13="Omni","não rejeita","90°, nos lados"))))) | L13: =IF(F13="","",IF(F13="Cardioide","Bem atrás do microfone",IF(OR(F13="Supercardioide",F13="Hipercardioide"),"Em diagonal, nunca bem atrás",IF(F13="Omni","Longe: o microfone não rejeita","Em um dos lados")))) | M13: =IF(AND(C13="",D13="",E13="",F13=""),"",IF(H13="Defeito","Defeito",IF(OR(H13="",H13="Não testado"),"Testar",IF(OR(D13="",E13="",F13=""),"Incompleto","OK"))))
B14: 2 | J14: =IF(E14="","",IF(G14="Sem fio","Não",IF(E14="Condensador","Sim",IF(E14="Fita","Não: veja o manual","Não")))) | K14: =IF(F14="","",IF(F14="Cardioide","180°, bem atrás",IF(F14="Supercardioide","cerca de 125°",IF(F14="Hipercardioide","cerca de 110°",IF(F14="Omni","não rejeita","90°, nos lados"))))) | L14: =IF(F14="","",IF(F14="Cardioide","Bem atrás do microfone",IF(OR(F14="Supercardioide",F14="Hipercardioide"),"Em diagonal, nunca bem atrás",IF(F14="Omni","Longe: o microfone não rejeita","Em um dos lados")))) | M14: =IF(AND(C14="",D14="",E14="",F14=""),"",IF(H14="Defeito","Defeito",IF(OR(H14="",H14="Não testado"),"Testar",IF(OR(D14="",E14="",F14=""),"Incompleto","OK"))))
B15: 3 | J15: =IF(E15="","",IF(G15="Sem fio","Não",IF(E15="Condensador","Sim",IF(E15="Fita","Não: veja o manual","Não")))) | K15: =IF(F15="","",IF(F15="Cardioide","180°, bem atrás",IF(F15="Supercardioide","cerca de 125°",IF(F15="Hipercardioide","cerca de 110°",IF(F15="Omni","não rejeita","90°, nos lados"))))) | L15: =IF(F15="","",IF(F15="Cardioide","Bem atrás do microfone",IF(OR(F15="Supercardioide",F15="Hipercardioide"),"Em diagonal, nunca bem atrás",IF(F15="Omni","Longe: o microfone não rejeita","Em um dos lados")))) | M15: =IF(AND(C15="",D15="",E15="",F15=""),"",IF(H15="Defeito","Defeito",IF(OR(H15="",H15="Não testado"),"Testar",IF(OR(D15="",E15="",F15=""),"Incompleto","OK"))))
B16: 4 | J16: =IF(E16="","",IF(G16="Sem fio","Não",IF(E16="Condensador","Sim",IF(E16="Fita","Não: veja o manual","Não")))) | K16: =IF(F16="","",IF(F16="Cardioide","180°, bem atrás",IF(F16="Supercardioide","cerca de 125°",IF(F16="Hipercardioide","cerca de 110°",IF(F16="Omni","não rejeita","90°, nos lados"))))) | L16: =IF(F16="","",IF(F16="Cardioide","Bem atrás do microfone",IF(OR(F16="Supercardioide",F16="Hipercardioide"),"Em diagonal, nunca bem atrás",IF(F16="Omni","Longe: o microfone não rejeita","Em um dos lados")))) | M16: =IF(AND(C16="",D16="",E16="",F16=""),"",IF(H16="Defeito","Defeito",IF(OR(H16="",H16="Não testado"),"Testar",IF(OR(D16="",E16="",F16=""),"Incompleto","OK"))))
B17: 5 | J17: =IF(E17="","",IF(G17="Sem fio","Não",IF(E17="Condensador","Sim",IF(E17="Fita","Não: veja o manual","Não")))) | K17: =IF(F17="","",IF(F17="Cardioide","180°, bem atrás",IF(F17="Supercardioide","cerca de 125°",IF(F17="Hipercardioide","cerca de 110°",IF(F17="Omni","não rejeita","90°, nos lados"))))) | L17: =IF(F17="","",IF(F17="Cardioide","Bem atrás do microfone",IF(OR(F17="Supercardioide",F17="Hipercardioide"),"Em diagonal, nunca bem atrás",IF(F17="Omni","Longe: o microfone não rejeita","Em um dos lados")))) | M17: =IF(AND(C17="",D17="",E17="",F17=""),"",IF(H17="Defeito","Defeito",IF(OR(H17="",H17="Não testado"),"Testar",IF(OR(D17="",E17="",F17=""),"Incompleto","OK"))))
B18: 6 | J18: =IF(E18="","",IF(G18="Sem fio","Não",IF(E18="Condensador","Sim",IF(E18="Fita","Não: veja o manual","Não")))) | K18: =IF(F18="","",IF(F18="Cardioide","180°, bem atrás",IF(F18="Supercardioide","cerca de 125°",IF(F18="Hipercardioide","cerca de 110°",IF(F18="Omni","não rejeita","90°, nos lados"))))) | L18: =IF(F18="","",IF(F18="Cardioide","Bem atrás do microfone",IF(OR(F18="Supercardioide",F18="Hipercardioide"),"Em diagonal, nunca bem atrás",IF(F18="Omni","Longe: o microfone não rejeita","Em um dos lados")))) | M18: =IF(AND(C18="",D18="",E18="",F18=""),"",IF(H18="Defeito","Defeito",IF(OR(H18="",H18="Não testado"),"Testar",IF(OR(D18="",E18="",F18=""),"Incompleto","OK"))))
B19: 7 | J19: =IF(E19="","",IF(G19="Sem fio","Não",IF(E19="Condensador","Sim",IF(E19="Fita","Não: veja o manual","Não")))) | K19: =IF(F19="","",IF(F19="Cardioide","180°, bem atrás",IF(F19="Supercardioide","cerca de 125°",IF(F19="Hipercardioide","cerca de 110°",IF(F19="Omni","não rejeita","90°, nos lados"))))) | L19: =IF(F19="","",IF(F19="Cardioide","Bem atrás do microfone",IF(OR(F19="Supercardioide",F19="Hipercardioide"),"Em diagonal, nunca bem atrás",IF(F19="Omni","Longe: o microfone não rejeita","Em um dos lados")))) | M19: =IF(AND(C19="",D19="",E19="",F19=""),"",IF(H19="Defeito","Defeito",IF(OR(H19="",H19="Não testado"),"Testar",IF(OR(D19="",E19="",F19=""),"Incompleto","OK"))))
B20: 8 | J20: =IF(E20="","",IF(G20="Sem fio","Não",IF(E20="Condensador","Sim",IF(E20="Fita","Não: veja o manual","Não")))) | K20: =IF(F20="","",IF(F20="Cardioide","180°, bem atrás",IF(F20="Supercardioide","cerca de 125°",IF(F20="Hipercardioide","cerca de 110°",IF(F20="Omni","não rejeita","90°, nos lados"))))) | L20: =IF(F20="","",IF(F20="Cardioide","Bem atrás do microfone",IF(OR(F20="Supercardioide",F20="Hipercardioide"),"Em diagonal, nunca bem atrás",IF(F20="Omni","Longe: o microfone não rejeita","Em um dos lados")))) | M20: =IF(AND(C20="",D20="",E20="",F20=""),"",IF(H20="Defeito","Defeito",IF(OR(H20="",H20="Não testado"),"Testar",IF(OR(D20="",E20="",F20=""),"Incompleto","OK"))))
B21: 9 | J21: =IF(E21="","",IF(G21="Sem fio","Não",IF(E21="Condensador","Sim",IF(E21="Fita","Não: veja o manual","Não")))) | K21: =IF(F21="","",IF(F21="Cardioide","180°, bem atrás",IF(F21="Supercardioide","cerca de 125°",IF(F21="Hipercardioide","cerca de 110°",IF(F21="Omni","não rejeita","90°, nos lados"))))) | L21: =IF(F21="","",IF(F21="Cardioide","Bem atrás do microfone",IF(OR(F21="Supercardioide",F21="Hipercardioide"),"Em diagonal, nunca bem atrás",IF(F21="Omni","Longe: o microfone não rejeita","Em um dos lados")))) | M21: =IF(AND(C21="",D21="",E21="",F21=""),"",IF(H21="Defeito","Defeito",IF(OR(H21="",H21="Não testado"),"Testar",IF(OR(D21="",E21="",F21=""),"Incompleto","OK"))))
B22: 10 | J22: =IF(E22="","",IF(G22="Sem fio","Não",IF(E22="Condensador","Sim",IF(E22="Fita","Não: veja o manual","Não")))) | K22: =IF(F22="","",IF(F22="Cardioide","180°, bem atrás",IF(F22="Supercardioide","cerca de 125°",IF(F22="Hipercardioide","cerca de 110°",IF(F22="Omni","não rejeita","90°, nos lados"))))) | L22: =IF(F22="","",IF(F22="Cardioide","Bem atrás do microfone",IF(OR(F22="Supercardioide",F22="Hipercardioide"),"Em diagonal, nunca bem atrás",IF(F22="Omni","Longe: o microfone não rejeita","Em um dos lados")))) | M22: =IF(AND(C22="",D22="",E22="",F22=""),"",IF(H22="Defeito","Defeito",IF(OR(H22="",H22="Não testado"),"Testar",IF(OR(D22="",E22="",F22=""),"Incompleto","OK"))))
B23: 11 | J23: =IF(E23="","",IF(G23="Sem fio","Não",IF(E23="Condensador","Sim",IF(E23="Fita","Não: veja o manual","Não")))) | K23: =IF(F23="","",IF(F23="Cardioide","180°, bem atrás",IF(F23="Supercardioide","cerca de 125°",IF(F23="Hipercardioide","cerca de 110°",IF(F23="Omni","não rejeita","90°, nos lados"))))) | L23: =IF(F23="","",IF(F23="Cardioide","Bem atrás do microfone",IF(OR(F23="Supercardioide",F23="Hipercardioide"),"Em diagonal, nunca bem atrás",IF(F23="Omni","Longe: o microfone não rejeita","Em um dos lados")))) | M23: =IF(AND(C23="",D23="",E23="",F23=""),"",IF(H23="Defeito","Defeito",IF(OR(H23="",H23="Não testado"),"Testar",IF(OR(D23="",E23="",F23=""),"Incompleto","OK"))))
B24: 12 | J24: =IF(E24="","",IF(G24="Sem fio","Não",IF(E24="Condensador","Sim",IF(E24="Fita","Não: veja o manual","Não")))) | K24: =IF(F24="","",IF(F24="Cardioide","180°, bem atrás",IF(F24="Supercardioide","cerca de 125°",IF(F24="Hipercardioide","cerca de 110°",IF(F24="Omni","não rejeita","90°, nos lados"))))) | L24: =IF(F24="","",IF(F24="Cardioide","Bem atrás do microfone",IF(OR(F24="Supercardioide",F24="Hipercardioide"),"Em diagonal, nunca bem atrás",IF(F24="Omni","Longe: o microfone não rejeita","Em um dos lados")))) | M24: =IF(AND(C24="",D24="",E24="",F24=""),"",IF(H24="Defeito","Defeito",IF(OR(H24="",H24="Não testado"),"Testar",IF(OR(D24="",E24="",F24=""),"Incompleto","OK"))))
... B42: 30 | J42: =IF(E42="","",IF(G42="Sem fio","Não",IF(E42="Condensador","Sim",IF(E42="Fita","Não: veja o manual","Não")))) | K42: =IF(F42="","",IF(F42="Cardioide","180°, bem atrás",IF(F42="Supercardioide","cerca de 125°",IF(F42="Hipercardioide","cerca de 110°",IF(F42="Omni","não rejeita","90°, nos lados"))))) | L42: =IF(F42="","",IF(F42="Cardioide","Bem atrás do microfone",IF(OR(F42="Supercardioide",F42="Hipercardioide"),"Em diagonal, nunca bem atrás",IF(F42="Omni","Longe: o microfone não rejeita","Em um dos lados")))) | M42: =IF(AND(C42="",D42="",E42="",F42=""),"",IF(H42="Defeito","Defeito",IF(OR(H42="",H42="Não testado"),"Testar",IF(OR(D42="",E42="",F42=""),"Incompleto","OK"))))
B44: Resumo automático
B45: Microfones cadastrados | F45: =COUNTA(D13:D42) -> 0
B46: Dinâmicos | F46: =COUNTIF(E13:E42,"Dinâmico") -> 0
B47: Condensadores | F47: =COUNTIF(E13:E42,"Condensador") -> 0
B48: Precisam de phantom | F48: =COUNTIF(J13:J42,"Sim") -> 0
B49: Sem fio | F49: =COUNTIF(G13:G42,"Sem fio") -> 0
B50: Com defeito | F50: =COUNTIF(M13:M42,"Defeito") -> 0
B51: A testar ou incompletos | F51: =COUNTIF(M13:M42,"Testar")+COUNTIF(M13:M42,"Incompleto") -> 0
B52: Aviso | F52: =IF(F45=0,"Cadastre os microfones",IF(F50>0,"Há microfone com defeito: separe para conserto",IF(F51>0,"Há microfone sem teste ou com cadastro incompleto","OK"))) -> Cadastre os microfones

Sheet Escolha por fonte
B1: Escolha de microfone por fonte
B2: Para cada canal, escolha o tipo de fonte e o número do microfone do inventário. As células cinza são calculadas.
B4: Evento | I4: A sugestão de cada fonte vem da aba Referência e é ponto de partida. “Tipo diferente” ou “Padrão diferente” pedem conferência, e não troca obrigatória.
B5: Local
B6: Data
B7: Operador
B9: Fontes do evento
B10: Canal | C10: Tipo de fonte | D10: Descrição | E10: Microfone nº | F10: Formato | G10: Tipo | H10: Padrão | I10: Phantom | J10: Sugestão: tipo e padrão | K10: Distância de partida | L10: Situação | M10: O que fazer | N10: Posição de partida
B11: nº | C11: lista | D11: quem ou o quê | E11: do inventário | F11: do inventário | G11: do inventário | H11: do inventário | I11: no canal | J11: da Referência | K11: da Referência | N11: da Referência
B12: Ex. | C12: Coral | D12: Coral, lado esquerdo | E12: 3 | F12: De mão | G12: Dinâmico | H12: Supercardioide | I12: Não | J12: Condensador, Cardioide | K12: 60 a 90 cm à frente da 1ª fila | L12: Tipo diferente | M12: Sugestão: Condensador. Confira se este serve
B13: 1 | F13: =IF(E13="","",IFERROR(""&VLOOKUP(E13,Inventário!$B$13:$J$42,3,FALSE()),"")) | G13: =IF(E13="","",IFERROR(""&VLOOKUP(E13,Inventário!$B$13:$J$42,4,FALSE()),"")) | H13: =IF(E13="","",IFERROR(""&VLOOKUP(E13,Inventário!$B$13:$J$42,5,FALSE()),"")) | I13: =IF(E13="","",IFERROR(""&VLOOKUP(E13,Inventário!$B$13:$J$42,9,FALSE()),"")) | J13: =IF(C13="","",IFERROR(VLOOKUP(C13,Referência!$B$6:$I$15,2,FALSE()),"")&", "&IFERROR(VLOOKUP(C13,Referência!$B$6:$I$15,3,FALSE()),"")) | K13: =IF(C13="","",IFERROR(VLOOKUP(C13,Referência!$B$6:$I$15,5,FALSE()),"")) | L13: =IF(E13="",IF(C13="","","Sem microfone"),IF(IFERROR(""&VLOOKUP(E13,Inventário!$B$13:$J$42,3,FALSE()),"")&IFERROR(""&VLOOKUP(E13,Inventário!$B$13:$J$42,4,FALSE()),"")&IFERROR(""&VLOOKUP(E13,Inventário!$B$13:$J$42,7,FALSE()),"")="","Não cadastrado",IF(IFERROR(""&VLOOKUP(E13,Inventário!$B$13:$J$42,7,FALSE()),"")="Defeito","Defeito",IF(COUNTIF($E$13:E13,E13)>1,"Repetido",IF(C13="","Sem fonte",IF(AND(IFERROR(VLOOKUP(C13,Referência!$B$6:$I$15,7,FALSE()),"")<>"Qualquer",G13<>IFERROR(VLOOKUP(C13,Referência!$B$6:$I$15,7,FALSE()),"")),"Tipo diferente",IF(NOT(OR(IFERROR(VLOOKUP(C13,Referência!$B$6:$I$15,8,FALSE()),"")="Qualquer",AND(IFERROR(VLOOKUP(C13,Referência!$B$6:$I$15,8,FALSE()),"")="Direcional",OR(H13="Cardioide",H13="Supercardioide",H13="Hipercardioide")),IFERROR(VLOOKUP(C13,Referência!$B$6:$I$15,8,FALSE()),"")=H13)),"Padrão diferente",IF(IFERROR(""&VLOOKUP(E13,Inventário!$B$13:$J$42,7,FALSE()),"")<>"OK","Testar","OK")))))))) | M13: =IF(L13="","",IF(L13="Sem microfone","Escolha um microfone do inventário",IF(L13="Não cadastrado","Cadastre o microfone na aba Inventário",IF(L13="Defeito","Troque de microfone e separe este para conserto",IF(L13="Repetido","Já está em um canal anterior: escolha outro",IF(L13="Sem fonte","Escolha o tipo de fonte",IF(L13="Tipo diferente","Sugestão: "&IFERROR(VLOOKUP(C13,Referência!$B$6:$I$15,7,FALSE()),"")&". Confira se este serve",IF(L13="Padrão diferente","Confira o padrão e o lugar do retorno",IF(L13="Testar","Teste com a voz antes do evento",IF(I13="Sim","Ligue o phantom com o canal fechado","Manter")))))))))) | N13: =IF(C13="","",IFERROR(VLOOKUP(C13,Referência!$B$6:$I$15,6,FALSE()),""))
B14: 2 | F14: =IF(E14="","",IFERROR(""&VLOOKUP(E14,Inventário!$B$13:$J$42,3,FALSE()),"")) | G14: =IF(E14="","",IFERROR(""&VLOOKUP(E14,Inventário!$B$13:$J$42,4,FALSE()),"")) | H14: =IF(E14="","",IFERROR(""&VLOOKUP(E14,Inventário!$B$13:$J$42,5,FALSE()),"")) | I14: =IF(E14="","",IFERROR(""&VLOOKUP(E14,Inventário!$B$13:$J$42,9,FALSE()),"")) | J14: =IF(C14="","",IFERROR(VLOOKUP(C14,Referência!$B$6:$I$15,2,FALSE()),"")&", "&IFERROR(VLOOKUP(C14,Referência!$B$6:$I$15,3,FALSE()),"")) | K14: =IF(C14="","",IFERROR(VLOOKUP(C14,Referência!$B$6:$I$15,5,FALSE()),"")) | L14: =IF(E14="",IF(C14="","","Sem microfone"),IF(IFERROR(""&VLOOKUP(E14,Inventário!$B$13:$J$42,3,FALSE()),"")&IFERROR(""&VLOOKUP(E14,Inventário!$B$13:$J$42,4,FALSE()),"")&IFERROR(""&VLOOKUP(E14,Inventário!$B$13:$J$42,7,FALSE()),"")="","Não cadastrado",IF(IFERROR(""&VLOOKUP(E14,Inventário!$B$13:$J$42,7,FALSE()),"")="Defeito","Defeito",IF(COUNTIF($E$13:E14,E14)>1,"Repetido",IF(C14="","Sem fonte",IF(AND(IFERROR(VLOOKUP(C14,Referência!$B$6:$I$15,7,FALSE()),"")<>"Qualquer",G14<>IFERROR(VLOOKUP(C14,Referência!$B$6:$I$15,7,FALSE()),"")),"Tipo diferente",IF(NOT(OR(IFERROR(VLOOKUP(C14,Referência!$B$6:$I$15,8,FALSE()),"")="Qualquer",AND(IFERROR(VLOOKUP(C14,Referência!$B$6:$I$15,8,FALSE()),"")="Direcional",OR(H14="Cardioide",H14="Supercardioide",H14="Hipercardioide")),IFERROR(VLOOKUP(C14,Referência!$B$6:$I$15,8,FALSE()),"")=H14)),"Padrão diferente",IF(IFERROR(""&VLOOKUP(E14,Inventário!$B$13:$J$42,7,FALSE()),"")<>"OK","Testar","OK")))))))) | M14: =IF(L14="","",IF(L14="Sem microfone","Escolha um microfone do inventário",IF(L14="Não cadastrado","Cadastre o microfone na aba Inventário",IF(L14="Defeito","Troque de microfone e separe este para conserto",IF(L14="Repetido","Já está em um canal anterior: escolha outro",IF(L14="Sem fonte","Escolha o tipo de fonte",IF(L14="Tipo diferente","Sugestão: "&IFERROR(VLOOKUP(C14,Referência!$B$6:$I$15,7,FALSE()),"")&". Confira se este serve",IF(L14="Padrão diferente","Confira o padrão e o lugar do retorno",IF(L14="Testar","Teste com a voz antes do evento",IF(I14="Sim","Ligue o phantom com o canal fechado","Manter")))))))))) | N14: =IF(C14="","",IFERROR(VLOOKUP(C14,Referência!$B$6:$I$15,6,FALSE()),""))
B15: 3 | F15: =IF(E15="","",IFERROR(""&VLOOKUP(E15,Inventário!$B$13:$J$42,3,FALSE()),"")) | G15: =IF(E15="","",IFERROR(""&VLOOKUP(E15,Inventário!$B$13:$J$42,4,FALSE()),"")) | H15: =IF(E15="","",IFERROR(""&VLOOKUP(E15,Inventário!$B$13:$J$42,5,FALSE()),"")) | I15: =IF(E15="","",IFERROR(""&VLOOKUP(E15,Inventário!$B$13:$J$42,9,FALSE()),"")) | J15: =IF(C15="","",IFERROR(VLOOKUP(C15,Referência!$B$6:$I$15,2,FALSE()),"")&", "&IFERROR(VLOOKUP(C15,Referência!$B$6:$I$15,3,FALSE()),"")) | K15: =IF(C15="","",IFERROR(VLOOKUP(C15,Referência!$B$6:$I$15,5,FALSE()),"")) | L15: =IF(E15="",IF(C15="","","Sem microfone"),IF(IFERROR(""&VLOOKUP(E15,Inventário!$B$13:$J$42,3,FALSE()),"")&IFERROR(""&VLOOKUP(E15,Inventário!$B$13:$J$42,4,FALSE()),"")&IFERROR(""&VLOOKUP(E15,Inventário!$B$13:$J$42,7,FALSE()),"")="","Não cadastrado",IF(IFERROR(""&VLOOKUP(E15,Inventário!$B$13:$J$42,7,FALSE()),"")="Defeito","Defeito",IF(COUNTIF($E$13:E15,E15)>1,"Repetido",IF(C15="","Sem fonte",IF(AND(IFERROR(VLOOKUP(C15,Referência!$B$6:$I$15,7,FALSE()),"")<>"Qualquer",G15<>IFERROR(VLOOKUP(C15,Referência!$B$6:$I$15,7,FALSE()),"")),"Tipo diferente",IF(NOT(OR(IFERROR(VLOOKUP(C15,Referência!$B$6:$I$15,8,FALSE()),"")="Qualquer",AND(IFERROR(VLOOKUP(C15,Referência!$B$6:$I$15,8,FALSE()),"")="Direcional",OR(H15="Cardioide",H15="Supercardioide",H15="Hipercardioide")),IFERROR(VLOOKUP(C15,Referência!$B$6:$I$15,8,FALSE()),"")=H15)),"Padrão diferente",IF(IFERROR(""&VLOOKUP(E15,Inventário!$B$13:$J$42,7,FALSE()),"")<>"OK","Testar","OK")))))))) | M15: =IF(L15="","",IF(L15="Sem microfone","Escolha um microfone do inventário",IF(L15="Não cadastrado","Cadastre o microfone na aba Inventário",IF(L15="Defeito","Troque de microfone e separe este para conserto",IF(L15="Repetido","Já está em um canal anterior: escolha outro",IF(L15="Sem fonte","Escolha o tipo de fonte",IF(L15="Tipo diferente","Sugestão: "&IFERROR(VLOOKUP(C15,Referência!$B$6:$I$15,7,FALSE()),"")&". Confira se este serve",IF(L15="Padrão diferente","Confira o padrão e o lugar do retorno",IF(L15="Testar","Teste com a voz antes do evento",IF(I15="Sim","Ligue o phantom com o canal fechado","Manter")))))))))) | N15: =IF(C15="","",IFERROR(VLOOKUP(C15,Referência!$B$6:$I$15,6,FALSE()),""))
B16: 4 | F16: =IF(E16="","",IFERROR(""&VLOOKUP(E16,Inventário!$B$13:$J$42,3,FALSE()),"")) | G16: =IF(E16="","",IFERROR(""&VLOOKUP(E16,Inventário!$B$13:$J$42,4,FALSE()),"")) | H16: =IF(E16="","",IFERROR(""&VLOOKUP(E16,Inventário!$B$13:$J$42,5,FALSE()),"")) | I16: =IF(E16="","",IFERROR(""&VLOOKUP(E16,Inventário!$B$13:$J$42,9,FALSE()),"")) | J16: =IF(C16="","",IFERROR(VLOOKUP(C16,Referência!$B$6:$I$15,2,FALSE()),"")&", "&IFERROR(VLOOKUP(C16,Referência!$B$6:$I$15,3,FALSE()),"")) | K16: =IF(C16="","",IFERROR(VLOOKUP(C16,Referência!$B$6:$I$15,5,FALSE()),"")) | L16: =IF(E16="",IF(C16="","","Sem microfone"),IF(IFERROR(""&VLOOKUP(E16,Inventário!$B$13:$J$42,3,FALSE()),"")&IFERROR(""&VLOOKUP(E16,Inventário!$B$13:$J$42,4,FALSE()),"")&IFERROR(""&VLOOKUP(E16,Inventário!$B$13:$J$42,7,FALSE()),"")="","Não cadastrado",IF(IFERROR(""&VLOOKUP(E16,Inventário!$B$13:$J$42,7,FALSE()),"")="Defeito","Defeito",IF(COUNTIF($E$13:E16,E16)>1,"Repetido",IF(C16="","Sem fonte",IF(AND(IFERROR(VLOOKUP(C16,Referência!$B$6:$I$15,7,FALSE()),"")<>"Qualquer",G16<>IFERROR(VLOOKUP(C16,Referência!$B$6:$I$15,7,FALSE()),"")),"Tipo diferente",IF(NOT(OR(IFERROR(VLOOKUP(C16,Referência!$B$6:$I$15,8,FALSE()),"")="Qualquer",AND(IFERROR(VLOOKUP(C16,Referência!$B$6:$I$15,8,FALSE()),"")="Direcional",OR(H16="Cardioide",H16="Supercardioide",H16="Hipercardioide")),IFERROR(VLOOKUP(C16,Referência!$B$6:$I$15,8,FALSE()),"")=H16)),"Padrão diferente",IF(IFERROR(""&VLOOKUP(E16,Inventário!$B$13:$J$42,7,FALSE()),"")<>"OK","Testar","OK")))))))) | M16: =IF(L16="","",IF(L16="Sem microfone","Escolha um microfone do inventário",IF(L16="Não cadastrado","Cadastre o microfone na aba Inventário",IF(L16="Defeito","Troque de microfone e separe este para conserto",IF(L16="Repetido","Já está em um canal anterior: escolha outro",IF(L16="Sem fonte","Escolha o tipo de fonte",IF(L16="Tipo diferente","Sugestão: "&IFERROR(VLOOKUP(C16,Referência!$B$6:$I$15,7,FALSE()),"")&". Confira se este serve",IF(L16="Padrão diferente","Confira o padrão e o lugar do retorno",IF(L16="Testar","Teste com a voz antes do evento",IF(I16="Sim","Ligue o phantom com o canal fechado","Manter")))))))))) | N16: =IF(C16="","",IFERROR(VLOOKUP(C16,Referência!$B$6:$I$15,6,FALSE()),""))
B17: 5 | F17: =IF(E17="","",IFERROR(""&VLOOKUP(E17,Inventário!$B$13:$J$42,3,FALSE()),"")) | G17: =IF(E17="","",IFERROR(""&VLOOKUP(E17,Inventário!$B$13:$J$42,4,FALSE()),"")) | H17: =IF(E17="","",IFERROR(""&VLOOKUP(E17,Inventário!$B$13:$J$42,5,FALSE()),"")) | I17: =IF(E17="","",IFERROR(""&VLOOKUP(E17,Inventário!$B$13:$J$42,9,FALSE()),"")) | J17: =IF(C17="","",IFERROR(VLOOKUP(C17,Referência!$B$6:$I$15,2,FALSE()),"")&", "&IFERROR(VLOOKUP(C17,Referência!$B$6:$I$15,3,FALSE()),"")) | K17: =IF(C17="","",IFERROR(VLOOKUP(C17,Referência!$B$6:$I$15,5,FALSE()),"")) | L17: =IF(E17="",IF(C17="","","Sem microfone"),IF(IFERROR(""&VLOOKUP(E17,Inventário!$B$13:$J$42,3,FALSE()),"")&IFERROR(""&VLOOKUP(E17,Inventário!$B$13:$J$42,4,FALSE()),"")&IFERROR(""&VLOOKUP(E17,Inventário!$B$13:$J$42,7,FALSE()),"")="","Não cadastrado",IF(IFERROR(""&VLOOKUP(E17,Inventário!$B$13:$J$42,7,FALSE()),"")="Defeito","Defeito",IF(COUNTIF($E$13:E17,E17)>1,"Repetido",IF(C17="","Sem fonte",IF(AND(IFERROR(VLOOKUP(C17,Referência!$B$6:$I$15,7,FALSE()),"")<>"Qualquer",G17<>IFERROR(VLOOKUP(C17,Referência!$B$6:$I$15,7,FALSE()),"")),"Tipo diferente",IF(NOT(OR(IFERROR(VLOOKUP(C17,Referência!$B$6:$I$15,8,FALSE()),"")="Qualquer",AND(IFERROR(VLOOKUP(C17,Referência!$B$6:$I$15,8,FALSE()),"")="Direcional",OR(H17="Cardioide",H17="Supercardioide",H17="Hipercardioide")),IFERROR(VLOOKUP(C17,Referência!$B$6:$I$15,8,FALSE()),"")=H17)),"Padrão diferente",IF(IFERROR(""&VLOOKUP(E17,Inventário!$B$13:$J$42,7,FALSE()),"")<>"OK","Testar","OK")))))))) | M17: =IF(L17="","",IF(L17="Sem microfone","Escolha um microfone do inventário",IF(L17="Não cadastrado","Cadastre o microfone na aba Inventário",IF(L17="Defeito","Troque de microfone e separe este para conserto",IF(L17="Repetido","Já está em um canal anterior: escolha outro",IF(L17="Sem fonte","Escolha o tipo de fonte",IF(L17="Tipo diferente","Sugestão: "&IFERROR(VLOOKUP(C17,Referência!$B$6:$I$15,7,FALSE()),"")&". Confira se este serve",IF(L17="Padrão diferente","Confira o padrão e o lugar do retorno",IF(L17="Testar","Teste com a voz antes do evento",IF(I17="Sim","Ligue o phantom com o canal fechado","Manter")))))))))) | N17: =IF(C17="","",IFERROR(VLOOKUP(C17,Referência!$B$6:$I$15,6,FALSE()),""))
B18: 6 | F18: =IF(E18="","",IFERROR(""&VLOOKUP(E18,Inventário!$B$13:$J$42,3,FALSE()),"")) | G18: =IF(E18="","",IFERROR(""&VLOOKUP(E18,Inventário!$B$13:$J$42,4,FALSE()),"")) | H18: =IF(E18="","",IFERROR(""&VLOOKUP(E18,Inventário!$B$13:$J$42,5,FALSE()),"")) | I18: =IF(E18="","",IFERROR(""&VLOOKUP(E18,Inventário!$B$13:$J$42,9,FALSE()),"")) | J18: =IF(C18="","",IFERROR(VLOOKUP(C18,Referência!$B$6:$I$15,2,FALSE()),"")&", "&IFERROR(VLOOKUP(C18,Referência!$B$6:$I$15,3,FALSE()),"")) | K18: =IF(C18="","",IFERROR(VLOOKUP(C18,Referência!$B$6:$I$15,5,FALSE()),"")) | L18: =IF(E18="",IF(C18="","","Sem microfone"),IF(IFERROR(""&VLOOKUP(E18,Inventário!$B$13:$J$42,3,FALSE()),"")&IFERROR(""&VLOOKUP(E18,Inventário!$B$13:$J$42,4,FALSE()),"")&IFERROR(""&VLOOKUP(E18,Inventário!$B$13:$J$42,7,FALSE()),"")="","Não cadastrado",IF(IFERROR(""&VLOOKUP(E18,Inventário!$B$13:$J$42,7,FALSE()),"")="Defeito","Defeito",IF(COUNTIF($E$13:E18,E18)>1,"Repetido",IF(C18="","Sem fonte",IF(AND(IFERROR(VLOOKUP(C18,Referência!$B$6:$I$15,7,FALSE()),"")<>"Qualquer",G18<>IFERROR(VLOOKUP(C18,Referência!$B$6:$I$15,7,FALSE()),"")),"Tipo diferente",IF(NOT(OR(IFERROR(VLOOKUP(C18,Referência!$B$6:$I$15,8,FALSE()),"")="Qualquer",AND(IFERROR(VLOOKUP(C18,Referência!$B$6:$I$15,8,FALSE()),"")="Direcional",OR(H18="Cardioide",H18="Supercardioide",H18="Hipercardioide")),IFERROR(VLOOKUP(C18,Referência!$B$6:$I$15,8,FALSE()),"")=H18)),"Padrão diferente",IF(IFERROR(""&VLOOKUP(E18,Inventário!$B$13:$J$42,7,FALSE()),"")<>"OK","Testar","OK")))))))) | M18: =IF(L18="","",IF(L18="Sem microfone","Escolha um microfone do inventário",IF(L18="Não cadastrado","Cadastre o microfone na aba Inventário",IF(L18="Defeito","Troque de microfone e separe este para conserto",IF(L18="Repetido","Já está em um canal anterior: escolha outro",IF(L18="Sem fonte","Escolha o tipo de fonte",IF(L18="Tipo diferente","Sugestão: "&IFERROR(VLOOKUP(C18,Referência!$B$6:$I$15,7,FALSE()),"")&". Confira se este serve",IF(L18="Padrão diferente","Confira o padrão e o lugar do retorno",IF(L18="Testar","Teste com a voz antes do evento",IF(I18="Sim","Ligue o phantom com o canal fechado","Manter")))))))))) | N18: =IF(C18="","",IFERROR(VLOOKUP(C18,Referência!$B$6:$I$15,6,FALSE()),""))
B19: 7 | F19: =IF(E19="","",IFERROR(""&VLOOKUP(E19,Inventário!$B$13:$J$42,3,FALSE()),"")) | G19: =IF(E19="","",IFERROR(""&VLOOKUP(E19,Inventário!$B$13:$J$42,4,FALSE()),"")) | H19: =IF(E19="","",IFERROR(""&VLOOKUP(E19,Inventário!$B$13:$J$42,5,FALSE()),"")) | I19: =IF(E19="","",IFERROR(""&VLOOKUP(E19,Inventário!$B$13:$J$42,9,FALSE()),"")) | J19: =IF(C19="","",IFERROR(VLOOKUP(C19,Referência!$B$6:$I$15,2,FALSE()),"")&", "&IFERROR(VLOOKUP(C19,Referência!$B$6:$I$15,3,FALSE()),"")) | K19: =IF(C19="","",IFERROR(VLOOKUP(C19,Referência!$B$6:$I$15,5,FALSE()),"")) | L19: =IF(E19="",IF(C19="","","Sem microfone"),IF(IFERROR(""&VLOOKUP(E19,Inventário!$B$13:$J$42,3,FALSE()),"")&IFERROR(""&VLOOKUP(E19,Inventário!$B$13:$J$42,4,FALSE()),"")&IFERROR(""&VLOOKUP(E19,Inventário!$B$13:$J$42,7,FALSE()),"")="","Não cadastrado",IF(IFERROR(""&VLOOKUP(E19,Inventário!$B$13:$J$42,7,FALSE()),"")="Defeito","Defeito",IF(COUNTIF($E$13:E19,E19)>1,"Repetido",IF(C19="","Sem fonte",IF(AND(IFERROR(VLOOKUP(C19,Referência!$B$6:$I$15,7,FALSE()),"")<>"Qualquer",G19<>IFERROR(VLOOKUP(C19,Referência!$B$6:$I$15,7,FALSE()),"")),"Tipo diferente",IF(NOT(OR(IFERROR(VLOOKUP(C19,Referência!$B$6:$I$15,8,FALSE()),"")="Qualquer",AND(IFERROR(VLOOKUP(C19,Referência!$B$6:$I$15,8,FALSE()),"")="Direcional",OR(H19="Cardioide",H19="Supercardioide",H19="Hipercardioide")),IFERROR(VLOOKUP(C19,Referência!$B$6:$I$15,8,FALSE()),"")=H19)),"Padrão diferente",IF(IFERROR(""&VLOOKUP(E19,Inventário!$B$13:$J$42,7,FALSE()),"")<>"OK","Testar","OK")))))))) | M19: =IF(L19="","",IF(L19="Sem microfone","Escolha um microfone do inventário",IF(L19="Não cadastrado","Cadastre o microfone na aba Inventário",IF(L19="Defeito","Troque de microfone e separe este para conserto",IF(L19="Repetido","Já está em um canal anterior: escolha outro",IF(L19="Sem fonte","Escolha o tipo de fonte",IF(L19="Tipo diferente","Sugestão: "&IFERROR(VLOOKUP(C19,Referência!$B$6:$I$15,7,FALSE()),"")&". Confira se este serve",IF(L19="Padrão diferente","Confira o padrão e o lugar do retorno",IF(L19="Testar","Teste com a voz antes do evento",IF(I19="Sim","Ligue o phantom com o canal fechado","Manter")))))))))) | N19: =IF(C19="","",IFERROR(VLOOKUP(C19,Referência!$B$6:$I$15,6,FALSE()),""))
B20: 8 | F20: =IF(E20="","",IFERROR(""&VLOOKUP(E20,Inventário!$B$13:$J$42,3,FALSE()),"")) | G20: =IF(E20="","",IFERROR(""&VLOOKUP(E20,Inventário!$B$13:$J$42,4,FALSE()),"")) | H20: =IF(E20="","",IFERROR(""&VLOOKUP(E20,Inventário!$B$13:$J$42,5,FALSE()),"")) | I20: =IF(E20="","",IFERROR(""&VLOOKUP(E20,Inventário!$B$13:$J$42,9,FALSE()),"")) | J20: =IF(C20="","",IFERROR(VLOOKUP(C20,Referência!$B$6:$I$15,2,FALSE()),"")&", "&IFERROR(VLOOKUP(C20,Referência!$B$6:$I$15,3,FALSE()),"")) | K20: =IF(C20="","",IFERROR(VLOOKUP(C20,Referência!$B$6:$I$15,5,FALSE()),"")) | L20: =IF(E20="",IF(C20="","","Sem microfone"),IF(IFERROR(""&VLOOKUP(E20,Inventário!$B$13:$J$42,3,FALSE()),"")&IFERROR(""&VLOOKUP(E20,Inventário!$B$13:$J$42,4,FALSE()),"")&IFERROR(""&VLOOKUP(E20,Inventário!$B$13:$J$42,7,FALSE()),"")="","Não cadastrado",IF(IFERROR(""&VLOOKUP(E20,Inventário!$B$13:$J$42,7,FALSE()),"")="Defeito","Defeito",IF(COUNTIF($E$13:E20,E20)>1,"Repetido",IF(C20="","Sem fonte",IF(AND(IFERROR(VLOOKUP(C20,Referência!$B$6:$I$15,7,FALSE()),"")<>"Qualquer",G20<>IFERROR(VLOOKUP(C20,Referência!$B$6:$I$15,7,FALSE()),"")),"Tipo diferente",IF(NOT(OR(IFERROR(VLOOKUP(C20,Referência!$B$6:$I$15,8,FALSE()),"")="Qualquer",AND(IFERROR(VLOOKUP(C20,Referência!$B$6:$I$15,8,FALSE()),"")="Direcional",OR(H20="Cardioide",H20="Supercardioide",H20="Hipercardioide")),IFERROR(VLOOKUP(C20,Referência!$B$6:$I$15,8,FALSE()),"")=H20)),"Padrão diferente",IF(IFERROR(""&VLOOKUP(E20,Inventário!$B$13:$J$42,7,FALSE()),"")<>"OK","Testar","OK")))))))) | M20: =IF(L20="","",IF(L20="Sem microfone","Escolha um microfone do inventário",IF(L20="Não cadastrado","Cadastre o microfone na aba Inventário",IF(L20="Defeito","Troque de microfone e separe este para conserto",IF(L20="Repetido","Já está em um canal anterior: escolha outro",IF(L20="Sem fonte","Escolha o tipo de fonte",IF(L20="Tipo diferente","Sugestão: "&IFERROR(VLOOKUP(C20,Referência!$B$6:$I$15,7,FALSE()),"")&". Confira se este serve",IF(L20="Padrão diferente","Confira o padrão e o lugar do retorno",IF(L20="Testar","Teste com a voz antes do evento",IF(I20="Sim","Ligue o phantom com o canal fechado","Manter")))))))))) | N20: =IF(C20="","",IFERROR(VLOOKUP(C20,Referência!$B$6:$I$15,6,FALSE()),""))
B21: 9 | F21: =IF(E21="","",IFERROR(""&VLOOKUP(E21,Inventário!$B$13:$J$42,3,FALSE()),"")) | G21: =IF(E21="","",IFERROR(""&VLOOKUP(E21,Inventário!$B$13:$J$42,4,FALSE()),"")) | H21: =IF(E21="","",IFERROR(""&VLOOKUP(E21,Inventário!$B$13:$J$42,5,FALSE()),"")) | I21: =IF(E21="","",IFERROR(""&VLOOKUP(E21,Inventário!$B$13:$J$42,9,FALSE()),"")) | J21: =IF(C21="","",IFERROR(VLOOKUP(C21,Referência!$B$6:$I$15,2,FALSE()),"")&", "&IFERROR(VLOOKUP(C21,Referência!$B$6:$I$15,3,FALSE()),"")) | K21: =IF(C21="","",IFERROR(VLOOKUP(C21,Referência!$B$6:$I$15,5,FALSE()),"")) | L21: =IF(E21="",IF(C21="","","Sem microfone"),IF(IFERROR(""&VLOOKUP(E21,Inventário!$B$13:$J$42,3,FALSE()),"")&IFERROR(""&VLOOKUP(E21,Inventário!$B$13:$J$42,4,FALSE()),"")&IFERROR(""&VLOOKUP(E21,Inventário!$B$13:$J$42,7,FALSE()),"")="","Não cadastrado",IF(IFERROR(""&VLOOKUP(E21,Inventário!$B$13:$J$42,7,FALSE()),"")="Defeito","Defeito",IF(COUNTIF($E$13:E21,E21)>1,"Repetido",IF(C21="","Sem fonte",IF(AND(IFERROR(VLOOKUP(C21,Referência!$B$6:$I$15,7,FALSE()),"")<>"Qualquer",G21<>IFERROR(VLOOKUP(C21,Referência!$B$6:$I$15,7,FALSE()),"")),"Tipo diferente",IF(NOT(OR(IFERROR(VLOOKUP(C21,Referência!$B$6:$I$15,8,FALSE()),"")="Qualquer",AND(IFERROR(VLOOKUP(C21,Referência!$B$6:$I$15,8,FALSE()),"")="Direcional",OR(H21="Cardioide",H21="Supercardioide",H21="Hipercardioide")),IFERROR(VLOOKUP(C21,Referência!$B$6:$I$15,8,FALSE()),"")=H21)),"Padrão diferente",IF(IFERROR(""&VLOOKUP(E21,Inventário!$B$13:$J$42,7,FALSE()),"")<>"OK","Testar","OK")))))))) | M21: =IF(L21="","",IF(L21="Sem microfone","Escolha um microfone do inventário",IF(L21="Não cadastrado","Cadastre o microfone na aba Inventário",IF(L21="Defeito","Troque de microfone e separe este para conserto",IF(L21="Repetido","Já está em um canal anterior: escolha outro",IF(L21="Sem fonte","Escolha o tipo de fonte",IF(L21="Tipo diferente","Sugestão: "&IFERROR(VLOOKUP(C21,Referência!$B$6:$I$15,7,FALSE()),"")&". Confira se este serve",IF(L21="Padrão diferente","Confira o padrão e o lugar do retorno",IF(L21="Testar","Teste com a voz antes do evento",IF(I21="Sim","Ligue o phantom com o canal fechado","Manter")))))))))) | N21: =IF(C21="","",IFERROR(VLOOKUP(C21,Referência!$B$6:$I$15,6,FALSE()),""))
B22: 10 | F22: =IF(E22="","",IFERROR(""&VLOOKUP(E22,Inventário!$B$13:$J$42,3,FALSE()),"")) | G22: =IF(E22="","",IFERROR(""&VLOOKUP(E22,Inventário!$B$13:$J$42,4,FALSE()),"")) | H22: =IF(E22="","",IFERROR(""&VLOOKUP(E22,Inventário!$B$13:$J$42,5,FALSE()),"")) | I22: =IF(E22="","",IFERROR(""&VLOOKUP(E22,Inventário!$B$13:$J$42,9,FALSE()),"")) | J22: =IF(C22="","",IFERROR(VLOOKUP(C22,Referência!$B$6:$I$15,2,FALSE()),"")&", "&IFERROR(VLOOKUP(C22,Referência!$B$6:$I$15,3,FALSE()),"")) | K22: =IF(C22="","",IFERROR(VLOOKUP(C22,Referência!$B$6:$I$15,5,FALSE()),"")) | L22: =IF(E22="",IF(C22="","","Sem microfone"),IF(IFERROR(""&VLOOKUP(E22,Inventário!$B$13:$J$42,3,FALSE()),"")&IFERROR(""&VLOOKUP(E22,Inventário!$B$13:$J$42,4,FALSE()),"")&IFERROR(""&VLOOKUP(E22,Inventário!$B$13:$J$42,7,FALSE()),"")="","Não cadastrado",IF(IFERROR(""&VLOOKUP(E22,Inventário!$B$13:$J$42,7,FALSE()),"")="Defeito","Defeito",IF(COUNTIF($E$13:E22,E22)>1,"Repetido",IF(C22="","Sem fonte",IF(AND(IFERROR(VLOOKUP(C22,Referência!$B$6:$I$15,7,FALSE()),"")<>"Qualquer",G22<>IFERROR(VLOOKUP(C22,Referência!$B$6:$I$15,7,FALSE()),"")),"Tipo diferente",IF(NOT(OR(IFERROR(VLOOKUP(C22,Referência!$B$6:$I$15,8,FALSE()),"")="Qualquer",AND(IFERROR(VLOOKUP(C22,Referência!$B$6:$I$15,8,FALSE()),"")="Direcional",OR(H22="Cardioide",H22="Supercardioide",H22="Hipercardioide")),IFERROR(VLOOKUP(C22,Referência!$B$6:$I$15,8,FALSE()),"")=H22)),"Padrão diferente",IF(IFERROR(""&VLOOKUP(E22,Inventário!$B$13:$J$42,7,FALSE()),"")<>"OK","Testar","OK")))))))) | M22: =IF(L22="","",IF(L22="Sem microfone","Escolha um microfone do inventário",IF(L22="Não cadastrado","Cadastre o microfone na aba Inventário",IF(L22="Defeito","Troque de microfone e separe este para conserto",IF(L22="Repetido","Já está em um canal anterior: escolha outro",IF(L22="Sem fonte","Escolha o tipo de fonte",IF(L22="Tipo diferente","Sugestão: "&IFERROR(VLOOKUP(C22,Referência!$B$6:$I$15,7,FALSE()),"")&". Confira se este serve",IF(L22="Padrão diferente","Confira o padrão e o lugar do retorno",IF(L22="Testar","Teste com a voz antes do evento",IF(I22="Sim","Ligue o phantom com o canal fechado","Manter")))))))))) | N22: =IF(C22="","",IFERROR(VLOOKUP(C22,Referência!$B$6:$I$15,6,FALSE()),""))
B23: 11 | F23: =IF(E23="","",IFERROR(""&VLOOKUP(E23,Inventário!$B$13:$J$42,3,FALSE()),"")) | G23: =IF(E23="","",IFERROR(""&VLOOKUP(E23,Inventário!$B$13:$J$42,4,FALSE()),"")) | H23: =IF(E23="","",IFERROR(""&VLOOKUP(E23,Inventário!$B$13:$J$42,5,FALSE()),"")) | I23: =IF(E23="","",IFERROR(""&VLOOKUP(E23,Inventário!$B$13:$J$42,9,FALSE()),"")) | J23: =IF(C23="","",IFERROR(VLOOKUP(C23,Referência!$B$6:$I$15,2,FALSE()),"")&", "&IFERROR(VLOOKUP(C23,Referência!$B$6:$I$15,3,FALSE()),"")) | K23: =IF(C23="","",IFERROR(VLOOKUP(C23,Referência!$B$6:$I$15,5,FALSE()),"")) | L23: =IF(E23="",IF(C23="","","Sem microfone"),IF(IFERROR(""&VLOOKUP(E23,Inventário!$B$13:$J$42,3,FALSE()),"")&IFERROR(""&VLOOKUP(E23,Inventário!$B$13:$J$42,4,FALSE()),"")&IFERROR(""&VLOOKUP(E23,Inventário!$B$13:$J$42,7,FALSE()),"")="","Não cadastrado",IF(IFERROR(""&VLOOKUP(E23,Inventário!$B$13:$J$42,7,FALSE()),"")="Defeito","Defeito",IF(COUNTIF($E$13:E23,E23)>1,"Repetido",IF(C23="","Sem fonte",IF(AND(IFERROR(VLOOKUP(C23,Referência!$B$6:$I$15,7,FALSE()),"")<>"Qualquer",G23<>IFERROR(VLOOKUP(C23,Referência!$B$6:$I$15,7,FALSE()),"")),"Tipo diferente",IF(NOT(OR(IFERROR(VLOOKUP(C23,Referência!$B$6:$I$15,8,FALSE()),"")="Qualquer",AND(IFERROR(VLOOKUP(C23,Referência!$B$6:$I$15,8,FALSE()),"")="Direcional",OR(H23="Cardioide",H23="Supercardioide",H23="Hipercardioide")),IFERROR(VLOOKUP(C23,Referência!$B$6:$I$15,8,FALSE()),"")=H23)),"Padrão diferente",IF(IFERROR(""&VLOOKUP(E23,Inventário!$B$13:$J$42,7,FALSE()),"")<>"OK","Testar","OK")))))))) | M23: =IF(L23="","",IF(L23="Sem microfone","Escolha um microfone do inventário",IF(L23="Não cadastrado","Cadastre o microfone na aba Inventário",IF(L23="Defeito","Troque de microfone e separe este para conserto",IF(L23="Repetido","Já está em um canal anterior: escolha outro",IF(L23="Sem fonte","Escolha o tipo de fonte",IF(L23="Tipo diferente","Sugestão: "&IFERROR(VLOOKUP(C23,Referência!$B$6:$I$15,7,FALSE()),"")&". Confira se este serve",IF(L23="Padrão diferente","Confira o padrão e o lugar do retorno",IF(L23="Testar","Teste com a voz antes do evento",IF(I23="Sim","Ligue o phantom com o canal fechado","Manter")))))))))) | N23: =IF(C23="","",IFERROR(VLOOKUP(C23,Referência!$B$6:$I$15,6,FALSE()),""))
B24: 12 | F24: =IF(E24="","",IFERROR(""&VLOOKUP(E24,Inventário!$B$13:$J$42,3,FALSE()),"")) | G24: =IF(E24="","",IFERROR(""&VLOOKUP(E24,Inventário!$B$13:$J$42,4,FALSE()),"")) | H24: =IF(E24="","",IFERROR(""&VLOOKUP(E24,Inventário!$B$13:$J$42,5,FALSE()),"")) | I24: =IF(E24="","",IFERROR(""&VLOOKUP(E24,Inventário!$B$13:$J$42,9,FALSE()),"")) | J24: =IF(C24="","",IFERROR(VLOOKUP(C24,Referência!$B$6:$I$15,2,FALSE()),"")&", "&IFERROR(VLOOKUP(C24,Referência!$B$6:$I$15,3,FALSE()),"")) | K24: =IF(C24="","",IFERROR(VLOOKUP(C24,Referência!$B$6:$I$15,5,FALSE()),"")) | L24: =IF(E24="",IF(C24="","","Sem microfone"),IF(IFERROR(""&VLOOKUP(E24,Inventário!$B$13:$J$42,3,FALSE()),"")&IFERROR(""&VLOOKUP(E24,Inventário!$B$13:$J$42,4,FALSE()),"")&IFERROR(""&VLOOKUP(E24,Inventário!$B$13:$J$42,7,FALSE()),"")="","Não cadastrado",IF(IFERROR(""&VLOOKUP(E24,Inventário!$B$13:$J$42,7,FALSE()),"")="Defeito","Defeito",IF(COUNTIF($E$13:E24,E24)>1,"Repetido",IF(C24="","Sem fonte",IF(AND(IFERROR(VLOOKUP(C24,Referência!$B$6:$I$15,7,FALSE()),"")<>"Qualquer",G24<>IFERROR(VLOOKUP(C24,Referência!$B$6:$I$15,7,FALSE()),"")),"Tipo diferente",IF(NOT(OR(IFERROR(VLOOKUP(C24,Referência!$B$6:$I$15,8,FALSE()),"")="Qualquer",AND(IFERROR(VLOOKUP(C24,Referência!$B$6:$I$15,8,FALSE()),"")="Direcional",OR(H24="Cardioide",H24="Supercardioide",H24="Hipercardioide")),IFERROR(VLOOKUP(C24,Referência!$B$6:$I$15,8,FALSE()),"")=H24)),"Padrão diferente",IF(IFERROR(""&VLOOKUP(E24,Inventário!$B$13:$J$42,7,FALSE()),"")<>"OK","Testar","OK")))))))) | M24: =IF(L24="","",IF(L24="Sem microfone","Escolha um microfone do inventário",IF(L24="Não cadastrado","Cadastre o microfone na aba Inventário",IF(L24="Defeito","Troque de microfone e separe este para conserto",IF(L24="Repetido","Já está em um canal anterior: escolha outro",IF(L24="Sem fonte","Escolha o tipo de fonte",IF(L24="Tipo diferente","Sugestão: "&IFERROR(VLOOKUP(C24,Referência!$B$6:$I$15,7,FALSE()),"")&". Confira se este serve",IF(L24="Padrão diferente","Confira o padrão e o lugar do retorno",IF(L24="Testar","Teste com a voz antes do evento",IF(I24="Sim","Ligue o phantom com o canal fechado","Manter")))))))))) | N24: =IF(C24="","",IFERROR(VLOOKUP(C24,Referência!$B$6:$I$15,6,FALSE()),""))
... B32: 20 | F32: =IF(E32="","",IFERROR(""&VLOOKUP(E32,Inventário!$B$13:$J$42,3,FALSE()),"")) | G32: =IF(E32="","",IFERROR(""&VLOOKUP(E32,Inventário!$B$13:$J$42,4,FALSE()),"")) | H32: =IF(E32="","",IFERROR(""&VLOOKUP(E32,Inventário!$B$13:$J$42,5,FALSE()),"")) | I32: =IF(E32="","",IFERROR(""&VLOOKUP(E32,Inventário!$B$13:$J$42,9,FALSE()),"")) | J32: =IF(C32="","",IFERROR(VLOOKUP(C32,Referência!$B$6:$I$15,2,FALSE()),"")&", "&IFERROR(VLOOKUP(C32,Referência!$B$6:$I$15,3,FALSE()),"")) | K32: =IF(C32="","",IFERROR(VLOOKUP(C32,Referência!$B$6:$I$15,5,FALSE()),"")) | L32: =IF(E32="",IF(C32="","","Sem microfone"),IF(IFERROR(""&VLOOKUP(E32,Inventário!$B$13:$J$42,3,FALSE()),"")&IFERROR(""&VLOOKUP(E32,Inventário!$B$13:$J$42,4,FALSE()),"")&IFERROR(""&VLOOKUP(E32,Inventário!$B$13:$J$42,7,FALSE()),"")="","Não cadastrado",IF(IFERROR(""&VLOOKUP(E32,Inventário!$B$13:$J$42,7,FALSE()),"")="Defeito","Defeito",IF(COUNTIF($E$13:E32,E32)>1,"Repetido",IF(C32="","Sem fonte",IF(AND(IFERROR(VLOOKUP(C32,Referência!$B$6:$I$15,7,FALSE()),"")<>"Qualquer",G32<>IFERROR(VLOOKUP(C32,Referência!$B$6:$I$15,7,FALSE()),"")),"Tipo diferente",IF(NOT(OR(IFERROR(VLOOKUP(C32,Referência!$B$6:$I$15,8,FALSE()),"")="Qualquer",AND(IFERROR(VLOOKUP(C32,Referência!$B$6:$I$15,8,FALSE()),"")="Direcional",OR(H32="Cardioide",H32="Supercardioide",H32="Hipercardioide")),IFERROR(VLOOKUP(C32,Referência!$B$6:$I$15,8,FALSE()),"")=H32)),"Padrão diferente",IF(IFERROR(""&VLOOKUP(E32,Inventário!$B$13:$J$42,7,FALSE()),"")<>"OK","Testar","OK")))))))) | M32: =IF(L32="","",IF(L32="Sem microfone","Escolha um microfone do inventário",IF(L32="Não cadastrado","Cadastre o microfone na aba Inventário",IF(L32="Defeito","Troque de microfone e separe este para conserto",IF(L32="Repetido","Já está em um canal anterior: escolha outro",IF(L32="Sem fonte","Escolha o tipo de fonte",IF(L32="Tipo diferente","Sugestão: "&IFERROR(VLOOKUP(C32,Referência!$B$6:$I$15,7,FALSE()),"")&". Confira se este serve",IF(L32="Padrão diferente","Confira o padrão e o lugar do retorno",IF(L32="Testar","Teste com a voz antes do evento",IF(I32="Sim","Ligue o phantom com o canal fechado","Manter")))))))))) | N32: =IF(C32="","",IFERROR(VLOOKUP(C32,Referência!$B$6:$I$15,6,FALSE()),""))
B34: Resumo automático
B35: Fontes listadas | E35: =COUNTA(D13:D32) -> 0
B36: Com microfone OK | E36: =COUNTIF(L13:L32,"OK") -> 0
B37: Canais com phantom | E37: =COUNTIF(I13:I32,"Sim") -> 0
B38: Defeito, repetido ou não cadastrado | E38: =COUNTIF(L13:L32,"Defeito")+COUNTIF(L13:L32,"Repetido")+COUNTIF(L13:L32,"Não cadastrado") -> 0
B39: A conferir | E39: =COUNTIF(L13:L32,"Tipo diferente")+COUNTIF(L13:L32,"Padrão diferente")+COUNTIF(L13:L32,"Testar")+COUNTIF(L13:L32,"Sem microfone")+COUNTIF(L13:L32,"Sem fonte") -> 0
B40: Aviso | E40: =IF(COUNTA(C13:C32)+COUNT(E13:E32)=0,"Liste as fontes do evento",IF(E38>0,"Há microfone com defeito, repetido ou não cadastrado: troque antes do evento",IF(E39>0,"Há escolhas a conferir","OK"))) -> Liste as fontes do evento

Sheet Regra 3 para 1
B1: Regra 3 para 1 — distância entre microfones abertos juntos
B2: Meça as distâncias em centímetros. As células cinza são calculadas.
B4: Evento | I4: A distância entre dois microfones abertos juntos deve ser pelo menos três vezes a distância de cada um até a sua fonte. Assim, o som de uma fonte chega ao microfone vizinho cerca de 10 dB mais fraco.
B5: Data
B6: Medido por
B8: Pares de microfones
B9: Par | C9: Microfone A | D9: Microfone B | E9: Abertos juntos? | F9: A até a fonte | G9: B até a fonte | H9: Entre os microfones | I9: Maior até a fonte | J9: Mínimo entre eles | K9: Razão | L9: Vazamento estimado | M9: Situação | N9: O que fazer
B10: nº | C10: quem usa | D10: quem usa | E10: Sim / Não | F10: cm | G10: cm | H10: cm | I10: cm | J10: cm = 3 × maior | K10: entre ÷ maior | L10: dB abaixo
B11: Ex. | C11: Debatedor 1 | D11: Debatedor 2 | E11: Sim | F11: 50 | G11: 50 | H11: 60 | I11: 50 | J11: 150 | K11: 1.2 | L11: 3.9 | M11: Fora da regra | N11: Aproxime cada microfone a até 20 cm da fonte, ou afaste os microfones para 150 cm
B12: A linha Ex. é o exemplo 2 do treinamento, antes da correção: a mesa de debate com som oco.
B13: 1 | I13: =IF(OR(F13="",G13="",H13=""),"",MAX(F13,G13)) | J13: =IF(I13="","",3*I13) | K13: =IF(OR(I13="",I13=0),"",ROUND(H13/I13,1)) | L13: =IF(OR(I13="",I13=0),"",ROUND(20*LOG10(SQRT(H13^2+I13^2)/I13),1)) | M13: =IF(K13="","",IF(E13="Não","Não somam",IF(K13>=3,"OK",IF(K13>=2,"Perto do limite","Fora da regra")))) | N13: =IF(M13="","",IF(M13="Não somam","Mantenha só um aberto por vez",IF(M13="OK","Manter","Aproxime cada microfone a até "&ROUND(H13/3,0)&" cm da fonte, ou afaste os microfones para "&J13&" cm")))
B14: 2 | I14: =IF(OR(F14="",G14="",H14=""),"",MAX(F14,G14)) | J14: =IF(I14="","",3*I14) | K14: =IF(OR(I14="",I14=0),"",ROUND(H14/I14,1)) | L14: =IF(OR(I14="",I14=0),"",ROUND(20*LOG10(SQRT(H14^2+I14^2)/I14),1)) | M14: =IF(K14="","",IF(E14="Não","Não somam",IF(K14>=3,"OK",IF(K14>=2,"Perto do limite","Fora da regra")))) | N14: =IF(M14="","",IF(M14="Não somam","Mantenha só um aberto por vez",IF(M14="OK","Manter","Aproxime cada microfone a até "&ROUND(H14/3,0)&" cm da fonte, ou afaste os microfones para "&J14&" cm")))
B15: 3 | I15: =IF(OR(F15="",G15="",H15=""),"",MAX(F15,G15)) | J15: =IF(I15="","",3*I15) | K15: =IF(OR(I15="",I15=0),"",ROUND(H15/I15,1)) | L15: =IF(OR(I15="",I15=0),"",ROUND(20*LOG10(SQRT(H15^2+I15^2)/I15),1)) | M15: =IF(K15="","",IF(E15="Não","Não somam",IF(K15>=3,"OK",IF(K15>=2,"Perto do limite","Fora da regra")))) | N15: =IF(M15="","",IF(M15="Não somam","Mantenha só um aberto por vez",IF(M15="OK","Manter","Aproxime cada microfone a até "&ROUND(H15/3,0)&" cm da fonte, ou afaste os microfones para "&J15&" cm")))
B16: 4 | I16: =IF(OR(F16="",G16="",H16=""),"",MAX(F16,G16)) | J16: =IF(I16="","",3*I16) | K16: =IF(OR(I16="",I16=0),"",ROUND(H16/I16,1)) | L16: =IF(OR(I16="",I16=0),"",ROUND(20*LOG10(SQRT(H16^2+I16^2)/I16),1)) | M16: =IF(K16="","",IF(E16="Não","Não somam",IF(K16>=3,"OK",IF(K16>=2,"Perto do limite","Fora da regra")))) | N16: =IF(M16="","",IF(M16="Não somam","Mantenha só um aberto por vez",IF(M16="OK","Manter","Aproxime cada microfone a até "&ROUND(H16/3,0)&" cm da fonte, ou afaste os microfones para "&J16&" cm")))
B17: 5 | I17: =IF(OR(F17="",G17="",H17=""),"",MAX(F17,G17)) | J17: =IF(I17="","",3*I17) | K17: =IF(OR(I17="",I17=0),"",ROUND(H17/I17,1)) | L17: =IF(OR(I17="",I17=0),"",ROUND(20*LOG10(SQRT(H17^2+I17^2)/I17),1)) | M17: =IF(K17="","",IF(E17="Não","Não somam",IF(K17>=3,"OK",IF(K17>=2,"Perto do limite","Fora da regra")))) | N17: =IF(M17="","",IF(M17="Não somam","Mantenha só um aberto por vez",IF(M17="OK","Manter","Aproxime cada microfone a até "&ROUND(H17/3,0)&" cm da fonte, ou afaste os microfones para "&J17&" cm")))
B18: 6 | I18: =IF(OR(F18="",G18="",H18=""),"",MAX(F18,G18)) | J18: =IF(I18="","",3*I18) | K18: =IF(OR(I18="",I18=0),"",ROUND(H18/I18,1)) | L18: =IF(OR(I18="",I18=0),"",ROUND(20*LOG10(SQRT(H18^2+I18^2)/I18),1)) | M18: =IF(K18="","",IF(E18="Não","Não somam",IF(K18>=3,"OK",IF(K18>=2,"Perto do limite","Fora da regra")))) | N18: =IF(M18="","",IF(M18="Não somam","Mantenha só um aberto por vez",IF(M18="OK","Manter","Aproxime cada microfone a até "&ROUND(H18/3,0)&" cm da fonte, ou afaste os microfones para "&J18&" cm")))
B19: 7 | I19: =IF(OR(F19="",G19="",H19=""),"",MAX(F19,G19)) | J19: =IF(I19="","",3*I19) | K19: =IF(OR(I19="",I19=0),"",ROUND(H19/I19,1)) | L19: =IF(OR(I19="",I19=0),"",ROUND(20*LOG10(SQRT(H19^2+I19^2)/I19),1)) | M19: =IF(K19="","",IF(E19="Não","Não somam",IF(K19>=3,"OK",IF(K19>=2,"Perto do limite","Fora da regra")))) | N19: =IF(M19="","",IF(M19="Não somam","Mantenha só um aberto por vez",IF(M19="OK","Manter","Aproxime cada microfone a até "&ROUND(H19/3,0)&" cm da fonte, ou afaste os microfones para "&J19&" cm")))
B20: 8 | I20: =IF(OR(F20="",G20="",H20=""),"",MAX(F20,G20)) | J20: =IF(I20="","",3*I20) | K20: =IF(OR(I20="",I20=0),"",ROUND(H20/I20,1)) | L20: =IF(OR(I20="",I20=0),"",ROUND(20*LOG10(SQRT(H20^2+I20^2)/I20),1)) | M20: =IF(K20="","",IF(E20="Não","Não somam",IF(K20>=3,"OK",IF(K20>=2,"Perto do limite","Fora da regra")))) | N20: =IF(M20="","",IF(M20="Não somam","Mantenha só um aberto por vez",IF(M20="OK","Manter","Aproxime cada microfone a até "&ROUND(H20/3,0)&" cm da fonte, ou afaste os microfones para "&J20&" cm")))
B21: 9 | I21: =IF(OR(F21="",G21="",H21=""),"",MAX(F21,G21)) | J21: =IF(I21="","",3*I21) | K21: =IF(OR(I21="",I21=0),"",ROUND(H21/I21,1)) | L21: =IF(OR(I21="",I21=0),"",ROUND(20*LOG10(SQRT(H21^2+I21^2)/I21),1)) | M21: =IF(K21="","",IF(E21="Não","Não somam",IF(K21>=3,"OK",IF(K21>=2,"Perto do limite","Fora da regra")))) | N21: =IF(M21="","",IF(M21="Não somam","Mantenha só um aberto por vez",IF(M21="OK","Manter","Aproxime cada microfone a até "&ROUND(H21/3,0)&" cm da fonte, ou afaste os microfones para "&J21&" cm")))
B22: 10 | I22: =IF(OR(F22="",G22="",H22=""),"",MAX(F22,G22)) | J22: =IF(I22="","",3*I22) | K22: =IF(OR(I22="",I22=0),"",ROUND(H22/I22,1)) | L22: =IF(OR(I22="",I22=0),"",ROUND(20*LOG10(SQRT(H22^2+I22^2)/I22),1)) | M22: =IF(K22="","",IF(E22="Não","Não somam",IF(K22>=3,"OK",IF(K22>=2,"Perto do limite","Fora da regra")))) | N22: =IF(M22="","",IF(M22="Não somam","Mantenha só um aberto por vez",IF(M22="OK","Manter","Aproxime cada microfone a até "&ROUND(H22/3,0)&" cm da fonte, ou afaste os microfones para "&J22&" cm")))
B23: 11 | I23: =IF(OR(F23="",G23="",H23=""),"",MAX(F23,G23)) | J23: =IF(I23="","",3*I23) | K23: =IF(OR(I23="",I23=0),"",ROUND(H23/I23,1)) | L23: =IF(OR(I23="",I23=0),"",ROUND(20*LOG10(SQRT(H23^2+I23^2)/I23),1)) | M23: =IF(K23="","",IF(E23="Não","Não somam",IF(K23>=3,"OK",IF(K23>=2,"Perto do limite","Fora da regra")))) | N23: =IF(M23="","",IF(M23="Não somam","Mantenha só um aberto por vez",IF(M23="OK","Manter","Aproxime cada microfone a até "&ROUND(H23/3,0)&" cm da fonte, ou afaste os microfones para "&J23&" cm")))
B24: 12 | I24: =IF(OR(F24="",G24="",H24=""),"",MAX(F24,G24)) | J24: =IF(I24="","",3*I24) | K24: =IF(OR(I24="",I24=0),"",ROUND(H24/I24,1)) | L24: =IF(OR(I24="",I24=0),"",ROUND(20*LOG10(SQRT(H24^2+I24^2)/I24),1)) | M24: =IF(K24="","",IF(E24="Não","Não somam",IF(K24>=3,"OK",IF(K24>=2,"Perto do limite","Fora da regra")))) | N24: =IF(M24="","",IF(M24="Não somam","Mantenha só um aberto por vez",IF(M24="OK","Manter","Aproxime cada microfone a até "&ROUND(H24/3,0)&" cm da fonte, ou afaste os microfones para "&J24&" cm")))
B26: Resumo automático
B27: Pares avaliados | E27: =COUNTIF(M13:M24,"OK")+COUNTIF(M13:M24,"Não somam")+COUNTIF(M13:M24,"Perto do limite")+COUNTIF(M13:M24,"Fora da regra") -> 0
B28: Dentro da regra | E28: =COUNTIF(M13:M24,"OK")+COUNTIF(M13:M24,"Não somam") -> 0
B29: Perto do limite | E29: =COUNTIF(M13:M24,"Perto do limite") -> 0
B30: Fora da regra | E30: =COUNTIF(M13:M24,"Fora da regra") -> 0
B31: Aviso | E31: =IF(E27=0,"Meça os pares de microfones abertos juntos",IF(E30>0,"Há par fora da regra: aproxime cada microfone da sua fonte",IF(E29>0,"Há par perto do limite: confira o timbre com os dois abertos","OK"))) -> Meça os pares de microfones abertos juntos
B32: O corte de 2 para “Perto do limite” é regra prática deste material. Dois microfones na mesma boca (dois goosenecks no púlpito) nunca cumprem a regra: use um só.

Sheet Referência
B1: Referência — microfones
B2: Valores de referência, para servir de ponto de partida. Confira o manual do seu equipamento.
B4: Ponto de partida por fonte (consultada pela aba Escolha por fonte: não mude a ordem das colunas)
B5: Fonte | C5: Tipo | D5: Padrão | E5: Formato | F5: Distância | G5: Posição e direção | H5: Tipo aceito | I5: Padrão aceito
B6: Voz cantada | C6: Dinâmico | D6: Cardioide ou supercardioide | E6: De mão | F6: 2 a 5 cm | G6: Apontado para a boca. Retorno na direção de maior rejeição do padrão. | H6: Qualquer | I6: Direcional
B7: Voz falada | C7: Dinâmico ou condensador | D7: Conforme o formato | E7: De mão, headset, gooseneck ou lapela | F7: O mais perto que o formato permite | G7: Um microfone por pessoa que fala, e só o dela aberto. | H7: Qualquer | I7: Qualquer
B8: Coral | C8: Condensador | D8: Cardioide | E8: Coral suspenso ou pedestal alto | F8: 60 a 90 cm à frente da 1ª fila | G8: Acima das cabeças, apontado para a última fila. Um para cada 15 a 20 vozes. | H8: Condensador | I8: Direcional
B9: Violão | C9: Condensador | D9: Cardioide | E9: Lápis | F9: 15 a 30 cm | G9: Apontado para a junção do braço com o corpo, e não para a boca do violão. | H9: Condensador | I9: Direcional
B10: Amplificador | C10: Dinâmico | D10: Cardioide | E10: De mão ou instrumento | F10: 2 a 10 cm da tela | G10: Apontado para o alto-falante: no centro, mais brilho; perto da borda, mais corpo. | H10: Dinâmico | I10: Direcional
B11: Bumbo | C11: Dinâmico | D11: Cardioide | E11: Instrumento (próprio para graves) | F11: Dentro do casco ou no furo da pele | G11: Perto da pele batida, mais ataque. No furo, mais corpo. | H11: Dinâmico | I11: Direcional
B12: Caixa e tons | C12: Dinâmico | D12: Cardioide ou supercardioide | E12: De mão ou clip | F12: 3 a 5 cm acima da pele | G12: Junto ao aro, apontado para o centro da pele. Na caixa, ponto surdo para o chimbal. | H12: Dinâmico | I12: Direcional
B13: Chimbal e pratos | C13: Condensador | D13: Cardioide | E13: Lápis | F13: Chimbal: 10 a 15 cm. Pratos: 60 a 100 cm | G13: Chimbal de cima, do lado oposto à caixa. Pratos: um ou dois apontados para baixo. | H13: Condensador | I13: Direcional
B14: Piano | C14: Condensador | D14: Cardioide | E14: Lápis | F14: 15 a 30 cm das cordas | G14: Tampa aberta. Com dois: um sobre as cordas agudas, outro sobre as graves. | H14: Condensador | I14: Direcional
B15: Ambiente | C15: Condensador | D15: Cardioide | E15: Lápis | F15: Longe das caixas do PA | G15: Voltado para o público. Só para a transmissão ou a gravação, fechado no PA. | H15: Condensador | I15: Qualquer
B16: Tipo aceito e Padrão aceito definem quando a aba Escolha por fonte marca “Tipo diferente” ou “Padrão diferente”. Direcional = cardioide, supercardioide ou hipercardioide.
B18: Padrões polares (valores do padrão ideal, em relação à frente)
B19: Padrão | C19: Lados (90°) | D19: Atrás (180°) | E19: Maior rejeição | F19: Onde pôr o retorno | G19: Uso típico
B20: Cardioide | C20: −6 dB | D20: quase nada | E20: 180°, bem atrás | F20: Bem atrás do microfone | G20: O mais comum: voz de mão, púlpito, coral, instrumentos.
B21: Supercardioide | C21: −9 dB | D21: −12 dB | E21: cerca de 125° | F21: Em diagonal, nunca bem atrás | G21: Voz em palco com volume alto, gooseneck, caixa e tons.
B22: Hipercardioide | C22: −12 dB | D22: −6 dB | E22: cerca de 110° | F22: Em diagonal, mais para o lado | G22: Quando o que atrapalha está dos lados.
B23: Omni | C23: 0 dB | D23: 0 dB | E23: não tem | F23: Longe: não ajuda a rejeitar | G23: Lapela e headset, sempre muito perto da boca. Sem efeito de proximidade.
B24: Figura de 8 | C24: quase nada | D24: 0 dB | E24: 90°, nos dois lados | F24: Em um dos lados | G24: Raro ao vivo. Padrão natural do microfone de fita.
B26: Dinâmico e condensador
C27: Dinâmico | E27: Condensador | G27: Observação
B28: Energia | C28: Não precisa | E28: Phantom, pilha ou transmissor
B29: Nível de saída | C29: 1 a 3 mV/Pa | E29: 5 a 30 mV/Pa
B30: Robustez | C30: Alta | E30: Menor
B31: Uso típico | C31: Voz de mão, bateria, amplificador | E31: Coral, púlpito, lapela, violão, pratos
B33: Distância até a fonte e nível no microfone (campo livre, em relação a 5 cm)
B34: Distância | C34: Nível | D34: Formato típico | F34: Observação
B35: 2,5 cm | C35: +6 dB | D35: Headset, canto de perto
B36: 5 cm | C36: 0 dB | D36: De mão (canto e fala)
B37: 10 cm | C37: −6 dB | D37: De mão (fala)
B38: 20 cm | C38: −12 dB | D38: Lapela, gooseneck de perto
B39: 40 cm | C39: −18 dB | D39: Gooseneck de longe
B40: 80 cm | C40: −24 dB | D40: Coral suspenso
B41: Faixas típicas, que variam com o modelo, a fonte e a sala. Confira o manual e a ficha técnica do seu microfone.

Sheet Checklist
B1: Checklist dos microfones
B2: Confira na montagem, antes do ajuste de ganho, e de novo ao guardar o equipamento.
B4: # | C4: Grupo | D4: Item | E4: Situação | F4: Observação
B5: 1 | C5: Escolha | D5: Cada fonte tem um microfone definido, com tipo e formato adequados a ela.
B6: 2 | C6: Escolha | D6: O padrão polar de cada microfone é conhecido, e cada retorno está na direção de maior rejeição do microfone à frente dele.
B7: 3 | C7: Escolha | D7: O phantom está ligado só nos canais que precisam dele, e foi ligado com o canal fechado.
B8: 4 | C8: Escolha | D8: Todos os microfones foram testados com a voz, um por vez, com o cabo e o canal que vão usar.
B9: 5 | C9: Posição | D9: Cada microfone está o mais perto da fonte que o formato permite, e apontado para ela.
B10: 6 | C10: Posição | D10: Os microfones que ficam abertos juntos respeitam a regra 3:1.
B11: 7 | C11: Posição | D11: Nenhum microfone fica à frente das caixas do PA nem apontado para um retorno.
B12: 8 | C12: Posição | D12: A lapela e o headset estão firmes, na posição certa, com a cápsula descoberta e o cabo preso.
B13: 9 | C13: Uso | D13: Quem usa microfone de mão foi orientado: perto da boca, apontado para ela, mão no corpo.
B14: 10 | C14: Uso | D14: Há espuma ou protetor de vento onde é preciso, e o filtro passa-altas está ligado nos canais de voz.
B15: 11 | C15: Uso | D15: Só ficam abertos os microfones em uso, e há um microfone reserva com fio, testado.
B16: 12 | C16: Depois | D16: Depois do evento, os microfones foram limpos, secos e guardados no estojo, e os defeitos foram anotados no inventário.
B18: Itens respondidos | E18: =COUNTA(E5:E16) -> 0
B19: Percentual atendido (Parcial vale metade) | E19: =IF(COUNTA(E5:E16)=0,"",(COUNTIF(E5:E16,"Sim")+COUNTIF(E5:E16,"Parcial")/2)/COUNTA(E5:E16))
B20: Situação | E20: =IF(COUNTA(E5:E16)<12,"Incompleto",IF(COUNTIF(E5:E16,"Não")=0,"OK","Há itens a resolver")) -> Incompleto

Sheet Exemplo - Escolha
B1: Escolha de microfone por fonte
B2: Exemplo preenchido, para consulta. Use a aba Escolha por fonte para o seu evento.
B4: Evento | D4: Culto de domingo, 19 h | I4: A sugestão de cada fonte vem da aba Referência e é ponto de partida. “Tipo diferente” ou “Padrão diferente” pedem conferência, e não troca obrigatória.
B5: Local | D5: Igreja de 200 lugares
B6: Data | D6: 46299
B7: Operador | D7: Operador de som da escala
B9: Fontes do evento
B10: Canal | C10: Tipo de fonte | D10: Descrição | E10: Microfone nº | F10: Formato | G10: Tipo | H10: Padrão | I10: Phantom | J10: Sugestão: tipo e padrão | K10: Distância de partida | L10: Situação | M10: O que fazer | N10: Posição de partida
