Workbook

Sheet Instruções
B1: Sinais e cabos de vídeo — como usar esta planilha
B2: Mapa de sinais, inventário de cabos e conversores e roteiro de diagnóstico, para usar na montagem e no evento.
B4: Legenda: onde preencher
B5: Amarelo-claro | C5: Células de entrada. É aqui que você digita.
B6: Cinza | C6: Células calculadas ou fixas (rótulos, contas, avisos). Não altere.
B7: Cinza em itálico | C7: Linha de exemplo (marcada com “Ex.”) e dicas de preenchimento. Não entram nas contas.
B8: Listas suspensas | C8: Formato, ligação, tipo de item e respostas Sim ou Não aceitam só as opções da lista.
B9: Formatos | C9: São escritos como nos menus dos equipamentos, com ponto: 1080p59.94. No treinamento, o mesmo formato aparece como 1080p59,94.
B10: Comentários | C10: Células com triângulo vermelho no canto trazem uma dica. Passe o mouse sobre elas.
B12: Ordem de preenchimento
B13: 1 | C13: Aba Mapa de sinais: escolha o padrão do sistema e confira a tabela de limites de comprimento.
B14: 2 | C14: Aba Mapa de sinais: registre um trecho por linha, da origem para o destino, com o comprimento pelo caminho real do cabo.
B15: 3 | C15: Veja a situação e o que fazer em cada trecho. Corrija o formato na origem, ou mude o tipo de ligação, e atualize a linha.
B16: 4 | C16: Aba Inventário: liste cabos, conversores, extensores e placas de captura, com a data e o resultado do teste.
B17: 5 | C17: Aba Checklist: confira os doze itens na montagem, antes do ensaio.
B18: 6 | C18: Aba Diagnóstico: se faltar imagem, responda às dez perguntas na ordem e registre a ocorrência.
B20: Abas da planilha
B21: Mapa de sinais | C21: Até 20 trechos, com alerta de formato diferente do padrão e de comprimento acima do recomendado.
B22: Inventário | C22: Até 30 itens, com situação calculada: OK, Testar, Testar de novo, Falta fonte ou Retirar.
B23: Diagnóstico | C23: Roteiro de dez perguntas para o “sem sinal”, com a correção do primeiro “Não”, e registro de ocorrências.
B24: Referência | C24: Tabela de formatos, tipos de ligação, aparelhos do caminho e sintomas com as causas prováveis.
B25: Checklist | C25: Os doze itens do treinamento, com percentual atendido.
B26: Exemplo - Mapa | C26: O sistema de uma igreja com três câmeras, antes das correções (exemplo 1 do treinamento).
B28: Regras e premissas do modelo
B29: Padrão do sistema | C29: É o formato em que todas as origens devem estar. O modelo compara o texto exato: 1080p59.94 e 1080p60 são formatos diferentes.
B30: Destino converte? | C30: Marque Sim quando o destino tem conversor de formato na entrada. O formato diferente passa a contar como Convertido, sem alerta.
B31: Classe do formato | C31: HD, 3G, 6G ou 12G, pela quantidade de dados. Os nomes vêm dos níveis do SDI e servem aqui para escolher o limite de qualquer ligação.
B32: Limites de comprimento | C32: São pontos de partida conservadores, e não especificação. Troque-os pelos valores do manual dos seus cabos e extensores.
B33: No limite | C33: Aviso para trechos acima de 80% do limite. O percentual pode ser trocado no alto da aba.
B34: Trecho com conversor | C34: Registre cada lado do conversor em uma linha: da origem ao conversor, e do conversor ao destino.
B35: Inventário | C35: O teste vence depois do prazo informado no alto da aba (180 dias no modelo), contado até a data da conferência.
B36: Exemplos | C36: Os dados da aba de exemplo são ilustrativos, criados para este material.

Sheet Mapa de sinais
B1: Mapa de sinais de vídeo — origem, formato, cabo e destino
B2: Preencha as células em amarelo-claro, um trecho por linha. As células cinza são calculadas.
B4: Evento ou sistema | G4: Limite recomendado (m) | H4: HD | I4: 3G | J4: 6G | K4: 12G | L4: HD: 720p, 1080i e 1080p até 30 · 3G: 1080p de 50 a 60 · 6G: 4K até 30 · 12G: 4K de 50 a 60
B5: Local | G5: HDMI passivo | H5: 10 | I5: 10 | J5: 5 | K5: 3 | L5: Cabo comum. Acima de 5 m, só cabo de boa qualidade e testado.
B6: Data | G6: HDMI ativo ou óptico | H6: 30 | I6: 30 | J6: 30 | K6: 30 | L6: Conforme o fabricante: há cabos ópticos de até 100 m. Têm sentido certo.
B7: Responsável | G7: SDI | H7: 100 | I7: 70 | J7: 50 | K7: 30 | L7: Coaxial de 75 ohms de bitola cheia. Com cabo fino, use a metade.
B8: Padrão do sistema | D8: 1080p59.94 | G8: HDBaseT | H8: 70 | I8: 70 | J8: 40 | K8: 40 | L8: Conforme a classe do extensor e a categoria do cabo de rede.
B9: Aviso “No limite” a partir de | D9: 0.8 | G9: Fibra | H9: 300 | I9: 300 | J9: 300 | K9: 300 | L9: Conforme o conversor. Fibra monomodo alcança quilômetros.
B10: O formato é escrito como nos menus dos equipamentos, com ponto: 1080p59.94. | G10: Rede (NDI) | H10: 100 | I10: 100 | J10: 100 | K10: 100 | L10: Por trecho de cabo, entre o aparelho e o switch de rede.
B11: 59.94 e 60 são formatos diferentes. Confira o que cada aparelho entrega de fato. | G11: USB | H11: 3 | I11: 3 | J11: 3 | K11: 3 | L11: USB 3 com cabo passivo. Em USB 2, até 5 m.
B13: Trechos do sistema, da origem para o destino
B14: # | C14: Origem | D14: Formato enviado | E14: Ligação | F14: Comprimento | G14: Destino | H14: Destino converte? | I14: Classe | J14: Limite | K14: Formato | L14: Cabo | M14: Situação | N14: O que fazer | O14: Observação
C15: aparelho e saída | D15: saída da origem | E15: cabo ou extensor | F15: metros | G15: aparelho e entrada | H15: Sim / Não | I15: do formato | J15: metros | K15: × padrão | L15: × limite
B16: Ex. | C16: Câmera 1 (fundo) | D16: 1080p59.94 | E16: SDI | F16: 40 | G16: Switcher, entrada 1 | H16: Não | I16: 3G | J16: 70 | K16: Igual | L16: OK | M16: OK | N16: Manter
B17: 1 | I17: =IF(D17="","",IFERROR(VLOOKUP(D17,Referência!$B$6:$I$26,5,0),"")) | J17: =IF(OR(D17="",E17=""),"",IFERROR(1/(1/INDEX($H$5:$K$11,MATCH(E17,$G$5:$G$11,0),VLOOKUP(D17,Referência!$B$6:$I$26,6,0))),"")) | K17: =IF(OR(D17="",$D$8=""),"",IF(D17=$D$8,"Igual",IF(H17="Sim","Convertido","Diferente"))) | L17: =IF(OR(F17="",J17=""),"",IF(F17>J17,"Acima",IF(F17>J17*IF($D$9="",1,$D$9),"No limite","OK"))) | M17: =IF(AND(K17="",L17=""),"",IF(AND(K17="Diferente",L17="Acima"),"Formato e cabo",IF(K17="Diferente","Formato",IF(L17="Acima","Comprimento",IF(L17="No limite","No limite",IF(OR(K17="",L17=""),"Incompleto","OK")))))) | N17: =IF(M17="","",IF(M17="Formato e cabo","Ajuste a origem para "&$D$8&" e troque o tipo de ligação do trecho",IF(M17="Formato","Ajuste a saída da origem para "&$D$8&", ou use um scaler antes do destino",IF(M17="Comprimento",IF(E17="HDMI passivo","Use SDI com conversor, HDBaseT ou cabo HDMI óptico",IF(E17="USB","Aproxime o computador ou use extensão USB ativa","Encurte o trecho, use cabo melhor ou passe para fibra")),IF(M17="No limite","Teste com o cabo no caminho real e tenha um reserva",IF(M17="Incompleto","Informe o formato, a ligação e o comprimento","Manter"))))))
B18: 2 | I18: =IF(D18="","",IFERROR(VLOOKUP(D18,Referência!$B$6:$I$26,5,0),"")) | J18: =IF(OR(D18="",E18=""),"",IFERROR(1/(1/INDEX($H$5:$K$11,MATCH(E18,$G$5:$G$11,0),VLOOKUP(D18,Referência!$B$6:$I$26,6,0))),"")) | K18: =IF(OR(D18="",$D$8=""),"",IF(D18=$D$8,"Igual",IF(H18="Sim","Convertido","Diferente"))) | L18: =IF(OR(F18="",J18=""),"",IF(F18>J18,"Acima",IF(F18>J18*IF($D$9="",1,$D$9),"No limite","OK"))) | M18: =IF(AND(K18="",L18=""),"",IF(AND(K18="Diferente",L18="Acima"),"Formato e cabo",IF(K18="Diferente","Formato",IF(L18="Acima","Comprimento",IF(L18="No limite","No limite",IF(OR(K18="",L18=""),"Incompleto","OK")))))) | N18: =IF(M18="","",IF(M18="Formato e cabo","Ajuste a origem para "&$D$8&" e troque o tipo de ligação do trecho",IF(M18="Formato","Ajuste a saída da origem para "&$D$8&", ou use um scaler antes do destino",IF(M18="Comprimento",IF(E18="HDMI passivo","Use SDI com conversor, HDBaseT ou cabo HDMI óptico",IF(E18="USB","Aproxime o computador ou use extensão USB ativa","Encurte o trecho, use cabo melhor ou passe para fibra")),IF(M18="No limite","Teste com o cabo no caminho real e tenha um reserva",IF(M18="Incompleto","Informe o formato, a ligação e o comprimento","Manter"))))))
B19: 3 | I19: =IF(D19="","",IFERROR(VLOOKUP(D19,Referência!$B$6:$I$26,5,0),"")) | J19: =IF(OR(D19="",E19=""),"",IFERROR(1/(1/INDEX($H$5:$K$11,MATCH(E19,$G$5:$G$11,0),VLOOKUP(D19,Referência!$B$6:$I$26,6,0))),"")) | K19: =IF(OR(D19="",$D$8=""),"",IF(D19=$D$8,"Igual",IF(H19="Sim","Convertido","Diferente"))) | L19: =IF(OR(F19="",J19=""),"",IF(F19>J19,"Acima",IF(F19>J19*IF($D$9="",1,$D$9),"No limite","OK"))) | M19: =IF(AND(K19="",L19=""),"",IF(AND(K19="Diferente",L19="Acima"),"Formato e cabo",IF(K19="Diferente","Formato",IF(L19="Acima","Comprimento",IF(L19="No limite","No limite",IF(OR(K19="",L19=""),"Incompleto","OK")))))) | N19: =IF(M19="","",IF(M19="Formato e cabo","Ajuste a origem para "&$D$8&" e troque o tipo de ligação do trecho",IF(M19="Formato","Ajuste a saída da origem para "&$D$8&", ou use um scaler antes do destino",IF(M19="Comprimento",IF(E19="HDMI passivo","Use SDI com conversor, HDBaseT ou cabo HDMI óptico",IF(E19="USB","Aproxime o computador ou use extensão USB ativa","Encurte o trecho, use cabo melhor ou passe para fibra")),IF(M19="No limite","Teste com o cabo no caminho real e tenha um reserva",IF(M19="Incompleto","Informe o formato, a ligação e o comprimento","Manter"))))))
B20: 4 | I20: =IF(D20="","",IFERROR(VLOOKUP(D20,Referência!$B$6:$I$26,5,0),"")) | J20: =IF(OR(D20="",E20=""),"",IFERROR(1/(1/INDEX($H$5:$K$11,MATCH(E20,$G$5:$G$11,0),VLOOKUP(D20,Referência!$B$6:$I$26,6,0))),"")) | K20: =IF(OR(D20="",$D$8=""),"",IF(D20=$D$8,"Igual",IF(H20="Sim","Convertido","Diferente"))) | L20: =IF(OR(F20="",J20=""),"",IF(F20>J20,"Acima",IF(F20>J20*IF($D$9="",1,$D$9),"No limite","OK"))) | M20: =IF(AND(K20="",L20=""),"",IF(AND(K20="Diferente",L20="Acima"),"Formato e cabo",IF(K20="Diferente","Formato",IF(L20="Acima","Comprimento",IF(L20="No limite","No limite",IF(OR(K20="",L20=""),"Incompleto","OK")))))) | N20: =IF(M20="","",IF(M20="Formato e cabo","Ajuste a origem para "&$D$8&" e troque o tipo de ligação do trecho",IF(M20="Formato","Ajuste a saída da origem para "&$D$8&", ou use um scaler antes do destino",IF(M20="Comprimento",IF(E20="HDMI passivo","Use SDI com conversor, HDBaseT ou cabo HDMI óptico",IF(E20="USB","Aproxime o computador ou use extensão USB ativa","Encurte o trecho, use cabo melhor ou passe para fibra")),IF(M20="No limite","Teste com o cabo no caminho real e tenha um reserva",IF(M20="Incompleto","Informe o formato, a ligação e o comprimento","Manter"))))))
B21: 5 | I21: =IF(D21="","",IFERROR(VLOOKUP(D21,Referência!$B$6:$I$26,5,0),"")) | J21: =IF(OR(D21="",E21=""),"",IFERROR(1/(1/INDEX($H$5:$K$11,MATCH(E21,$G$5:$G$11,0),VLOOKUP(D21,Referência!$B$6:$I$26,6,0))),"")) | K21: =IF(OR(D21="",$D$8=""),"",IF(D21=$D$8,"Igual",IF(H21="Sim","Convertido","Diferente"))) | L21: =IF(OR(F21="",J21=""),"",IF(F21>J21,"Acima",IF(F21>J21*IF($D$9="",1,$D$9),"No limite","OK"))) | M21: =IF(AND(K21="",L21=""),"",IF(AND(K21="Diferente",L21="Acima"),"Formato e cabo",IF(K21="Diferente","Formato",IF(L21="Acima","Comprimento",IF(L21="No limite","No limite",IF(OR(K21="",L21=""),"Incompleto","OK")))))) | N21: =IF(M21="","",IF(M21="Formato e cabo","Ajuste a origem para "&$D$8&" e troque o tipo de ligação do trecho",IF(M21="Formato","Ajuste a saída da origem para "&$D$8&", ou use um scaler antes do destino",IF(M21="Comprimento",IF(E21="HDMI passivo","Use SDI com conversor, HDBaseT ou cabo HDMI óptico",IF(E21="USB","Aproxime o computador ou use extensão USB ativa","Encurte o trecho, use cabo melhor ou passe para fibra")),IF(M21="No limite","Teste com o cabo no caminho real e tenha um reserva",IF(M21="Incompleto","Informe o formato, a ligação e o comprimento","Manter"))))))
B22: 6 | I22: =IF(D22="","",IFERROR(VLOOKUP(D22,Referência!$B$6:$I$26,5,0),"")) | J22: =IF(OR(D22="",E22=""),"",IFERROR(1/(1/INDEX($H$5:$K$11,MATCH(E22,$G$5:$G$11,0),VLOOKUP(D22,Referência!$B$6:$I$26,6,0))),"")) | K22: =IF(OR(D22="",$D$8=""),"",IF(D22=$D$8,"Igual",IF(H22="Sim","Convertido","Diferente"))) | L22: =IF(OR(F22="",J22=""),"",IF(F22>J22,"Acima",IF(F22>J22*IF($D$9="",1,$D$9),"No limite","OK"))) | M22: =IF(AND(K22="",L22=""),"",IF(AND(K22="Diferente",L22="Acima"),"Formato e cabo",IF(K22="Diferente","Formato",IF(L22="Acima","Comprimento",IF(L22="No limite","No limite",IF(OR(K22="",L22=""),"Incompleto","OK")))))) | N22: =IF(M22="","",IF(M22="Formato e cabo","Ajuste a origem para "&$D$8&" e troque o tipo de ligação do trecho",IF(M22="Formato","Ajuste a saída da origem para "&$D$8&", ou use um scaler antes do destino",IF(M22="Comprimento",IF(E22="HDMI passivo","Use SDI com conversor, HDBaseT ou cabo HDMI óptico",IF(E22="USB","Aproxime o computador ou use extensão USB ativa","Encurte o trecho, use cabo melhor ou passe para fibra")),IF(M22="No limite","Teste com o cabo no caminho real e tenha um reserva",IF(M22="Incompleto","Informe o formato, a ligação e o comprimento","Manter"))))))
B23: 7 | I23: =IF(D23="","",IFERROR(VLOOKUP(D23,Referência!$B$6:$I$26,5,0),"")) | J23: =IF(OR(D23="",E23=""),"",IFERROR(1/(1/INDEX($H$5:$K$11,MATCH(E23,$G$5:$G$11,0),VLOOKUP(D23,Referência!$B$6:$I$26,6,0))),"")) | K23: =IF(OR(D23="",$D$8=""),"",IF(D23=$D$8,"Igual",IF(H23="Sim","Convertido","Diferente"))) | L23: =IF(OR(F23="",J23=""),"",IF(F23>J23,"Acima",IF(F23>J23*IF($D$9="",1,$D$9),"No limite","OK"))) | M23: =IF(AND(K23="",L23=""),"",IF(AND(K23="Diferente",L23="Acima"),"Formato e cabo",IF(K23="Diferente","Formato",IF(L23="Acima","Comprimento",IF(L23="No limite","No limite",IF(OR(K23="",L23=""),"Incompleto","OK")))))) | N23: =IF(M23="","",IF(M23="Formato e cabo","Ajuste a origem para "&$D$8&" e troque o tipo de ligação do trecho",IF(M23="Formato","Ajuste a saída da origem para "&$D$8&", ou use um scaler antes do destino",IF(M23="Comprimento",IF(E23="HDMI passivo","Use SDI com conversor, HDBaseT ou cabo HDMI óptico",IF(E23="USB","Aproxime o computador ou use extensão USB ativa","Encurte o trecho, use cabo melhor ou passe para fibra")),IF(M23="No limite","Teste com o cabo no caminho real e tenha um reserva",IF(M23="Incompleto","Informe o formato, a ligação e o comprimento","Manter"))))))
B24: 8 | I24: =IF(D24="","",IFERROR(VLOOKUP(D24,Referência!$B$6:$I$26,5,0),"")) | J24: =IF(OR(D24="",E24=""),"",IFERROR(1/(1/INDEX($H$5:$K$11,MATCH(E24,$G$5:$G$11,0),VLOOKUP(D24,Referência!$B$6:$I$26,6,0))),"")) | K24: =IF(OR(D24="",$D$8=""),"",IF(D24=$D$8,"Igual",IF(H24="Sim","Convertido","Diferente"))) | L24: =IF(OR(F24="",J24=""),"",IF(F24>J24,"Acima",IF(F24>J24*IF($D$9="",1,$D$9),"No limite","OK"))) | M24: =IF(AND(K24="",L24=""),"",IF(AND(K24="Diferente",L24="Acima"),"Formato e cabo",IF(K24="Diferente","Formato",IF(L24="Acima","Comprimento",IF(L24="No limite","No limite",IF(OR(K24="",L24=""),"Incompleto","OK")))))) | N24: =IF(M24="","",IF(M24="Formato e cabo","Ajuste a origem para "&$D$8&" e troque o tipo de ligação do trecho",IF(M24="Formato","Ajuste a saída da origem para "&$D$8&", ou use um scaler antes do destino",IF(M24="Comprimento",IF(E24="HDMI passivo","Use SDI com conversor, HDBaseT ou cabo HDMI óptico",IF(E24="USB","Aproxime o computador ou use extensão USB ativa","Encurte o trecho, use cabo melhor ou passe para fibra")),IF(M24="No limite","Teste com o cabo no caminho real e tenha um reserva",IF(M24="Incompleto","Informe o formato, a ligação e o comprimento","Manter"))))))
B25: 9 | I25: =IF(D25="","",IFERROR(VLOOKUP(D25,Referência!$B$6:$I$26,5,0),"")) | J25: =IF(OR(D25="",E25=""),"",IFERROR(1/(1/INDEX($H$5:$K$11,MATCH(E25,$G$5:$G$11,0),VLOOKUP(D25,Referência!$B$6:$I$26,6,0))),"")) | K25: =IF(OR(D25="",$D$8=""),"",IF(D25=$D$8,"Igual",IF(H25="Sim","Convertido","Diferente"))) | L25: =IF(OR(F25="",J25=""),"",IF(F25>J25,"Acima",IF(F25>J25*IF($D$9="",1,$D$9),"No limite","OK"))) | M25: =IF(AND(K25="",L25=""),"",IF(AND(K25="Diferente",L25="Acima"),"Formato e cabo",IF(K25="Diferente","Formato",IF(L25="Acima","Comprimento",IF(L25="No limite","No limite",IF(OR(K25="",L25=""),"Incompleto","OK")))))) | N25: =IF(M25="","",IF(M25="Formato e cabo","Ajuste a origem para "&$D$8&" e troque o tipo de ligação do trecho",IF(M25="Formato","Ajuste a saída da origem para "&$D$8&", ou use um scaler antes do destino",IF(M25="Comprimento",IF(E25="HDMI passivo","Use SDI com conversor, HDBaseT ou cabo HDMI óptico",IF(E25="USB","Aproxime o computador ou use extensão USB ativa","Encurte o trecho, use cabo melhor ou passe para fibra")),IF(M25="No limite","Teste com o cabo no caminho real e tenha um reserva",IF(M25="Incompleto","Informe o formato, a ligação e o comprimento","Manter"))))))
B26: 10 | I26: =IF(D26="","",IFERROR(VLOOKUP(D26,Referência!$B$6:$I$26,5,0),"")) | J26: =IF(OR(D26="",E26=""),"",IFERROR(1/(1/INDEX($H$5:$K$11,MATCH(E26,$G$5:$G$11,0),VLOOKUP(D26,Referência!$B$6:$I$26,6,0))),"")) | K26: =IF(OR(D26="",$D$8=""),"",IF(D26=$D$8,"Igual",IF(H26="Sim","Convertido","Diferente"))) | L26: =IF(OR(F26="",J26=""),"",IF(F26>J26,"Acima",IF(F26>J26*IF($D$9="",1,$D$9),"No limite","OK"))) | M26: =IF(AND(K26="",L26=""),"",IF(AND(K26="Diferente",L26="Acima"),"Formato e cabo",IF(K26="Diferente","Formato",IF(L26="Acima","Comprimento",IF(L26="No limite","No limite",IF(OR(K26="",L26=""),"Incompleto","OK")))))) | N26: =IF(M26="","",IF(M26="Formato e cabo","Ajuste a origem para "&$D$8&" e troque o tipo de ligação do trecho",IF(M26="Formato","Ajuste a saída da origem para "&$D$8&", ou use um scaler antes do destino",IF(M26="Comprimento",IF(E26="HDMI passivo","Use SDI com conversor, HDBaseT ou cabo HDMI óptico",IF(E26="USB","Aproxime o computador ou use extensão USB ativa","Encurte o trecho, use cabo melhor ou passe para fibra")),IF(M26="No limite","Teste com o cabo no caminho real e tenha um reserva",IF(M26="Incompleto","Informe o formato, a ligação e o comprimento","Manter"))))))
B27: 11 | I27: =IF(D27="","",IFERROR(VLOOKUP(D27,Referência!$B$6:$I$26,5,0),"")) | J27: =IF(OR(D27="",E27=""),"",IFERROR(1/(1/INDEX($H$5:$K$11,MATCH(E27,$G$5:$G$11,0),VLOOKUP(D27,Referência!$B$6:$I$26,6,0))),"")) | K27: =IF(OR(D27="",$D$8=""),"",IF(D27=$D$8,"Igual",IF(H27="Sim","Convertido","Diferente"))) | L27: =IF(OR(F27="",J27=""),"",IF(F27>J27,"Acima",IF(F27>J27*IF($D$9="",1,$D$9),"No limite","OK"))) | M27: =IF(AND(K27="",L27=""),"",IF(AND(K27="Diferente",L27="Acima"),"Formato e cabo",IF(K27="Diferente","Formato",IF(L27="Acima","Comprimento",IF(L27="No limite","No limite",IF(OR(K27="",L27=""),"Incompleto","OK")))))) | N27: =IF(M27="","",IF(M27="Formato e cabo","Ajuste a origem para "&$D$8&" e troque o tipo de ligação do trecho",IF(M27="Formato","Ajuste a saída da origem para "&$D$8&", ou use um scaler antes do destino",IF(M27="Comprimento",IF(E27="HDMI passivo","Use SDI com conversor, HDBaseT ou cabo HDMI óptico",IF(E27="USB","Aproxime o computador ou use extensão USB ativa","Encurte o trecho, use cabo melhor ou passe para fibra")),IF(M27="No limite","Teste com o cabo no caminho real e tenha um reserva",IF(M27="Incompleto","Informe o formato, a ligação e o comprimento","Manter"))))))
B28: 12 | I28: =IF(D28="","",IFERROR(VLOOKUP(D28,Referência!$B$6:$I$26,5,0),"")) | J28: =IF(OR(D28="",E28=""),"",IFERROR(1/(1/INDEX($H$5:$K$11,MATCH(E28,$G$5:$G$11,0),VLOOKUP(D28,Referência!$B$6:$I$26,6,0))),"")) | K28: =IF(OR(D28="",$D$8=""),"",IF(D28=$D$8,"Igual",IF(H28="Sim","Convertido","Diferente"))) | L28: =IF(OR(F28="",J28=""),"",IF(F28>J28,"Acima",IF(F28>J28*IF($D$9="",1,$D$9),"No limite","OK"))) | M28: =IF(AND(K28="",L28=""),"",IF(AND(K28="Diferente",L28="Acima"),"Formato e cabo",IF(K28="Diferente","Formato",IF(L28="Acima","Comprimento",IF(L28="No limite","No limite",IF(OR(K28="",L28=""),"Incompleto","OK")))))) | N28: =IF(M28="","",IF(M28="Formato e cabo","Ajuste a origem para "&$D$8&" e troque o tipo de ligação do trecho",IF(M28="Formato","Ajuste a saída da origem para "&$D$8&", ou use um scaler antes do destino",IF(M28="Comprimento",IF(E28="HDMI passivo","Use SDI com conversor, HDBaseT ou cabo HDMI óptico",IF(E28="USB","Aproxime o computador ou use extensão USB ativa","Encurte o trecho, use cabo melhor ou passe para fibra")),IF(M28="No limite","Teste com o cabo no caminho real e tenha um reserva",IF(M28="Incompleto","Informe o formato, a ligação e o comprimento","Manter"))))))
... B36: 20 | I36: =IF(D36="","",IFERROR(VLOOKUP(D36,Referência!$B$6:$I$26,5,0),"")) | J36: =IF(OR(D36="",E36=""),"",IFERROR(1/(1/INDEX($H$5:$K$11,MATCH(E36,$G$5:$G$11,0),VLOOKUP(D36,Referência!$B$6:$I$26,6,0))),"")) | K36: =IF(OR(D36="",$D$8=""),"",IF(D36=$D$8,"Igual",IF(H36="Sim","Convertido","Diferente"))) | L36: =IF(OR(F36="",J36=""),"",IF(F36>J36,"Acima",IF(F36>J36*IF($D$9="",1,$D$9),"No limite","OK"))) | M36: =IF(AND(K36="",L36=""),"",IF(AND(K36="Diferente",L36="Acima"),"Formato e cabo",IF(K36="Diferente","Formato",IF(L36="Acima","Comprimento",IF(L36="No limite","No limite",IF(OR(K36="",L36=""),"Incompleto","OK")))))) | N36: =IF(M36="","",IF(M36="Formato e cabo","Ajuste a origem para "&$D$8&" e troque o tipo de ligação do trecho",IF(M36="Formato","Ajuste a saída da origem para "&$D$8&", ou use um scaler antes do destino",IF(M36="Comprimento",IF(E36="HDMI passivo","Use SDI com conversor, HDBaseT ou cabo HDMI óptico",IF(E36="USB","Aproxime o computador ou use extensão USB ativa","Encurte o trecho, use cabo melhor ou passe para fibra")),IF(M36="No limite","Teste com o cabo no caminho real e tenha um reserva",IF(M36="Incompleto","Informe o formato, a ligação e o comprimento","Manter"))))))
B38: Resumo automático
B39: Trechos registrados | F39: =COUNTA(C17:C36) -> 0
B40: Trechos com situação OK | F40: =COUNTIF(M17:M36,"OK") -> 0
B41: Formato diferente do padrão | F41: =COUNTIF(M17:M36,"Formato")+COUNTIF(M17:M36,"Formato e cabo") -> 0
B42: Comprimento acima do recomendado | F42: =COUNTIF(M17:M36,"Comprimento")+COUNTIF(M17:M36,"Formato e cabo") -> 0
B43: Comprimento no limite | F43: =COUNTIF(M17:M36,"No limite") -> 0
B44: Trechos com conversão de formato | F44: =COUNTIF(K17:K36,"Convertido") -> 0
B45: Cabo total (m) | F45: =IF(COUNT(F17:F36)=0,"",SUM(F17:F36))
B46: Aviso | F46: =IF($D$8="","Informe o padrão do sistema",IF(F39=0,"Liste os trechos",IF(F41>0,"Há origem em formato diferente do padrão: corrija antes do ensaio",IF(F42>0,"Há trecho acima do comprimento recomendado: mude o tipo de ligação",IF(COUNTIF(M17:M36,"Incompleto")>0,"Há trecho incompleto",IF(F43>0,"Há trecho no limite: teste no caminho real e leve reserva","OK")))))) -> Liste os trechos
B47: Os limites são pontos de partida conservadores, e não especificação. Troque-os pelos valores do manual dos seus cabos e extensores, ou pelo que você comprovou em teste.

Sheet Inventário
B1: Inventário de cabos e conversores de vídeo
B2: Um item por linha. Teste cada cabo no formato do sistema e anote a data. As células cinza são calculadas.
B4: Local ou sistema | H4: Identifique cada cabo nas duas pontas com o mesmo nome que está nesta lista.
B5: Responsável | H5: Teste do cabo: no formato do sistema, por alguns minutos, mexendo de leve nos conectores.
B6: Data da conferência | H6: Cabo intermitente é cabo com defeito: tire do uso antes que falhe no evento.
B7: Testar de novo após (dias) | D7: 180 | H7: Guarde cada conversor junto da própria fonte e do cabo curto que o acompanha.
B9: Cabos, conversores, extensores e placas de captura
B10: # | C10: Item e identificação | D10: Tipo | E10: Comprimento | F10: Suporta até | G10: Qtde | H10: Precisa de fonte? | I10: Fonte junto? | J10: Testado em | K10: Resultado | L10: Onde fica | M10: Dias | N10: Situação | O10: O que fazer | P10: Observação
C11: nome da etiqueta | E11: metros | F11: classe | H11: Sim / Não | I11: Sim / Não | J11: data | K11: do teste | M11: desde o teste
B12: Ex. | C12: SDI-01, coaxial preto | D12: Cabo SDI | E12: 40 | F12: 3G | G12: 1 | H12: Não | J12: 04/10/2026 | K12: OK | L12: Caixa de cabos 2 | M12: 0 | N12: OK | O12: Manter
B13: 1 | M13: =IF(OR(J13="",$D$6=""),"",$D$6-J13) | N13: =IF(C13="","",IF(OR(K13="Com defeito",K13="Intermitente"),"Retirar",IF(AND(H13="Sim",I13<>"Sim"),"Falta fonte",IF(OR(J13="",K13=""),"Testar",IF(AND(M13<>"",$D$7<>"",M13>$D$7),"Testar de novo","OK"))))) | O13: =IF(N13="","",IF(N13="Retirar","Marque como defeituoso e tire do uso",IF(N13="Falta fonte","Localize a fonte e guarde junto do aparelho",IF(N13="Testar","Teste no formato do sistema e anote a data",IF(N13="Testar de novo","Teste vencido: repita antes do próximo evento","Manter")))))
B14: 2 | M14: =IF(OR(J14="",$D$6=""),"",$D$6-J14) | N14: =IF(C14="","",IF(OR(K14="Com defeito",K14="Intermitente"),"Retirar",IF(AND(H14="Sim",I14<>"Sim"),"Falta fonte",IF(OR(J14="",K14=""),"Testar",IF(AND(M14<>"",$D$7<>"",M14>$D$7),"Testar de novo","OK"))))) | O14: =IF(N14="","",IF(N14="Retirar","Marque como defeituoso e tire do uso",IF(N14="Falta fonte","Localize a fonte e guarde junto do aparelho",IF(N14="Testar","Teste no formato do sistema e anote a data",IF(N14="Testar de novo","Teste vencido: repita antes do próximo evento","Manter")))))
B15: 3 | M15: =IF(OR(J15="",$D$6=""),"",$D$6-J15) | N15: =IF(C15="","",IF(OR(K15="Com defeito",K15="Intermitente"),"Retirar",IF(AND(H15="Sim",I15<>"Sim"),"Falta fonte",IF(OR(J15="",K15=""),"Testar",IF(AND(M15<>"",$D$7<>"",M15>$D$7),"Testar de novo","OK"))))) | O15: =IF(N15="","",IF(N15="Retirar","Marque como defeituoso e tire do uso",IF(N15="Falta fonte","Localize a fonte e guarde junto do aparelho",IF(N15="Testar","Teste no formato do sistema e anote a data",IF(N15="Testar de novo","Teste vencido: repita antes do próximo evento","Manter")))))
B16: 4 | M16: =IF(OR(J16="",$D$6=""),"",$D$6-J16) | N16: =IF(C16="","",IF(OR(K16="Com defeito",K16="Intermitente"),"Retirar",IF(AND(H16="Sim",I16<>"Sim"),"Falta fonte",IF(OR(J16="",K16=""),"Testar",IF(AND(M16<>"",$D$7<>"",M16>$D$7),"Testar de novo","OK"))))) | O16: =IF(N16="","",IF(N16="Retirar","Marque como defeituoso e tire do uso",IF(N16="Falta fonte","Localize a fonte e guarde junto do aparelho",IF(N16="Testar","Teste no formato do sistema e anote a data",IF(N16="Testar de novo","Teste vencido: repita antes do próximo evento","Manter")))))
B17: 5 | M17: =IF(OR(J17="",$D$6=""),"",$D$6-J17) | N17: =IF(C17="","",IF(OR(K17="Com defeito",K17="Intermitente"),"Retirar",IF(AND(H17="Sim",I17<>"Sim"),"Falta fonte",IF(OR(J17="",K17=""),"Testar",IF(AND(M17<>"",$D$7<>"",M17>$D$7),"Testar de novo","OK"))))) | O17: =IF(N17="","",IF(N17="Retirar","Marque como defeituoso e tire do uso",IF(N17="Falta fonte","Localize a fonte e guarde junto do aparelho",IF(N17="Testar","Teste no formato do sistema e anote a data",IF(N17="Testar de novo","Teste vencido: repita antes do próximo evento","Manter")))))
B18: 6 | M18: =IF(OR(J18="",$D$6=""),"",$D$6-J18) | N18: =IF(C18="","",IF(OR(K18="Com defeito",K18="Intermitente"),"Retirar",IF(AND(H18="Sim",I18<>"Sim"),"Falta fonte",IF(OR(J18="",K18=""),"Testar",IF(AND(M18<>"",$D$7<>"",M18>$D$7),"Testar de novo","OK"))))) | O18: =IF(N18="","",IF(N18="Retirar","Marque como defeituoso e tire do uso",IF(N18="Falta fonte","Localize a fonte e guarde junto do aparelho",IF(N18="Testar","Teste no formato do sistema e anote a data",IF(N18="Testar de novo","Teste vencido: repita antes do próximo evento","Manter")))))
B19: 7 | M19: =IF(OR(J19="",$D$6=""),"",$D$6-J19) | N19: =IF(C19="","",IF(OR(K19="Com defeito",K19="Intermitente"),"Retirar",IF(AND(H19="Sim",I19<>"Sim"),"Falta fonte",IF(OR(J19="",K19=""),"Testar",IF(AND(M19<>"",$D$7<>"",M19>$D$7),"Testar de novo","OK"))))) | O19: =IF(N19="","",IF(N19="Retirar","Marque como defeituoso e tire do uso",IF(N19="Falta fonte","Localize a fonte e guarde junto do aparelho",IF(N19="Testar","Teste no formato do sistema e anote a data",IF(N19="Testar de novo","Teste vencido: repita antes do próximo evento","Manter")))))
B20: 8 | M20: =IF(OR(J20="",$D$6=""),"",$D$6-J20) | N20: =IF(C20="","",IF(OR(K20="Com defeito",K20="Intermitente"),"Retirar",IF(AND(H20="Sim",I20<>"Sim"),"Falta fonte",IF(OR(J20="",K20=""),"Testar",IF(AND(M20<>"",$D$7<>"",M20>$D$7),"Testar de novo","OK"))))) | O20: =IF(N20="","",IF(N20="Retirar","Marque como defeituoso e tire do uso",IF(N20="Falta fonte","Localize a fonte e guarde junto do aparelho",IF(N20="Testar","Teste no formato do sistema e anote a data",IF(N20="Testar de novo","Teste vencido: repita antes do próximo evento","Manter")))))
B21: 9 | M21: =IF(OR(J21="",$D$6=""),"",$D$6-J21) | N21: =IF(C21="","",IF(OR(K21="Com defeito",K21="Intermitente"),"Retirar",IF(AND(H21="Sim",I21<>"Sim"),"Falta fonte",IF(OR(J21="",K21=""),"Testar",IF(AND(M21<>"",$D$7<>"",M21>$D$7),"Testar de novo","OK"))))) | O21: =IF(N21="","",IF(N21="Retirar","Marque como defeituoso e tire do uso",IF(N21="Falta fonte","Localize a fonte e guarde junto do aparelho",IF(N21="Testar","Teste no formato do sistema e anote a data",IF(N21="Testar de novo","Teste vencido: repita antes do próximo evento","Manter")))))
B22: 10 | M22: =IF(OR(J22="",$D$6=""),"",$D$6-J22) | N22: =IF(C22="","",IF(OR(K22="Com defeito",K22="Intermitente"),"Retirar",IF(AND(H22="Sim",I22<>"Sim"),"Falta fonte",IF(OR(J22="",K22=""),"Testar",IF(AND(M22<>"",$D$7<>"",M22>$D$7),"Testar de novo","OK"))))) | O22: =IF(N22="","",IF(N22="Retirar","Marque como defeituoso e tire do uso",IF(N22="Falta fonte","Localize a fonte e guarde junto do aparelho",IF(N22="Testar","Teste no formato do sistema e anote a data",IF(N22="Testar de novo","Teste vencido: repita antes do próximo evento","Manter")))))
B23: 11 | M23: =IF(OR(J23="",$D$6=""),"",$D$6-J23) | N23: =IF(C23="","",IF(OR(K23="Com defeito",K23="Intermitente"),"Retirar",IF(AND(H23="Sim",I23<>"Sim"),"Falta fonte",IF(OR(J23="",K23=""),"Testar",IF(AND(M23<>"",$D$7<>"",M23>$D$7),"Testar de novo","OK"))))) | O23: =IF(N23="","",IF(N23="Retirar","Marque como defeituoso e tire do uso",IF(N23="Falta fonte","Localize a fonte e guarde junto do aparelho",IF(N23="Testar","Teste no formato do sistema e anote a data",IF(N23="Testar de novo","Teste vencido: repita antes do próximo evento","Manter")))))
B24: 12 | M24: =IF(OR(J24="",$D$6=""),"",$D$6-J24) | N24: =IF(C24="","",IF(OR(K24="Com defeito",K24="Intermitente"),"Retirar",IF(AND(H24="Sim",I24<>"Sim"),"Falta fonte",IF(OR(J24="",K24=""),"Testar",IF(AND(M24<>"",$D$7<>"",M24>$D$7),"Testar de novo","OK"))))) | O24: =IF(N24="","",IF(N24="Retirar","Marque como defeituoso e tire do uso",IF(N24="Falta fonte","Localize a fonte e guarde junto do aparelho",IF(N24="Testar","Teste no formato do sistema e anote a data",IF(N24="Testar de novo","Teste vencido: repita antes do próximo evento","Manter")))))
... B42: 30 | M42: =IF(OR(J42="",$D$6=""),"",$D$6-J42) | N42: =IF(C42="","",IF(OR(K42="Com defeito",K42="Intermitente"),"Retirar",IF(AND(H42="Sim",I42<>"Sim"),"Falta fonte",IF(OR(J42="",K42=""),"Testar",IF(AND(M42<>"",$D$7<>"",M42>$D$7),"Testar de novo","OK"))))) | O42: =IF(N42="","",IF(N42="Retirar","Marque como defeituoso e tire do uso",IF(N42="Falta fonte","Localize a fonte e guarde junto do aparelho",IF(N42="Testar","Teste no formato do sistema e anote a data",IF(N42="Testar de novo","Teste vencido: repita antes do próximo evento","Manter")))))
B44: Resumo automático
B45: Itens registrados | F45: =COUNTA(C13:C42) -> 0
B46: Em condições de uso (OK) | F46: =COUNTIF(N13:N42,"OK") -> 0
B47: A testar | F47: =COUNTIF(N13:N42,"Testar")+COUNTIF(N13:N42,"Testar de novo") -> 0
B48: Sem a fonte | F48: =COUNTIF(N13:N42,"Falta fonte") -> 0
B49: A retirar do uso | F49: =COUNTIF(N13:N42,"Retirar") -> 0
B50: Aviso | F50: =IF(F45=0,"Liste os itens",IF(F49>0,"Há item com defeito: retire antes do evento",IF(F48>0,"Há aparelho sem a fonte",IF(F47>0,"Há item sem teste em dia","OK")))) -> Liste os itens

Sheet Diagnóstico
B1: Diagnóstico — roteiro para “sem sinal”
B2: Responda na ordem. No primeiro “Não”, faça a correção indicada, teste e só então siga adiante.
B4: Evento | F4: Mude uma coisa de cada vez e teste depois de cada mudança.
B5: Data | F5: Tenha à mão um cabo curto testado e um monitor ou TV de teste.
B6: Trecho (origem → destino) | F6: Imagem que pisca ou chuvisca aponta para o cabo: comece pelos itens 3, 4 e 8.
B7: Sintoma | F7: Tela preta só com um conteúdo ou um aparelho aponta para o item 7.
B8: Quem conferiu | F8: Depois de resolver, registre a ocorrência no fim desta aba.
B10: Roteiro, do destino para a origem
B11: # | C11: Pergunta | E11: Resposta | F11: Se a resposta for Não | G11: Observação
B12: 1 | C12: O destino (projetor, TV, switcher) está ligado e na entrada em que o cabo está? | F12: Ligue o destino e selecione a entrada certa.
B13: 2 | C13: A origem está ligada, acordada e com a saída de vídeo ativa? No computador: tela estendida ou duplicada. | F13: Ligue ou acorde a origem. No computador, ative a segunda tela.
B14: 3 | C14: Os conectores estão encaixados até o fim nas duas pontas, e os BNC, travados? | F14: Refaça os encaixes, uma ponta por vez, olhando a imagem.
B15: 4 | C15: O cabo ativo ou óptico está no sentido certo, com a ponta de origem na origem? Com cabo comum, responda Sim. | F15: Inverta o cabo.
B16: 5 | C16: Os conversores, extensores e distribuidores do trecho estão com a luz de energia acesa? | F16: Religue a fonte. Se a luz não acender, troque de tomada ou de fonte.
B17: 6 | C17: O formato de saída da origem é o padrão do sistema, ou um formato que o destino aceita? | F17: Ajuste a saída da origem para o padrão do sistema e espere alguns segundos.
B18: 7 | C18: A origem é livre de proteção (câmera, ou computador com conteúdo próprio)? | F18: Provável HDCP: teste a origem direto em uma TV e troque a fonte do conteúdo.
B19: 8 | C19: O comprimento do trecho está dentro do recomendado na aba Mapa de sinais? | F19: Teste com um cabo mais curto. Se resolver, mude o tipo de ligação do trecho.
B20: 9 | C20: A origem, ligada direto em um monitor por um cabo curto e testado, mostra imagem? | F20: O defeito está na origem: confira o menu de saída, reinicie e teste outra porta.
B21: 10 | C21: Outra origem que funciona, ligada no lugar desta, aparece no destino? | F21: O defeito está no cabo, no conversor ou na entrada do destino: troque um de cada vez.
B23: Resultado
B24: Itens respondidos | E24: =COUNTA(E12:E21) -> 0
B25: Primeiro item com resposta Não | E25: =IF(COUNTIF(E12:E21,"Não")=0,"",MATCH("Não",E12:E21,0))
B26: O que fazer agora | E26: =IF(E25<>"",INDEX(F12:F21,E25),IF(COUNTA(E12:E21)=0,"Responda às perguntas na ordem",IF(COUNTA(E12:E21)<10,"Continue respondendo na ordem","Tudo conferido. Religue na ordem destino, meio, origem. Se continuar, troque um aparelho por vez"))) -> Responda às perguntas na ordem
B27: Situação | E27: =IF(COUNTA(E12:E21)=0,"",IF(E25<>"","Corrigir o item "&E25,IF(COUNTA(E12:E21)<10,"Em andamento","OK")))
B29: Registro de ocorrências
B30: # | C30: Data | D30: Trecho e sintoma | F30: Causa encontrada e o que resolveu | G30: Para não repetir
B31: 1
B32: 2
B33: 3
B34: 4
B35: 5
B36: 6
B37: 7
B38: 8

Sheet Referência
B1: Referência — formatos, ligações e sintomas
B2: Valores de referência, para servir de ponto de partida. Confira o manual do seu equipamento.
B4: Formatos de vídeo (tabela consultada pelas outras abas: não altere a primeira coluna)
B5: Formato | C5: Resolução | D5: Varredura | E5: Imagens por segundo | F5: Classe | G5: Nº | H5: SDI necessário | I5: Cabo HDMI indicado
B6: 720p50 | C6: 1280 × 720 | D6: Progressiva | E6: 50 quadros | F6: HD | G6: 1 | H6: HD-SDI | I6: High Speed
B7: 720p59.94 | C7: 1280 × 720 | D7: Progressiva | E7: 59,94 quadros | F7: HD | G7: 1 | H7: HD-SDI | I7: High Speed
B8: 720p60 | C8: 1280 × 720 | D8: Progressiva | E8: 60 quadros | F8: HD | G8: 1 | H8: HD-SDI | I8: High Speed
B9: 1080i50 | C9: 1920 × 1080 | D9: Entrelaçada | E9: 50 campos | F9: HD | G9: 1 | H9: HD-SDI | I9: High Speed
B10: 1080i59.94 | C10: 1920 × 1080 | D10: Entrelaçada | E10: 59,94 campos | F10: HD | G10: 1 | H10: HD-SDI | I10: High Speed
B11: 1080i60 | C11: 1920 × 1080 | D11: Entrelaçada | E11: 60 campos | F11: HD | G11: 1 | H11: HD-SDI | I11: High Speed
B12: 1080p23.98 | C12: 1920 × 1080 | D12: Progressiva | E12: 23,98 quadros | F12: HD | G12: 1 | H12: HD-SDI | I12: High Speed
B13: 1080p24 | C13: 1920 × 1080 | D13: Progressiva | E13: 24 quadros | F13: HD | G13: 1 | H13: HD-SDI | I13: High Speed
B14: 1080p25 | C14: 1920 × 1080 | D14: Progressiva | E14: 25 quadros | F14: HD | G14: 1 | H14: HD-SDI | I14: High Speed
B15: 1080p29.97 | C15: 1920 × 1080 | D15: Progressiva | E15: 29,97 quadros | F15: HD | G15: 1 | H15: HD-SDI | I15: High Speed
B16: 1080p30 | C16: 1920 × 1080 | D16: Progressiva | E16: 30 quadros | F16: HD | G16: 1 | H16: HD-SDI | I16: High Speed
B17: 1080p50 | C17: 1920 × 1080 | D17: Progressiva | E17: 50 quadros | F17: 3G | G17: 2 | H17: 3G-SDI | I17: High Speed
... B26: Outro | C26: resolução de computador | D26: – | E26: – | F26: 3G | G26: 2 | H26: confira no manual | I26: confira no manual
B27: A classe mostra quanto o formato exige do cabo. “Outro” é tratado como 1080p a 60 quadros. Os mesmos números aparecem nos menus com ponto: 59.94.
B29: Tipos de ligação
B30: Ligação | C30: Conector e cabo | E30: Distância prática | H30: Ponto de atenção
B31: HDMI passivo | C31: HDMI normal, mini ou micro. Cabo de 19 vias. | E31: Até 5 m sem preocupação. De 5 a 10 m, com cabo bom. | H31: Sem trava. Leva EDID e HDCP. O 4K a 60 pede cabo Premium High Speed e trecho de até 3 m.
B32: HDMI ativo ou óptico | C32: HDMI com circuito ou fibra dentro do cabo. | E32: De 10 a 100 m, conforme o fabricante. | H32: Tem sentido certo: a ponta de origem vai na origem. Não dobre em ângulo fechado.
B33: SDI | C33: BNC com trava. Coaxial de 75 ohms. | E33: HD: cerca de 100 m. 3G: de 70 a 100 m. 12G: de 30 a 70 m. | H33: Não carrega HDCP nem EDID: o formato tem de estar certo nos dois lados. Cabo de 50 ohms não serve.
B34: HDBaseT | C34: RJ45. Cabo de rede, de um extensor ao outro. | E34: De 40 a 100 m, conforme a classe e a resolução. | H34: Ponto a ponto: não passa por switch de rede. Cabo de cobre inteiro, de categoria 6 ou melhor.
B35: Fibra | C35: Conversores nas pontas e cabo óptico. | E35: Centenas de metros a quilômetros. | H35: Isola os aparelhos eletricamente. Conectores limpos e com tampa. Nunca olhe para a ponta ligada.
B36: Rede (NDI) | C36: RJ45. Rede local de 1 gigabit, cabeada. | E36: 100 m por trecho de cabo. | H36: Vídeo comprimido e com algum atraso. Rede separada da do público. Wi-Fi não é confiável.
B37: USB | C37: USB-A ou USB-C. Leva o vídeo ao computador. | E37: De 2 a 3 m em USB 3. Até 5 m em USB 2. | H37: Ligue direto no computador, sem hub. Em USB 2, a imagem é comprimida e costuma ficar em 30 quadros.
B39: Aparelhos do caminho
B40: Aparelho | D40: O que faz | H40: O que não faz
B41: Conversor de interface | D41: Troca o tipo de ligação: HDMI para SDI, SDI para HDMI, para fibra. | H41: Não muda o formato. Em geral tem um só sentido. Não passa conteúdo protegido para SDI.
B42: Scaler | D42: Muda a resolução e a taxa de quadros para o formato escolhido. | H42: Não cria detalhe. Entre famílias de taxa (50 e 59,94), deixa pequenos trancos. Acrescenta atraso.
B43: Distribuidor (splitter) | D43: Copia uma entrada para duas ou mais saídas. | H43: Não muda o formato. Apresenta à origem um só EDID, que pode rebaixar o formato para todas as telas.
B44: Placa de captura | D44: Leva HDMI ou SDI para o computador, como uma webcam. | H44: Não aceita HDCP. Modelos simples entregam só 30 quadros ao computador.
B46: Sintomas e causas prováveis
B47: O que se vê | D47: Causa mais provável | H47: Primeira coisa a fazer
B48: Tela preta ou “sem sinal” | D48: Entrada errada no destino, formato não aceito ou conversor sem energia. | H48: Conferir a entrada, a fonte do conversor e o formato de saída da origem.
B49: Pontos brilhantes, linhas, apagões | D49: Sinal no limite: cabo longo demais, cabo ruim, emenda ou conector frouxo. | H49: Trocar por cabo mais curto ou por outro tipo de ligação.
B50: Preto só com um conteúdo | D50: HDCP. | H50: Testar a origem direto em uma TV. Trocar a fonte do conteúdo.
B51: Computador só oferece resolução baixa | D51: O EDID não chegou à origem. | H51: Religar o cabo na origem com o destino já ligado. Testar sem o extensor.
B52: Movimento aos trancos | D52: Taxas de quadros de famílias diferentes no caminho. | H52: Igualar a taxa da origem ao padrão do sistema.
...

Sheet Checklist
B1: Checklist dos sinais de vídeo
B2: Confira na montagem, antes do ensaio. Escolha a situação de cada item na lista suspensa.
B4: # | C4: Grupo | D4: Item | E4: Situação | F4: Observação
B5: 1 | C5: Preparação | D5: O padrão do sistema (resolução, varredura e taxa de quadros) está definido e anotado.
B6: 2 | C6: Preparação | D6: O diagrama de sinal está desenhado, e o mapa de sinais tem o comprimento de cada trecho.
B7: 3 | C7: Preparação | D7: Cada câmera e cada computador está configurado para enviar o padrão do sistema.
B8: 4 | C8: Cabos | D8: Nenhum trecho passa do comprimento recomendado: os longos usam SDI, extensor, cabo óptico ou fibra.
B9: 5 | C9: Cabos | D9: Os cabos ativos e ópticos estão no sentido certo, com a ponta de origem na origem.
B10: 6 | C10: Cabos | D10: Os conectores BNC estão travados, os HDMI têm alívio de tensão, e os cabos no chão estão presos.
B11: 7 | C11: Conversores | D11: Cada conversor, extensor e distribuidor está alimentado, com a fonte presa e a luz de sinal acesa.
B12: 8 | C12: Conversores | D12: A saída de cada computador está em 1920 × 1080, na taxa do sistema, estendida ou duplicada conforme o uso.
B13: 9 | C13: Teste | D13: Cada entrada do switcher mostra imagem estável por dez minutos, sem piscar nem chuviscar.
B14: 10 | C14: Teste | D14: Cada destino mostra a imagem inteira, sem cortes, sem barras inesperadas e sem esticar.
B15: 11 | C15: Teste | D15: O áudio embutido chega aonde deve, e o som do computador sai pela saída prevista.
B16: 12 | C16: Teste | D16: As mídias do evento foram testadas no caminho real, e há um cabo curto testado e um conversor de reserva.
B18: Itens respondidos | E18: =COUNTA(E5:E16) -> 0
B19: Percentual atendido (Parcial vale metade) | E19: =IF(COUNTA(E5:E16)=0,"",(COUNTIF(E5:E16,"Sim")+COUNTIF(E5:E16,"Parcial")/2)/COUNTA(E5:E16))
B20: Situação | E20: =IF(COUNTA(E5:E16)<12,"Incompleto",IF(COUNTIF(E5:E16,"Não")=0,"OK","Há itens a resolver")) -> Incompleto

Sheet Exemplo - Mapa
B1: Mapa de sinais de vídeo — origem, formato, cabo e destino
B2: Exemplo preenchido, para consulta. Use a aba Mapa de sinais para o seu sistema.
B4: Evento ou sistema | D4: Culto de domingo, 19 h | G4: Limite recomendado (m) | H4: HD | I4: 3G | J4: 6G | K4: 12G | L4: HD: 720p, 1080i e 1080p até 30 · 3G: 1080p de 50 a 60 · 6G: 4K até 30 · 12G: 4K de 50 a 60
B5: Local | D5: Igreja de 200 lugares | G5: HDMI passivo | H5: 10 | I5: 10 | J5: 5 | K5: 3 | L5: Cabo comum. Acima de 5 m, só cabo de boa qualidade e testado.
B6: Data | D6: 46299 | G6: HDMI ativo ou óptico | H6: 30 | I6: 30 | J6: 30 | K6: 30 | L6: Conforme o fabricante: há cabos ópticos de até 100 m. Têm sentido certo.
B7: Responsável | D7: Operador de vídeo da escala | G7: SDI | H7: 100 | I7: 70 | J7: 50 | K7: 30 | L7: Coaxial de 75 ohms de bitola cheia. Com cabo fino, use a metade.
B8: Padrão do sistema | D8: 1080p59.94 | G8: HDBaseT | H8: 70 | I8: 70 | J8: 40 | K8: 40 | L8: Conforme a classe do extensor e a categoria do cabo de rede.
B9: Aviso “No limite” a partir de | D9: 0.8 | G9: Fibra | H9: 300 | I9: 300 | J9: 300 | K9: 300 | L9: Conforme o conversor. Fibra monomodo alcança quilômetros.
B10: O formato é escrito como nos menus dos equipamentos, com ponto: 1080p59.94. | G10: Rede (NDI) | H10: 100 | I10: 100 | J10: 100 | K10: 100 | L10: Por trecho de cabo, entre o aparelho e o switch de rede.
B11: 59.94 e 60 são formatos diferentes. Confira o que cada aparelho entrega de fato. | G11: USB | H11: 3 | I11: 3 | J11: 3 | K11: 3 | L11: USB 3 com cabo passivo. Em USB 2, até 5 m.
B13: Trechos do sistema, da origem para o destino
B14: # | C14: Origem | D14: Formato enviado | E14: Ligação | F14: Comprimento | G14: Destino | H14: Destino converte? | I14: Classe | J14: Limite | K14: Formato | L14: Cabo | M14: Situação | N14: O que fazer | O14: Observação
C15: aparelho e saída | D15: saída da origem | E15: cabo ou extensor | F15: metros | G15: aparelho e entrada | H15: Sim / Não | I15: do formato | J15: metros | K15: × padrão | L15: × limite
B16: Situação antes das correções. As colunas de I a N são calculadas. O que foi ajustado está no fim da aba.
B17: 1 | C17: Câmera 1 (fundo, central) | D17: 1080p59.94 | E17: SDI | F17: 40 | G17: Switcher, entrada 1 | H17: Não | I17: =IF(D17="","",IFERROR(VLOOKUP(D17,Referência!$B$6:$I$26,5,0),"")) -> 3G | J17: =IF(OR(D17="",E17=""),"",IFERROR(1/(1/INDEX($H$5:$K$11,MATCH(E17,$G$5:$G$11,0),VLOOKUP(D17,Referência!$B$6:$I$26,6,0))),"")) -> 70 | K17: =IF(OR(D17="",$D$8=""),"",IF(D17=$D$8,"Igual",IF(H17="Sim","Convertido","Diferente"))) -> Igual | L17: =IF(OR(F17="",J17=""),"",IF(F17>J17,"Acima",IF(F17>J17*IF($D$9="",1,$D$9),"No limite","OK"))) -> OK | M17: =IF(AND(K17="",L17=""),"",IF(AND(K17="Diferente",L17="Acima"),"Formato e cabo",IF(K17="Diferente","Formato",IF(L17="Acima","Comprimento",IF(L17="No limite","No limite",IF(OR(K17="",L17=""),"Incompleto","OK")))))) -> OK | N17: =IF(M17="","",IF(M17="Formato e cabo","Ajuste a origem para "&$D$8&" e troque o tipo de ligação do trecho",IF(M17="Formato","Ajuste a saída da origem para "&$D$8&", ou use um scaler antes do destino",IF(M17="Comprimento",IF(E17="HDMI passivo","Use SDI com conversor, HDBaseT ou cabo HDMI óptico",IF(E17="USB","Aproxime o computador ou use extensão USB ativa","Encurte o trecho, use cabo melhor ou passe para fibra")),IF(M17="No limite","Teste com o cabo no caminho real e tenha um reserva",IF(M17="Incompleto","Informe o formato, a ligação e o comprimento","Manter")))))) -> Manter
B18: 2 | C18: Câmera 2 (lateral) | D18: 1080p59.94 | E18: HDMI passivo | F18: 15 | G18: Switcher, entrada 2 | H18: Não | I18: =IF(D18="","",IFERROR(VLOOKUP(D18,Referência!$B$6:$I$26,5,0),"")) -> 3G | J18: =IF(OR(D18="",E18=""),"",IFERROR(1/(1/INDEX($H$5:$K$11,MATCH(E18,$G$5:$G$11,0),VLOOKUP(D18,Referência!$B$6:$I$26,6,0))),"")) -> 10 | K18: =IF(OR(D18="",$D$8=""),"",IF(D18=$D$8,"Igual",IF(H18="Sim","Convertido","Diferente"))) -> Igual | L18: =IF(OR(F18="",J18=""),"",IF(F18>J18,"Acima",IF(F18>J18*IF($D$9="",1,$D$9),"No limite","OK"))) -> Acima | M18: =IF(AND(K18="",L18=""),"",IF(AND(K18="Diferente",L18="Acima"),"Formato e cabo",IF(K18="Diferente","Formato",IF(L18="Acima","Comprimento",IF(L18="No limite","No limite",IF(OR(K18="",L18=""),"Incompleto","OK")))))) -> Comprimento | N18: =IF(M18="","",IF(M18="Formato e cabo","Ajuste a origem para "&$D$8&" e troque o tipo de ligação do trecho",IF(M18="Formato","Ajuste a saída da origem para "&$D$8&", ou use um scaler antes do destino",IF(M18="Comprimento",IF(E18="HDMI passivo","Use SDI com conversor, HDBaseT ou cabo HDMI óptico",IF(E18="USB","Aproxime o computador ou use extensão USB ativa","Encurte o trecho, use cabo melhor ou passe para fibra")),IF(M18="No limite","Teste com o cabo no caminho real e tenha um reserva",IF(M18="Incompleto","Informe o formato, a ligação e o comprimento","Manter")))))) -> Use SDI com conversor, HDBaseT ou cabo HDMI óptico
B19: 3 | C19: Câmera 3 (palco) | D19: 1080i59.94 | E19: HDMI passivo | F19: 3 | G19: Switcher, entrada 3 | H19: Não | I19: =IF(D19="","",IFERROR(VLOOKUP(D19,Referência!$B$6:$I$26,5,0),"")) -> HD | J19: =IF(OR(D19="",E19=""),"",IFERROR(1/(1/INDEX($H$5:$K$11,MATCH(E19,$G$5:$G$11,0),VLOOKUP(D19,Referência!$B$6:$I$26,6,0))),"")) -> 10 | K19: =IF(OR(D19="",$D$8=""),"",IF(D19=$D$8,"Igual",IF(H19="Sim","Convertido","Diferente"))) -> Diferente | L19: =IF(OR(F19="",J19=""),"",IF(F19>J19,"Acima",IF(F19>J19*IF($D$9="",1,$D$9),"No limite","OK"))) -> OK | M19: =IF(AND(K19="",L19=""),"",IF(AND(K19="Diferente",L19="Acima"),"Formato e cabo",IF(K19="Diferente","Formato",IF(L19="Acima","Comprimento",IF(L19="No limite","No limite",IF(OR(K19="",L19=""),"Incompleto","OK")))))) -> Formato | N19: =IF(M19="","",IF(M19="Formato e cabo","Ajuste a origem para "&$D$8&" e troque o tipo de ligação do trecho",IF(M19="Formato","Ajuste a saída da origem para "&$D$8&", ou use um scaler antes do destino",IF(M19="Comprimento",IF(E19="HDMI passivo","Use SDI com conversor, HDBaseT ou cabo HDMI óptico",IF(E19="USB","Aproxime o computador ou use extensão USB ativa","Encurte o trecho, use cabo melhor ou passe para fibra")),IF(M19="No limite","Teste com o cabo no caminho real e tenha um reserva",IF(M19="Incompleto","Informe o formato, a ligação e o comprimento","Manter")))))) -> Ajuste a saída da origem para 1080p59.94, ou use um scaler antes do destino
B20: 4 | C20: Computador das letras | D20: 1080p60 | E20: HDMI passivo | F20: 2 | G20: Switcher, entrada 4 | H20: Não | I20: =IF(D20="","",IFERROR(VLOOKUP(D20,Referência!$B$6:$I$26,5,0),"")) -> 3G | J20: =IF(OR(D20="",E20=""),"",IFERROR(1/(1/INDEX($H$5:$K$11,MATCH(E20,$G$5:$G$11,0),VLOOKUP(D20,Referência!$B$6:$I$26,6,0))),"")) -> 10 | K20: =IF(OR(D20="",$D$8=""),"",IF(D20=$D$8,"Igual",IF(H20="Sim","Convertido","Diferente"))) -> Diferente | L20: =IF(OR(F20="",J20=""),"",IF(F20>J20,"Acima",IF(F20>J20*IF($D$9="",1,$D$9),"No limite","OK"))) -> OK | M20: =IF(AND(K20="",L20=""),"",IF(AND(K20="Diferente",L20="Acima"),"Formato e cabo",IF(K20="Diferente","Formato",IF(L20="Acima","Comprimento",IF(L20="No limite","No limite",IF(OR(K20="",L20=""),"Incompleto","OK")))))) -> Formato | N20: =IF(M20="","",IF(M20="Formato e cabo","Ajuste a origem para "&$D$8&" e troque o tipo de ligação do trecho",IF(M20="Formato","Ajuste a saída da origem para "&$D$8&", ou use um scaler antes do destino",IF(M20="Comprimento",IF(E20="HDMI passivo","Use SDI com conversor, HDBaseT ou cabo HDMI óptico",IF(E20="USB","Aproxime o computador ou use extensão USB ativa","Encurte o trecho, use cabo melhor ou passe para fibra")),IF(M20="No limite","Teste com o cabo no caminho real e tenha um reserva",IF(M20="Incompleto","Informe o formato, a ligação e o comprimento","Manter")))))) -> Ajuste a saída da origem para 1080p59.94, ou use um scaler antes do destino
B21: 5 | C21: Notebook de visitante | D21: Outro | E21: HDMI passivo | F21: 5 | G21: Scaler | H21: Sim | I21: =IF(D21="","",IFERROR(VLOOKUP(D21,Referência!$B$6:$I$26,5,0),"")) -> 3G | J21: =IF(OR(D21="",E21=""),"",IFERROR(1/(1/INDEX($H$5:$K$11,MATCH(E21,$G$5:$G$11,0),VLOOKUP(D21,Referência!$B$6:$I$26,6,0))),"")) -> 10 | K21: =IF(OR(D21="",$D$8=""),"",IF(D21=$D$8,"Igual",IF(H21="Sim","Convertido","Diferente"))) -> Convertido | L21: =IF(OR(F21="",J21=""),"",IF(F21>J21,"Acima",IF(F21>J21*IF($D$9="",1,$D$9),"No limite","OK"))) -> OK | M21: =IF(AND(K21="",L21=""),"",IF(AND(K21="Diferente",L21="Acima"),"Formato e cabo",IF(K21="Diferente","Formato",IF(L21="Acima","Comprimento",IF(L21="No limite","No limite",IF(OR(K21="",L21=""),"Incompleto","OK")))))) -> OK | N21: =IF(M21="","",IF(M21="Formato e cabo","Ajuste a origem para "&$D$8&" e troque o tipo de ligação do trecho",IF(M21="Formato","Ajuste a saída da origem para "&$D$8&", ou use um scaler antes do destino",IF(M21="Comprimento",IF(E21="HDMI passivo","Use SDI com conversor, HDBaseT ou cabo HDMI óptico",IF(E21="USB","Aproxime o computador ou use extensão USB ativa","Encurte o trecho, use cabo melhor ou passe para fibra")),IF(M21="No limite","Teste com o cabo no caminho real e tenha um reserva",IF(M21="Incompleto","Informe o formato, a ligação e o comprimento","Manter")))))) -> Manter
B22: 6 | C22: Scaler | D22: 1080p59.94 | E22: HDMI passivo | F22: 1 | G22: Switcher, entrada 5 | H22: Não | I22: =IF(D22="","",IFERROR(VLOOKUP(D22,Referência!$B$6:$I$26,5,0),"")) -> 3G | J22: =IF(OR(D22="",E22=""),"",IFERROR(1/(1/INDEX($H$5:$K$11,MATCH(E22,$G$5:$G$11,0),VLOOKUP(D22,Referência!$B$6:$I$26,6,0))),"")) -> 10 | K22: =IF(OR(D22="",$D$8=""),"",IF(D22=$D$8,"Igual",IF(H22="Sim","Convertido","Diferente"))) -> Igual | L22: =IF(OR(F22="",J22=""),"",IF(F22>J22,"Acima",IF(F22>J22*IF($D$9="",1,$D$9),"No limite","OK"))) -> OK | M22: =IF(AND(K22="",L22=""),"",IF(AND(K22="Diferente",L22="Acima"),"Formato e cabo",IF(K22="Diferente","Formato",IF(L22="Acima","Comprimento",IF(L22="No limite","No limite",IF(OR(K22="",L22=""),"Incompleto","OK")))))) -> OK | N22: =IF(M22="","",IF(M22="Formato e cabo","Ajuste a origem para "&$D$8&" e troque o tipo de ligação do trecho",IF(M22="Formato","Ajuste a saída da origem para "&$D$8&", ou use um scaler antes do destino",IF(M22="Comprimento",IF(E22="HDMI passivo","Use SDI com conversor, HDBaseT ou cabo HDMI óptico",IF(E22="USB","Aproxime o computador ou use extensão USB ativa","Encurte o trecho, use cabo melhor ou passe para fibra")),IF(M22="No limite","Teste com o cabo no caminho real e tenha um reserva",IF(M22="Incompleto","Informe o formato, a ligação e o comprimento","Manter")))))) -> Manter
B23: 7 | C23: Switcher, saída de programa 1 | D23: 1080p59.94 | E23: HDBaseT | F23: 35 | G23: Projetor (telão) | H23: Não | I23: =IF(D23="","",IFERROR(VLOOKUP(D23,Referência!$B$6:$I$26,5,0),"")) -> 3G | J23: =IF(OR(D23="",E23=""),"",IFERROR(1/(1/INDEX($H$5:$K$11,MATCH(E23,$G$5:$G$11,0),VLOOKUP(D23,Referência!$B$6:$I$26,6,0))),"")) -> 70 | K23: =IF(OR(D23="",$D$8=""),"",IF(D23=$D$8,"Igual",IF(H23="Sim","Convertido","Diferente"))) -> Igual | L23: =IF(OR(F23="",J23=""),"",IF(F23>J23,"Acima",IF(F23>J23*IF($D$9="",1,$D$9),"No limite","OK"))) -> OK | M23: =IF(AND(K23="",L23=""),"",IF(AND(K23="Diferente",L23="Acima"),"Formato e cabo",IF(K23="Diferente","Formato",IF(L23="Acima","Comprimento",IF(L23="No limite","No limite",IF(OR(K23="",L23=""),"Incompleto","OK")))))) -> OK | N23: =IF(M23="","",IF(M23="Formato e cabo","Ajuste a origem para "&$D$8&" e troque o tipo de ligação do trecho",IF(M23="Formato","Ajuste a saída da origem para "&$D$8&", ou use um scaler antes do destino",IF(M23="Comprimento",IF(E23="HDMI passivo","Use SDI com conversor, HDBaseT ou cabo HDMI óptico",IF(E23="USB","Aproxime o computador ou use extensão USB ativa","Encurte o trecho, use cabo melhor ou passe para fibra")),IF(M23="No limite","Teste com o cabo no caminho real e tenha um reserva",IF(M23="Incompleto","Informe o formato, a ligação e o comprimento","Manter")))))) -> Manter
B24: 8 | C24: Switcher, saída de programa 2 | D24: 1080p59.94 | E24: HDMI ativo ou óptico | F24: 20 | G24: TV de retorno do palco | H24: Não | I24: =IF(D24="","",IFERROR(VLOOKUP(D24,Referência!$B$6:$I$26,5,0),"")) -> 3G | J24: =IF(OR(D24="",E24=""),"",IFERROR(1/(1/INDEX($H$5:$K$11,MATCH(E24,$G$5:$G$11,0),VLOOKUP(D24,Referência!$B$6:$I$26,6,0))),"")) -> 30 | K24: =IF(OR(D24="",$D$8=""),"",IF(D24=$D$8,"Igual",IF(H24="Sim","Convertido","Diferente"))) -> Igual | L24: =IF(OR(F24="",J24=""),"",IF(F24>J24,"Acima",IF(F24>J24*IF($D$9="",1,$D$9),"No limite","OK"))) -> OK | M24: =IF(AND(K24="",L24=""),"",IF(AND(K24="Diferente",L24="Acima"),"Formato e cabo",IF(K24="Diferente","Formato",IF(L24="Acima","Comprimento",IF(L24="No limite","No limite",IF(OR(K24="",L24=""),"Incompleto","OK")))))) -> OK | N24: =IF(M24="","",IF(M24="Formato e cabo","Ajuste a origem para "&$D$8&" e troque o tipo de ligação do trecho",IF(M24="Formato","Ajuste a saída da origem para "&$D$8&", ou use um scaler antes do destino",IF(M24="Comprimento",IF(E24="HDMI passivo","Use SDI com conversor, HDBaseT ou cabo HDMI óptico",IF(E24="USB","Aproxime o computador ou use extensão USB ativa","Encurte o trecho, use cabo melhor ou passe para fibra")),IF(M24="No limite","Teste com o cabo no caminho real e tenha um reserva",IF(M24="Incompleto","Informe o formato, a ligação e o comprimento","Manter")))))) -> Manter
B25: 9 | C25: Switcher, saída auxiliar | D25: 1080p59.94 | E25: SDI | F25: 2 | G25: Placa de captura | H25: Não | I25: =IF(D25="","",IFERROR(VLOOKUP(D25,Referência!$B$6:$I$26,5,0),"")) -> 3G | J25: =IF(OR(D25="",E25=""),"",IFERROR(1/(1/INDEX($H$5:$K$11,MATCH(E25,$G$5:$G$11,0),VLOOKUP(D25,Referência!$B$6:$I$26,6,0))),"")) -> 70 | K25: =IF(OR(D25="",$D$8=""),"",IF(D25=$D$8,"Igual",IF(H25="Sim","Convertido","Diferente"))) -> Igual | L25: =IF(OR(F25="",J25=""),"",IF(F25>J25,"Acima",IF(F25>J25*IF($D$9="",1,$D$9),"No limite","OK"))) -> OK | M25: =IF(AND(K25="",L25=""),"",IF(AND(K25="Diferente",L25="Acima"),"Formato e cabo",IF(K25="Diferente","Formato",IF(L25="Acima","Comprimento",IF(L25="No limite","No limite",IF(OR(K25="",L25=""),"Incompleto","OK")))))) -> OK | N25: =IF(M25="","",IF(M25="Formato e cabo","Ajuste a origem para "&$D$8&" e troque o tipo de ligação do trecho",IF(M25="Formato","Ajuste a saída da origem para "&$D$8&", ou use um scaler antes do destino",IF(M25="Comprimento",IF(E25="HDMI passivo","Use SDI com conversor, HDBaseT ou cabo HDMI óptico",IF(E25="USB","Aproxime o computador ou use extensão USB ativa","Encurte o trecho, use cabo melhor ou passe para fibra")),IF(M25="No limite","Teste com o cabo no caminho real e tenha um reserva",IF(M25="Incompleto","Informe o formato, a ligação e o comprimento","Manter")))))) -> Manter
B26: 10 | C26: Placa de captura | D26: 1080p59.94 | E26: USB | F26: 3 | G26: Computador da transmissão | H26: Não | I26: =IF(D26="","",IFERROR(VLOOKUP(D26,Referência!$B$6:$I$26,5,0),"")) -> 3G | J26: =IF(OR(D26="",E26=""),"",IFERROR(1/(1/INDEX($H$5:$K$11,MATCH(E26,$G$5:$G$11,0),VLOOKUP(D26,Referência!$B$6:$I$26,6,0))),"")) -> 3 | K26: =IF(OR(D26="",$D$8=""),"",IF(D26=$D$8,"Igual",IF(H26="Sim","Convertido","Diferente"))) -> Igual | L26: =IF(OR(F26="",J26=""),"",IF(F26>J26,"Acima",IF(F26>J26*IF($D$9="",1,$D$9),"No limite","OK"))) -> No limite | M26: =IF(AND(K26="",L26=""),"",IF(AND(K26="Diferente",L26="Acima"),"Formato e cabo",IF(K26="Diferente","Formato",IF(L26="Acima","Comprimento",IF(L26="No limite","No limite",IF(OR(K26="",L26=""),"Incompleto","OK")))))) -> No limite | N26: =IF(M26="","",IF(M26="Formato e cabo","Ajuste a origem para "&$D$8&" e troque o tipo de ligação do trecho",IF(M26="Formato","Ajuste a saída da origem para "&$D$8&", ou use um scaler antes do destino",IF(M26="Comprimento",IF(E26="HDMI passivo","Use SDI com conversor, HDBaseT ou cabo HDMI óptico",IF(E26="USB","Aproxime o computador ou use extensão USB ativa","Encurte o trecho, use cabo melhor ou passe para fibra")),IF(M26="No limite","Teste com o cabo no caminho real e tenha um reserva",IF(M26="Incompleto","Informe o formato, a ligação e o comprimento","Manter")))))) -> Teste com o cabo no caminho real e tenha um reserva
B27: 11 | I27: =IF(D27="","",IFERROR(VLOOKUP(D27,Referência!$B$6:$I$26,5,0),"")) | J27: =IF(OR(D27="",E27=""),"",IFERROR(1/(1/INDEX($H$5:$K$11,MATCH(E27,$G$5:$G$11,0),VLOOKUP(D27,Referência!$B$6:$I$26,6,0))),"")) | K27: =IF(OR(D27="",$D$8=""),"",IF(D27=$D$8,"Igual",IF(H27="Sim","Convertido","Diferente"))) | L27: =IF(OR(F27="",J27=""),"",IF(F27>J27,"Acima",IF(F27>J27*IF($D$9="",1,$D$9),"No limite","OK"))) | M27: =IF(AND(K27="",L27=""),"",IF(AND(K27="Diferente",L27="Acima"),"Formato e cabo",IF(K27="Diferente","Formato",IF(L27="Acima","Comprimento",IF(L27="No limite","No limite",IF(OR(K27="",L27=""),"Incompleto","OK")))))) | N27: =IF(M27="","",IF(M27="Formato e cabo","Ajuste a origem para "&$D$8&" e troque o tipo de ligação do trecho",IF(M27="Formato","Ajuste a saída da origem para "&$D$8&", ou use um scaler antes do destino",IF(M27="Comprimento",IF(E27="HDMI passivo","Use SDI com conversor, HDBaseT ou cabo HDMI óptico",IF(E27="USB","Aproxime o computador ou use extensão USB ativa","Encurte o trecho, use cabo melhor ou passe para fibra")),IF(M27="No limite","Teste com o cabo no caminho real e tenha um reserva",IF(M27="Incompleto","Informe o formato, a ligação e o comprimento","Manter"))))))
