Workbook

Sheet Instruções
B1: Microfones sem fio — como usar esta planilha
B2: Plano de frequências com alertas, teste de RF por sistema e controle de pilhas, para usar na montagem do evento.
B4: Legenda: onde preencher
B5: Amarelo-claro | C5: Células de entrada. É aqui que você digita.
B6: Cinza | C6: Células calculadas ou fixas (rótulos, contas, avisos). Não altere.
B7: Cinza em itálico | C7: Linha de exemplo (marcada com “Ex.”) e dicas de preenchimento. Não entram nas contas.
B8: Listas suspensas | C8: Transmissor, faixa, tipo de pilha e as respostas Sim ou Não aceitam só as opções da lista.
B9: Frequências | C9: Digite a frequência em MHz, como aparece no visor do receptor: 538,425. Não escreva a unidade.
B10: Comentários | C10: Células com triângulo vermelho no canto trazem uma dica. Passe o mouse sobre elas.
B12: Ordem de preenchimento
B13: 1 | C13: Aba Plano de frequências: preencha o cabeçalho e os canais de TV digital ativos na sua cidade (canal físico).
B14: 2 | C14: No local: com os transmissores desligados, faça a varredura (scan) em cada receptor e escolha o grupo e os canais.
B15: 3 | C15: Aba Plano de frequências: liste cada sistema, quem usa, o grupo, o canal e a frequência do visor.
B16: 4 | C16: Veja a situação de cada linha. Troque as frequências com alerta e digite as novas, até o aviso ficar em OK.
B17: 5 | C17: Aba Pilhas e baterias: anote a autonomia e o tempo de uso de cada transmissor. Troque o que a planilha mandar trocar.
B18: 6 | C18: Aba Teste de RF: com tudo montado, faça os cinco testes de cada sistema e responda Sim ou Não.
B19: 7 | C19: Aba Checklist: confira os doze itens antes de abrir as portas.
B21: Abas da planilha
B22: Plano de frequências | C22: Até 16 sistemas, com alerta de frequência repetida, próxima demais, em canal de TV ativo, na faixa a evitar ou com intermodulação.
B23: Teste de RF | C23: Os cinco testes de cada sistema do plano, com a situação e o que fazer em cada caso.
B24: Pilhas e baterias | C24: Carga restante e folga de cada transmissor para as horas do evento, com a quantidade de pilhas a separar.
B25: Referência | C25: Faixas, valores de partida da coordenação, antenas, pilhas e tabela de sintomas.
B26: Checklist | C26: Os doze itens do treinamento, com percentual atendido.
B27: Exemplo - Plano | C27: Seis sistemas com as frequências escolhidas à mão, antes da correção (exemplo 1 do treinamento).
B29: Regras e premissas do modelo
B30: Valores de partida | C30: Distância mínima de 0,35 MHz entre frequências e margem de 0,1 MHz para intermodulação são ponto de partida para sistemas analógicos. Confira o manual do seu sistema e troque os valores no alto da aba.
B31: Canal de TV | C31: A conta supõe canais de 6 MHz, do 14 (470 MHz) ao 51 (698 MHz), como na TV digital brasileira. Informe o canal físico, que não é o número mostrado na TV.
B32: Faixa a evitar | C32: Vem preenchida com a faixa da telefonia móvel no Brasil (698 a 806 MHz). As regras mudam: confira a regulamentação vigente no seu local.
B33: Intermodulação | C33: A planilha calcula os produtos de terceira ordem de dois transmissores (2 × A − B) e conta os que caem perto de cada frequência. Produtos de três transmissores ficam de fora.
B34: Limite da conferência | C34: O plano sem alerta é um bom começo, e não uma garantia. Os grupos do fabricante, o programa de coordenação e o teste com todos os transmissores ligados continuam valendo.
B35: Sistemas de 2,4 GHz | C35: Não têm frequência fixa: deixe a frequência em branco e escolha a faixa 2,4 GHz. A situação aparece como Automática.
B36: Pilhas | C36: Situação OK quando a carga restante cobre as horas do evento vezes o fator de margem. O fator de 1,5 é regra prática deste material.
B37: Exemplo | C37: Os dados da aba de exemplo são ilustrativos, criados para este material.

Sheet Plano de frequências
B1: Plano de frequências — microfones sem fio
B2: Preencha as células em amarelo-claro. As células cinza conferem repetição, proximidade, TV e intermodulação.
R3: Lista de faixas
B4: Evento | G4: Distância mínima entre frequências (MHz) | L4: 0.35 | M4: Ponto de partida para sistemas analógicos. O manual do seu sistema dá o valor certo. | R4: VHF
B5: Local | G5: Margem de intermodulação (MHz) | L5: 0.1 | M5: Distância mínima entre uma frequência e um produto do tipo 2 × A − B. | R5: UHF
B6: Data | G6: Faixa a evitar: de (MHz) | L6: 698 | M6: Faixa da telefonia móvel no Brasil. Confira a regulamentação vigente no seu local. | R6: 2,4 GHz
B7: Responsável | G7: Faixa a evitar: até (MHz) | L7: 806 | M7: Deixe as duas células em branco se não quiser esta conferência. | R7: Outra
B9: Canais de TV digital ativos na cidade | M9: Canal físico (de RF), de 14 a 51: não é o número que aparece na TV. Até oito canais.
B11: Plano de frequências
B12: # | C12: Sistema (receptor) | D12: Usuário ou função | E12: Transmissor | F12: Faixa | G12: Grupo | H12: Canal | I12: Frequência | J12: Canal de TV | K12: Menor distância | L12: Do sistema | M12: Produtos perto | N12: Situação | O12: O que fazer | P12: Observação | R12: Cálculo auxiliar (não altere): distância entre os sistemas, em MHz | AI12: Cálculo auxiliar (não altere): produtos 2 × A − B, em kHz (A na linha, B na coluna)
B13: nº | C13: modelo ou etiqueta | D13: quem usa | E13: tipo | G13: do visor | H13: do visor | I13: MHz | J13: 6 MHz cada | K13: MHz | L13: nº | M13: intermod. | R13: 1 | S13: 2 | T13: 3 | U13: 4 | V13: 5 | W13: 6 | X13: 7 | Y13: 8 | Z13: 9 | AA13: 10 | AB13: 11 | AC13: 12 | AD13: 13 | AE13: 14 | AF13: 15 | AG13: 16 | AI13: 1 | AJ13: 2 | AK13: 3 | AL13: 4 | AM13: 5 | AN13: 6 | AO13: 7 | AP13: 8 | AQ13: 9 | AR13: 10 | AS13: 11 | AT13: 12 | AU13: 13 | AV13: 14 | AW13: 15 | AX13: 16
B14: Ex. | C14: Receptor 1 (UHF) | D14: Pastor | E14: Headset | F14: UHF | G14: 3 | H14: 7 | I14: 538.425 | J14: 25 | K14: 0.75 | L14: 2 | M14: 0 | N14: OK | O14: Manter
B15: 1 | J15: =IF(I15="","",IF(AND(I15>=470,I15<698),INT((I15-470)/6)+14,"–")) | K15: =IF(OR(I15="",COUNT($R15:$AG15)=0),"",MIN($R15:$AG15)) | L15: =IF(K15="","",MATCH(K15,$R15:$AG15,0)) | M15: =IF(I15="","",COUNTIFS($AI$15:$AX$30,">"&ROUND((I15-$L$5)*1000,0),$AI$15:$AX$30,"<"&ROUND((I15+$L$5)*1000,0))-COUNTIFS($AI15:$AX15,">"&ROUND((I15-$L$5)*1000,0),$AI15:$AX15,"<"&ROUND((I15+$L$5)*1000,0))-COUNTIFS(AI$15:AI$30,">"&ROUND((I15-$L$5)*1000,0),AI$15:AI$30,"<"&ROUND((I15+$L$5)*1000,0))) | N15: =IF(I15="",IF(AND(C15<>"",F15="2,4 GHz"),"Automática",""),IF(AND(K15<>"",K15<0.0005),"Repetida",IF(AND(K15<>"",$L$4<>"",K15<$L$4),"Próxima",IF(AND($L$6<>"",$L$7<>"",I15>=$L$6,I15<=$L$7),"Telefonia",IF(AND(I15>=470,I15<698,COUNTIF($E$9:$L$9,INT((I15-470)/6)+14)>0),"TV",IF(M15>0,"Intermod.","OK")))))) | O15: =IF(N15="","",IF(N15="Automática","Sem frequência fixa: o sistema escolhe o canal. Afaste o receptor do roteador Wi-Fi",IF(N15="Repetida","Mesma frequência do sistema nº "&L15&": troque o canal de um dos dois",IF(N15="Próxima","Perto demais do sistema nº "&L15&": afaste as duas frequências",IF(N15="Telefonia","Dentro da faixa a evitar: troque de frequência ou de equipamento",IF(N15="TV","Dentro do canal de TV "&J15&", ativo na cidade: use um canal de TV livre",IF(N15="Intermod.","Há "&M15&" produto(s) de intermodulação perto: troque esta frequência ou use o grupo do fabricante","Manter"))))))) | S15: =IF(OR($I15="",$I16=""),"",ROUND(ABS($I15-$I16),4)) | T15: =IF(OR($I15="",$I17=""),"",ROUND(ABS($I15-$I17),4)) | U15: =IF(OR($I15="",$I18=""),"",ROUND(ABS($I15-$I18),4)) | V15: =IF(OR($I15="",$I19=""),"",ROUND(ABS($I15-$I19),4)) | W15: =IF(OR($I15="",$I20=""),"",ROUND(ABS($I15-$I20),4)) | X15: =IF(OR($I15="",$I21=""),"",ROUND(ABS($I15-$I21),4)) | Y15: =IF(OR($I15="",$I22=""),"",ROUND(ABS($I15-$I22),4)) | Z15: =IF(OR($I15="",$I23=""),"",ROUND(ABS($I15-$I23),4)) | AA15: =IF(OR($I15="",$I24=""),"",ROUND(ABS($I15-$I24),4)) | AB15: =IF(OR($I15="",$I25=""),"",ROUND(ABS($I15-$I25),4)) | AC15: =IF(OR($I15="",$I26=""),"",ROUND(ABS($I15-$I26),4)) | AD15: =IF(OR($I15="",$I27=""),"",ROUND(ABS($I15-$I27),4)) | AE15: =IF(OR($I15="",$I28=""),"",ROUND(ABS($I15-$I28),4)) | AF15: =IF(OR($I15="",$I29=""),"",ROUND(ABS($I15-$I29),4)) | AG15: =IF(OR($I15="",$I30=""),"",ROUND(ABS($I15-$I30),4)) | AJ15: =IF(OR($I15="",$I16=""),"",ROUND((2*$I15-$I16)*1000,0)) | AK15: =IF(OR($I15="",$I17=""),"",ROUND((2*$I15-$I17)*1000,0)) | AL15: =IF(OR($I15="",$I18=""),"",ROUND((2*$I15-$I18)*1000,0)) | AM15: =IF(OR($I15="",$I19=""),"",ROUND((2*$I15-$I19)*1000,0)) | AN15: =IF(OR($I15="",$I20=""),"",ROUND((2*$I15-$I20)*1000,0)) | AO15: =IF(OR($I15="",$I21=""),"",ROUND((2*$I15-$I21)*1000,0)) | AP15: =IF(OR($I15="",$I22=""),"",ROUND((2*$I15-$I22)*1000,0)) | AQ15: =IF(OR($I15="",$I23=""),"",ROUND((2*$I15-$I23)*1000,0)) | AR15: =IF(OR($I15="",$I24=""),"",ROUND((2*$I15-$I24)*1000,0)) | AS15: =IF(OR($I15="",$I25=""),"",ROUND((2*$I15-$I25)*1000,0)) | AT15: =IF(OR($I15="",$I26=""),"",ROUND((2*$I15-$I26)*1000,0)) | AU15: =IF(OR($I15="",$I27=""),"",ROUND((2*$I15-$I27)*1000,0)) | AV15: =IF(OR($I15="",$I28=""),"",ROUND((2*$I15-$I28)*1000,0)) | AW15: =IF(OR($I15="",$I29=""),"",ROUND((2*$I15-$I29)*1000,0)) | AX15: =IF(OR($I15="",$I30=""),"",ROUND((2*$I15-$I30)*1000,0))
B16: 2 | J16: =IF(I16="","",IF(AND(I16>=470,I16<698),INT((I16-470)/6)+14,"–")) | K16: =IF(OR(I16="",COUNT($R16:$AG16)=0),"",MIN($R16:$AG16)) | L16: =IF(K16="","",MATCH(K16,$R16:$AG16,0)) | M16: =IF(I16="","",COUNTIFS($AI$15:$AX$30,">"&ROUND((I16-$L$5)*1000,0),$AI$15:$AX$30,"<"&ROUND((I16+$L$5)*1000,0))-COUNTIFS($AI16:$AX16,">"&ROUND((I16-$L$5)*1000,0),$AI16:$AX16,"<"&ROUND((I16+$L$5)*1000,0))-COUNTIFS(AJ$15:AJ$30,">"&ROUND((I16-$L$5)*1000,0),AJ$15:AJ$30,"<"&ROUND((I16+$L$5)*1000,0))) | N16: =IF(I16="",IF(AND(C16<>"",F16="2,4 GHz"),"Automática",""),IF(AND(K16<>"",K16<0.0005),"Repetida",IF(AND(K16<>"",$L$4<>"",K16<$L$4),"Próxima",IF(AND($L$6<>"",$L$7<>"",I16>=$L$6,I16<=$L$7),"Telefonia",IF(AND(I16>=470,I16<698,COUNTIF($E$9:$L$9,INT((I16-470)/6)+14)>0),"TV",IF(M16>0,"Intermod.","OK")))))) | O16: =IF(N16="","",IF(N16="Automática","Sem frequência fixa: o sistema escolhe o canal. Afaste o receptor do roteador Wi-Fi",IF(N16="Repetida","Mesma frequência do sistema nº "&L16&": troque o canal de um dos dois",IF(N16="Próxima","Perto demais do sistema nº "&L16&": afaste as duas frequências",IF(N16="Telefonia","Dentro da faixa a evitar: troque de frequência ou de equipamento",IF(N16="TV","Dentro do canal de TV "&J16&", ativo na cidade: use um canal de TV livre",IF(N16="Intermod.","Há "&M16&" produto(s) de intermodulação perto: troque esta frequência ou use o grupo do fabricante","Manter"))))))) | R16: =IF(OR($I16="",$I15=""),"",ROUND(ABS($I16-$I15),4)) | T16: =IF(OR($I16="",$I17=""),"",ROUND(ABS($I16-$I17),4)) | U16: =IF(OR($I16="",$I18=""),"",ROUND(ABS($I16-$I18),4)) | V16: =IF(OR($I16="",$I19=""),"",ROUND(ABS($I16-$I19),4)) | W16: =IF(OR($I16="",$I20=""),"",ROUND(ABS($I16-$I20),4)) | X16: =IF(OR($I16="",$I21=""),"",ROUND(ABS($I16-$I21),4)) | Y16: =IF(OR($I16="",$I22=""),"",ROUND(ABS($I16-$I22),4)) | Z16: =IF(OR($I16="",$I23=""),"",ROUND(ABS($I16-$I23),4)) | AA16: =IF(OR($I16="",$I24=""),"",ROUND(ABS($I16-$I24),4)) | AB16: =IF(OR($I16="",$I25=""),"",ROUND(ABS($I16-$I25),4)) | AC16: =IF(OR($I16="",$I26=""),"",ROUND(ABS($I16-$I26),4)) | AD16: =IF(OR($I16="",$I27=""),"",ROUND(ABS($I16-$I27),4)) | AE16: =IF(OR($I16="",$I28=""),"",ROUND(ABS($I16-$I28),4)) | AF16: =IF(OR($I16="",$I29=""),"",ROUND(ABS($I16-$I29),4)) | AG16: =IF(OR($I16="",$I30=""),"",ROUND(ABS($I16-$I30),4)) | AI16: =IF(OR($I16="",$I15=""),"",ROUND((2*$I16-$I15)*1000,0)) | AK16: =IF(OR($I16="",$I17=""),"",ROUND((2*$I16-$I17)*1000,0)) | AL16: =IF(OR($I16="",$I18=""),"",ROUND((2*$I16-$I18)*1000,0)) | AM16: =IF(OR($I16="",$I19=""),"",ROUND((2*$I16-$I19)*1000,0)) | AN16: =IF(OR($I16="",$I20=""),"",ROUND((2*$I16-$I20)*1000,0)) | AO16: =IF(OR($I16="",$I21=""),"",ROUND((2*$I16-$I21)*1000,0)) | AP16: =IF(OR($I16="",$I22=""),"",ROUND((2*$I16-$I22)*1000,0)) | AQ16: =IF(OR($I16="",$I23=""),"",ROUND((2*$I16-$I23)*1000,0)) | AR16: =IF(OR($I16="",$I24=""),"",ROUND((2*$I16-$I24)*1000,0)) | AS16: =IF(OR($I16="",$I25=""),"",ROUND((2*$I16-$I25)*1000,0)) | AT16: =IF(OR($I16="",$I26=""),"",ROUND((2*$I16-$I26)*1000,0)) | AU16: =IF(OR($I16="",$I27=""),"",ROUND((2*$I16-$I27)*1000,0)) | AV16: =IF(OR($I16="",$I28=""),"",ROUND((2*$I16-$I28)*1000,0)) | AW16: =IF(OR($I16="",$I29=""),"",ROUND((2*$I16-$I29)*1000,0)) | AX16: =IF(OR($I16="",$I30=""),"",ROUND((2*$I16-$I30)*1000,0))
B17: 3 | J17: =IF(I17="","",IF(AND(I17>=470,I17<698),INT((I17-470)/6)+14,"–")) | K17: =IF(OR(I17="",COUNT($R17:$AG17)=0),"",MIN($R17:$AG17)) | L17: =IF(K17="","",MATCH(K17,$R17:$AG17,0)) | M17: =IF(I17="","",COUNTIFS($AI$15:$AX$30,">"&ROUND((I17-$L$5)*1000,0),$AI$15:$AX$30,"<"&ROUND((I17+$L$5)*1000,0))-COUNTIFS($AI17:$AX17,">"&ROUND((I17-$L$5)*1000,0),$AI17:$AX17,"<"&ROUND((I17+$L$5)*1000,0))-COUNTIFS(AK$15:AK$30,">"&ROUND((I17-$L$5)*1000,0),AK$15:AK$30,"<"&ROUND((I17+$L$5)*1000,0))) | N17: =IF(I17="",IF(AND(C17<>"",F17="2,4 GHz"),"Automática",""),IF(AND(K17<>"",K17<0.0005),"Repetida",IF(AND(K17<>"",$L$4<>"",K17<$L$4),"Próxima",IF(AND($L$6<>"",$L$7<>"",I17>=$L$6,I17<=$L$7),"Telefonia",IF(AND(I17>=470,I17<698,COUNTIF($E$9:$L$9,INT((I17-470)/6)+14)>0),"TV",IF(M17>0,"Intermod.","OK")))))) | O17: =IF(N17="","",IF(N17="Automática","Sem frequência fixa: o sistema escolhe o canal. Afaste o receptor do roteador Wi-Fi",IF(N17="Repetida","Mesma frequência do sistema nº "&L17&": troque o canal de um dos dois",IF(N17="Próxima","Perto demais do sistema nº "&L17&": afaste as duas frequências",IF(N17="Telefonia","Dentro da faixa a evitar: troque de frequência ou de equipamento",IF(N17="TV","Dentro do canal de TV "&J17&", ativo na cidade: use um canal de TV livre",IF(N17="Intermod.","Há "&M17&" produto(s) de intermodulação perto: troque esta frequência ou use o grupo do fabricante","Manter"))))))) | R17: =IF(OR($I17="",$I15=""),"",ROUND(ABS($I17-$I15),4)) | S17: =IF(OR($I17="",$I16=""),"",ROUND(ABS($I17-$I16),4)) | U17: =IF(OR($I17="",$I18=""),"",ROUND(ABS($I17-$I18),4)) | V17: =IF(OR($I17="",$I19=""),"",ROUND(ABS($I17-$I19),4)) | W17: =IF(OR($I17="",$I20=""),"",ROUND(ABS($I17-$I20),4)) | X17: =IF(OR($I17="",$I21=""),"",ROUND(ABS($I17-$I21),4)) | Y17: =IF(OR($I17="",$I22=""),"",ROUND(ABS($I17-$I22),4)) | Z17: =IF(OR($I17="",$I23=""),"",ROUND(ABS($I17-$I23),4)) | AA17: =IF(OR($I17="",$I24=""),"",ROUND(ABS($I17-$I24),4)) | AB17: =IF(OR($I17="",$I25=""),"",ROUND(ABS($I17-$I25),4)) | AC17: =IF(OR($I17="",$I26=""),"",ROUND(ABS($I17-$I26),4)) | AD17: =IF(OR($I17="",$I27=""),"",ROUND(ABS($I17-$I27),4)) | AE17: =IF(OR($I17="",$I28=""),"",ROUND(ABS($I17-$I28),4)) | AF17: =IF(OR($I17="",$I29=""),"",ROUND(ABS($I17-$I29),4)) | AG17: =IF(OR($I17="",$I30=""),"",ROUND(ABS($I17-$I30),4)) | AI17: =IF(OR($I17="",$I15=""),"",ROUND((2*$I17-$I15)*1000,0)) | AJ17: =IF(OR($I17="",$I16=""),"",ROUND((2*$I17-$I16)*1000,0)) | AL17: =IF(OR($I17="",$I18=""),"",ROUND((2*$I17-$I18)*1000,0)) | AM17: =IF(OR($I17="",$I19=""),"",ROUND((2*$I17-$I19)*1000,0)) | AN17: =IF(OR($I17="",$I20=""),"",ROUND((2*$I17-$I20)*1000,0)) | AO17: =IF(OR($I17="",$I21=""),"",ROUND((2*$I17-$I21)*1000,0)) | AP17: =IF(OR($I17="",$I22=""),"",ROUND((2*$I17-$I22)*1000,0)) | AQ17: =IF(OR($I17="",$I23=""),"",ROUND((2*$I17-$I23)*1000,0)) | AR17: =IF(OR($I17="",$I24=""),"",ROUND((2*$I17-$I24)*1000,0)) | AS17: =IF(OR($I17="",$I25=""),"",ROUND((2*$I17-$I25)*1000,0)) | AT17: =IF(OR($I17="",$I26=""),"",ROUND((2*$I17-$I26)*1000,0)) | AU17: =IF(OR($I17="",$I27=""),"",ROUND((2*$I17-$I27)*1000,0)) | AV17: =IF(OR($I17="",$I28=""),"",ROUND((2*$I17-$I28)*1000,0)) | AW17: =IF(OR($I17="",$I29=""),"",ROUND((2*$I17-$I29)*1000,0)) | AX17: =IF(OR($I17="",$I30=""),"",ROUND((2*$I17-$I30)*1000,0))
B18: 4 | J18: =IF(I18="","",IF(AND(I18>=470,I18<698),INT((I18-470)/6)+14,"–")) | K18: =IF(OR(I18="",COUNT($R18:$AG18)=0),"",MIN($R18:$AG18)) | L18: =IF(K18="","",MATCH(K18,$R18:$AG18,0)) | M18: =IF(I18="","",COUNTIFS($AI$15:$AX$30,">"&ROUND((I18-$L$5)*1000,0),$AI$15:$AX$30,"<"&ROUND((I18+$L$5)*1000,0))-COUNTIFS($AI18:$AX18,">"&ROUND((I18-$L$5)*1000,0),$AI18:$AX18,"<"&ROUND((I18+$L$5)*1000,0))-COUNTIFS(AL$15:AL$30,">"&ROUND((I18-$L$5)*1000,0),AL$15:AL$30,"<"&ROUND((I18+$L$5)*1000,0))) | N18: =IF(I18="",IF(AND(C18<>"",F18="2,4 GHz"),"Automática",""),IF(AND(K18<>"",K18<0.0005),"Repetida",IF(AND(K18<>"",$L$4<>"",K18<$L$4),"Próxima",IF(AND($L$6<>"",$L$7<>"",I18>=$L$6,I18<=$L$7),"Telefonia",IF(AND(I18>=470,I18<698,COUNTIF($E$9:$L$9,INT((I18-470)/6)+14)>0),"TV",IF(M18>0,"Intermod.","OK")))))) | O18: =IF(N18="","",IF(N18="Automática","Sem frequência fixa: o sistema escolhe o canal. Afaste o receptor do roteador Wi-Fi",IF(N18="Repetida","Mesma frequência do sistema nº "&L18&": troque o canal de um dos dois",IF(N18="Próxima","Perto demais do sistema nº "&L18&": afaste as duas frequências",IF(N18="Telefonia","Dentro da faixa a evitar: troque de frequência ou de equipamento",IF(N18="TV","Dentro do canal de TV "&J18&", ativo na cidade: use um canal de TV livre",IF(N18="Intermod.","Há "&M18&" produto(s) de intermodulação perto: troque esta frequência ou use o grupo do fabricante","Manter"))))))) | R18: =IF(OR($I18="",$I15=""),"",ROUND(ABS($I18-$I15),4)) | S18: =IF(OR($I18="",$I16=""),"",ROUND(ABS($I18-$I16),4)) | T18: =IF(OR($I18="",$I17=""),"",ROUND(ABS($I18-$I17),4)) | V18: =IF(OR($I18="",$I19=""),"",ROUND(ABS($I18-$I19),4)) | W18: =IF(OR($I18="",$I20=""),"",ROUND(ABS($I18-$I20),4)) | X18: =IF(OR($I18="",$I21=""),"",ROUND(ABS($I18-$I21),4)) | Y18: =IF(OR($I18="",$I22=""),"",ROUND(ABS($I18-$I22),4)) | Z18: =IF(OR($I18="",$I23=""),"",ROUND(ABS($I18-$I23),4)) | AA18: =IF(OR($I18="",$I24=""),"",ROUND(ABS($I18-$I24),4)) | AB18: =IF(OR($I18="",$I25=""),"",ROUND(ABS($I18-$I25),4)) | AC18: =IF(OR($I18="",$I26=""),"",ROUND(ABS($I18-$I26),4)) | AD18: =IF(OR($I18="",$I27=""),"",ROUND(ABS($I18-$I27),4)) | AE18: =IF(OR($I18="",$I28=""),"",ROUND(ABS($I18-$I28),4)) | AF18: =IF(OR($I18="",$I29=""),"",ROUND(ABS($I18-$I29),4)) | AG18: =IF(OR($I18="",$I30=""),"",ROUND(ABS($I18-$I30),4)) | AI18: =IF(OR($I18="",$I15=""),"",ROUND((2*$I18-$I15)*1000,0)) | AJ18: =IF(OR($I18="",$I16=""),"",ROUND((2*$I18-$I16)*1000,0)) | AK18: =IF(OR($I18="",$I17=""),"",ROUND((2*$I18-$I17)*1000,0)) | AM18: =IF(OR($I18="",$I19=""),"",ROUND((2*$I18-$I19)*1000,0)) | AN18: =IF(OR($I18="",$I20=""),"",ROUND((2*$I18-$I20)*1000,0)) | AO18: =IF(OR($I18="",$I21=""),"",ROUND((2*$I18-$I21)*1000,0)) | AP18: =IF(OR($I18="",$I22=""),"",ROUND((2*$I18-$I22)*1000,0)) | AQ18: =IF(OR($I18="",$I23=""),"",ROUND((2*$I18-$I23)*1000,0)) | AR18: =IF(OR($I18="",$I24=""),"",ROUND((2*$I18-$I24)*1000,0)) | AS18: =IF(OR($I18="",$I25=""),"",ROUND((2*$I18-$I25)*1000,0)) | AT18: =IF(OR($I18="",$I26=""),"",ROUND((2*$I18-$I26)*1000,0)) | AU18: =IF(OR($I18="",$I27=""),"",ROUND((2*$I18-$I27)*1000,0)) | AV18: =IF(OR($I18="",$I28=""),"",ROUND((2*$I18-$I28)*1000,0)) | AW18: =IF(OR($I18="",$I29=""),"",ROUND((2*$I18-$I29)*1000,0)) | AX18: =IF(OR($I18="",$I30=""),"",ROUND((2*$I18-$I30)*1000,0))
B19: 5 | J19: =IF(I19="","",IF(AND(I19>=470,I19<698),INT((I19-470)/6)+14,"–")) | K19: =IF(OR(I19="",COUNT($R19:$AG19)=0),"",MIN($R19:$AG19)) | L19: =IF(K19="","",MATCH(K19,$R19:$AG19,0)) | M19: =IF(I19="","",COUNTIFS($AI$15:$AX$30,">"&ROUND((I19-$L$5)*1000,0),$AI$15:$AX$30,"<"&ROUND((I19+$L$5)*1000,0))-COUNTIFS($AI19:$AX19,">"&ROUND((I19-$L$5)*1000,0),$AI19:$AX19,"<"&ROUND((I19+$L$5)*1000,0))-COUNTIFS(AM$15:AM$30,">"&ROUND((I19-$L$5)*1000,0),AM$15:AM$30,"<"&ROUND((I19+$L$5)*1000,0))) | N19: =IF(I19="",IF(AND(C19<>"",F19="2,4 GHz"),"Automática",""),IF(AND(K19<>"",K19<0.0005),"Repetida",IF(AND(K19<>"",$L$4<>"",K19<$L$4),"Próxima",IF(AND($L$6<>"",$L$7<>"",I19>=$L$6,I19<=$L$7),"Telefonia",IF(AND(I19>=470,I19<698,COUNTIF($E$9:$L$9,INT((I19-470)/6)+14)>0),"TV",IF(M19>0,"Intermod.","OK")))))) | O19: =IF(N19="","",IF(N19="Automática","Sem frequência fixa: o sistema escolhe o canal. Afaste o receptor do roteador Wi-Fi",IF(N19="Repetida","Mesma frequência do sistema nº "&L19&": troque o canal de um dos dois",IF(N19="Próxima","Perto demais do sistema nº "&L19&": afaste as duas frequências",IF(N19="Telefonia","Dentro da faixa a evitar: troque de frequência ou de equipamento",IF(N19="TV","Dentro do canal de TV "&J19&", ativo na cidade: use um canal de TV livre",IF(N19="Intermod.","Há "&M19&" produto(s) de intermodulação perto: troque esta frequência ou use o grupo do fabricante","Manter"))))))) | R19: =IF(OR($I19="",$I15=""),"",ROUND(ABS($I19-$I15),4)) | S19: =IF(OR($I19="",$I16=""),"",ROUND(ABS($I19-$I16),4)) | T19: =IF(OR($I19="",$I17=""),"",ROUND(ABS($I19-$I17),4)) | U19: =IF(OR($I19="",$I18=""),"",ROUND(ABS($I19-$I18),4)) | W19: =IF(OR($I19="",$I20=""),"",ROUND(ABS($I19-$I20),4)) | X19: =IF(OR($I19="",$I21=""),"",ROUND(ABS($I19-$I21),4)) | Y19: =IF(OR($I19="",$I22=""),"",ROUND(ABS($I19-$I22),4)) | Z19: =IF(OR($I19="",$I23=""),"",ROUND(ABS($I19-$I23),4)) | AA19: =IF(OR($I19="",$I24=""),"",ROUND(ABS($I19-$I24),4)) | AB19: =IF(OR($I19="",$I25=""),"",ROUND(ABS($I19-$I25),4)) | AC19: =IF(OR($I19="",$I26=""),"",ROUND(ABS($I19-$I26),4)) | AD19: =IF(OR($I19="",$I27=""),"",ROUND(ABS($I19-$I27),4)) | AE19: =IF(OR($I19="",$I28=""),"",ROUND(ABS($I19-$I28),4)) | AF19: =IF(OR($I19="",$I29=""),"",ROUND(ABS($I19-$I29),4)) | AG19: =IF(OR($I19="",$I30=""),"",ROUND(ABS($I19-$I30),4)) | AI19: =IF(OR($I19="",$I15=""),"",ROUND((2*$I19-$I15)*1000,0)) | AJ19: =IF(OR($I19="",$I16=""),"",ROUND((2*$I19-$I16)*1000,0)) | AK19: =IF(OR($I19="",$I17=""),"",ROUND((2*$I19-$I17)*1000,0)) | AL19: =IF(OR($I19="",$I18=""),"",ROUND((2*$I19-$I18)*1000,0)) | AN19: =IF(OR($I19="",$I20=""),"",ROUND((2*$I19-$I20)*1000,0)) | AO19: =IF(OR($I19="",$I21=""),"",ROUND((2*$I19-$I21)*1000,0)) | AP19: =IF(OR($I19="",$I22=""),"",ROUND((2*$I19-$I22)*1000,0)) | AQ19: =IF(OR($I19="",$I23=""),"",ROUND((2*$I19-$I23)*1000,0)) | AR19: =IF(OR($I19="",$I24=""),"",ROUND((2*$I19-$I24)*1000,0)) | AS19: =IF(OR($I19="",$I25=""),"",ROUND((2*$I19-$I25)*1000,0)) | AT19: =IF(OR($I19="",$I26=""),"",ROUND((2*$I19-$I26)*1000,0)) | AU19: =IF(OR($I19="",$I27=""),"",ROUND((2*$I19-$I27)*1000,0)) | AV19: =IF(OR($I19="",$I28=""),"",ROUND((2*$I19-$I28)*1000,0)) | AW19: =IF(OR($I19="",$I29=""),"",ROUND((2*$I19-$I29)*1000,0)) | AX19: =IF(OR($I19="",$I30=""),"",ROUND((2*$I19-$I30)*1000,0))
B20: 6 | J20: =IF(I20="","",IF(AND(I20>=470,I20<698),INT((I20-470)/6)+14,"–")) | K20: =IF(OR(I20="",COUNT($R20:$AG20)=0),"",MIN($R20:$AG20)) | L20: =IF(K20="","",MATCH(K20,$R20:$AG20,0)) | M20: =IF(I20="","",COUNTIFS($AI$15:$AX$30,">"&ROUND((I20-$L$5)*1000,0),$AI$15:$AX$30,"<"&ROUND((I20+$L$5)*1000,0))-COUNTIFS($AI20:$AX20,">"&ROUND((I20-$L$5)*1000,0),$AI20:$AX20,"<"&ROUND((I20+$L$5)*1000,0))-COUNTIFS(AN$15:AN$30,">"&ROUND((I20-$L$5)*1000,0),AN$15:AN$30,"<"&ROUND((I20+$L$5)*1000,0))) | N20: =IF(I20="",IF(AND(C20<>"",F20="2,4 GHz"),"Automática",""),IF(AND(K20<>"",K20<0.0005),"Repetida",IF(AND(K20<>"",$L$4<>"",K20<$L$4),"Próxima",IF(AND($L$6<>"",$L$7<>"",I20>=$L$6,I20<=$L$7),"Telefonia",IF(AND(I20>=470,I20<698,COUNTIF($E$9:$L$9,INT((I20-470)/6)+14)>0),"TV",IF(M20>0,"Intermod.","OK")))))) | O20: =IF(N20="","",IF(N20="Automática","Sem frequência fixa: o sistema escolhe o canal. Afaste o receptor do roteador Wi-Fi",IF(N20="Repetida","Mesma frequência do sistema nº "&L20&": troque o canal de um dos dois",IF(N20="Próxima","Perto demais do sistema nº "&L20&": afaste as duas frequências",IF(N20="Telefonia","Dentro da faixa a evitar: troque de frequência ou de equipamento",IF(N20="TV","Dentro do canal de TV "&J20&", ativo na cidade: use um canal de TV livre",IF(N20="Intermod.","Há "&M20&" produto(s) de intermodulação perto: troque esta frequência ou use o grupo do fabricante","Manter"))))))) | R20: =IF(OR($I20="",$I15=""),"",ROUND(ABS($I20-$I15),4)) | S20: =IF(OR($I20="",$I16=""),"",ROUND(ABS($I20-$I16),4)) | T20: =IF(OR($I20="",$I17=""),"",ROUND(ABS($I20-$I17),4)) | U20: =IF(OR($I20="",$I18=""),"",ROUND(ABS($I20-$I18),4)) | V20: =IF(OR($I20="",$I19=""),"",ROUND(ABS($I20-$I19),4)) | X20: =IF(OR($I20="",$I21=""),"",ROUND(ABS($I20-$I21),4)) | Y20: =IF(OR($I20="",$I22=""),"",ROUND(ABS($I20-$I22),4)) | Z20: =IF(OR($I20="",$I23=""),"",ROUND(ABS($I20-$I23),4)) | AA20: =IF(OR($I20="",$I24=""),"",ROUND(ABS($I20-$I24),4)) | AB20: =IF(OR($I20="",$I25=""),"",ROUND(ABS($I20-$I25),4)) | AC20: =IF(OR($I20="",$I26=""),"",ROUND(ABS($I20-$I26),4)) | AD20: =IF(OR($I20="",$I27=""),"",ROUND(ABS($I20-$I27),4)) | AE20: =IF(OR($I20="",$I28=""),"",ROUND(ABS($I20-$I28),4)) | AF20: =IF(OR($I20="",$I29=""),"",ROUND(ABS($I20-$I29),4)) | AG20: =IF(OR($I20="",$I30=""),"",ROUND(ABS($I20-$I30),4)) | AI20: =IF(OR($I20="",$I15=""),"",ROUND((2*$I20-$I15)*1000,0)) | AJ20: =IF(OR($I20="",$I16=""),"",ROUND((2*$I20-$I16)*1000,0)) | AK20: =IF(OR($I20="",$I17=""),"",ROUND((2*$I20-$I17)*1000,0)) | AL20: =IF(OR($I20="",$I18=""),"",ROUND((2*$I20-$I18)*1000,0)) | AM20: =IF(OR($I20="",$I19=""),"",ROUND((2*$I20-$I19)*1000,0)) | AO20: =IF(OR($I20="",$I21=""),"",ROUND((2*$I20-$I21)*1000,0)) | AP20: =IF(OR($I20="",$I22=""),"",ROUND((2*$I20-$I22)*1000,0)) | AQ20: =IF(OR($I20="",$I23=""),"",ROUND((2*$I20-$I23)*1000,0)) | AR20: =IF(OR($I20="",$I24=""),"",ROUND((2*$I20-$I24)*1000,0)) | AS20: =IF(OR($I20="",$I25=""),"",ROUND((2*$I20-$I25)*1000,0)) | AT20: =IF(OR($I20="",$I26=""),"",ROUND((2*$I20-$I26)*1000,0)) | AU20: =IF(OR($I20="",$I27=""),"",ROUND((2*$I20-$I27)*1000,0)) | AV20: =IF(OR($I20="",$I28=""),"",ROUND((2*$I20-$I28)*1000,0)) | AW20: =IF(OR($I20="",$I29=""),"",ROUND((2*$I20-$I29)*1000,0)) | AX20: =IF(OR($I20="",$I30=""),"",ROUND((2*$I20-$I30)*1000,0))
B21: 7 | J21: =IF(I21="","",IF(AND(I21>=470,I21<698),INT((I21-470)/6)+14,"–")) | K21: =IF(OR(I21="",COUNT($R21:$AG21)=0),"",MIN($R21:$AG21)) | L21: =IF(K21="","",MATCH(K21,$R21:$AG21,0)) | M21: =IF(I21="","",COUNTIFS($AI$15:$AX$30,">"&ROUND((I21-$L$5)*1000,0),$AI$15:$AX$30,"<"&ROUND((I21+$L$5)*1000,0))-COUNTIFS($AI21:$AX21,">"&ROUND((I21-$L$5)*1000,0),$AI21:$AX21,"<"&ROUND((I21+$L$5)*1000,0))-COUNTIFS(AO$15:AO$30,">"&ROUND((I21-$L$5)*1000,0),AO$15:AO$30,"<"&ROUND((I21+$L$5)*1000,0))) | N21: =IF(I21="",IF(AND(C21<>"",F21="2,4 GHz"),"Automática",""),IF(AND(K21<>"",K21<0.0005),"Repetida",IF(AND(K21<>"",$L$4<>"",K21<$L$4),"Próxima",IF(AND($L$6<>"",$L$7<>"",I21>=$L$6,I21<=$L$7),"Telefonia",IF(AND(I21>=470,I21<698,COUNTIF($E$9:$L$9,INT((I21-470)/6)+14)>0),"TV",IF(M21>0,"Intermod.","OK")))))) | O21: =IF(N21="","",IF(N21="Automática","Sem frequência fixa: o sistema escolhe o canal. Afaste o receptor do roteador Wi-Fi",IF(N21="Repetida","Mesma frequência do sistema nº "&L21&": troque o canal de um dos dois",IF(N21="Próxima","Perto demais do sistema nº "&L21&": afaste as duas frequências",IF(N21="Telefonia","Dentro da faixa a evitar: troque de frequência ou de equipamento",IF(N21="TV","Dentro do canal de TV "&J21&", ativo na cidade: use um canal de TV livre",IF(N21="Intermod.","Há "&M21&" produto(s) de intermodulação perto: troque esta frequência ou use o grupo do fabricante","Manter"))))))) | R21: =IF(OR($I21="",$I15=""),"",ROUND(ABS($I21-$I15),4)) | S21: =IF(OR($I21="",$I16=""),"",ROUND(ABS($I21-$I16),4)) | T21: =IF(OR($I21="",$I17=""),"",ROUND(ABS($I21-$I17),4)) | U21: =IF(OR($I21="",$I18=""),"",ROUND(ABS($I21-$I18),4)) | V21: =IF(OR($I21="",$I19=""),"",ROUND(ABS($I21-$I19),4)) | W21: =IF(OR($I21="",$I20=""),"",ROUND(ABS($I21-$I20),4)) | Y21: =IF(OR($I21="",$I22=""),"",ROUND(ABS($I21-$I22),4)) | Z21: =IF(OR($I21="",$I23=""),"",ROUND(ABS($I21-$I23),4)) | AA21: =IF(OR($I21="",$I24=""),"",ROUND(ABS($I21-$I24),4)) | AB21: =IF(OR($I21="",$I25=""),"",ROUND(ABS($I21-$I25),4)) | AC21: =IF(OR($I21="",$I26=""),"",ROUND(ABS($I21-$I26),4)) | AD21: =IF(OR($I21="",$I27=""),"",ROUND(ABS($I21-$I27),4)) | AE21: =IF(OR($I21="",$I28=""),"",ROUND(ABS($I21-$I28),4)) | AF21: =IF(OR($I21="",$I29=""),"",ROUND(ABS($I21-$I29),4)) | AG21: =IF(OR($I21="",$I30=""),"",ROUND(ABS($I21-$I30),4)) | AI21: =IF(OR($I21="",$I15=""),"",ROUND((2*$I21-$I15)*1000,0)) | AJ21: =IF(OR($I21="",$I16=""),"",ROUND((2*$I21-$I16)*1000,0)) | AK21: =IF(OR($I21="",$I17=""),"",ROUND((2*$I21-$I17)*1000,0)) | AL21: =IF(OR($I21="",$I18=""),"",ROUND((2*$I21-$I18)*1000,0)) | AM21: =IF(OR($I21="",$I19=""),"",ROUND((2*$I21-$I19)*1000,0)) | AN21: =IF(OR($I21="",$I20=""),"",ROUND((2*$I21-$I20)*1000,0)) | AP21: =IF(OR($I21="",$I22=""),"",ROUND((2*$I21-$I22)*1000,0)) | AQ21: =IF(OR($I21="",$I23=""),"",ROUND((2*$I21-$I23)*1000,0)) | AR21: =IF(OR($I21="",$I24=""),"",ROUND((2*$I21-$I24)*1000,0)) | AS21: =IF(OR($I21="",$I25=""),"",ROUND((2*$I21-$I25)*1000,0)) | AT21: =IF(OR($I21="",$I26=""),"",ROUND((2*$I21-$I26)*1000,0)) | AU21: =IF(OR($I21="",$I27=""),"",ROUND((2*$I21-$I27)*1000,0)) | AV21: =IF(OR($I21="",$I28=""),"",ROUND((2*$I21-$I28)*1000,0)) | AW21: =IF(OR($I21="",$I29=""),"",ROUND((2*$I21-$I29)*1000,0)) | AX21: =IF(OR($I21="",$I30=""),"",ROUND((2*$I21-$I30)*1000,0))
B22: 8 | J22: =IF(I22="","",IF(AND(I22>=470,I22<698),INT((I22-470)/6)+14,"–")) | K22: =IF(OR(I22="",COUNT($R22:$AG22)=0),"",MIN($R22:$AG22)) | L22: =IF(K22="","",MATCH(K22,$R22:$AG22,0)) | M22: =IF(I22="","",COUNTIFS($AI$15:$AX$30,">"&ROUND((I22-$L$5)*1000,0),$AI$15:$AX$30,"<"&ROUND((I22+$L$5)*1000,0))-COUNTIFS($AI22:$AX22,">"&ROUND((I22-$L$5)*1000,0),$AI22:$AX22,"<"&ROUND((I22+$L$5)*1000,0))-COUNTIFS(AP$15:AP$30,">"&ROUND((I22-$L$5)*1000,0),AP$15:AP$30,"<"&ROUND((I22+$L$5)*1000,0))) | N22: =IF(I22="",IF(AND(C22<>"",F22="2,4 GHz"),"Automática",""),IF(AND(K22<>"",K22<0.0005),"Repetida",IF(AND(K22<>"",$L$4<>"",K22<$L$4),"Próxima",IF(AND($L$6<>"",$L$7<>"",I22>=$L$6,I22<=$L$7),"Telefonia",IF(AND(I22>=470,I22<698,COUNTIF($E$9:$L$9,INT((I22-470)/6)+14)>0),"TV",IF(M22>0,"Intermod.","OK")))))) | O22: =IF(N22="","",IF(N22="Automática","Sem frequência fixa: o sistema escolhe o canal. Afaste o receptor do roteador Wi-Fi",IF(N22="Repetida","Mesma frequência do sistema nº "&L22&": troque o canal de um dos dois",IF(N22="Próxima","Perto demais do sistema nº "&L22&": afaste as duas frequências",IF(N22="Telefonia","Dentro da faixa a evitar: troque de frequência ou de equipamento",IF(N22="TV","Dentro do canal de TV "&J22&", ativo na cidade: use um canal de TV livre",IF(N22="Intermod.","Há "&M22&" produto(s) de intermodulação perto: troque esta frequência ou use o grupo do fabricante","Manter"))))))) | R22: =IF(OR($I22="",$I15=""),"",ROUND(ABS($I22-$I15),4)) | S22: =IF(OR($I22="",$I16=""),"",ROUND(ABS($I22-$I16),4)) | T22: =IF(OR($I22="",$I17=""),"",ROUND(ABS($I22-$I17),4)) | U22: =IF(OR($I22="",$I18=""),"",ROUND(ABS($I22-$I18),4)) | V22: =IF(OR($I22="",$I19=""),"",ROUND(ABS($I22-$I19),4)) | W22: =IF(OR($I22="",$I20=""),"",ROUND(ABS($I22-$I20),4)) | X22: =IF(OR($I22="",$I21=""),"",ROUND(ABS($I22-$I21),4)) | Z22: =IF(OR($I22="",$I23=""),"",ROUND(ABS($I22-$I23),4)) | AA22: =IF(OR($I22="",$I24=""),"",ROUND(ABS($I22-$I24),4)) | AB22: =IF(OR($I22="",$I25=""),"",ROUND(ABS($I22-$I25),4)) | AC22: =IF(OR($I22="",$I26=""),"",ROUND(ABS($I22-$I26),4)) | AD22: =IF(OR($I22="",$I27=""),"",ROUND(ABS($I22-$I27),4)) | AE22: =IF(OR($I22="",$I28=""),"",ROUND(ABS($I22-$I28),4)) | AF22: =IF(OR($I22="",$I29=""),"",ROUND(ABS($I22-$I29),4)) | AG22: =IF(OR($I22="",$I30=""),"",ROUND(ABS($I22-$I30),4)) | AI22: =IF(OR($I22="",$I15=""),"",ROUND((2*$I22-$I15)*1000,0)) | AJ22: =IF(OR($I22="",$I16=""),"",ROUND((2*$I22-$I16)*1000,0)) | AK22: =IF(OR($I22="",$I17=""),"",ROUND((2*$I22-$I17)*1000,0)) | AL22: =IF(OR($I22="",$I18=""),"",ROUND((2*$I22-$I18)*1000,0)) | AM22: =IF(OR($I22="",$I19=""),"",ROUND((2*$I22-$I19)*1000,0)) | AN22: =IF(OR($I22="",$I20=""),"",ROUND((2*$I22-$I20)*1000,0)) | AO22: =IF(OR($I22="",$I21=""),"",ROUND((2*$I22-$I21)*1000,0)) | AQ22: =IF(OR($I22="",$I23=""),"",ROUND((2*$I22-$I23)*1000,0)) | AR22: =IF(OR($I22="",$I24=""),"",ROUND((2*$I22-$I24)*1000,0)) | AS22: =IF(OR($I22="",$I25=""),"",ROUND((2*$I22-$I25)*1000,0)) | AT22: =IF(OR($I22="",$I26=""),"",ROUND((2*$I22-$I26)*1000,0)) | AU22: =IF(OR($I22="",$I27=""),"",ROUND((2*$I22-$I27)*1000,0)) | AV22: =IF(OR($I22="",$I28=""),"",ROUND((2*$I22-$I28)*1000,0)) | AW22: =IF(OR($I22="",$I29=""),"",ROUND((2*$I22-$I29)*1000,0)) | AX22: =IF(OR($I22="",$I30=""),"",ROUND((2*$I22-$I30)*1000,0))
B23: 9 | J23: =IF(I23="","",IF(AND(I23>=470,I23<698),INT((I23-470)/6)+14,"–")) | K23: =IF(OR(I23="",COUNT($R23:$AG23)=0),"",MIN($R23:$AG23)) | L23: =IF(K23="","",MATCH(K23,$R23:$AG23,0)) | M23: =IF(I23="","",COUNTIFS($AI$15:$AX$30,">"&ROUND((I23-$L$5)*1000,0),$AI$15:$AX$30,"<"&ROUND((I23+$L$5)*1000,0))-COUNTIFS($AI23:$AX23,">"&ROUND((I23-$L$5)*1000,0),$AI23:$AX23,"<"&ROUND((I23+$L$5)*1000,0))-COUNTIFS(AQ$15:AQ$30,">"&ROUND((I23-$L$5)*1000,0),AQ$15:AQ$30,"<"&ROUND((I23+$L$5)*1000,0))) | N23: =IF(I23="",IF(AND(C23<>"",F23="2,4 GHz"),"Automática",""),IF(AND(K23<>"",K23<0.0005),"Repetida",IF(AND(K23<>"",$L$4<>"",K23<$L$4),"Próxima",IF(AND($L$6<>"",$L$7<>"",I23>=$L$6,I23<=$L$7),"Telefonia",IF(AND(I23>=470,I23<698,COUNTIF($E$9:$L$9,INT((I23-470)/6)+14)>0),"TV",IF(M23>0,"Intermod.","OK")))))) | O23: =IF(N23="","",IF(N23="Automática","Sem frequência fixa: o sistema escolhe o canal. Afaste o receptor do roteador Wi-Fi",IF(N23="Repetida","Mesma frequência do sistema nº "&L23&": troque o canal de um dos dois",IF(N23="Próxima","Perto demais do sistema nº "&L23&": afaste as duas frequências",IF(N23="Telefonia","Dentro da faixa a evitar: troque de frequência ou de equipamento",IF(N23="TV","Dentro do canal de TV "&J23&", ativo na cidade: use um canal de TV livre",IF(N23="Intermod.","Há "&M23&" produto(s) de intermodulação perto: troque esta frequência ou use o grupo do fabricante","Manter"))))))) | R23: =IF(OR($I23="",$I15=""),"",ROUND(ABS($I23-$I15),4)) | S23: =IF(OR($I23="",$I16=""),"",ROUND(ABS($I23-$I16),4)) | T23: =IF(OR($I23="",$I17=""),"",ROUND(ABS($I23-$I17),4)) | U23: =IF(OR($I23="",$I18=""),"",ROUND(ABS($I23-$I18),4)) | V23: =IF(OR($I23="",$I19=""),"",ROUND(ABS($I23-$I19),4)) | W23: =IF(OR($I23="",$I20=""),"",ROUND(ABS($I23-$I20),4)) | X23: =IF(OR($I23="",$I21=""),"",ROUND(ABS($I23-$I21),4)) | Y23: =IF(OR($I23="",$I22=""),"",ROUND(ABS($I23-$I22),4)) | AA23: =IF(OR($I23="",$I24=""),"",ROUND(ABS($I23-$I24),4)) | AB23: =IF(OR($I23="",$I25=""),"",ROUND(ABS($I23-$I25),4)) | AC23: =IF(OR($I23="",$I26=""),"",ROUND(ABS($I23-$I26),4)) | AD23: =IF(OR($I23="",$I27=""),"",ROUND(ABS($I23-$I27),4)) | AE23: =IF(OR($I23="",$I28=""),"",ROUND(ABS($I23-$I28),4)) | AF23: =IF(OR($I23="",$I29=""),"",ROUND(ABS($I23-$I29),4)) | AG23: =IF(OR($I23="",$I30=""),"",ROUND(ABS($I23-$I30),4)) | AI23: =IF(OR($I23="",$I15=""),"",ROUND((2*$I23-$I15)*1000,0)) | AJ23: =IF(OR($I23="",$I16=""),"",ROUND((2*$I23-$I16)*1000,0)) | AK23: =IF(OR($I23="",$I17=""),"",ROUND((2*$I23-$I17)*1000,0)) | AL23: =IF(OR($I23="",$I18=""),"",ROUND((2*$I23-$I18)*1000,0)) | AM23: =IF(OR($I23="",$I19=""),"",ROUND((2*$I23-$I19)*1000,0)) | AN23: =IF(OR($I23="",$I20=""),"",ROUND((2*$I23-$I20)*1000,0)) | AO23: =IF(OR($I23="",$I21=""),"",ROUND((2*$I23-$I21)*1000,0)) | AP23: =IF(OR($I23="",$I22=""),"",ROUND((2*$I23-$I22)*1000,0)) | AR23: =IF(OR($I23="",$I24=""),"",ROUND((2*$I23-$I24)*1000,0)) | AS23: =IF(OR($I23="",$I25=""),"",ROUND((2*$I23-$I25)*1000,0)) | AT23: =IF(OR($I23="",$I26=""),"",ROUND((2*$I23-$I26)*1000,0)) | AU23: =IF(OR($I23="",$I27=""),"",ROUND((2*$I23-$I27)*1000,0)) | AV23: =IF(OR($I23="",$I28=""),"",ROUND((2*$I23-$I28)*1000,0)) | AW23: =IF(OR($I23="",$I29=""),"",ROUND((2*$I23-$I29)*1000,0)) | AX23: =IF(OR($I23="",$I30=""),"",ROUND((2*$I23-$I30)*1000,0))
B24: 10 | J24: =IF(I24="","",IF(AND(I24>=470,I24<698),INT((I24-470)/6)+14,"–")) | K24: =IF(OR(I24="",COUNT($R24:$AG24)=0),"",MIN($R24:$AG24)) | L24: =IF(K24="","",MATCH(K24,$R24:$AG24,0)) | M24: =IF(I24="","",COUNTIFS($AI$15:$AX$30,">"&ROUND((I24-$L$5)*1000,0),$AI$15:$AX$30,"<"&ROUND((I24+$L$5)*1000,0))-COUNTIFS($AI24:$AX24,">"&ROUND((I24-$L$5)*1000,0),$AI24:$AX24,"<"&ROUND((I24+$L$5)*1000,0))-COUNTIFS(AR$15:AR$30,">"&ROUND((I24-$L$5)*1000,0),AR$15:AR$30,"<"&ROUND((I24+$L$5)*1000,0))) | N24: =IF(I24="",IF(AND(C24<>"",F24="2,4 GHz"),"Automática",""),IF(AND(K24<>"",K24<0.0005),"Repetida",IF(AND(K24<>"",$L$4<>"",K24<$L$4),"Próxima",IF(AND($L$6<>"",$L$7<>"",I24>=$L$6,I24<=$L$7),"Telefonia",IF(AND(I24>=470,I24<698,COUNTIF($E$9:$L$9,INT((I24-470)/6)+14)>0),"TV",IF(M24>0,"Intermod.","OK")))))) | O24: =IF(N24="","",IF(N24="Automática","Sem frequência fixa: o sistema escolhe o canal. Afaste o receptor do roteador Wi-Fi",IF(N24="Repetida","Mesma frequência do sistema nº "&L24&": troque o canal de um dos dois",IF(N24="Próxima","Perto demais do sistema nº "&L24&": afaste as duas frequências",IF(N24="Telefonia","Dentro da faixa a evitar: troque de frequência ou de equipamento",IF(N24="TV","Dentro do canal de TV "&J24&", ativo na cidade: use um canal de TV livre",IF(N24="Intermod.","Há "&M24&" produto(s) de intermodulação perto: troque esta frequência ou use o grupo do fabricante","Manter"))))))) | R24: =IF(OR($I24="",$I15=""),"",ROUND(ABS($I24-$I15),4)) | S24: =IF(OR($I24="",$I16=""),"",ROUND(ABS($I24-$I16),4)) | T24: =IF(OR($I24="",$I17=""),"",ROUND(ABS($I24-$I17),4)) | U24: =IF(OR($I24="",$I18=""),"",ROUND(ABS($I24-$I18),4)) | V24: =IF(OR($I24="",$I19=""),"",ROUND(ABS($I24-$I19),4)) | W24: =IF(OR($I24="",$I20=""),"",ROUND(ABS($I24-$I20),4)) | X24: =IF(OR($I24="",$I21=""),"",ROUND(ABS($I24-$I21),4)) | Y24: =IF(OR($I24="",$I22=""),"",ROUND(ABS($I24-$I22),4)) | Z24: =IF(OR($I24="",$I23=""),"",ROUND(ABS($I24-$I23),4)) | AB24: =IF(OR($I24="",$I25=""),"",ROUND(ABS($I24-$I25),4)) | AC24: =IF(OR($I24="",$I26=""),"",ROUND(ABS($I24-$I26),4)) | AD24: =IF(OR($I24="",$I27=""),"",ROUND(ABS($I24-$I27),4)) | AE24: =IF(OR($I24="",$I28=""),"",ROUND(ABS($I24-$I28),4)) | AF24: =IF(OR($I24="",$I29=""),"",ROUND(ABS($I24-$I29),4)) | AG24: =IF(OR($I24="",$I30=""),"",ROUND(ABS($I24-$I30),4)) | AI24: =IF(OR($I24="",$I15=""),"",ROUND((2*$I24-$I15)*1000,0)) | AJ24: =IF(OR($I24="",$I16=""),"",ROUND((2*$I24-$I16)*1000,0)) | AK24: =IF(OR($I24="",$I17=""),"",ROUND((2*$I24-$I17)*1000,0)) | AL24: =IF(OR($I24="",$I18=""),"",ROUND((2*$I24-$I18)*1000,0)) | AM24: =IF(OR($I24="",$I19=""),"",ROUND((2*$I24-$I19)*1000,0)) | AN24: =IF(OR($I24="",$I20=""),"",ROUND((2*$I24-$I20)*1000,0)) | AO24: =IF(OR($I24="",$I21=""),"",ROUND((2*$I24-$I21)*1000,0)) | AP24: =IF(OR($I24="",$I22=""),"",ROUND((2*$I24-$I22)*1000,0)) | AQ24: =IF(OR($I24="",$I23=""),"",ROUND((2*$I24-$I23)*1000,0)) | AS24: =IF(OR($I24="",$I25=""),"",ROUND((2*$I24-$I25)*1000,0)) | AT24: =IF(OR($I24="",$I26=""),"",ROUND((2*$I24-$I26)*1000,0)) | AU24: =IF(OR($I24="",$I27=""),"",ROUND((2*$I24-$I27)*1000,0)) | AV24: =IF(OR($I24="",$I28=""),"",ROUND((2*$I24-$I28)*1000,0)) | AW24: =IF(OR($I24="",$I29=""),"",ROUND((2*$I24-$I29)*1000,0)) | AX24: =IF(OR($I24="",$I30=""),"",ROUND((2*$I24-$I30)*1000,0))
B25: 11 | J25: =IF(I25="","",IF(AND(I25>=470,I25<698),INT((I25-470)/6)+14,"–")) | K25: =IF(OR(I25="",COUNT($R25:$AG25)=0),"",MIN($R25:$AG25)) | L25: =IF(K25="","",MATCH(K25,$R25:$AG25,0)) | M25: =IF(I25="","",COUNTIFS($AI$15:$AX$30,">"&ROUND((I25-$L$5)*1000,0),$AI$15:$AX$30,"<"&ROUND((I25+$L$5)*1000,0))-COUNTIFS($AI25:$AX25,">"&ROUND((I25-$L$5)*1000,0),$AI25:$AX25,"<"&ROUND((I25+$L$5)*1000,0))-COUNTIFS(AS$15:AS$30,">"&ROUND((I25-$L$5)*1000,0),AS$15:AS$30,"<"&ROUND((I25+$L$5)*1000,0))) | N25: =IF(I25="",IF(AND(C25<>"",F25="2,4 GHz"),"Automática",""),IF(AND(K25<>"",K25<0.0005),"Repetida",IF(AND(K25<>"",$L$4<>"",K25<$L$4),"Próxima",IF(AND($L$6<>"",$L$7<>"",I25>=$L$6,I25<=$L$7),"Telefonia",IF(AND(I25>=470,I25<698,COUNTIF($E$9:$L$9,INT((I25-470)/6)+14)>0),"TV",IF(M25>0,"Intermod.","OK")))))) | O25: =IF(N25="","",IF(N25="Automática","Sem frequência fixa: o sistema escolhe o canal. Afaste o receptor do roteador Wi-Fi",IF(N25="Repetida","Mesma frequência do sistema nº "&L25&": troque o canal de um dos dois",IF(N25="Próxima","Perto demais do sistema nº "&L25&": afaste as duas frequências",IF(N25="Telefonia","Dentro da faixa a evitar: troque de frequência ou de equipamento",IF(N25="TV","Dentro do canal de TV "&J25&", ativo na cidade: use um canal de TV livre",IF(N25="Intermod.","Há "&M25&" produto(s) de intermodulação perto: troque esta frequência ou use o grupo do fabricante","Manter"))))))) | R25: =IF(OR($I25="",$I15=""),"",ROUND(ABS($I25-$I15),4)) | S25: =IF(OR($I25="",$I16=""),"",ROUND(ABS($I25-$I16),4)) | T25: =IF(OR($I25="",$I17=""),"",ROUND(ABS($I25-$I17),4)) | U25: =IF(OR($I25="",$I18=""),"",ROUND(ABS($I25-$I18),4)) | V25: =IF(OR($I25="",$I19=""),"",ROUND(ABS($I25-$I19),4)) | W25: =IF(OR($I25="",$I20=""),"",ROUND(ABS($I25-$I20),4)) | X25: =IF(OR($I25="",$I21=""),"",ROUND(ABS($I25-$I21),4)) | Y25: =IF(OR($I25="",$I22=""),"",ROUND(ABS($I25-$I22),4)) | Z25: =IF(OR($I25="",$I23=""),"",ROUND(ABS($I25-$I23),4)) | AA25: =IF(OR($I25="",$I24=""),"",ROUND(ABS($I25-$I24),4)) | AC25: =IF(OR($I25="",$I26=""),"",ROUND(ABS($I25-$I26),4)) | AD25: =IF(OR($I25="",$I27=""),"",ROUND(ABS($I25-$I27),4)) | AE25: =IF(OR($I25="",$I28=""),"",ROUND(ABS($I25-$I28),4)) | AF25: =IF(OR($I25="",$I29=""),"",ROUND(ABS($I25-$I29),4)) | AG25: =IF(OR($I25="",$I30=""),"",ROUND(ABS($I25-$I30),4)) | AI25: =IF(OR($I25="",$I15=""),"",ROUND((2*$I25-$I15)*1000,0)) | AJ25: =IF(OR($I25="",$I16=""),"",ROUND((2*$I25-$I16)*1000,0)) | AK25: =IF(OR($I25="",$I17=""),"",ROUND((2*$I25-$I17)*1000,0)) | AL25: =IF(OR($I25="",$I18=""),"",ROUND((2*$I25-$I18)*1000,0)) | AM25: =IF(OR($I25="",$I19=""),"",ROUND((2*$I25-$I19)*1000,0)) | AN25: =IF(OR($I25="",$I20=""),"",ROUND((2*$I25-$I20)*1000,0)) | AO25: =IF(OR($I25="",$I21=""),"",ROUND((2*$I25-$I21)*1000,0)) | AP25: =IF(OR($I25="",$I22=""),"",ROUND((2*$I25-$I22)*1000,0)) | AQ25: =IF(OR($I25="",$I23=""),"",ROUND((2*$I25-$I23)*1000,0)) | AR25: =IF(OR($I25="",$I24=""),"",ROUND((2*$I25-$I24)*1000,0)) | AT25: =IF(OR($I25="",$I26=""),"",ROUND((2*$I25-$I26)*1000,0)) | AU25: =IF(OR($I25="",$I27=""),"",ROUND((2*$I25-$I27)*1000,0)) | AV25: =IF(OR($I25="",$I28=""),"",ROUND((2*$I25-$I28)*1000,0)) | AW25: =IF(OR($I25="",$I29=""),"",ROUND((2*$I25-$I29)*1000,0)) | AX25: =IF(OR($I25="",$I30=""),"",ROUND((2*$I25-$I30)*1000,0))
B26: 12 | J26: =IF(I26="","",IF(AND(I26>=470,I26<698),INT((I26-470)/6)+14,"–")) | K26: =IF(OR(I26="",COUNT($R26:$AG26)=0),"",MIN($R26:$AG26)) | L26: =IF(K26="","",MATCH(K26,$R26:$AG26,0)) | M26: =IF(I26="","",COUNTIFS($AI$15:$AX$30,">"&ROUND((I26-$L$5)*1000,0),$AI$15:$AX$30,"<"&ROUND((I26+$L$5)*1000,0))-COUNTIFS($AI26:$AX26,">"&ROUND((I26-$L$5)*1000,0),$AI26:$AX26,"<"&ROUND((I26+$L$5)*1000,0))-COUNTIFS(AT$15:AT$30,">"&ROUND((I26-$L$5)*1000,0),AT$15:AT$30,"<"&ROUND((I26+$L$5)*1000,0))) | N26: =IF(I26="",IF(AND(C26<>"",F26="2,4 GHz"),"Automática",""),IF(AND(K26<>"",K26<0.0005),"Repetida",IF(AND(K26<>"",$L$4<>"",K26<$L$4),"Próxima",IF(AND($L$6<>"",$L$7<>"",I26>=$L$6,I26<=$L$7),"Telefonia",IF(AND(I26>=470,I26<698,COUNTIF($E$9:$L$9,INT((I26-470)/6)+14)>0),"TV",IF(M26>0,"Intermod.","OK")))))) | O26: =IF(N26="","",IF(N26="Automática","Sem frequência fixa: o sistema escolhe o canal. Afaste o receptor do roteador Wi-Fi",IF(N26="Repetida","Mesma frequência do sistema nº "&L26&": troque o canal de um dos dois",IF(N26="Próxima","Perto demais do sistema nº "&L26&": afaste as duas frequências",IF(N26="Telefonia","Dentro da faixa a evitar: troque de frequência ou de equipamento",IF(N26="TV","Dentro do canal de TV "&J26&", ativo na cidade: use um canal de TV livre",IF(N26="Intermod.","Há "&M26&" produto(s) de intermodulação perto: troque esta frequência ou use o grupo do fabricante","Manter"))))))) | R26: =IF(OR($I26="",$I15=""),"",ROUND(ABS($I26-$I15),4)) | S26: =IF(OR($I26="",$I16=""),"",ROUND(ABS($I26-$I16),4)) | T26: =IF(OR($I26="",$I17=""),"",ROUND(ABS($I26-$I17),4)) | U26: =IF(OR($I26="",$I18=""),"",ROUND(ABS($I26-$I18),4)) | V26: =IF(OR($I26="",$I19=""),"",ROUND(ABS($I26-$I19),4)) | W26: =IF(OR($I26="",$I20=""),"",ROUND(ABS($I26-$I20),4)) | X26: =IF(OR($I26="",$I21=""),"",ROUND(ABS($I26-$I21),4)) | Y26: =IF(OR($I26="",$I22=""),"",ROUND(ABS($I26-$I22),4)) | Z26: =IF(OR($I26="",$I23=""),"",ROUND(ABS($I26-$I23),4)) | AA26: =IF(OR($I26="",$I24=""),"",ROUND(ABS($I26-$I24),4)) | AB26: =IF(OR($I26="",$I25=""),"",ROUND(ABS($I26-$I25),4)) | AD26: =IF(OR($I26="",$I27=""),"",ROUND(ABS($I26-$I27),4)) | AE26: =IF(OR($I26="",$I28=""),"",ROUND(ABS($I26-$I28),4)) | AF26: =IF(OR($I26="",$I29=""),"",ROUND(ABS($I26-$I29),4)) | AG26: =IF(OR($I26="",$I30=""),"",ROUND(ABS($I26-$I30),4)) | AI26: =IF(OR($I26="",$I15=""),"",ROUND((2*$I26-$I15)*1000,0)) | AJ26: =IF(OR($I26="",$I16=""),"",ROUND((2*$I26-$I16)*1000,0)) | AK26: =IF(OR($I26="",$I17=""),"",ROUND((2*$I26-$I17)*1000,0)) | AL26: =IF(OR($I26="",$I18=""),"",ROUND((2*$I26-$I18)*1000,0)) | AM26: =IF(OR($I26="",$I19=""),"",ROUND((2*$I26-$I19)*1000,0)) | AN26: =IF(OR($I26="",$I20=""),"",ROUND((2*$I26-$I20)*1000,0)) | AO26: =IF(OR($I26="",$I21=""),"",ROUND((2*$I26-$I21)*1000,0)) | AP26: =IF(OR($I26="",$I22=""),"",ROUND((2*$I26-$I22)*1000,0)) | AQ26: =IF(OR($I26="",$I23=""),"",ROUND((2*$I26-$I23)*1000,0)) | AR26: =IF(OR($I26="",$I24=""),"",ROUND((2*$I26-$I24)*1000,0)) | AS26: =IF(OR($I26="",$I25=""),"",ROUND((2*$I26-$I25)*1000,0)) | AU26: =IF(OR($I26="",$I27=""),"",ROUND((2*$I26-$I27)*1000,0)) | AV26: =IF(OR($I26="",$I28=""),"",ROUND((2*$I26-$I28)*1000,0)) | AW26: =IF(OR($I26="",$I29=""),"",ROUND((2*$I26-$I29)*1000,0)) | AX26: =IF(OR($I26="",$I30=""),"",ROUND((2*$I26-$I30)*1000,0))
B27: 13 | J27: =IF(I27="","",IF(AND(I27>=470,I27<698),INT((I27-470)/6)+14,"–")) | K27: =IF(OR(I27="",COUNT($R27:$AG27)=0),"",MIN($R27:$AG27)) | L27: =IF(K27="","",MATCH(K27,$R27:$AG27,0)) | M27: =IF(I27="","",COUNTIFS($AI$15:$AX$30,">"&ROUND((I27-$L$5)*1000,0),$AI$15:$AX$30,"<"&ROUND((I27+$L$5)*1000,0))-COUNTIFS($AI27:$AX27,">"&ROUND((I27-$L$5)*1000,0),$AI27:$AX27,"<"&ROUND((I27+$L$5)*1000,0))-COUNTIFS(AU$15:AU$30,">"&ROUND((I27-$L$5)*1000,0),AU$15:AU$30,"<"&ROUND((I27+$L$5)*1000,0))) | N27: =IF(I27="",IF(AND(C27<>"",F27="2,4 GHz"),"Automática",""),IF(AND(K27<>"",K27<0.0005),"Repetida",IF(AND(K27<>"",$L$4<>"",K27<$L$4),"Próxima",IF(AND($L$6<>"",$L$7<>"",I27>=$L$6,I27<=$L$7),"Telefonia",IF(AND(I27>=470,I27<698,COUNTIF($E$9:$L$9,INT((I27-470)/6)+14)>0),"TV",IF(M27>0,"Intermod.","OK")))))) | O27: =IF(N27="","",IF(N27="Automática","Sem frequência fixa: o sistema escolhe o canal. Afaste o receptor do roteador Wi-Fi",IF(N27="Repetida","Mesma frequência do sistema nº "&L27&": troque o canal de um dos dois",IF(N27="Próxima","Perto demais do sistema nº "&L27&": afaste as duas frequências",IF(N27="Telefonia","Dentro da faixa a evitar: troque de frequência ou de equipamento",IF(N27="TV","Dentro do canal de TV "&J27&", ativo na cidade: use um canal de TV livre",IF(N27="Intermod.","Há "&M27&" produto(s) de intermodulação perto: troque esta frequência ou use o grupo do fabricante","Manter"))))))) | R27: =IF(OR($I27="",$I15=""),"",ROUND(ABS($I27-$I15),4)) | S27: =IF(OR($I27="",$I16=""),"",ROUND(ABS($I27-$I16),4)) | T27: =IF(OR($I27="",$I17=""),"",ROUND(ABS($I27-$I17),4)) | U27: =IF(OR($I27="",$I18=""),"",ROUND(ABS($I27-$I18),4)) | V27: =IF(OR($I27="",$I19=""),"",ROUND(ABS($I27-$I19),4)) | W27: =IF(OR($I27="",$I20=""),"",ROUND(ABS($I27-$I20),4)) | X27: =IF(OR($I27="",$I21=""),"",ROUND(ABS($I27-$I21),4)) | Y27: =IF(OR($I27="",$I22=""),"",ROUND(ABS($I27-$I22),4)) | Z27: =IF(OR($I27="",$I23=""),"",ROUND(ABS($I27-$I23),4)) | AA27: =IF(OR($I27="",$I24=""),"",ROUND(ABS($I27-$I24),4)) | AB27: =IF(OR($I27="",$I25=""),"",ROUND(ABS($I27-$I25),4)) | AC27: =IF(OR($I27="",$I26=""),"",ROUND(ABS($I27-$I26),4)) | AE27: =IF(OR($I27="",$I28=""),"",ROUND(ABS($I27-$I28),4)) | AF27: =IF(OR($I27="",$I29=""),"",ROUND(ABS($I27-$I29),4)) | AG27: =IF(OR($I27="",$I30=""),"",ROUND(ABS($I27-$I30),4)) | AI27: =IF(OR($I27="",$I15=""),"",ROUND((2*$I27-$I15)*1000,0)) | AJ27: =IF(OR($I27="",$I16=""),"",ROUND((2*$I27-$I16)*1000,0)) | AK27: =IF(OR($I27="",$I17=""),"",ROUND((2*$I27-$I17)*1000,0)) | AL27: =IF(OR($I27="",$I18=""),"",ROUND((2*$I27-$I18)*1000,0)) | AM27: =IF(OR($I27="",$I19=""),"",ROUND((2*$I27-$I19)*1000,0)) | AN27: =IF(OR($I27="",$I20=""),"",ROUND((2*$I27-$I20)*1000,0)) | AO27: =IF(OR($I27="",$I21=""),"",ROUND((2*$I27-$I21)*1000,0)) | AP27: =IF(OR($I27="",$I22=""),"",ROUND((2*$I27-$I22)*1000,0)) | AQ27: =IF(OR($I27="",$I23=""),"",ROUND((2*$I27-$I23)*1000,0)) | AR27: =IF(OR($I27="",$I24=""),"",ROUND((2*$I27-$I24)*1000,0)) | AS27: =IF(OR($I27="",$I25=""),"",ROUND((2*$I27-$I25)*1000,0)) | AT27: =IF(OR($I27="",$I26=""),"",ROUND((2*$I27-$I26)*1000,0)) | AV27: =IF(OR($I27="",$I28=""),"",ROUND((2*$I27-$I28)*1000,0)) | AW27: =IF(OR($I27="",$I29=""),"",ROUND((2*$I27-$I29)*1000,0)) | AX27: =IF(OR($I27="",$I30=""),"",ROUND((2*$I27-$I30)*1000,0))
B28: 14 | J28: =IF(I28="","",IF(AND(I28>=470,I28<698),INT((I28-470)/6)+14,"–")) | K28: =IF(OR(I28="",COUNT($R28:$AG28)=0),"",MIN($R28:$AG28)) | L28: =IF(K28="","",MATCH(K28,$R28:$AG28,0)) | M28: =IF(I28="","",COUNTIFS($AI$15:$AX$30,">"&ROUND((I28-$L$5)*1000,0),$AI$15:$AX$30,"<"&ROUND((I28+$L$5)*1000,0))-COUNTIFS($AI28:$AX28,">"&ROUND((I28-$L$5)*1000,0),$AI28:$AX28,"<"&ROUND((I28+$L$5)*1000,0))-COUNTIFS(AV$15:AV$30,">"&ROUND((I28-$L$5)*1000,0),AV$15:AV$30,"<"&ROUND((I28+$L$5)*1000,0))) | N28: =IF(I28="",IF(AND(C28<>"",F28="2,4 GHz"),"Automática",""),IF(AND(K28<>"",K28<0.0005),"Repetida",IF(AND(K28<>"",$L$4<>"",K28<$L$4),"Próxima",IF(AND($L$6<>"",$L$7<>"",I28>=$L$6,I28<=$L$7),"Telefonia",IF(AND(I28>=470,I28<698,COUNTIF($E$9:$L$9,INT((I28-470)/6)+14)>0),"TV",IF(M28>0,"Intermod.","OK")))))) | O28: =IF(N28="","",IF(N28="Automática","Sem frequência fixa: o sistema escolhe o canal. Afaste o receptor do roteador Wi-Fi",IF(N28="Repetida","Mesma frequência do sistema nº "&L28&": troque o canal de um dos dois",IF(N28="Próxima","Perto demais do sistema nº "&L28&": afaste as duas frequências",IF(N28="Telefonia","Dentro da faixa a evitar: troque de frequência ou de equipamento",IF(N28="TV","Dentro do canal de TV "&J28&", ativo na cidade: use um canal de TV livre",IF(N28="Intermod.","Há "&M28&" produto(s) de intermodulação perto: troque esta frequência ou use o grupo do fabricante","Manter"))))))) | R28: =IF(OR($I28="",$I15=""),"",ROUND(ABS($I28-$I15),4)) | S28: =IF(OR($I28="",$I16=""),"",ROUND(ABS($I28-$I16),4)) | T28: =IF(OR($I28="",$I17=""),"",ROUND(ABS($I28-$I17),4)) | U28: =IF(OR($I28="",$I18=""),"",ROUND(ABS($I28-$I18),4)) | V28: =IF(OR($I28="",$I19=""),"",ROUND(ABS($I28-$I19),4)) | W28: =IF(OR($I28="",$I20=""),"",ROUND(ABS($I28-$I20),4)) | X28: =IF(OR($I28="",$I21=""),"",ROUND(ABS($I28-$I21),4)) | Y28: =IF(OR($I28="",$I22=""),"",ROUND(ABS($I28-$I22),4)) | Z28: =IF(OR($I28="",$I23=""),"",ROUND(ABS($I28-$I23),4)) | AA28: =IF(OR($I28="",$I24=""),"",ROUND(ABS($I28-$I24),4)) | AB28: =IF(OR($I28="",$I25=""),"",ROUND(ABS($I28-$I25),4)) | AC28: =IF(OR($I28="",$I26=""),"",ROUND(ABS($I28-$I26),4)) | AD28: =IF(OR($I28="",$I27=""),"",ROUND(ABS($I28-$I27),4)) | AF28: =IF(OR($I28="",$I29=""),"",ROUND(ABS($I28-$I29),4)) | AG28: =IF(OR($I28="",$I30=""),"",ROUND(ABS($I28-$I30),4)) | AI28: =IF(OR($I28="",$I15=""),"",ROUND((2*$I28-$I15)*1000,0)) | AJ28: =IF(OR($I28="",$I16=""),"",ROUND((2*$I28-$I16)*1000,0)) | AK28: =IF(OR($I28="",$I17=""),"",ROUND((2*$I28-$I17)*1000,0)) | AL28: =IF(OR($I28="",$I18=""),"",ROUND((2*$I28-$I18)*1000,0)) | AM28: =IF(OR($I28="",$I19=""),"",ROUND((2*$I28-$I19)*1000,0)) | AN28: =IF(OR($I28="",$I20=""),"",ROUND((2*$I28-$I20)*1000,0)) | AO28: =IF(OR($I28="",$I21=""),"",ROUND((2*$I28-$I21)*1000,0)) | AP28: =IF(OR($I28="",$I22=""),"",ROUND((2*$I28-$I22)*1000,0)) | AQ28: =IF(OR($I28="",$I23=""),"",ROUND((2*$I28-$I23)*1000,0)) | AR28: =IF(OR($I28="",$I24=""),"",ROUND((2*$I28-$I24)*1000,0)) | AS28: =IF(OR($I28="",$I25=""),"",ROUND((2*$I28-$I25)*1000,0)) | AT28: =IF(OR($I28="",$I26=""),"",ROUND((2*$I28-$I26)*1000,0)) | AU28: =IF(OR($I28="",$I27=""),"",ROUND((2*$I28-$I27)*1000,0)) | AW28: =IF(OR($I28="",$I29=""),"",ROUND((2*$I28-$I29)*1000,0)) | AX28: =IF(OR($I28="",$I30=""),"",ROUND((2*$I28-$I30)*1000,0))
B29: 15 | J29: =IF(I29="","",IF(AND(I29>=470,I29<698),INT((I29-470)/6)+14,"–")) | K29: =IF(OR(I29="",COUNT($R29:$AG29)=0),"",MIN($R29:$AG29)) | L29: =IF(K29="","",MATCH(K29,$R29:$AG29,0)) | M29: =IF(I29="","",COUNTIFS($AI$15:$AX$30,">"&ROUND((I29-$L$5)*1000,0),$AI$15:$AX$30,"<"&ROUND((I29+$L$5)*1000,0))-COUNTIFS($AI29:$AX29,">"&ROUND((I29-$L$5)*1000,0),$AI29:$AX29,"<"&ROUND((I29+$L$5)*1000,0))-COUNTIFS(AW$15:AW$30,">"&ROUND((I29-$L$5)*1000,0),AW$15:AW$30,"<"&ROUND((I29+$L$5)*1000,0))) | N29: =IF(I29="",IF(AND(C29<>"",F29="2,4 GHz"),"Automática",""),IF(AND(K29<>"",K29<0.0005),"Repetida",IF(AND(K29<>"",$L$4<>"",K29<$L$4),"Próxima",IF(AND($L$6<>"",$L$7<>"",I29>=$L$6,I29<=$L$7),"Telefonia",IF(AND(I29>=470,I29<698,COUNTIF($E$9:$L$9,INT((I29-470)/6)+14)>0),"TV",IF(M29>0,"Intermod.","OK")))))) | O29: =IF(N29="","",IF(N29="Automática","Sem frequência fixa: o sistema escolhe o canal. Afaste o receptor do roteador Wi-Fi",IF(N29="Repetida","Mesma frequência do sistema nº "&L29&": troque o canal de um dos dois",IF(N29="Próxima","Perto demais do sistema nº "&L29&": afaste as duas frequências",IF(N29="Telefonia","Dentro da faixa a evitar: troque de frequência ou de equipamento",IF(N29="TV","Dentro do canal de TV "&J29&", ativo na cidade: use um canal de TV livre",IF(N29="Intermod.","Há "&M29&" produto(s) de intermodulação perto: troque esta frequência ou use o grupo do fabricante","Manter"))))))) | R29: =IF(OR($I29="",$I15=""),"",ROUND(ABS($I29-$I15),4)) | S29: =IF(OR($I29="",$I16=""),"",ROUND(ABS($I29-$I16),4)) | T29: =IF(OR($I29="",$I17=""),"",ROUND(ABS($I29-$I17),4)) | U29: =IF(OR($I29="",$I18=""),"",ROUND(ABS($I29-$I18),4)) | V29: =IF(OR($I29="",$I19=""),"",ROUND(ABS($I29-$I19),4)) | W29: =IF(OR($I29="",$I20=""),"",ROUND(ABS($I29-$I20),4)) | X29: =IF(OR($I29="",$I21=""),"",ROUND(ABS($I29-$I21),4)) | Y29: =IF(OR($I29="",$I22=""),"",ROUND(ABS($I29-$I22),4)) | Z29: =IF(OR($I29="",$I23=""),"",ROUND(ABS($I29-$I23),4)) | AA29: =IF(OR($I29="",$I24=""),"",ROUND(ABS($I29-$I24),4)) | AB29: =IF(OR($I29="",$I25=""),"",ROUND(ABS($I29-$I25),4)) | AC29: =IF(OR($I29="",$I26=""),"",ROUND(ABS($I29-$I26),4)) | AD29: =IF(OR($I29="",$I27=""),"",ROUND(ABS($I29-$I27),4)) | AE29: =IF(OR($I29="",$I28=""),"",ROUND(ABS($I29-$I28),4)) | AG29: =IF(OR($I29="",$I30=""),"",ROUND(ABS($I29-$I30),4)) | AI29: =IF(OR($I29="",$I15=""),"",ROUND((2*$I29-$I15)*1000,0)) | AJ29: =IF(OR($I29="",$I16=""),"",ROUND((2*$I29-$I16)*1000,0)) | AK29: =IF(OR($I29="",$I17=""),"",ROUND((2*$I29-$I17)*1000,0)) | AL29: =IF(OR($I29="",$I18=""),"",ROUND((2*$I29-$I18)*1000,0)) | AM29: =IF(OR($I29="",$I19=""),"",ROUND((2*$I29-$I19)*1000,0)) | AN29: =IF(OR($I29="",$I20=""),"",ROUND((2*$I29-$I20)*1000,0)) | AO29: =IF(OR($I29="",$I21=""),"",ROUND((2*$I29-$I21)*1000,0)) | AP29: =IF(OR($I29="",$I22=""),"",ROUND((2*$I29-$I22)*1000,0)) | AQ29: =IF(OR($I29="",$I23=""),"",ROUND((2*$I29-$I23)*1000,0)) | AR29: =IF(OR($I29="",$I24=""),"",ROUND((2*$I29-$I24)*1000,0)) | AS29: =IF(OR($I29="",$I25=""),"",ROUND((2*$I29-$I25)*1000,0)) | AT29: =IF(OR($I29="",$I26=""),"",ROUND((2*$I29-$I26)*1000,0)) | AU29: =IF(OR($I29="",$I27=""),"",ROUND((2*$I29-$I27)*1000,0)) | AV29: =IF(OR($I29="",$I28=""),"",ROUND((2*$I29-$I28)*1000,0)) | AX29: =IF(OR($I29="",$I30=""),"",ROUND((2*$I29-$I30)*1000,0))
B30: 16 | J30: =IF(I30="","",IF(AND(I30>=470,I30<698),INT((I30-470)/6)+14,"–")) | K30: =IF(OR(I30="",COUNT($R30:$AG30)=0),"",MIN($R30:$AG30)) | L30: =IF(K30="","",MATCH(K30,$R30:$AG30,0)) | M30: =IF(I30="","",COUNTIFS($AI$15:$AX$30,">"&ROUND((I30-$L$5)*1000,0),$AI$15:$AX$30,"<"&ROUND((I30+$L$5)*1000,0))-COUNTIFS($AI30:$AX30,">"&ROUND((I30-$L$5)*1000,0),$AI30:$AX30,"<"&ROUND((I30+$L$5)*1000,0))-COUNTIFS(AX$15:AX$30,">"&ROUND((I30-$L$5)*1000,0),AX$15:AX$30,"<"&ROUND((I30+$L$5)*1000,0))) | N30: =IF(I30="",IF(AND(C30<>"",F30="2,4 GHz"),"Automática",""),IF(AND(K30<>"",K30<0.0005),"Repetida",IF(AND(K30<>"",$L$4<>"",K30<$L$4),"Próxima",IF(AND($L$6<>"",$L$7<>"",I30>=$L$6,I30<=$L$7),"Telefonia",IF(AND(I30>=470,I30<698,COUNTIF($E$9:$L$9,INT((I30-470)/6)+14)>0),"TV",IF(M30>0,"Intermod.","OK")))))) | O30: =IF(N30="","",IF(N30="Automática","Sem frequência fixa: o sistema escolhe o canal. Afaste o receptor do roteador Wi-Fi",IF(N30="Repetida","Mesma frequência do sistema nº "&L30&": troque o canal de um dos dois",IF(N30="Próxima","Perto demais do sistema nº "&L30&": afaste as duas frequências",IF(N30="Telefonia","Dentro da faixa a evitar: troque de frequência ou de equipamento",IF(N30="TV","Dentro do canal de TV "&J30&", ativo na cidade: use um canal de TV livre",IF(N30="Intermod.","Há "&M30&" produto(s) de intermodulação perto: troque esta frequência ou use o grupo do fabricante","Manter"))))))) | R30: =IF(OR($I30="",$I15=""),"",ROUND(ABS($I30-$I15),4)) | S30: =IF(OR($I30="",$I16=""),"",ROUND(ABS($I30-$I16),4)) | T30: =IF(OR($I30="",$I17=""),"",ROUND(ABS($I30-$I17),4)) | U30: =IF(OR($I30="",$I18=""),"",ROUND(ABS($I30-$I18),4)) | V30: =IF(OR($I30="",$I19=""),"",ROUND(ABS($I30-$I19),4)) | W30: =IF(OR($I30="",$I20=""),"",ROUND(ABS($I30-$I20),4)) | X30: =IF(OR($I30="",$I21=""),"",ROUND(ABS($I30-$I21),4)) | Y30: =IF(OR($I30="",$I22=""),"",ROUND(ABS($I30-$I22),4)) | Z30: =IF(OR($I30="",$I23=""),"",ROUND(ABS($I30-$I23),4)) | AA30: =IF(OR($I30="",$I24=""),"",ROUND(ABS($I30-$I24),4)) | AB30: =IF(OR($I30="",$I25=""),"",ROUND(ABS($I30-$I25),4)) | AC30: =IF(OR($I30="",$I26=""),"",ROUND(ABS($I30-$I26),4)) | AD30: =IF(OR($I30="",$I27=""),"",ROUND(ABS($I30-$I27),4)) | AE30: =IF(OR($I30="",$I28=""),"",ROUND(ABS($I30-$I28),4)) | AF30: =IF(OR($I30="",$I29=""),"",ROUND(ABS($I30-$I29),4)) | AI30: =IF(OR($I30="",$I15=""),"",ROUND((2*$I30-$I15)*1000,0)) | AJ30: =IF(OR($I30="",$I16=""),"",ROUND((2*$I30-$I16)*1000,0)) | AK30: =IF(OR($I30="",$I17=""),"",ROUND((2*$I30-$I17)*1000,0)) | AL30: =IF(OR($I30="",$I18=""),"",ROUND((2*$I30-$I18)*1000,0)) | AM30: =IF(OR($I30="",$I19=""),"",ROUND((2*$I30-$I19)*1000,0)) | AN30: =IF(OR($I30="",$I20=""),"",ROUND((2*$I30-$I20)*1000,0)) | AO30: =IF(OR($I30="",$I21=""),"",ROUND((2*$I30-$I21)*1000,0)) | AP30: =IF(OR($I30="",$I22=""),"",ROUND((2*$I30-$I22)*1000,0)) | AQ30: =IF(OR($I30="",$I23=""),"",ROUND((2*$I30-$I23)*1000,0)) | AR30: =IF(OR($I30="",$I24=""),"",ROUND((2*$I30-$I24)*1000,0)) | AS30: =IF(OR($I30="",$I25=""),"",ROUND((2*$I30-$I25)*1000,0)) | AT30: =IF(OR($I30="",$I26=""),"",ROUND((2*$I30-$I26)*1000,0)) | AU30: =IF(OR($I30="",$I27=""),"",ROUND((2*$I30-$I27)*1000,0)) | AV30: =IF(OR($I30="",$I28=""),"",ROUND((2*$I30-$I28)*1000,0)) | AW30: =IF(OR($I30="",$I29=""),"",ROUND((2*$I30-$I29)*1000,0))
B32: Resumo automático
B33: Sistemas listados | I33: =COUNTA(C15:C30) -> 0
B34: Com frequência informada | I34: =COUNT(I15:I30) -> 0
B35: Sem alerta (OK) | I35: =COUNTIF(N15:N30,"OK") -> 0
B36: Repetidas ou próximas demais | I36: =COUNTIF(N15:N30,"Repetida")+COUNTIF(N15:N30,"Próxima") -> 0
B37: Em canal de TV ativo ou na faixa a evitar | I37: =COUNTIF(N15:N30,"TV")+COUNTIF(N15:N30,"Telefonia") -> 0
B38: Com risco de intermodulação | I38: =COUNTIF(N15:N30,"Intermod.") -> 0
B39: Em 2,4 GHz, com frequência automática | I39: =COUNTIF(N15:N30,"Automática") -> 0
B40: Aviso | I40: =IF(I33+I34=0,"Liste os sistemas e as frequências",IF(I36>0,"Há frequências repetidas ou próximas demais: corrija antes de ligar os transmissores",IF(I37>0,"Há frequência em canal de TV ativo ou na faixa a evitar: troque",IF(I38>0,"Há risco de intermodulação: troque as frequências marcadas ou use o grupo do fabricante","OK")))) -> Liste os sistemas e as frequências
B41: A conferência cobre só os produtos de terceira ordem de dois transmissores (2 × A − B). Ela não substitui os grupos do fabricante, o programa de coordenação nem o teste com todos os transmissores ligados.

Sheet Teste de RF
B1: Teste de RF — sistema por sistema
B2: Os sistemas vêm da aba Plano de frequências. Responda Sim ou Não a cada teste, com o sistema montado no local.
B4: Evento | F4: Teste 1: todos os transmissores desligados, receptores ligados, telão e luz ligados.
B5: Data | F5: Teste 2: todos os transmissores ligados e afastados uns dos outros; desligue um de cada vez e olhe o receptor dele.
B6: Quem testou | F6: Testes 3 a 5: uma pessoa anda por toda a área de uso falando forte; outra olha o receptor e ouve no fone.
B8: Registro dos testes
B9: # | C9: Sistema | D9: Usuário | E9: Frequência | F9: 1. Transmissores desligados: mostra RF? | G9: 2. Só este desligado, os outros ligados: mostra RF? | H9: 3. Caminhada: houve falha? | I9: 4. Antenas A e B recebem? | J9: 5. Pico de áudio acende? | K9: Situação | L9: O que fazer | M9: Observação
