Workbook

Sheet Instruções
B1: Microfonia — como usar esta planilha
B2: Registro do ring-out, diagnóstico dos apitos e estimativa da margem, para usar na montagem e depois do evento.
B4: Legenda: onde preencher
B5: Amarelo-claro | C5: Células de entrada. É aqui que você digita.
B6: Cinza | C6: Células calculadas ou fixas (rótulos, contas, avisos). Não altere.
B7: Cinza em itálico | C7: Linha de exemplo (marcada com “Ex.”) e dicas de preenchimento. Não entram nas contas.
B8: Listas suspensas | C8: Tipo de saída, equalizador, saída do corte, som do apito, causa e Sim / Não aceitam só as opções da lista.
B9: Números | C9: Digite só o número, com o sinal de menos quando houver: -6, e não “-6 dB”. Frequência em Hz: 2500, e não 2,5k.
B10: Comentários | C10: Células com triângulo vermelho no canto trazem uma dica. Passe o mouse sobre elas.
B12: Ordem de preenchimento
B13: 1 | C13: Antes do ring-out: posição das caixas, microfones perto da fonte e ganho pelo medidor (módulo 4 do treinamento).
B14: 2 | C14: Aba Ring-out: preencha o cabeçalho, confira os quatro parâmetros e liste as saídas, com nomes únicos.
B15: 3 | C15: Para cada saída: anote o nível do primeiro apito antes dos cortes. Registre cada corte na tabela de baixo.
B16: 4 | C16: Anote o apito depois dos cortes e o nível de operação. Veja a margem, a situação e o que fazer.
B17: 5 | C17: Aba Margem: com a margem do ring-out, estime a margem em cada momento do evento pelos microfones abertos.
B18: 6 | C18: Aba Checklist: confira os doze itens antes da passagem de som.
B19: 7 | C19: Depois do evento, aba Ocorrências: anote cada apito, a causa e o que foi feito. Aplique a medida definitiva.
B21: Abas da planilha
B22: Ring-out | C22: Até 8 saídas e 30 cortes, com ganho obtido, margem, situação de cada saída e de cada corte.
B23: Ocorrências | C23: Até 20 apitos, com a medida definitiva sugerida para cada causa e a contagem por causa.
B24: Margem | C24: Margem estimada por microfones abertos em cada momento do evento, e calculadora de distância.
B25: Referência | C25: Faixas do apito, Q e largura, microfones abertos, medidas, posição do retorno e causas.
B26: Checklist | C26: Os doze itens do treinamento, com percentual atendido.
B27: Exemplo - Ring-out | C27: O ring-out de um culto com três saídas e nove cortes (exemplo 1 do treinamento).
B29: Regras e premissas do modelo
B30: Níveis | C30: Os níveis da aba Ring-out são a posição do master de cada saída, em dB. Use sempre o mesmo controle para medir e para operar.
B31: Margem | C31: Apito depois dos cortes menos o nível de operação. Sem margem: abaixo de 3 dB. Margem curta: abaixo da margem mínima (6 dB).
B32: Cortes | C32: Corte fundo: além do corte mais fundo aceito (−9 dB). Corte largo: Q abaixo do mínimo (4). Realce: valor positivo.
B33: Largura | C33: Largura em oitavas calculada pelo Q do paramétrico. No gráfico de 31 bandas, cerca de 1/3 de oitava.
B34: Microfones abertos | C34: Cada vez que o número dobra, a margem cai cerca de 3 dB (10 × log da razão). É uma estimativa, e não uma medida.
B35: Distância | C35: Metade da distância: +6 dB (20 × log da razão). Na caixa, o valor cheio só aparece ao ar livre.
B36: Exemplos | C36: Os dados do exemplo são ilustrativos, criados para este material. As regras são práticas, e não norma.

Sheet Ring-out
B1: Ring-out — registro por saída e por corte
B2: Preencha as células em amarelo-claro durante o ring-out. As células cinza são calculadas.
B4: Evento ou sistema | I4: Margem mínima (dB) | L4: 6 | M4: Regra prática: pelo menos 6 dB entre a operação e o primeiro apito.
B5: Local | I5: Corte mais fundo aceito (dB) | L5: -9 | M5: Corte além disso indica problema de posição, e não de equalização.
B6: Data | I6: Q mínimo do corte | L6: 4 | M6: Q perto de 4 = 1/3 de oitava. Corte de microfonia: Q de 5 a 10.
B7: Operador | I7: Máximo de cortes por saída | L7: 5 | M7: Mais cortes que isso deixam o som oco.
B8: Mesa e equalizador | I8: Níveis em dB, na posição do master de cada saída. O ponto de apito é onde a primeira nota começa a soar.
B10: Saídas: nível do primeiro apito e nível de operação
B11: # | C11: Saída | D11: Tipo | E11: Microfones abertos | F11: Apito antes dos cortes | G11: Apito depois dos cortes | H11: Nível de operação | I11: Cortes | J11: Ganho obtido | K11: Margem | L11: Situação | M11: O que fazer | N11: Observação
C12: nome único | E12: no ring-out | F12: dB | G12: dB | H12: dB | I12: na tabela abaixo | J12: depois − antes | K12: apito − operação
B13: Ex. | C13: Retorno da cantora | D13: Retorno | E13: 1 | F13: -8 | G13: -2 | H13: -9 | I13: 3 | J13: 6 | K13: 7 | L13: OK | M13: Manter
B14: 1 | I14: =IF(C14="","",COUNTIF($C$27:$C$56,C14)) | J14: =IF(OR(F14="",G14=""),"",G14-F14) | K14: =IF(OR(G14="",H14=""),"",G14-H14) | L14: =IF(AND(C14="",F14="",G14="",H14=""),"",IF(OR(G14="",H14=""),"Incompleto",IF(AND(J14<>"",J14<0),"Confira os níveis",IF(K14<3,"Sem margem",IF(K14<$L$4,"Margem curta",IF(I14>$L$7,"Cortes demais",IF(COUNTIFS($C$27:$C$56,C14,$L$27:$L$56,"Corte fundo")+COUNTIFS($C$27:$C$56,C14,$L$27:$L$56,"Corte largo")+COUNTIFS($C$27:$C$56,C14,$L$27:$L$56,"Realce")>0,"Rever cortes","OK"))))))) | M14: =IF(L14="","",IF(L14="Incompleto","Anote o apito depois dos cortes e o nível de operação",IF(L14="Confira os níveis","O apito depois dos cortes ficou abaixo do de antes: meça de novo",IF(OR(L14="Sem margem",L14="Margem curta"),"Baixe a saída "&($L$4-K14)&" dB, ou reveja a posição e a distância",IF(L14="Cortes demais","Cortes demais: reveja a posição das caixas e dos microfones",IF(L14="Rever cortes","Há corte fundo, largo ou realce nesta saída: veja a tabela de cortes","Manter"))))))
B15: 2 | I15: =IF(C15="","",COUNTIF($C$27:$C$56,C15)) | J15: =IF(OR(F15="",G15=""),"",G15-F15) | K15: =IF(OR(G15="",H15=""),"",G15-H15) | L15: =IF(AND(C15="",F15="",G15="",H15=""),"",IF(OR(G15="",H15=""),"Incompleto",IF(AND(J15<>"",J15<0),"Confira os níveis",IF(K15<3,"Sem margem",IF(K15<$L$4,"Margem curta",IF(I15>$L$7,"Cortes demais",IF(COUNTIFS($C$27:$C$56,C15,$L$27:$L$56,"Corte fundo")+COUNTIFS($C$27:$C$56,C15,$L$27:$L$56,"Corte largo")+COUNTIFS($C$27:$C$56,C15,$L$27:$L$56,"Realce")>0,"Rever cortes","OK"))))))) | M15: =IF(L15="","",IF(L15="Incompleto","Anote o apito depois dos cortes e o nível de operação",IF(L15="Confira os níveis","O apito depois dos cortes ficou abaixo do de antes: meça de novo",IF(OR(L15="Sem margem",L15="Margem curta"),"Baixe a saída "&($L$4-K15)&" dB, ou reveja a posição e a distância",IF(L15="Cortes demais","Cortes demais: reveja a posição das caixas e dos microfones",IF(L15="Rever cortes","Há corte fundo, largo ou realce nesta saída: veja a tabela de cortes","Manter"))))))
B16: 3 | I16: =IF(C16="","",COUNTIF($C$27:$C$56,C16)) | J16: =IF(OR(F16="",G16=""),"",G16-F16) | K16: =IF(OR(G16="",H16=""),"",G16-H16) | L16: =IF(AND(C16="",F16="",G16="",H16=""),"",IF(OR(G16="",H16=""),"Incompleto",IF(AND(J16<>"",J16<0),"Confira os níveis",IF(K16<3,"Sem margem",IF(K16<$L$4,"Margem curta",IF(I16>$L$7,"Cortes demais",IF(COUNTIFS($C$27:$C$56,C16,$L$27:$L$56,"Corte fundo")+COUNTIFS($C$27:$C$56,C16,$L$27:$L$56,"Corte largo")+COUNTIFS($C$27:$C$56,C16,$L$27:$L$56,"Realce")>0,"Rever cortes","OK"))))))) | M16: =IF(L16="","",IF(L16="Incompleto","Anote o apito depois dos cortes e o nível de operação",IF(L16="Confira os níveis","O apito depois dos cortes ficou abaixo do de antes: meça de novo",IF(OR(L16="Sem margem",L16="Margem curta"),"Baixe a saída "&($L$4-K16)&" dB, ou reveja a posição e a distância",IF(L16="Cortes demais","Cortes demais: reveja a posição das caixas e dos microfones",IF(L16="Rever cortes","Há corte fundo, largo ou realce nesta saída: veja a tabela de cortes","Manter"))))))
B17: 4 | I17: =IF(C17="","",COUNTIF($C$27:$C$56,C17)) | J17: =IF(OR(F17="",G17=""),"",G17-F17) | K17: =IF(OR(G17="",H17=""),"",G17-H17) | L17: =IF(AND(C17="",F17="",G17="",H17=""),"",IF(OR(G17="",H17=""),"Incompleto",IF(AND(J17<>"",J17<0),"Confira os níveis",IF(K17<3,"Sem margem",IF(K17<$L$4,"Margem curta",IF(I17>$L$7,"Cortes demais",IF(COUNTIFS($C$27:$C$56,C17,$L$27:$L$56,"Corte fundo")+COUNTIFS($C$27:$C$56,C17,$L$27:$L$56,"Corte largo")+COUNTIFS($C$27:$C$56,C17,$L$27:$L$56,"Realce")>0,"Rever cortes","OK"))))))) | M17: =IF(L17="","",IF(L17="Incompleto","Anote o apito depois dos cortes e o nível de operação",IF(L17="Confira os níveis","O apito depois dos cortes ficou abaixo do de antes: meça de novo",IF(OR(L17="Sem margem",L17="Margem curta"),"Baixe a saída "&($L$4-K17)&" dB, ou reveja a posição e a distância",IF(L17="Cortes demais","Cortes demais: reveja a posição das caixas e dos microfones",IF(L17="Rever cortes","Há corte fundo, largo ou realce nesta saída: veja a tabela de cortes","Manter"))))))
B18: 5 | I18: =IF(C18="","",COUNTIF($C$27:$C$56,C18)) | J18: =IF(OR(F18="",G18=""),"",G18-F18) | K18: =IF(OR(G18="",H18=""),"",G18-H18) | L18: =IF(AND(C18="",F18="",G18="",H18=""),"",IF(OR(G18="",H18=""),"Incompleto",IF(AND(J18<>"",J18<0),"Confira os níveis",IF(K18<3,"Sem margem",IF(K18<$L$4,"Margem curta",IF(I18>$L$7,"Cortes demais",IF(COUNTIFS($C$27:$C$56,C18,$L$27:$L$56,"Corte fundo")+COUNTIFS($C$27:$C$56,C18,$L$27:$L$56,"Corte largo")+COUNTIFS($C$27:$C$56,C18,$L$27:$L$56,"Realce")>0,"Rever cortes","OK"))))))) | M18: =IF(L18="","",IF(L18="Incompleto","Anote o apito depois dos cortes e o nível de operação",IF(L18="Confira os níveis","O apito depois dos cortes ficou abaixo do de antes: meça de novo",IF(OR(L18="Sem margem",L18="Margem curta"),"Baixe a saída "&($L$4-K18)&" dB, ou reveja a posição e a distância",IF(L18="Cortes demais","Cortes demais: reveja a posição das caixas e dos microfones",IF(L18="Rever cortes","Há corte fundo, largo ou realce nesta saída: veja a tabela de cortes","Manter"))))))
B19: 6 | I19: =IF(C19="","",COUNTIF($C$27:$C$56,C19)) | J19: =IF(OR(F19="",G19=""),"",G19-F19) | K19: =IF(OR(G19="",H19=""),"",G19-H19) | L19: =IF(AND(C19="",F19="",G19="",H19=""),"",IF(OR(G19="",H19=""),"Incompleto",IF(AND(J19<>"",J19<0),"Confira os níveis",IF(K19<3,"Sem margem",IF(K19<$L$4,"Margem curta",IF(I19>$L$7,"Cortes demais",IF(COUNTIFS($C$27:$C$56,C19,$L$27:$L$56,"Corte fundo")+COUNTIFS($C$27:$C$56,C19,$L$27:$L$56,"Corte largo")+COUNTIFS($C$27:$C$56,C19,$L$27:$L$56,"Realce")>0,"Rever cortes","OK"))))))) | M19: =IF(L19="","",IF(L19="Incompleto","Anote o apito depois dos cortes e o nível de operação",IF(L19="Confira os níveis","O apito depois dos cortes ficou abaixo do de antes: meça de novo",IF(OR(L19="Sem margem",L19="Margem curta"),"Baixe a saída "&($L$4-K19)&" dB, ou reveja a posição e a distância",IF(L19="Cortes demais","Cortes demais: reveja a posição das caixas e dos microfones",IF(L19="Rever cortes","Há corte fundo, largo ou realce nesta saída: veja a tabela de cortes","Manter"))))))
B20: 7 | I20: =IF(C20="","",COUNTIF($C$27:$C$56,C20)) | J20: =IF(OR(F20="",G20=""),"",G20-F20) | K20: =IF(OR(G20="",H20=""),"",G20-H20) | L20: =IF(AND(C20="",F20="",G20="",H20=""),"",IF(OR(G20="",H20=""),"Incompleto",IF(AND(J20<>"",J20<0),"Confira os níveis",IF(K20<3,"Sem margem",IF(K20<$L$4,"Margem curta",IF(I20>$L$7,"Cortes demais",IF(COUNTIFS($C$27:$C$56,C20,$L$27:$L$56,"Corte fundo")+COUNTIFS($C$27:$C$56,C20,$L$27:$L$56,"Corte largo")+COUNTIFS($C$27:$C$56,C20,$L$27:$L$56,"Realce")>0,"Rever cortes","OK"))))))) | M20: =IF(L20="","",IF(L20="Incompleto","Anote o apito depois dos cortes e o nível de operação",IF(L20="Confira os níveis","O apito depois dos cortes ficou abaixo do de antes: meça de novo",IF(OR(L20="Sem margem",L20="Margem curta"),"Baixe a saída "&($L$4-K20)&" dB, ou reveja a posição e a distância",IF(L20="Cortes demais","Cortes demais: reveja a posição das caixas e dos microfones",IF(L20="Rever cortes","Há corte fundo, largo ou realce nesta saída: veja a tabela de cortes","Manter"))))))
B21: 8 | I21: =IF(C21="","",COUNTIF($C$27:$C$56,C21)) | J21: =IF(OR(F21="",G21=""),"",G21-F21) | K21: =IF(OR(G21="",H21=""),"",G21-H21) | L21: =IF(AND(C21="",F21="",G21="",H21=""),"",IF(OR(G21="",H21=""),"Incompleto",IF(AND(J21<>"",J21<0),"Confira os níveis",IF(K21<3,"Sem margem",IF(K21<$L$4,"Margem curta",IF(I21>$L$7,"Cortes demais",IF(COUNTIFS($C$27:$C$56,C21,$L$27:$L$56,"Corte fundo")+COUNTIFS($C$27:$C$56,C21,$L$27:$L$56,"Corte largo")+COUNTIFS($C$27:$C$56,C21,$L$27:$L$56,"Realce")>0,"Rever cortes","OK"))))))) | M21: =IF(L21="","",IF(L21="Incompleto","Anote o apito depois dos cortes e o nível de operação",IF(L21="Confira os níveis","O apito depois dos cortes ficou abaixo do de antes: meça de novo",IF(OR(L21="Sem margem",L21="Margem curta"),"Baixe a saída "&($L$4-K21)&" dB, ou reveja a posição e a distância",IF(L21="Cortes demais","Cortes demais: reveja a posição das caixas e dos microfones",IF(L21="Rever cortes","Há corte fundo, largo ou realce nesta saída: veja a tabela de cortes","Manter"))))))
B23: Cortes de equalizador, na ordem em que foram feitos
B24: # | C24: Saída | D24: Ordem na saída | E24: Frequência | F24: Corte | G24: Q | H24: Equalizador | I24: Faixa | J24: Largura | K24: Largura | L24: Situação | M24: O que fazer | N24: Observação
C25: da lista | E25: Hz | F25: dB, negativo | G25: no paramétrico | I25: pelo som | J25: oitava | K25: Hz, aprox.
B26: Ex. | C26: Retorno da cantora | D26: 1 | E26: 2500 | F26: -6 | G26: 8 | H26: Paramétrico | I26: Médio-agudo | J26: 0.18 | K26: 313 | L26: OK | M26: Manter
B27: 1 | D27: =IF(OR(C27="",E27=""),"",COUNTIF($C$27:C27,C27)) | I27: =IF(E27="","",IF(E27<250,"Grave",IF(E27<500,"Médio-grave",IF(E27<2000,"Médio",IF(E27<=5000,"Médio-agudo","Agudo"))))) | J27: =IF(OR(E27="",AND(H27<>"Gráfico",OR(G27="",G27<=0))),"",IF(H27="Gráfico",0.33,ROUND(2*LOG10(1/(2*G27)+(1/(4*G27^2)+1)^0.5)/LOG10(2),2))) | K27: =IF(OR(E27="",AND(H27<>"Gráfico",OR(G27="",G27<=0))),"",ROUND(E27*IF(H27="Gráfico",0.232,1/G27),0)) | L27: =IF(E27="","",IF(COUNTIF($C$14:$C$21,C27)=0,"Saída?",IF(AND(F27<>"",F27>0),"Realce",IF(AND(F27<>"",F27<$L$5),"Corte fundo",IF(AND(H27<>"Gráfico",G27<>"",G27<$L$6),"Corte largo","OK"))))) | M27: =IF(L27="","",IF(L27="Saída?","Escreva a saída igual à da tabela de cima",IF(L27="Realce","Realce aumenta o ganho do ciclo: troque por corte",IF(L27="Corte fundo","Corte além de "&ABS($L$5)&" dB: reveja a posição antes de aprofundar",IF(L27="Corte largo","Estreite o corte: Q de pelo menos "&$L$6,"Manter")))))
B28: 2 | D28: =IF(OR(C28="",E28=""),"",COUNTIF($C$27:C28,C28)) | I28: =IF(E28="","",IF(E28<250,"Grave",IF(E28<500,"Médio-grave",IF(E28<2000,"Médio",IF(E28<=5000,"Médio-agudo","Agudo"))))) | J28: =IF(OR(E28="",AND(H28<>"Gráfico",OR(G28="",G28<=0))),"",IF(H28="Gráfico",0.33,ROUND(2*LOG10(1/(2*G28)+(1/(4*G28^2)+1)^0.5)/LOG10(2),2))) | K28: =IF(OR(E28="",AND(H28<>"Gráfico",OR(G28="",G28<=0))),"",ROUND(E28*IF(H28="Gráfico",0.232,1/G28),0)) | L28: =IF(E28="","",IF(COUNTIF($C$14:$C$21,C28)=0,"Saída?",IF(AND(F28<>"",F28>0),"Realce",IF(AND(F28<>"",F28<$L$5),"Corte fundo",IF(AND(H28<>"Gráfico",G28<>"",G28<$L$6),"Corte largo","OK"))))) | M28: =IF(L28="","",IF(L28="Saída?","Escreva a saída igual à da tabela de cima",IF(L28="Realce","Realce aumenta o ganho do ciclo: troque por corte",IF(L28="Corte fundo","Corte além de "&ABS($L$5)&" dB: reveja a posição antes de aprofundar",IF(L28="Corte largo","Estreite o corte: Q de pelo menos "&$L$6,"Manter")))))
B29: 3 | D29: =IF(OR(C29="",E29=""),"",COUNTIF($C$27:C29,C29)) | I29: =IF(E29="","",IF(E29<250,"Grave",IF(E29<500,"Médio-grave",IF(E29<2000,"Médio",IF(E29<=5000,"Médio-agudo","Agudo"))))) | J29: =IF(OR(E29="",AND(H29<>"Gráfico",OR(G29="",G29<=0))),"",IF(H29="Gráfico",0.33,ROUND(2*LOG10(1/(2*G29)+(1/(4*G29^2)+1)^0.5)/LOG10(2),2))) | K29: =IF(OR(E29="",AND(H29<>"Gráfico",OR(G29="",G29<=0))),"",ROUND(E29*IF(H29="Gráfico",0.232,1/G29),0)) | L29: =IF(E29="","",IF(COUNTIF($C$14:$C$21,C29)=0,"Saída?",IF(AND(F29<>"",F29>0),"Realce",IF(AND(F29<>"",F29<$L$5),"Corte fundo",IF(AND(H29<>"Gráfico",G29<>"",G29<$L$6),"Corte largo","OK"))))) | M29: =IF(L29="","",IF(L29="Saída?","Escreva a saída igual à da tabela de cima",IF(L29="Realce","Realce aumenta o ganho do ciclo: troque por corte",IF(L29="Corte fundo","Corte além de "&ABS($L$5)&" dB: reveja a posição antes de aprofundar",IF(L29="Corte largo","Estreite o corte: Q de pelo menos "&$L$6,"Manter")))))
B30: 4 | D30: =IF(OR(C30="",E30=""),"",COUNTIF($C$27:C30,C30)) | I30: =IF(E30="","",IF(E30<250,"Grave",IF(E30<500,"Médio-grave",IF(E30<2000,"Médio",IF(E30<=5000,"Médio-agudo","Agudo"))))) | J30: =IF(OR(E30="",AND(H30<>"Gráfico",OR(G30="",G30<=0))),"",IF(H30="Gráfico",0.33,ROUND(2*LOG10(1/(2*G30)+(1/(4*G30^2)+1)^0.5)/LOG10(2),2))) | K30: =IF(OR(E30="",AND(H30<>"Gráfico",OR(G30="",G30<=0))),"",ROUND(E30*IF(H30="Gráfico",0.232,1/G30),0)) | L30: =IF(E30="","",IF(COUNTIF($C$14:$C$21,C30)=0,"Saída?",IF(AND(F30<>"",F30>0),"Realce",IF(AND(F30<>"",F30<$L$5),"Corte fundo",IF(AND(H30<>"Gráfico",G30<>"",G30<$L$6),"Corte largo","OK"))))) | M30: =IF(L30="","",IF(L30="Saída?","Escreva a saída igual à da tabela de cima",IF(L30="Realce","Realce aumenta o ganho do ciclo: troque por corte",IF(L30="Corte fundo","Corte além de "&ABS($L$5)&" dB: reveja a posição antes de aprofundar",IF(L30="Corte largo","Estreite o corte: Q de pelo menos "&$L$6,"Manter")))))
B31: 5 | D31: =IF(OR(C31="",E31=""),"",COUNTIF($C$27:C31,C31)) | I31: =IF(E31="","",IF(E31<250,"Grave",IF(E31<500,"Médio-grave",IF(E31<2000,"Médio",IF(E31<=5000,"Médio-agudo","Agudo"))))) | J31: =IF(OR(E31="",AND(H31<>"Gráfico",OR(G31="",G31<=0))),"",IF(H31="Gráfico",0.33,ROUND(2*LOG10(1/(2*G31)+(1/(4*G31^2)+1)^0.5)/LOG10(2),2))) | K31: =IF(OR(E31="",AND(H31<>"Gráfico",OR(G31="",G31<=0))),"",ROUND(E31*IF(H31="Gráfico",0.232,1/G31),0)) | L31: =IF(E31="","",IF(COUNTIF($C$14:$C$21,C31)=0,"Saída?",IF(AND(F31<>"",F31>0),"Realce",IF(AND(F31<>"",F31<$L$5),"Corte fundo",IF(AND(H31<>"Gráfico",G31<>"",G31<$L$6),"Corte largo","OK"))))) | M31: =IF(L31="","",IF(L31="Saída?","Escreva a saída igual à da tabela de cima",IF(L31="Realce","Realce aumenta o ganho do ciclo: troque por corte",IF(L31="Corte fundo","Corte além de "&ABS($L$5)&" dB: reveja a posição antes de aprofundar",IF(L31="Corte largo","Estreite o corte: Q de pelo menos "&$L$6,"Manter")))))
B32: 6 | D32: =IF(OR(C32="",E32=""),"",COUNTIF($C$27:C32,C32)) | I32: =IF(E32="","",IF(E32<250,"Grave",IF(E32<500,"Médio-grave",IF(E32<2000,"Médio",IF(E32<=5000,"Médio-agudo","Agudo"))))) | J32: =IF(OR(E32="",AND(H32<>"Gráfico",OR(G32="",G32<=0))),"",IF(H32="Gráfico",0.33,ROUND(2*LOG10(1/(2*G32)+(1/(4*G32^2)+1)^0.5)/LOG10(2),2))) | K32: =IF(OR(E32="",AND(H32<>"Gráfico",OR(G32="",G32<=0))),"",ROUND(E32*IF(H32="Gráfico",0.232,1/G32),0)) | L32: =IF(E32="","",IF(COUNTIF($C$14:$C$21,C32)=0,"Saída?",IF(AND(F32<>"",F32>0),"Realce",IF(AND(F32<>"",F32<$L$5),"Corte fundo",IF(AND(H32<>"Gráfico",G32<>"",G32<$L$6),"Corte largo","OK"))))) | M32: =IF(L32="","",IF(L32="Saída?","Escreva a saída igual à da tabela de cima",IF(L32="Realce","Realce aumenta o ganho do ciclo: troque por corte",IF(L32="Corte fundo","Corte além de "&ABS($L$5)&" dB: reveja a posição antes de aprofundar",IF(L32="Corte largo","Estreite o corte: Q de pelo menos "&$L$6,"Manter")))))
B33: 7 | D33: =IF(OR(C33="",E33=""),"",COUNTIF($C$27:C33,C33)) | I33: =IF(E33="","",IF(E33<250,"Grave",IF(E33<500,"Médio-grave",IF(E33<2000,"Médio",IF(E33<=5000,"Médio-agudo","Agudo"))))) | J33: =IF(OR(E33="",AND(H33<>"Gráfico",OR(G33="",G33<=0))),"",IF(H33="Gráfico",0.33,ROUND(2*LOG10(1/(2*G33)+(1/(4*G33^2)+1)^0.5)/LOG10(2),2))) | K33: =IF(OR(E33="",AND(H33<>"Gráfico",OR(G33="",G33<=0))),"",ROUND(E33*IF(H33="Gráfico",0.232,1/G33),0)) | L33: =IF(E33="","",IF(COUNTIF($C$14:$C$21,C33)=0,"Saída?",IF(AND(F33<>"",F33>0),"Realce",IF(AND(F33<>"",F33<$L$5),"Corte fundo",IF(AND(H33<>"Gráfico",G33<>"",G33<$L$6),"Corte largo","OK"))))) | M33: =IF(L33="","",IF(L33="Saída?","Escreva a saída igual à da tabela de cima",IF(L33="Realce","Realce aumenta o ganho do ciclo: troque por corte",IF(L33="Corte fundo","Corte além de "&ABS($L$5)&" dB: reveja a posição antes de aprofundar",IF(L33="Corte largo","Estreite o corte: Q de pelo menos "&$L$6,"Manter")))))
B34: 8 | D34: =IF(OR(C34="",E34=""),"",COUNTIF($C$27:C34,C34)) | I34: =IF(E34="","",IF(E34<250,"Grave",IF(E34<500,"Médio-grave",IF(E34<2000,"Médio",IF(E34<=5000,"Médio-agudo","Agudo"))))) | J34: =IF(OR(E34="",AND(H34<>"Gráfico",OR(G34="",G34<=0))),"",IF(H34="Gráfico",0.33,ROUND(2*LOG10(1/(2*G34)+(1/(4*G34^2)+1)^0.5)/LOG10(2),2))) | K34: =IF(OR(E34="",AND(H34<>"Gráfico",OR(G34="",G34<=0))),"",ROUND(E34*IF(H34="Gráfico",0.232,1/G34),0)) | L34: =IF(E34="","",IF(COUNTIF($C$14:$C$21,C34)=0,"Saída?",IF(AND(F34<>"",F34>0),"Realce",IF(AND(F34<>"",F34<$L$5),"Corte fundo",IF(AND(H34<>"Gráfico",G34<>"",G34<$L$6),"Corte largo","OK"))))) | M34: =IF(L34="","",IF(L34="Saída?","Escreva a saída igual à da tabela de cima",IF(L34="Realce","Realce aumenta o ganho do ciclo: troque por corte",IF(L34="Corte fundo","Corte além de "&ABS($L$5)&" dB: reveja a posição antes de aprofundar",IF(L34="Corte largo","Estreite o corte: Q de pelo menos "&$L$6,"Manter")))))
B35: 9 | D35: =IF(OR(C35="",E35=""),"",COUNTIF($C$27:C35,C35)) | I35: =IF(E35="","",IF(E35<250,"Grave",IF(E35<500,"Médio-grave",IF(E35<2000,"Médio",IF(E35<=5000,"Médio-agudo","Agudo"))))) | J35: =IF(OR(E35="",AND(H35<>"Gráfico",OR(G35="",G35<=0))),"",IF(H35="Gráfico",0.33,ROUND(2*LOG10(1/(2*G35)+(1/(4*G35^2)+1)^0.5)/LOG10(2),2))) | K35: =IF(OR(E35="",AND(H35<>"Gráfico",OR(G35="",G35<=0))),"",ROUND(E35*IF(H35="Gráfico",0.232,1/G35),0)) | L35: =IF(E35="","",IF(COUNTIF($C$14:$C$21,C35)=0,"Saída?",IF(AND(F35<>"",F35>0),"Realce",IF(AND(F35<>"",F35<$L$5),"Corte fundo",IF(AND(H35<>"Gráfico",G35<>"",G35<$L$6),"Corte largo","OK"))))) | M35: =IF(L35="","",IF(L35="Saída?","Escreva a saída igual à da tabela de cima",IF(L35="Realce","Realce aumenta o ganho do ciclo: troque por corte",IF(L35="Corte fundo","Corte além de "&ABS($L$5)&" dB: reveja a posição antes de aprofundar",IF(L35="Corte largo","Estreite o corte: Q de pelo menos "&$L$6,"Manter")))))
B36: 10 | D36: =IF(OR(C36="",E36=""),"",COUNTIF($C$27:C36,C36)) | I36: =IF(E36="","",IF(E36<250,"Grave",IF(E36<500,"Médio-grave",IF(E36<2000,"Médio",IF(E36<=5000,"Médio-agudo","Agudo"))))) | J36: =IF(OR(E36="",AND(H36<>"Gráfico",OR(G36="",G36<=0))),"",IF(H36="Gráfico",0.33,ROUND(2*LOG10(1/(2*G36)+(1/(4*G36^2)+1)^0.5)/LOG10(2),2))) | K36: =IF(OR(E36="",AND(H36<>"Gráfico",OR(G36="",G36<=0))),"",ROUND(E36*IF(H36="Gráfico",0.232,1/G36),0)) | L36: =IF(E36="","",IF(COUNTIF($C$14:$C$21,C36)=0,"Saída?",IF(AND(F36<>"",F36>0),"Realce",IF(AND(F36<>"",F36<$L$5),"Corte fundo",IF(AND(H36<>"Gráfico",G36<>"",G36<$L$6),"Corte largo","OK"))))) | M36: =IF(L36="","",IF(L36="Saída?","Escreva a saída igual à da tabela de cima",IF(L36="Realce","Realce aumenta o ganho do ciclo: troque por corte",IF(L36="Corte fundo","Corte além de "&ABS($L$5)&" dB: reveja a posição antes de aprofundar",IF(L36="Corte largo","Estreite o corte: Q de pelo menos "&$L$6,"Manter")))))
B37: 11 | D37: =IF(OR(C37="",E37=""),"",COUNTIF($C$27:C37,C37)) | I37: =IF(E37="","",IF(E37<250,"Grave",IF(E37<500,"Médio-grave",IF(E37<2000,"Médio",IF(E37<=5000,"Médio-agudo","Agudo"))))) | J37: =IF(OR(E37="",AND(H37<>"Gráfico",OR(G37="",G37<=0))),"",IF(H37="Gráfico",0.33,ROUND(2*LOG10(1/(2*G37)+(1/(4*G37^2)+1)^0.5)/LOG10(2),2))) | K37: =IF(OR(E37="",AND(H37<>"Gráfico",OR(G37="",G37<=0))),"",ROUND(E37*IF(H37="Gráfico",0.232,1/G37),0)) | L37: =IF(E37="","",IF(COUNTIF($C$14:$C$21,C37)=0,"Saída?",IF(AND(F37<>"",F37>0),"Realce",IF(AND(F37<>"",F37<$L$5),"Corte fundo",IF(AND(H37<>"Gráfico",G37<>"",G37<$L$6),"Corte largo","OK"))))) | M37: =IF(L37="","",IF(L37="Saída?","Escreva a saída igual à da tabela de cima",IF(L37="Realce","Realce aumenta o ganho do ciclo: troque por corte",IF(L37="Corte fundo","Corte além de "&ABS($L$5)&" dB: reveja a posição antes de aprofundar",IF(L37="Corte largo","Estreite o corte: Q de pelo menos "&$L$6,"Manter")))))
B38: 12 | D38: =IF(OR(C38="",E38=""),"",COUNTIF($C$27:C38,C38)) | I38: =IF(E38="","",IF(E38<250,"Grave",IF(E38<500,"Médio-grave",IF(E38<2000,"Médio",IF(E38<=5000,"Médio-agudo","Agudo"))))) | J38: =IF(OR(E38="",AND(H38<>"Gráfico",OR(G38="",G38<=0))),"",IF(H38="Gráfico",0.33,ROUND(2*LOG10(1/(2*G38)+(1/(4*G38^2)+1)^0.5)/LOG10(2),2))) | K38: =IF(OR(E38="",AND(H38<>"Gráfico",OR(G38="",G38<=0))),"",ROUND(E38*IF(H38="Gráfico",0.232,1/G38),0)) | L38: =IF(E38="","",IF(COUNTIF($C$14:$C$21,C38)=0,"Saída?",IF(AND(F38<>"",F38>0),"Realce",IF(AND(F38<>"",F38<$L$5),"Corte fundo",IF(AND(H38<>"Gráfico",G38<>"",G38<$L$6),"Corte largo","OK"))))) | M38: =IF(L38="","",IF(L38="Saída?","Escreva a saída igual à da tabela de cima",IF(L38="Realce","Realce aumenta o ganho do ciclo: troque por corte",IF(L38="Corte fundo","Corte além de "&ABS($L$5)&" dB: reveja a posição antes de aprofundar",IF(L38="Corte largo","Estreite o corte: Q de pelo menos "&$L$6,"Manter")))))
... B56: 30 | D56: =IF(OR(C56="",E56=""),"",COUNTIF($C$27:C56,C56)) | I56: =IF(E56="","",IF(E56<250,"Grave",IF(E56<500,"Médio-grave",IF(E56<2000,"Médio",IF(E56<=5000,"Médio-agudo","Agudo"))))) | J56: =IF(OR(E56="",AND(H56<>"Gráfico",OR(G56="",G56<=0))),"",IF(H56="Gráfico",0.33,ROUND(2*LOG10(1/(2*G56)+(1/(4*G56^2)+1)^0.5)/LOG10(2),2))) | K56: =IF(OR(E56="",AND(H56<>"Gráfico",OR(G56="",G56<=0))),"",ROUND(E56*IF(H56="Gráfico",0.232,1/G56),0)) | L56: =IF(E56="","",IF(COUNTIF($C$14:$C$21,C56)=0,"Saída?",IF(AND(F56<>"",F56>0),"Realce",IF(AND(F56<>"",F56<$L$5),"Corte fundo",IF(AND(H56<>"Gráfico",G56<>"",G56<$L$6),"Corte largo","OK"))))) | M56: =IF(L56="","",IF(L56="Saída?","Escreva a saída igual à da tabela de cima",IF(L56="Realce","Realce aumenta o ganho do ciclo: troque por corte",IF(L56="Corte fundo","Corte além de "&ABS($L$5)&" dB: reveja a posição antes de aprofundar",IF(L56="Corte largo","Estreite o corte: Q de pelo menos "&$L$6,"Manter")))))
B58: Resumo automático
B59: Saídas registradas | F59: =COUNTA(C14:C21) -> 0
B60: Saídas OK | F60: =COUNTIF($L$14:$L$21,"OK") -> 0
B61: Saídas sem margem ou com margem curta | F61: =COUNTIF($L$14:$L$21,"Sem margem")+COUNTIF($L$14:$L$21,"Margem curta") -> 0
...

Sheet Ocorrências
B1: Ocorrências — diagnóstico de cada apito durante os eventos
B2: Anote cada apito logo depois do evento: o que aconteceu, a causa e o que foi feito na hora. A medida definitiva é sugerida.
B4: Registro de ocorrências
B5: # | C5: Data | D5: Momento do evento | E5: Saída | F5: Canal | G5: Som do apito | H5: Frequência | I5: Causa | J5: Medida na hora | K5: Resolvido? | L5: Faixa pela frequência | M5: Medida definitiva sugerida | N5: Situação | O5: Observação
C6: dd/mm/aaaa | G6: pelo ouvido | H6: Hz, se medida | I6: da lista | K6: Sim / Não
B7: Ex. | D7: Pregação | E7: Frente | F7: Pastor (púlpito) | G7: Médio-agudo | H7: 2500 | I7: Microfones abertos sem uso | J7: Fader do pastor −3 dB; mute nos microfones da banda | K7: Sim | L7: Médio-agudo | M7: Mute em tudo o que não está em uso; criar grupos de mute por momento do evento. | N7: Resolvida
B8: A linha Ex. reproduz o exemplo 3 do treinamento.
B9: 1 | L9: =IF(H9="","",IF(H9<250,"Grave",IF(H9<500,"Médio-grave",IF(H9<2000,"Médio",IF(H9<=5000,"Médio-agudo","Agudo"))))) | M9: =IF(I9="","",IFERROR(VLOOKUP(I9,Referência!$B$45:$C$55,2,FALSE()),"")) | N9: =IF(AND(C9="",D9="",F9="",I9=""),"",IF(K9="Sim","Resolvida","Aberta"))
B10: 2 | L10: =IF(H10="","",IF(H10<250,"Grave",IF(H10<500,"Médio-grave",IF(H10<2000,"Médio",IF(H10<=5000,"Médio-agudo","Agudo"))))) | M10: =IF(I10="","",IFERROR(VLOOKUP(I10,Referência!$B$45:$C$55,2,FALSE()),"")) | N10: =IF(AND(C10="",D10="",F10="",I10=""),"",IF(K10="Sim","Resolvida","Aberta"))
B11: 3 | L11: =IF(H11="","",IF(H11<250,"Grave",IF(H11<500,"Médio-grave",IF(H11<2000,"Médio",IF(H11<=5000,"Médio-agudo","Agudo"))))) | M11: =IF(I11="","",IFERROR(VLOOKUP(I11,Referência!$B$45:$C$55,2,FALSE()),"")) | N11: =IF(AND(C11="",D11="",F11="",I11=""),"",IF(K11="Sim","Resolvida","Aberta"))
B12: 4 | L12: =IF(H12="","",IF(H12<250,"Grave",IF(H12<500,"Médio-grave",IF(H12<2000,"Médio",IF(H12<=5000,"Médio-agudo","Agudo"))))) | M12: =IF(I12="","",IFERROR(VLOOKUP(I12,Referência!$B$45:$C$55,2,FALSE()),"")) | N12: =IF(AND(C12="",D12="",F12="",I12=""),"",IF(K12="Sim","Resolvida","Aberta"))
B13: 5 | L13: =IF(H13="","",IF(H13<250,"Grave",IF(H13<500,"Médio-grave",IF(H13<2000,"Médio",IF(H13<=5000,"Médio-agudo","Agudo"))))) | M13: =IF(I13="","",IFERROR(VLOOKUP(I13,Referência!$B$45:$C$55,2,FALSE()),"")) | N13: =IF(AND(C13="",D13="",F13="",I13=""),"",IF(K13="Sim","Resolvida","Aberta"))
B14: 6 | L14: =IF(H14="","",IF(H14<250,"Grave",IF(H14<500,"Médio-grave",IF(H14<2000,"Médio",IF(H14<=5000,"Médio-agudo","Agudo"))))) | M14: =IF(I14="","",IFERROR(VLOOKUP(I14,Referência!$B$45:$C$55,2,FALSE()),"")) | N14: =IF(AND(C14="",D14="",F14="",I14=""),"",IF(K14="Sim","Resolvida","Aberta"))
B15: 7 | L15: =IF(H15="","",IF(H15<250,"Grave",IF(H15<500,"Médio-grave",IF(H15<2000,"Médio",IF(H15<=5000,"Médio-agudo","Agudo"))))) | M15: =IF(I15="","",IFERROR(VLOOKUP(I15,Referência!$B$45:$C$55,2,FALSE()),"")) | N15: =IF(AND(C15="",D15="",F15="",I15=""),"",IF(K15="Sim","Resolvida","Aberta"))
B16: 8 | L16: =IF(H16="","",IF(H16<250,"Grave",IF(H16<500,"Médio-grave",IF(H16<2000,"Médio",IF(H16<=5000,"Médio-agudo","Agudo"))))) | M16: =IF(I16="","",IFERROR(VLOOKUP(I16,Referência!$B$45:$C$55,2,FALSE()),"")) | N16: =IF(AND(C16="",D16="",F16="",I16=""),"",IF(K16="Sim","Resolvida","Aberta"))
B17: 9 | L17: =IF(H17="","",IF(H17<250,"Grave",IF(H17<500,"Médio-grave",IF(H17<2000,"Médio",IF(H17<=5000,"Médio-agudo","Agudo"))))) | M17: =IF(I17="","",IFERROR(VLOOKUP(I17,Referência!$B$45:$C$55,2,FALSE()),"")) | N17: =IF(AND(C17="",D17="",F17="",I17=""),"",IF(K17="Sim","Resolvida","Aberta"))
B18: 10 | L18: =IF(H18="","",IF(H18<250,"Grave",IF(H18<500,"Médio-grave",IF(H18<2000,"Médio",IF(H18<=5000,"Médio-agudo","Agudo"))))) | M18: =IF(I18="","",IFERROR(VLOOKUP(I18,Referência!$B$45:$C$55,2,FALSE()),"")) | N18: =IF(AND(C18="",D18="",F18="",I18=""),"",IF(K18="Sim","Resolvida","Aberta"))
B19: 11 | L19: =IF(H19="","",IF(H19<250,"Grave",IF(H19<500,"Médio-grave",IF(H19<2000,"Médio",IF(H19<=5000,"Médio-agudo","Agudo"))))) | M19: =IF(I19="","",IFERROR(VLOOKUP(I19,Referência!$B$45:$C$55,2,FALSE()),"")) | N19: =IF(AND(C19="",D19="",F19="",I19=""),"",IF(K19="Sim","Resolvida","Aberta"))
B20: 12 | L20: =IF(H20="","",IF(H20<250,"Grave",IF(H20<500,"Médio-grave",IF(H20<2000,"Médio",IF(H20<=5000,"Médio-agudo","Agudo"))))) | M20: =IF(I20="","",IFERROR(VLOOKUP(I20,Referência!$B$45:$C$55,2,FALSE()),"")) | N20: =IF(AND(C20="",D20="",F20="",I20=""),"",IF(K20="Sim","Resolvida","Aberta"))
... B28: 20 | L28: =IF(H28="","",IF(H28<250,"Grave",IF(H28<500,"Médio-grave",IF(H28<2000,"Médio",IF(H28<=5000,"Médio-agudo","Agudo"))))) | M28: =IF(I28="","",IFERROR(VLOOKUP(I28,Referência!$B$45:$C$55,2,FALSE()),"")) | N28: =IF(AND(C28="",D28="",F28="",I28=""),"",IF(K28="Sim","Resolvida","Aberta"))
B30: Ocorrências por causa
D31: Caixa mal posicionada | G31: =COUNTIF($I$9:$I$28,D31) -> 0
D32: Microfone longe da fonte | G32: =COUNTIF($I$9:$I$28,D32) -> 0
D33: Mão na cápsula | G33: =COUNTIF($I$9:$I$28,D33) -> 0
D34: Microfone virado para a caixa | G34: =COUNTIF($I$9:$I$28,D34) -> 0
D35: Microfones abertos sem uso | G35: =COUNTIF($I$9:$I$28,D35) -> 0
D36: Retorno alto | G36: =COUNTIF($I$9:$I$28,D36) -> 0
D37: Volume da sala alto | G37: =COUNTIF($I$9:$I$28,D37) -> 0
D38: Realce de EQ ou compressor | G38: =COUNTIF($I$9:$I$28,D38) -> 0
D39: Pessoa na frente da caixa | G39: =COUNTIF($I$9:$I$28,D39) -> 0
D40: Sala reflexiva | G40: =COUNTIF($I$9:$I$28,D40) -> 0
D41: Não identificada | G41: =COUNTIF($I$9:$I$28,D41) -> 0
B43: Ocorrências registradas | G43: =COUNTIF($N$9:$N$28,"Resolvida")+COUNTIF($N$9:$N$28,"Aberta") -> 0
B44: Abertas | G44: =COUNTIF($N$9:$N$28,"Aberta") -> 0
B45: Causa mais frequente | G45: =IF(MAX(G31:G41)=0,"",INDEX(D31:D41,MATCH(MAX(G31:G41),G31:G41,0)))
B46: Aviso | G46: =IF(G43=0,"Sem ocorrências registradas",IF(G44>0,"Há ocorrência aberta: aplique a medida definitiva antes do próximo evento","OK")) -> Sem ocorrências registradas

Sheet Margem
B1: Margem — microfones abertos e distância
B2: Estimativa da margem antes da microfonia em cada momento do evento, e calculadora de distância.
B4: Ponto de partida: o ring-out
B5: Margem medida no ring-out (dB) | E5: Da aba Ring-out: apito depois dos cortes menos o nível de operação.
B6: Microfones abertos no ring-out | E6: Quantos microfones estavam abertos quando a margem foi medida.
B7: Margem mínima (dB) | D7: 6 | E7: Regra prática: 6 dB.
B8: Máximo de microfones abertos com a margem mínima | D8: =IF(OR(D5="",D6="",D7="",D6<1),"",MAX(0,ROUND(D6*10^((D5-D7)/10)-0.4999,0))) | E8: Regra: cada vez que o número de microfones abertos dobra, a margem cai cerca de 3 dB.
B10: Margem em cada momento do evento
B11: # | C11: Momento do evento | D11: Microfones abertos | E11: Mudança da margem | F11: Margem estimada | G11: Situação | H11: O que fazer
D12: ao mesmo tempo | E12: dB | F12: dB
B13: Ex. | C13: Pregação com a banda aberta (ring-out: 7 dB com 2) | D13: 8 | E13: -6 | F13: 1 | G13: Sem margem | H13: Feche microfones sem uso: com a margem mínima, até 2 abertos
B14: 1 | E14: =IF(OR(D14="",$D$6="",D14<1,$D$6<1),"",ROUND(10*LOG10($D$6/D14),1)) | F14: =IF(OR(E14="",$D$5=""),"",$D$5+E14) | G14: =IF(F14="","",IF(F14<3,"Sem margem",IF(F14<$D$7,"Margem curta","OK"))) | H14: =IF(G14="","",IF(G14="OK","Manter","Feche microfones sem uso: com a margem mínima, até "&$D$8&" abertos"))
B15: 2 | E15: =IF(OR(D15="",$D$6="",D15<1,$D$6<1),"",ROUND(10*LOG10($D$6/D15),1)) | F15: =IF(OR(E15="",$D$5=""),"",$D$5+E15) | G15: =IF(F15="","",IF(F15<3,"Sem margem",IF(F15<$D$7,"Margem curta","OK"))) | H15: =IF(G15="","",IF(G15="OK","Manter","Feche microfones sem uso: com a margem mínima, até "&$D$8&" abertos"))
B16: 3 | E16: =IF(OR(D16="",$D$6="",D16<1,$D$6<1),"",ROUND(10*LOG10($D$6/D16),1)) | F16: =IF(OR(E16="",$D$5=""),"",$D$5+E16) | G16: =IF(F16="","",IF(F16<3,"Sem margem",IF(F16<$D$7,"Margem curta","OK"))) | H16: =IF(G16="","",IF(G16="OK","Manter","Feche microfones sem uso: com a margem mínima, até "&$D$8&" abertos"))
B17: 4 | E17: =IF(OR(D17="",$D$6="",D17<1,$D$6<1),"",ROUND(10*LOG10($D$6/D17),1)) | F17: =IF(OR(E17="",$D$5=""),"",$D$5+E17) | G17: =IF(F17="","",IF(F17<3,"Sem margem",IF(F17<$D$7,"Margem curta","OK"))) | H17: =IF(G17="","",IF(G17="OK","Manter","Feche microfones sem uso: com a margem mínima, até "&$D$8&" abertos"))
B18: 5 | E18: =IF(OR(D18="",$D$6="",D18<1,$D$6<1),"",ROUND(10*LOG10($D$6/D18),1)) | F18: =IF(OR(E18="",$D$5=""),"",$D$5+E18) | G18: =IF(F18="","",IF(F18<3,"Sem margem",IF(F18<$D$7,"Margem curta","OK"))) | H18: =IF(G18="","",IF(G18="OK","Manter","Feche microfones sem uso: com a margem mínima, até "&$D$8&" abertos"))
B19: 6 | E19: =IF(OR(D19="",$D$6="",D19<1,$D$6<1),"",ROUND(10*LOG10($D$6/D19),1)) | F19: =IF(OR(E19="",$D$5=""),"",$D$5+E19) | G19: =IF(F19="","",IF(F19<3,"Sem margem",IF(F19<$D$7,"Margem curta","OK"))) | H19: =IF(G19="","",IF(G19="OK","Manter","Feche microfones sem uso: com a margem mínima, até "&$D$8&" abertos"))
B20: 7 | E20: =IF(OR(D20="",$D$6="",D20<1,$D$6<1),"",ROUND(10*LOG10($D$6/D20),1)) | F20: =IF(OR(E20="",$D$5=""),"",$D$5+E20) | G20: =IF(F20="","",IF(F20<3,"Sem margem",IF(F20<$D$7,"Margem curta","OK"))) | H20: =IF(G20="","",IF(G20="OK","Manter","Feche microfones sem uso: com a margem mínima, até "&$D$8&" abertos"))
B21: 8 | E21: =IF(OR(D21="",$D$6="",D21<1,$D$6<1),"",ROUND(10*LOG10($D$6/D21),1)) | F21: =IF(OR(E21="",$D$5=""),"",$D$5+E21) | G21: =IF(F21="","",IF(F21<3,"Sem margem",IF(F21<$D$7,"Margem curta","OK"))) | H21: =IF(G21="","",IF(G21="OK","Manter","Feche microfones sem uso: com a margem mínima, até "&$D$8&" abertos"))
B22: 9 | E22: =IF(OR(D22="",$D$6="",D22<1,$D$6<1),"",ROUND(10*LOG10($D$6/D22),1)) | F22: =IF(OR(E22="",$D$5=""),"",$D$5+E22) | G22: =IF(F22="","",IF(F22<3,"Sem margem",IF(F22<$D$7,"Margem curta","OK"))) | H22: =IF(G22="","",IF(G22="OK","Manter","Feche microfones sem uso: com a margem mínima, até "&$D$8&" abertos"))
B23: 10 | E23: =IF(OR(D23="",$D$6="",D23<1,$D$6<1),"",ROUND(10*LOG10($D$6/D23),1)) | F23: =IF(OR(E23="",$D$5=""),"",$D$5+E23) | G23: =IF(F23="","",IF(F23<3,"Sem margem",IF(F23<$D$7,"Margem curta","OK"))) | H23: =IF(G23="","",IF(G23="OK","Manter","Feche microfones sem uso: com a margem mínima, até "&$D$8&" abertos"))
B25: Calculadora de distância
B26: Fonte–microfone
B27: Distância atual da boca ao microfone (cm) | E27: Positivo: a voz chega mais forte, e o sistema precisa amplificar menos. Essa diferença vira margem.
B28: Nova distância (cm)
B29: Mudança na voz captada (dB) | D29: =IF(OR(D27="",D28="",D27<=0,D28<=0),"",ROUND(20*LOG10(D27/D28),1))
B30: Caixa–microfone
B31: Distância atual da caixa ao microfone (m) | E31: Valor ao ar livre. Em sala reflexiva, o som volta pelas paredes, e o ganho real é menor.
B32: Nova distância (m)
B33: Ganho de margem, no máximo (dB) | D33: =IF(OR(D31="",D32="",D31<=0,D32<=0),"",ROUND(20*LOG10(D32/D31),1))
B35: Estimativas pela lei do inverso do quadrado e pela regra dos 3 dB por dobro de microfones abertos. A medida real vem do ring-out.

Sheet Referência
B1: Referência — microfonia
B2: Valores de referência, para servir de ponto de partida. Confira o manual do seu equipamento.
B4: Faixas do apito
B5: Faixa | C5: Frequência | D5: Como soa | E5: Onde costuma aparecer
B6: Grave | C6: até 250 Hz | D6: ronco | E6: Lapela, microfone de violão ou de bumbo, microfone perto do subwoofer. Ligue o filtro passa-altas.
B7: Médio-grave | C7: 250 a 500 Hz | D7: uivo, embolado | E7: Púlpito e coral captados de longe, sala reverberante, caixa atrás de quem fala.
B8: Médio | C8: 500 Hz a 2 kHz | D8: buzina, som de cano | E8: Retorno de chão alto, mão em volta da cápsula.
B9: Médio-agudo | C9: 2 a 5 kHz | D9: apito claro | E9: Microfone de voz com retorno de chão, microfone apontado para a caixa.
B10: Agudo | C10: acima de 5 kHz | D10: silvo fino | E10: Condensador, lapela ou headset que passa perto de uma caixa.
B12: Q e largura do corte (equalizador paramétrico)
B13: Q | C13: Largura | D13: Uso | E13: Observação
B14: 1,4 | C14: 1 oitava | D14: largo demais | E14: Tira o apito e leva junto um pedaço grande do som.
B15: 2,9 | C15: 1/2 oitava | D15: largo | E15: Ainda largo para microfonia.
B16: 4,3 | C16: 1/3 de oitava | D16: como o EQ gráfico | E16: Largura de cada controle do equalizador gráfico de 31 bandas.
B17: 8,7 | C17: 1/6 de oitava | D17: bom ponto de partida | E17: Faixa usual para cortes de microfonia: Q de 5 a 10.
B18: 14,4 | C18: 1/10 de oitava | D18: muito estreito | E18: Preciso, mas pede a frequência exata.
B20: Microfones abertos e margem
B21: Microfones abertos | C21: Mudança da margem | D21: Regra | E21: Observação
B22: 1 | C22: 0 dB | D22: referência | E22: Supõe microfones parecidos, no mesmo nível, captando o sistema de forma parecida.
B23: 2 | C23: −3 dB | D23: dobrou | E23: Feche os microfones que não estão em uso.
B24: 4 | C24: −6 dB | D24: dobrou duas vezes | E24: Use grupos de mute ou DCA por momento do evento.
B25: 8 | C25: −9 dB | D25: três vezes | E25: Mixagem automática (automixer) ajuda em debates com muitos microfones.
B26: 16 | C26: −12 dB | D26: quatro vezes | E26: Faça o ring-out com os microfones que ficam abertos juntos.
B28: Medidas e efeito na margem
B29: Medida | C29: Efeito | D29: Ordem | E29: Do que depende
B30: Posição das caixas | C30: vários dB | D30: 1 | E30: Caixas à frente da linha dos microfones; retorno na direção de menor captação.
B31: Microfone na metade da distância | C31: +6 dB | D31: 2 | E31: Vale a cada metade. De 20 cm para 5 cm, 12 dB.
B32: Caixa ao dobro da distância | C32: até +6 dB | D32: 1 | E32: O valor cheio só ao ar livre. Em sala reflexiva, menos.
B33: Metade dos microfones abertos | C33: +3 dB | D33: 3 | E33: De os microfones captarem o sistema de forma parecida.
B34: Ring-out | C34: 3 a 6 dB | D34: 4 | E34: Faixa típica. Se os primeiros cortes rendem pouco, a posição está ruim.
B36: Posição do retorno pelo padrão polar
B37: Padrão polar | C37: Menor captação | D37: Onde fica o retorno | E37: Observação
B38: Cardioide | C38: atrás, a 180° | D38: bem à frente do músico | E38: Chega pela parte de trás do microfone.
B39: Supercardioide | C39: cerca de 125° | D39: na diagonal, ou dois retornos | E39: Bem atrás ainda há um pequeno lóbulo de captação.
B40: Hipercardioide | C40: cerca de 110° | D40: mais para o lado | E40: Lóbulo traseiro maior que o do supercardioide.
B41: Onidirecional | C41: nenhuma | D41: não há posição boa | E41: A margem vem só da distância e do volume.
B43: Causa e medida definitiva (usada na aba Ocorrências)
B44: Causa | C44: Medida definitiva
B45: Caixa mal posicionada | C45: Levar as caixas para a frente da linha dos microfones, apontadas para o público.
B46: Microfone longe da fonte | C46: Aproximar o microfone da boca; trocar lapela por headset ou microfone de mão.
...

Sheet Checklist
B1: Checklist contra a microfonia
B2: Confira na montagem, antes da passagem de som. Escolha a situação de cada item na lista suspensa.
B4: # | C4: Grupo | D4: Item | E4: Situação | F4: Observação
B5: 1 | C5: Posição | D5: As caixas da frente estão à frente da linha dos microfones e apontam para o público.
B6: 2 | C6: Posição | D6: As caixas apontam para as pessoas, e não para paredes, vidro ou teto.
B7: 3 | C7: Posição | D7: Cada retorno está na direção em que o microfone capta menos: atrás do cardioide, na diagonal do supercardioide.
B8: 4 | C8: Microfone | D8: Cada microfone está o mais perto possível da fonte, e quem usa foi orientado: perto da boca, grade livre.
B9: 5 | C9: Ganho | D9: O ganho de cada canal foi ajustado pelo medidor, e o filtro passa-altas está ligado nos microfones de voz.
B10: 6 | C10: Ganho | D10: O volume dos retornos é o menor que atende os músicos.
B11: 7 | C11: Ganho | D11: Só ficam abertos os microfones em uso. Os demais estão em mute, e há grupos de mute para os conjuntos.
B12: 8 | C12: Ring-out | D12: O ring-out foi feito em cada retorno e nas caixas da frente, com os microfones que ficam abertos juntos.
B13: 9 | C13: Ring-out | D13: Os cortes são estreitos e poucos: até uns cinco por saída, nenhum além de uns 9 dB.
B14: 10 | C14: Ring-out | D14: Há pelo menos 6 dB de margem entre o nível de operação e o ponto do primeiro apito, em cada saída.
B15: 11 | C15: Teste | D15: Os microfones que andam foram testados no caminho real, inclusive perto das caixas.
B16: 12 | C16: Registro | D16: As frequências, os cortes e os níveis de cada saída estão anotados.
B18: Itens respondidos | E18: =COUNTA(E5:E16) -> 0
B19: Percentual atendido (Parcial vale metade) | E19: =IF(COUNTA(E5:E16)=0,"",(COUNTIF(E5:E16,"Sim")+COUNTIF(E5:E16,"Parcial")/2)/COUNTA(E5:E16))
B20: Situação | E20: =IF(COUNTA(E5:E16)<12,"Incompleto",IF(COUNTIF(E5:E16,"Não")=0,"OK","Há itens a resolver")) -> Incompleto

Sheet Exemplo - Ring-out
B1: Ring-out — registro por saída e por corte
B2: Exemplo preenchido, para consulta. Use a aba Ring-out para o seu sistema.
B4: Evento ou sistema | D4: Culto de domingo, 19 h | I4: Margem mínima (dB) | L4: 6 | M4: Regra prática: pelo menos 6 dB entre a operação e o primeiro apito.
B5: Local | D5: Igreja de 200 lugares | I5: Corte mais fundo aceito (dB) | L5: -9 | M5: Corte além disso indica problema de posição, e não de equalização.
B6: Data | D6: 46299 | I6: Q mínimo do corte | L6: 4 | M6: Q perto de 4 = 1/3 de oitava. Corte de microfonia: Q de 5 a 10.
B7: Operador | D7: Operador de som da escala | I7: Máximo de cortes por saída | L7: 5 | M7: Mais cortes que isso deixam o som oco.
B8: Mesa e equalizador | D8: Mesa digital, EQ paramétrico nas saídas | I8: Níveis em dB, na posição do master de cada saída. O ponto de apito é onde a primeira nota começa a soar.
B10: Saídas: nível do primeiro apito e nível de operação
B11: # | C11: Saída | D11: Tipo | E11: Microfones abertos | F11: Apito antes dos cortes | G11: Apito depois dos cortes | H11: Nível de operação | I11: Cortes | J11: Ganho obtido | K11: Margem | L11: Situação | M11: O que fazer | N11: Observação
C12: nome único | E12: no ring-out | F12: dB | G12: dB | H12: dB | I12: na tabela abaixo | J12: depois − antes | K12: apito − operação
B13: Ring-out das três saídas do exemplo 1. As colunas de I a M são calculadas.
B14: 1 | C14: Retorno 1 - voz principal | D14: Retorno | E14: 1 | F14: -8 | G14: -2 | H14: -9 | I14: =IF(C14="","",COUNTIF($C$27:$C$56,C14)) -> 4 | J14: =IF(OR(F14="",G14=""),"",G14-F14) -> 6 | K14: =IF(OR(G14="",H14=""),"",G14-H14) -> 7 | L14: =IF(AND(C14="",F14="",G14="",H14=""),"",IF(OR(G14="",H14=""),"Incompleto",IF(AND(J14<>"",J14<0),"Confira os níveis",IF(K14<3,"Sem margem",IF(K14<$L$4,"Margem curta",IF(I14>$L$7,"Cortes demais",IF(COUNTIFS($C$27:$C$56,C14,$L$27:$L$56,"Corte fundo")+COUNTIFS($C$27:$C$56,C14,$L$27:$L$56,"Corte largo")+COUNTIFS($C$27:$C$56,C14,$L$27:$L$56,"Realce")>0,"Rever cortes","OK"))))))) -> OK | M14: =IF(L14="","",IF(L14="Incompleto","Anote o apito depois dos cortes e o nível de operação",IF(L14="Confira os níveis","O apito depois dos cortes ficou abaixo do de antes: meça de novo",IF(OR(L14="Sem margem",L14="Margem curta"),"Baixe a saída "&($L$4-K14)&" dB, ou reveja a posição e a distância",IF(L14="Cortes demais","Cortes demais: reveja a posição das caixas e dos microfones",IF(L14="Rever cortes","Há corte fundo, largo ou realce nesta saída: veja a tabela de cortes","Manter")))))) -> Manter
B15: 2 | C15: Retorno 2 - vozes de apoio | D15: Retorno | E15: 3 | F15: -10 | G15: -5 | H15: -9 | I15: =IF(C15="","",COUNTIF($C$27:$C$56,C15)) -> 3 | J15: =IF(OR(F15="",G15=""),"",G15-F15) -> 5 | K15: =IF(OR(G15="",H15=""),"",G15-H15) -> 4 | L15: =IF(AND(C15="",F15="",G15="",H15=""),"",IF(OR(G15="",H15=""),"Incompleto",IF(AND(J15<>"",J15<0),"Confira os níveis",IF(K15<3,"Sem margem",IF(K15<$L$4,"Margem curta",IF(I15>$L$7,"Cortes demais",IF(COUNTIFS($C$27:$C$56,C15,$L$27:$L$56,"Corte fundo")+COUNTIFS($C$27:$C$56,C15,$L$27:$L$56,"Corte largo")+COUNTIFS($C$27:$C$56,C15,$L$27:$L$56,"Realce")>0,"Rever cortes","OK"))))))) -> Margem curta | M15: =IF(L15="","",IF(L15="Incompleto","Anote o apito depois dos cortes e o nível de operação",IF(L15="Confira os níveis","O apito depois dos cortes ficou abaixo do de antes: meça de novo",IF(OR(L15="Sem margem",L15="Margem curta"),"Baixe a saída "&($L$4-K15)&" dB, ou reveja a posição e a distância",IF(L15="Cortes demais","Cortes demais: reveja a posição das caixas e dos microfones",IF(L15="Rever cortes","Há corte fundo, largo ou realce nesta saída: veja a tabela de cortes","Manter")))))) -> Baixe a saída 2 dB, ou reveja a posição e a distância
B16: 3 | C16: Frente (PA) | D16: Frente | E16: 4 | F16: 3 | G16: 7 | H16: 0 | I16: =IF(C16="","",COUNTIF($C$27:$C$56,C16)) -> 2 | J16: =IF(OR(F16="",G16=""),"",G16-F16) -> 4 | K16: =IF(OR(G16="",H16=""),"",G16-H16) -> 7 | L16: =IF(AND(C16="",F16="",G16="",H16=""),"",IF(OR(G16="",H16=""),"Incompleto",IF(AND(J16<>"",J16<0),"Confira os níveis",IF(K16<3,"Sem margem",IF(K16<$L$4,"Margem curta",IF(I16>$L$7,"Cortes demais",IF(COUNTIFS($C$27:$C$56,C16,$L$27:$L$56,"Corte fundo")+COUNTIFS($C$27:$C$56,C16,$L$27:$L$56,"Corte largo")+COUNTIFS($C$27:$C$56,C16,$L$27:$L$56,"Realce")>0,"Rever cortes","OK"))))))) -> Rever cortes | M16: =IF(L16="","",IF(L16="Incompleto","Anote o apito depois dos cortes e o nível de operação",IF(L16="Confira os níveis","O apito depois dos cortes ficou abaixo do de antes: meça de novo",IF(OR(L16="Sem margem",L16="Margem curta"),"Baixe a saída "&($L$4-K16)&" dB, ou reveja a posição e a distância",IF(L16="Cortes demais","Cortes demais: reveja a posição das caixas e dos microfones",IF(L16="Rever cortes","Há corte fundo, largo ou realce nesta saída: veja a tabela de cortes","Manter")))))) -> Há corte fundo, largo ou realce nesta saída: veja a tabela de cortes
B17: 4 | I17: =IF(C17="","",COUNTIF($C$27:$C$56,C17)) | J17: =IF(OR(F17="",G17=""),"",G17-F17) | K17: =IF(OR(G17="",H17=""),"",G17-H17) | L17: =IF(AND(C17="",F17="",G17="",H17=""),"",IF(OR(G17="",H17=""),"Incompleto",IF(AND(J17<>"",J17<0),"Confira os níveis",IF(K17<3,"Sem margem",IF(K17<$L$4,"Margem curta",IF(I17>$L$7,"Cortes demais",IF(COUNTIFS($C$27:$C$56,C17,$L$27:$L$56,"Corte fundo")+COUNTIFS($C$27:$C$56,C17,$L$27:$L$56,"Corte largo")+COUNTIFS($C$27:$C$56,C17,$L$27:$L$56,"Realce")>0,"Rever cortes","OK"))))))) | M17: =IF(L17="","",IF(L17="Incompleto","Anote o apito depois dos cortes e o nível de operação",IF(L17="Confira os níveis","O apito depois dos cortes ficou abaixo do de antes: meça de novo",IF(OR(L17="Sem margem",L17="Margem curta"),"Baixe a saída "&($L$4-K17)&" dB, ou reveja a posição e a distância",IF(L17="Cortes demais","Cortes demais: reveja a posição das caixas e dos microfones",IF(L17="Rever cortes","Há corte fundo, largo ou realce nesta saída: veja a tabela de cortes","Manter"))))))
B18: 5 | I18: =IF(C18="","",COUNTIF($C$27:$C$56,C18)) | J18: =IF(OR(F18="",G18=""),"",G18-F18) | K18: =IF(OR(G18="",H18=""),"",G18-H18) | L18: =IF(AND(C18="",F18="",G18="",H18=""),"",IF(OR(G18="",H18=""),"Incompleto",IF(AND(J18<>"",J18<0),"Confira os níveis",IF(K18<3,"Sem margem",IF(K18<$L$4,"Margem curta",IF(I18>$L$7,"Cortes demais",IF(COUNTIFS($C$27:$C$56,C18,$L$27:$L$56,"Corte fundo")+COUNTIFS($C$27:$C$56,C18,$L$27:$L$56,"Corte largo")+COUNTIFS($C$27:$C$56,C18,$L$27:$L$56,"Realce")>0,"Rever cortes","OK"))))))) | M18: =IF(L18="","",IF(L18="Incompleto","Anote o apito depois dos cortes e o nível de operação",IF(L18="Confira os níveis","O apito depois dos cortes ficou abaixo do de antes: meça de novo",IF(OR(L18="Sem margem",L18="Margem curta"),"Baixe a saída "&($L$4-K18)&" dB, ou reveja a posição e a distância",IF(L18="Cortes demais","Cortes demais: reveja a posição das caixas e dos microfones",IF(L18="Rever cortes","Há corte fundo, largo ou realce nesta saída: veja a tabela de cortes","Manter"))))))
B19: 6 | I19: =IF(C19="","",COUNTIF($C$27:$C$56,C19)) | J19: =IF(OR(F19="",G19=""),"",G19-F19) | K19: =IF(OR(G19="",H19=""),"",G19-H19) | L19: =IF(AND(C19="",F19="",G19="",H19=""),"",IF(OR(G19="",H19=""),"Incompleto",IF(AND(J19<>"",J19<0),"Confira os níveis",IF(K19<3,"Sem margem",IF(K19<$L$4,"Margem curta",IF(I19>$L$7,"Cortes demais",IF(COUNTIFS($C$27:$C$56,C19,$L$27:$L$56,"Corte fundo")+COUNTIFS($C$27:$C$56,C19,$L$27:$L$56,"Corte largo")+COUNTIFS($C$27:$C$56,C19,$L$27:$L$56,"Realce")>0,"Rever cortes","OK"))))))) | M19: =IF(L19="","",IF(L19="Incompleto","Anote o apito depois dos cortes e o nível de operação",IF(L19="Confira os níveis","O apito depois dos cortes ficou abaixo do de antes: meça de novo",IF(OR(L19="Sem margem",L19="Margem curta"),"Baixe a saída "&($L$4-K19)&" dB, ou reveja a posição e a distância",IF(L19="Cortes demais","Cortes demais: reveja a posição das caixas e dos microfones",IF(L19="Rever cortes","Há corte fundo, largo ou realce nesta saída: veja a tabela de cortes","Manter"))))))
B20: 7 | I20: =IF(C20="","",COUNTIF($C$27:$C$56,C20)) | J20: =IF(OR(F20="",G20=""),"",G20-F20) | K20: =IF(OR(G20="",H20=""),"",G20-H20) | L20: =IF(AND(C20="",F20="",G20="",H20=""),"",IF(OR(G20="",H20=""),"Incompleto",IF(AND(J20<>"",J20<0),"Confira os níveis",IF(K20<3,"Sem margem",IF(K20<$L$4,"Margem curta",IF(I20>$L$7,"Cortes demais",IF(COUNTIFS($C$27:$C$56,C20,$L$27:$L$56,"Corte fundo")+COUNTIFS($C$27:$C$56,C20,$L$27:$L$56,"Corte largo")+COUNTIFS($C$27:$C$56,C20,$L$27:$L$56,"Realce")>0,"Rever cortes","OK"))))))) | M20: =IF(L20="","",IF(L20="Incompleto","Anote o apito depois dos cortes e o nível de operação",IF(L20="Confira os níveis","O apito depois dos cortes ficou abaixo do de antes: meça de novo",IF(OR(L20="Sem margem",L20="Margem curta"),"Baixe a saída "&($L$4-K20)&" dB, ou reveja a posição e a distância",IF(L20="Cortes demais","Cortes demais: reveja a posição das caixas e dos microfones",IF(L20="Rever cortes","Há corte fundo, largo ou realce nesta saída: veja a tabela de cortes","Manter"))))))
B21: 8 | I21: =IF(C21="","",COUNTIF($C$27:$C$56,C21)) | J21: =IF(OR(F21="",G21=""),"",G21-F21) | K21: =IF(OR(G21="",H21=""),"",G21-H21) | L21: =IF(AND(C21="",F21="",G21="",H21=""),"",IF(OR(G21="",H21=""),"Incompleto",IF(AND(J21<>"",J21<0),"Confira os níveis",IF(K21<3,"Sem margem",IF(K21<$L$4,"Margem curta",IF(I21>$L$7,"Cortes demais",IF(COUNTIFS($C$27:$C$56,C21,$L$27:$L$56,"Corte fundo")+COUNTIFS($C$27:$C$56,C21,$L$27:$L$56,"Corte largo")+COUNTIFS($C$27:$C$56,C21,$L$27:$L$56,"Realce")>0,"Rever cortes","OK"))))))) | M21: =IF(L21="","",IF(L21="Incompleto","Anote o apito depois dos cortes e o nível de operação",IF(L21="Confira os níveis","O apito depois dos cortes ficou abaixo do de antes: meça de novo",IF(OR(L21="Sem margem",L21="Margem curta"),"Baixe a saída "&($L$4-K21)&" dB, ou reveja a posição e a distância",IF(L21="Cortes demais","Cortes demais: reveja a posição das caixas e dos microfones",IF(L21="Rever cortes","Há corte fundo, largo ou realce nesta saída: veja a tabela de cortes","Manter"))))))
B23: Cortes de equalizador, na ordem em que foram feitos
B24: # | C24: Saída | D24: Ordem na saída | E24: Frequência | F24: Corte | G24: Q | H24: Equalizador | I24: Faixa | J24: Largura | K24: Largura | L24: Situação | M24: O que fazer | N24: Observação
C25: da lista | E25: Hz | F25: dB, negativo | G25: no paramétrico | I25: pelo som | J25: oitava | K25: Hz, aprox.
B26: Os nove cortes do exemplo 1, antes do ajuste de posição do retorno 2. As colunas D, I, J, K, L e M são calculadas.
B27: 1 | C27: Retorno 1 - voz principal | D27: =IF(OR(C27="",E27=""),"",COUNTIF($C$27:C27,C27)) -> 1 | E27: 2500 | F27: -6 | G27: 8 | H27: Paramétrico | I27: =IF(E27="","",IF(E27<250,"Grave",IF(E27<500,"Médio-grave",IF(E27<2000,"Médio",IF(E27<=5000,"Médio-agudo","Agudo"))))) -> Médio-agudo | J27: =IF(OR(E27="",AND(H27<>"Gráfico",OR(G27="",G27<=0))),"",IF(H27="Gráfico",0.33,ROUND(2*LOG10(1/(2*G27)+(1/(4*G27^2)+1)^0.5)/LOG10(2),2))) -> 0.18 | K27: =IF(OR(E27="",AND(H27<>"Gráfico",OR(G27="",G27<=0))),"",ROUND(E27*IF(H27="Gráfico",0.232,1/G27),0)) -> 313 | L27: =IF(E27="","",IF(COUNTIF($C$14:$C$21,C27)=0,"Saída?",IF(AND(F27<>"",F27>0),"Realce",IF(AND(F27<>"",F27<$L$5),"Corte fundo",IF(AND(H27<>"Gráfico",G27<>"",G27<$L$6),"Corte largo","OK"))))) -> OK | M27: =IF(L27="","",IF(L27="Saída?","Escreva a saída igual à da tabela de cima",IF(L27="Realce","Realce aumenta o ganho do ciclo: troque por corte",IF(L27="Corte fundo","Corte além de "&ABS($L$5)&" dB: reveja a posição antes de aprofundar",IF(L27="Corte largo","Estreite o corte: Q de pelo menos "&$L$6,"Manter"))))) -> Manter
B28: 2 | C28: Retorno 1 - voz principal | D28: =IF(OR(C28="",E28=""),"",COUNTIF($C$27:C28,C28)) -> 2 | E28: 630 | F28: -4 | G28: 8 | H28: Paramétrico | I28: =IF(E28="","",IF(E28<250,"Grave",IF(E28<500,"Médio-grave",IF(E28<2000,"Médio",IF(E28<=5000,"Médio-agudo","Agudo"))))) -> Médio | J28: =IF(OR(E28="",AND(H28<>"Gráfico",OR(G28="",G28<=0))),"",IF(H28="Gráfico",0.33,ROUND(2*LOG10(1/(2*G28)+(1/(4*G28^2)+1)^0.5)/LOG10(2),2))) -> 0.18 | K28: =IF(OR(E28="",AND(H28<>"Gráfico",OR(G28="",G28<=0))),"",ROUND(E28*IF(H28="Gráfico",0.232,1/G28),0)) -> 79 | L28: =IF(E28="","",IF(COUNTIF($C$14:$C$21,C28)=0,"Saída?",IF(AND(F28<>"",F28>0),"Realce",IF(AND(F28<>"",F28<$L$5),"Corte fundo",IF(AND(H28<>"Gráfico",G28<>"",G28<$L$6),"Corte largo","OK"))))) -> OK | M28: =IF(L28="","",IF(L28="Saída?","Escreva a saída igual à da tabela de cima",IF(L28="Realce","Realce aumenta o ganho do ciclo: troque por corte",IF(L28="Corte fundo","Corte além de "&ABS($L$5)&" dB: reveja a posição antes de aprofundar",IF(L28="Corte largo","Estreite o corte: Q de pelo menos "&$L$6,"Manter"))))) -> Manter
B29: 3 | C29: Retorno 1 - voz principal | D29: =IF(OR(C29="",E29=""),"",COUNTIF($C$27:C29,C29)) -> 3 | E29: 4000 | F29: -5 | G29: 8 | H29: Paramétrico | I29: =IF(E29="","",IF(E29<250,"Grave",IF(E29<500,"Médio-grave",IF(E29<2000,"Médio",IF(E29<=5000,"Médio-agudo","Agudo"))))) -> Médio-agudo | J29: =IF(OR(E29="",AND(H29<>"Gráfico",OR(G29="",G29<=0))),"",IF(H29="Gráfico",0.33,ROUND(2*LOG10(1/(2*G29)+(1/(4*G29^2)+1)^0.5)/LOG10(2),2))) -> 0.18 | K29: =IF(OR(E29="",AND(H29<>"Gráfico",OR(G29="",G29<=0))),"",ROUND(E29*IF(H29="Gráfico",0.232,1/G29),0)) -> 500 | L29: =IF(E29="","",IF(COUNTIF($C$14:$C$21,C29)=0,"Saída?",IF(AND(F29<>"",F29>0),"Realce",IF(AND(F29<>"",F29<$L$5),"Corte fundo",IF(AND(H29<>"Gráfico",G29<>"",G29<$L$6),"Corte largo","OK"))))) -> OK | M29: =IF(L29="","",IF(L29="Saída?","Escreva a saída igual à da tabela de cima",IF(L29="Realce","Realce aumenta o ganho do ciclo: troque por corte",IF(L29="Corte fundo","Corte além de "&ABS($L$5)&" dB: reveja a posição antes de aprofundar",IF(L29="Corte largo","Estreite o corte: Q de pelo menos "&$L$6,"Manter"))))) -> Manter
B30: 4 | C30: Retorno 1 - voz principal | D30: =IF(OR(C30="",E30=""),"",COUNTIF($C$27:C30,C30)) -> 4 | E30: 250 | F30: -3 | G30: 8 | H30: Paramétrico | I30: =IF(E30="","",IF(E30<250,"Grave",IF(E30<500,"Médio-grave",IF(E30<2000,"Médio",IF(E30<=5000,"Médio-agudo","Agudo"))))) -> Médio-grave | J30: =IF(OR(E30="",AND(H30<>"Gráfico",OR(G30="",G30<=0))),"",IF(H30="Gráfico",0.33,ROUND(2*LOG10(1/(2*G30)+(1/(4*G30^2)+1)^0.5)/LOG10(2),2))) -> 0.18 | K30: =IF(OR(E30="",AND(H30<>"Gráfico",OR(G30="",G30<=0))),"",ROUND(E30*IF(H30="Gráfico",0.232,1/G30),0)) -> 31 | L30: =IF(E30="","",IF(COUNTIF($C$14:$C$21,C30)=0,"Saída?",IF(AND(F30<>"",F30>0),"Realce",IF(AND(F30<>"",F30<$L$5),"Corte fundo",IF(AND(H30<>"Gráfico",G30<>"",G30<$L$6),"Corte largo","OK"))))) -> OK | M30: =IF(L30="","",IF(L30="Saída?","Escreva a saída igual à da tabela de cima",IF(L30="Realce","Realce aumenta o ganho do ciclo: troque por corte",IF(L30="Corte fundo","Corte além de "&ABS($L$5)&" dB: reveja a posição antes de aprofundar",IF(L30="Corte largo","Estreite o corte: Q de pelo menos "&$L$6,"Manter"))))) -> Manter
B31: 5 | C31: Retorno 2 - vozes de apoio | D31: =IF(OR(C31="",E31=""),"",COUNTIF($C$27:C31,C31)) -> 1 | E31: 1600 | F31: -5 | G31: 8 | H31: Paramétrico | I31: =IF(E31="","",IF(E31<250,"Grave",IF(E31<500,"Médio-grave",IF(E31<2000,"Médio",IF(E31<=5000,"Médio-agudo","Agudo"))))) -> Médio | J31: =IF(OR(E31="",AND(H31<>"Gráfico",OR(G31="",G31<=0))),"",IF(H31="Gráfico",0.33,ROUND(2*LOG10(1/(2*G31)+(1/(4*G31^2)+1)^0.5)/LOG10(2),2))) -> 0.18 | K31: =IF(OR(E31="",AND(H31<>"Gráfico",OR(G31="",G31<=0))),"",ROUND(E31*IF(H31="Gráfico",0.232,1/G31),0)) -> 200 | L31: =IF(E31="","",IF(COUNTIF($C$14:$C$21,C31)=0,"Saída?",IF(AND(F31<>"",F31>0),"Realce",IF(AND(F31<>"",F31<$L$5),"Corte fundo",IF(AND(H31<>"Gráfico",G31<>"",G31<$L$6),"Corte largo","OK"))))) -> OK | M31: =IF(L31="","",IF(L31="Saída?","Escreva a saída igual à da tabela de cima",IF(L31="Realce","Realce aumenta o ganho do ciclo: troque por corte",IF(L31="Corte fundo","Corte além de "&ABS($L$5)&" dB: reveja a posição antes de aprofundar",IF(L31="Corte largo","Estreite o corte: Q de pelo menos "&$L$6,"Manter"))))) -> Manter
B32: 6 | C32: Retorno 2 - vozes de apoio | D32: =IF(OR(C32="",E32=""),"",COUNTIF($C$27:C32,C32)) -> 2 | E32: 400 | F32: -10 | G32: 8 | H32: Paramétrico | I32: =IF(E32="","",IF(E32<250,"Grave",IF(E32<500,"Médio-grave",IF(E32<2000,"Médio",IF(E32<=5000,"Médio-agudo","Agudo"))))) -> Médio-grave | J32: =IF(OR(E32="",AND(H32<>"Gráfico",OR(G32="",G32<=0))),"",IF(H32="Gráfico",0.33,ROUND(2*LOG10(1/(2*G32)+(1/(4*G32^2)+1)^0.5)/LOG10(2),2))) -> 0.18 | K32: =IF(OR(E32="",AND(H32<>"Gráfico",OR(G32="",G32<=0))),"",ROUND(E32*IF(H32="Gráfico",0.232,1/G32),0)) -> 50 | L32: =IF(E32="","",IF(COUNTIF($C$14:$C$21,C32)=0,"Saída?",IF(AND(F32<>"",F32>0),"Realce",IF(AND(F32<>"",F32<$L$5),"Corte fundo",IF(AND(H32<>"Gráfico",G32<>"",G32<$L$6),"Corte largo","OK"))))) -> Corte fundo | M32: =IF(L32="","",IF(L32="Saída?","Escreva a saída igual à da tabela de cima",IF(L32="Realce","Realce aumenta o ganho do ciclo: troque por corte",IF(L32="Corte fundo","Corte além de "&ABS($L$5)&" dB: reveja a posição antes de aprofundar",IF(L32="Corte largo","Estreite o corte: Q de pelo menos "&$L$6,"Manter"))))) -> Corte além de 9 dB: reveja a posição antes de aprofundar
