Workbook

Sheet Instruções
B1: Lentes, foco e cor — como usar esta planilha
B2: Calculadora de enquadramento, faixa em foco e ficha de balanço de branco, para planejar as câmeras e ajustá-las no evento.
B4: Legenda: onde preencher
B5: Amarelo-claro | C5: Células de entrada. É aqui que você digita.
B6: Cinza | C6: Células calculadas ou fixas (rótulos, contas, avisos). Não altere.
B7: Cinza em itálico | C7: Linha de exemplo (marcada com “Ex.”) e dicas de preenchimento. Não entram nas contas.
B8: Listas suspensas | C8: Sensor, modo de balanço, perfil e as colunas Sim / Não aceitam só as opções da lista.
B9: Números | C9: Digite só o número, sem unidade: 18 (metros), 140 (mm), 5.6 (abertura), 3200 (kelvin).
B10: Comentários | C10: Células com triângulo vermelho no canto trazem uma dica. Passe o mouse sobre elas.
B12: Ordem de preenchimento
B13: 1 | C13: Na visita ao local: meça a distância de cada posição de câmera até o lugar da pessoa.
B14: 2 | C14: Aba Enquadramento: para cada câmera, o sensor, a distância, a largura de cena desejada e a faixa da lente.
B15: 3 | C15: Veja a situação. Em Falta tele ou Falta angular, mude a posição (coluna Q), troque a lente ou aceite a cena obtida.
B16: 4 | C16: Informe a abertura e veja a faixa em foco estimada. Se for estreita para quem anda, feche a íris.
B17: 5 | C17: No evento, com a luz ligada: faça o balanço com cartão branco em cada câmera.
B18: 6 | C18: Aba Balanço de branco: anote modo, kelvin, tint e perfil, compare no monitor e siga a coluna O que fazer.
B19: 7 | C19: Aba Checklist: confira os doze itens antes de o evento começar.
B21: Abas da planilha
B22: Enquadramento | C22: Calculadora para até 12 câmeras: focal necessária, situação, cena obtida, distância que fecha a cena e faixa em foco.
B23: Balanço de branco | C23: Ficha de cor para até 8 câmeras, com diferença para a luz e para a câmera de referência.
B24: Referência | C24: Largura dos sensores (usada pela calculadora), temperaturas de cor, distâncias focais e modos de foco e de balanço.
B25: Checklist | C25: Os doze itens do treinamento, com percentual atendido.
B26: Exemplo - Enquadramento | C26: As quatro câmeras de uma igreja, antes da mudança de posição (exemplo 1 do treinamento).
B27: Exemplo - Balanço | C27: As quatro câmeras de uma formatura com cores diferentes no corte (exemplo 2 do treinamento).
B29: Regras e premissas do modelo
B30: Conta da lente | C30: Largura da cena = distância × largura do sensor ÷ distância focal. Vale para assunto distante, como em evento. Diferenças de 5 a 10% para o quadro real são normais.
B31: Equivalente full frame | C31: Focal necessária × 36 ÷ largura do sensor. Serve para comparar câmeras de sensores diferentes.
B32: Situação | C32: OK quando a focal necessária está dentro da faixa da lente. Falta tele quando passa do máximo; Falta angular quando fica abaixo do mínimo. Zoom digital não conta.
B33: Faixa em foco | C33: Estimativa usual, com círculo de confusão igual à largura do sensor ÷ 1200. Em tela grande ou em 4K, a faixa nítida é menor. Confira no local.
B34: Balanço de branco | C34: Os cortes de 500 K para a luz e 200 K entre câmeras são regra prática deste material, e podem ser trocados no alto da aba.
B35: Exemplos | C35: Os dados das abas de exemplo são ilustrativos, criados para este material.

Sheet Enquadramento
B1: Enquadramento — que lente usar de onde a câmera está
B2: Preencha as células em amarelo-claro. A planilha calcula a distância focal necessária, a cena obtida e a faixa em foco.
B4: Evento | J4: largura da cena = distância × largura do sensor ÷ distância focal
B5: Local | J5: distância focal necessária = distância × largura do sensor ÷ largura desejada
B6: Data | J6: A faixa em foco é uma estimativa usual (círculo de confusão = largura do sensor ÷ 1200), para assunto distante.
B7: Operador | J7: Sensor que não está na lista: escolha Outro e digite a largura na aba Referência.
B9: Calculadora de enquadramento, uma linha por câmera
B10: # | C10: Câmera e quadro pedido | D10: Sensor | E10: Largura do sensor | F10: Distância | G10: Cena desejada | H10: Lente mín. | I10: Lente máx. | J10: Abertura | K10: Focal necessária | L10: Equivalente full frame | M10: Situação | N10: Focal a usar | O10: Cena obtida | P10: Altura (16:9) | Q10: Distância que fecha a cena | R10: Foco de | S10: Foco até | T10: O que fazer | U10: Observação
B11: nº | C11: posição e o que mostra | D11: lista | E11: mm | F11: m | G11: largura, m | H11: mm | I11: mm | J11: f/ | K11: mm | L11: mm | N11: mm | O11: largura, m | P11: m | Q11: m | R11: m | S11: m
B12: Ex. | C12: Fundo: pastor da cintura para cima | D12: Micro 4/3 | E12: 17.3 | F12: 18 | G12: 1.6 | H12: 14 | I12: 140 | J12: 5.6 | K12: 194.6 | L12: 405 | M12: Falta tele | N12: 140 | O12: 2.22 | P12: 1.25 | Q12: 12.9 | R12: 16.77 | S12: 19.43 | T12: Aproxime a câmera até a distância indicada, use lente mais longa ou aceite a cena obtida
B13: 1 | E13: =IF(D13="","",IFERROR(VLOOKUP(D13,Referência!$B$6:$C$16,2,FALSE()),"")) | K13: =IF(OR(E13="",F13="",G13="",G13=0,E13=0),"",ROUND(F13*E13/G13,1)) | L13: =IF(K13="","",ROUND(K13*36/E13,0)) | M13: =IF(OR(K13="",H13="",I13=""),"",IF(K13>I13,"Falta tele",IF(K13<H13,"Falta angular","OK"))) | N13: =IF(K13="","",IF(OR(H13="",I13=""),K13,MIN(MAX(K13,H13),I13))) | O13: =IF(N13="","",ROUND(F13*E13/N13,2)) | P13: =IF(O13="","",ROUND(O13*9/16,2)) | Q13: =IF(M13="Falta tele",ROUND(I13*G13/E13,1),IF(M13="Falta angular",ROUND(H13*G13/E13,1),"")) | R13: =IF(OR(N13="",J13="",J13=0),"",ROUND((F13*1000)*((N13^2/(J13*E13/1200)+N13)-N13)/((N13^2/(J13*E13/1200)+N13)+(F13*1000)-2*N13)/1000,2)) | S13: =IF(OR(N13="",J13="",J13=0),"",IF((F13*1000)>=(N13^2/(J13*E13/1200)+N13),"infinito",ROUND((F13*1000)*((N13^2/(J13*E13/1200)+N13)-N13)/((N13^2/(J13*E13/1200)+N13)-(F13*1000))/1000,2))) | T13: =IF(M13="","",IF(M13="Falta tele","Aproxime a câmera até a distância indicada, use lente mais longa ou aceite a cena obtida",IF(M13="Falta angular","Afaste a câmera até a distância indicada, use lente mais aberta ou aceite a cena obtida",IF(AND(ISNUMBER(S13),ISNUMBER(R13)),IF(S13-R13<0.5,"A lente alcança. Faixa em foco estreita: feche a íris se a pessoa anda","A lente alcança. Deixe o zoom digital desligado"),"A lente alcança. Deixe o zoom digital desligado"))))
B14: 2 | E14: =IF(D14="","",IFERROR(VLOOKUP(D14,Referência!$B$6:$C$16,2,FALSE()),"")) | K14: =IF(OR(E14="",F14="",G14="",G14=0,E14=0),"",ROUND(F14*E14/G14,1)) | L14: =IF(K14="","",ROUND(K14*36/E14,0)) | M14: =IF(OR(K14="",H14="",I14=""),"",IF(K14>I14,"Falta tele",IF(K14<H14,"Falta angular","OK"))) | N14: =IF(K14="","",IF(OR(H14="",I14=""),K14,MIN(MAX(K14,H14),I14))) | O14: =IF(N14="","",ROUND(F14*E14/N14,2)) | P14: =IF(O14="","",ROUND(O14*9/16,2)) | Q14: =IF(M14="Falta tele",ROUND(I14*G14/E14,1),IF(M14="Falta angular",ROUND(H14*G14/E14,1),"")) | R14: =IF(OR(N14="",J14="",J14=0),"",ROUND((F14*1000)*((N14^2/(J14*E14/1200)+N14)-N14)/((N14^2/(J14*E14/1200)+N14)+(F14*1000)-2*N14)/1000,2)) | S14: =IF(OR(N14="",J14="",J14=0),"",IF((F14*1000)>=(N14^2/(J14*E14/1200)+N14),"infinito",ROUND((F14*1000)*((N14^2/(J14*E14/1200)+N14)-N14)/((N14^2/(J14*E14/1200)+N14)-(F14*1000))/1000,2))) | T14: =IF(M14="","",IF(M14="Falta tele","Aproxime a câmera até a distância indicada, use lente mais longa ou aceite a cena obtida",IF(M14="Falta angular","Afaste a câmera até a distância indicada, use lente mais aberta ou aceite a cena obtida",IF(AND(ISNUMBER(S14),ISNUMBER(R14)),IF(S14-R14<0.5,"A lente alcança. Faixa em foco estreita: feche a íris se a pessoa anda","A lente alcança. Deixe o zoom digital desligado"),"A lente alcança. Deixe o zoom digital desligado"))))
B15: 3 | E15: =IF(D15="","",IFERROR(VLOOKUP(D15,Referência!$B$6:$C$16,2,FALSE()),"")) | K15: =IF(OR(E15="",F15="",G15="",G15=0,E15=0),"",ROUND(F15*E15/G15,1)) | L15: =IF(K15="","",ROUND(K15*36/E15,0)) | M15: =IF(OR(K15="",H15="",I15=""),"",IF(K15>I15,"Falta tele",IF(K15<H15,"Falta angular","OK"))) | N15: =IF(K15="","",IF(OR(H15="",I15=""),K15,MIN(MAX(K15,H15),I15))) | O15: =IF(N15="","",ROUND(F15*E15/N15,2)) | P15: =IF(O15="","",ROUND(O15*9/16,2)) | Q15: =IF(M15="Falta tele",ROUND(I15*G15/E15,1),IF(M15="Falta angular",ROUND(H15*G15/E15,1),"")) | R15: =IF(OR(N15="",J15="",J15=0),"",ROUND((F15*1000)*((N15^2/(J15*E15/1200)+N15)-N15)/((N15^2/(J15*E15/1200)+N15)+(F15*1000)-2*N15)/1000,2)) | S15: =IF(OR(N15="",J15="",J15=0),"",IF((F15*1000)>=(N15^2/(J15*E15/1200)+N15),"infinito",ROUND((F15*1000)*((N15^2/(J15*E15/1200)+N15)-N15)/((N15^2/(J15*E15/1200)+N15)-(F15*1000))/1000,2))) | T15: =IF(M15="","",IF(M15="Falta tele","Aproxime a câmera até a distância indicada, use lente mais longa ou aceite a cena obtida",IF(M15="Falta angular","Afaste a câmera até a distância indicada, use lente mais aberta ou aceite a cena obtida",IF(AND(ISNUMBER(S15),ISNUMBER(R15)),IF(S15-R15<0.5,"A lente alcança. Faixa em foco estreita: feche a íris se a pessoa anda","A lente alcança. Deixe o zoom digital desligado"),"A lente alcança. Deixe o zoom digital desligado"))))
B16: 4 | E16: =IF(D16="","",IFERROR(VLOOKUP(D16,Referência!$B$6:$C$16,2,FALSE()),"")) | K16: =IF(OR(E16="",F16="",G16="",G16=0,E16=0),"",ROUND(F16*E16/G16,1)) | L16: =IF(K16="","",ROUND(K16*36/E16,0)) | M16: =IF(OR(K16="",H16="",I16=""),"",IF(K16>I16,"Falta tele",IF(K16<H16,"Falta angular","OK"))) | N16: =IF(K16="","",IF(OR(H16="",I16=""),K16,MIN(MAX(K16,H16),I16))) | O16: =IF(N16="","",ROUND(F16*E16/N16,2)) | P16: =IF(O16="","",ROUND(O16*9/16,2)) | Q16: =IF(M16="Falta tele",ROUND(I16*G16/E16,1),IF(M16="Falta angular",ROUND(H16*G16/E16,1),"")) | R16: =IF(OR(N16="",J16="",J16=0),"",ROUND((F16*1000)*((N16^2/(J16*E16/1200)+N16)-N16)/((N16^2/(J16*E16/1200)+N16)+(F16*1000)-2*N16)/1000,2)) | S16: =IF(OR(N16="",J16="",J16=0),"",IF((F16*1000)>=(N16^2/(J16*E16/1200)+N16),"infinito",ROUND((F16*1000)*((N16^2/(J16*E16/1200)+N16)-N16)/((N16^2/(J16*E16/1200)+N16)-(F16*1000))/1000,2))) | T16: =IF(M16="","",IF(M16="Falta tele","Aproxime a câmera até a distância indicada, use lente mais longa ou aceite a cena obtida",IF(M16="Falta angular","Afaste a câmera até a distância indicada, use lente mais aberta ou aceite a cena obtida",IF(AND(ISNUMBER(S16),ISNUMBER(R16)),IF(S16-R16<0.5,"A lente alcança. Faixa em foco estreita: feche a íris se a pessoa anda","A lente alcança. Deixe o zoom digital desligado"),"A lente alcança. Deixe o zoom digital desligado"))))
B17: 5 | E17: =IF(D17="","",IFERROR(VLOOKUP(D17,Referência!$B$6:$C$16,2,FALSE()),"")) | K17: =IF(OR(E17="",F17="",G17="",G17=0,E17=0),"",ROUND(F17*E17/G17,1)) | L17: =IF(K17="","",ROUND(K17*36/E17,0)) | M17: =IF(OR(K17="",H17="",I17=""),"",IF(K17>I17,"Falta tele",IF(K17<H17,"Falta angular","OK"))) | N17: =IF(K17="","",IF(OR(H17="",I17=""),K17,MIN(MAX(K17,H17),I17))) | O17: =IF(N17="","",ROUND(F17*E17/N17,2)) | P17: =IF(O17="","",ROUND(O17*9/16,2)) | Q17: =IF(M17="Falta tele",ROUND(I17*G17/E17,1),IF(M17="Falta angular",ROUND(H17*G17/E17,1),"")) | R17: =IF(OR(N17="",J17="",J17=0),"",ROUND((F17*1000)*((N17^2/(J17*E17/1200)+N17)-N17)/((N17^2/(J17*E17/1200)+N17)+(F17*1000)-2*N17)/1000,2)) | S17: =IF(OR(N17="",J17="",J17=0),"",IF((F17*1000)>=(N17^2/(J17*E17/1200)+N17),"infinito",ROUND((F17*1000)*((N17^2/(J17*E17/1200)+N17)-N17)/((N17^2/(J17*E17/1200)+N17)-(F17*1000))/1000,2))) | T17: =IF(M17="","",IF(M17="Falta tele","Aproxime a câmera até a distância indicada, use lente mais longa ou aceite a cena obtida",IF(M17="Falta angular","Afaste a câmera até a distância indicada, use lente mais aberta ou aceite a cena obtida",IF(AND(ISNUMBER(S17),ISNUMBER(R17)),IF(S17-R17<0.5,"A lente alcança. Faixa em foco estreita: feche a íris se a pessoa anda","A lente alcança. Deixe o zoom digital desligado"),"A lente alcança. Deixe o zoom digital desligado"))))
B18: 6 | E18: =IF(D18="","",IFERROR(VLOOKUP(D18,Referência!$B$6:$C$16,2,FALSE()),"")) | K18: =IF(OR(E18="",F18="",G18="",G18=0,E18=0),"",ROUND(F18*E18/G18,1)) | L18: =IF(K18="","",ROUND(K18*36/E18,0)) | M18: =IF(OR(K18="",H18="",I18=""),"",IF(K18>I18,"Falta tele",IF(K18<H18,"Falta angular","OK"))) | N18: =IF(K18="","",IF(OR(H18="",I18=""),K18,MIN(MAX(K18,H18),I18))) | O18: =IF(N18="","",ROUND(F18*E18/N18,2)) | P18: =IF(O18="","",ROUND(O18*9/16,2)) | Q18: =IF(M18="Falta tele",ROUND(I18*G18/E18,1),IF(M18="Falta angular",ROUND(H18*G18/E18,1),"")) | R18: =IF(OR(N18="",J18="",J18=0),"",ROUND((F18*1000)*((N18^2/(J18*E18/1200)+N18)-N18)/((N18^2/(J18*E18/1200)+N18)+(F18*1000)-2*N18)/1000,2)) | S18: =IF(OR(N18="",J18="",J18=0),"",IF((F18*1000)>=(N18^2/(J18*E18/1200)+N18),"infinito",ROUND((F18*1000)*((N18^2/(J18*E18/1200)+N18)-N18)/((N18^2/(J18*E18/1200)+N18)-(F18*1000))/1000,2))) | T18: =IF(M18="","",IF(M18="Falta tele","Aproxime a câmera até a distância indicada, use lente mais longa ou aceite a cena obtida",IF(M18="Falta angular","Afaste a câmera até a distância indicada, use lente mais aberta ou aceite a cena obtida",IF(AND(ISNUMBER(S18),ISNUMBER(R18)),IF(S18-R18<0.5,"A lente alcança. Faixa em foco estreita: feche a íris se a pessoa anda","A lente alcança. Deixe o zoom digital desligado"),"A lente alcança. Deixe o zoom digital desligado"))))
B19: 7 | E19: =IF(D19="","",IFERROR(VLOOKUP(D19,Referência!$B$6:$C$16,2,FALSE()),"")) | K19: =IF(OR(E19="",F19="",G19="",G19=0,E19=0),"",ROUND(F19*E19/G19,1)) | L19: =IF(K19="","",ROUND(K19*36/E19,0)) | M19: =IF(OR(K19="",H19="",I19=""),"",IF(K19>I19,"Falta tele",IF(K19<H19,"Falta angular","OK"))) | N19: =IF(K19="","",IF(OR(H19="",I19=""),K19,MIN(MAX(K19,H19),I19))) | O19: =IF(N19="","",ROUND(F19*E19/N19,2)) | P19: =IF(O19="","",ROUND(O19*9/16,2)) | Q19: =IF(M19="Falta tele",ROUND(I19*G19/E19,1),IF(M19="Falta angular",ROUND(H19*G19/E19,1),"")) | R19: =IF(OR(N19="",J19="",J19=0),"",ROUND((F19*1000)*((N19^2/(J19*E19/1200)+N19)-N19)/((N19^2/(J19*E19/1200)+N19)+(F19*1000)-2*N19)/1000,2)) | S19: =IF(OR(N19="",J19="",J19=0),"",IF((F19*1000)>=(N19^2/(J19*E19/1200)+N19),"infinito",ROUND((F19*1000)*((N19^2/(J19*E19/1200)+N19)-N19)/((N19^2/(J19*E19/1200)+N19)-(F19*1000))/1000,2))) | T19: =IF(M19="","",IF(M19="Falta tele","Aproxime a câmera até a distância indicada, use lente mais longa ou aceite a cena obtida",IF(M19="Falta angular","Afaste a câmera até a distância indicada, use lente mais aberta ou aceite a cena obtida",IF(AND(ISNUMBER(S19),ISNUMBER(R19)),IF(S19-R19<0.5,"A lente alcança. Faixa em foco estreita: feche a íris se a pessoa anda","A lente alcança. Deixe o zoom digital desligado"),"A lente alcança. Deixe o zoom digital desligado"))))
B20: 8 | E20: =IF(D20="","",IFERROR(VLOOKUP(D20,Referência!$B$6:$C$16,2,FALSE()),"")) | K20: =IF(OR(E20="",F20="",G20="",G20=0,E20=0),"",ROUND(F20*E20/G20,1)) | L20: =IF(K20="","",ROUND(K20*36/E20,0)) | M20: =IF(OR(K20="",H20="",I20=""),"",IF(K20>I20,"Falta tele",IF(K20<H20,"Falta angular","OK"))) | N20: =IF(K20="","",IF(OR(H20="",I20=""),K20,MIN(MAX(K20,H20),I20))) | O20: =IF(N20="","",ROUND(F20*E20/N20,2)) | P20: =IF(O20="","",ROUND(O20*9/16,2)) | Q20: =IF(M20="Falta tele",ROUND(I20*G20/E20,1),IF(M20="Falta angular",ROUND(H20*G20/E20,1),"")) | R20: =IF(OR(N20="",J20="",J20=0),"",ROUND((F20*1000)*((N20^2/(J20*E20/1200)+N20)-N20)/((N20^2/(J20*E20/1200)+N20)+(F20*1000)-2*N20)/1000,2)) | S20: =IF(OR(N20="",J20="",J20=0),"",IF((F20*1000)>=(N20^2/(J20*E20/1200)+N20),"infinito",ROUND((F20*1000)*((N20^2/(J20*E20/1200)+N20)-N20)/((N20^2/(J20*E20/1200)+N20)-(F20*1000))/1000,2))) | T20: =IF(M20="","",IF(M20="Falta tele","Aproxime a câmera até a distância indicada, use lente mais longa ou aceite a cena obtida",IF(M20="Falta angular","Afaste a câmera até a distância indicada, use lente mais aberta ou aceite a cena obtida",IF(AND(ISNUMBER(S20),ISNUMBER(R20)),IF(S20-R20<0.5,"A lente alcança. Faixa em foco estreita: feche a íris se a pessoa anda","A lente alcança. Deixe o zoom digital desligado"),"A lente alcança. Deixe o zoom digital desligado"))))
B21: 9 | E21: =IF(D21="","",IFERROR(VLOOKUP(D21,Referência!$B$6:$C$16,2,FALSE()),"")) | K21: =IF(OR(E21="",F21="",G21="",G21=0,E21=0),"",ROUND(F21*E21/G21,1)) | L21: =IF(K21="","",ROUND(K21*36/E21,0)) | M21: =IF(OR(K21="",H21="",I21=""),"",IF(K21>I21,"Falta tele",IF(K21<H21,"Falta angular","OK"))) | N21: =IF(K21="","",IF(OR(H21="",I21=""),K21,MIN(MAX(K21,H21),I21))) | O21: =IF(N21="","",ROUND(F21*E21/N21,2)) | P21: =IF(O21="","",ROUND(O21*9/16,2)) | Q21: =IF(M21="Falta tele",ROUND(I21*G21/E21,1),IF(M21="Falta angular",ROUND(H21*G21/E21,1),"")) | R21: =IF(OR(N21="",J21="",J21=0),"",ROUND((F21*1000)*((N21^2/(J21*E21/1200)+N21)-N21)/((N21^2/(J21*E21/1200)+N21)+(F21*1000)-2*N21)/1000,2)) | S21: =IF(OR(N21="",J21="",J21=0),"",IF((F21*1000)>=(N21^2/(J21*E21/1200)+N21),"infinito",ROUND((F21*1000)*((N21^2/(J21*E21/1200)+N21)-N21)/((N21^2/(J21*E21/1200)+N21)-(F21*1000))/1000,2))) | T21: =IF(M21="","",IF(M21="Falta tele","Aproxime a câmera até a distância indicada, use lente mais longa ou aceite a cena obtida",IF(M21="Falta angular","Afaste a câmera até a distância indicada, use lente mais aberta ou aceite a cena obtida",IF(AND(ISNUMBER(S21),ISNUMBER(R21)),IF(S21-R21<0.5,"A lente alcança. Faixa em foco estreita: feche a íris se a pessoa anda","A lente alcança. Deixe o zoom digital desligado"),"A lente alcança. Deixe o zoom digital desligado"))))
B22: 10 | E22: =IF(D22="","",IFERROR(VLOOKUP(D22,Referência!$B$6:$C$16,2,FALSE()),"")) | K22: =IF(OR(E22="",F22="",G22="",G22=0,E22=0),"",ROUND(F22*E22/G22,1)) | L22: =IF(K22="","",ROUND(K22*36/E22,0)) | M22: =IF(OR(K22="",H22="",I22=""),"",IF(K22>I22,"Falta tele",IF(K22<H22,"Falta angular","OK"))) | N22: =IF(K22="","",IF(OR(H22="",I22=""),K22,MIN(MAX(K22,H22),I22))) | O22: =IF(N22="","",ROUND(F22*E22/N22,2)) | P22: =IF(O22="","",ROUND(O22*9/16,2)) | Q22: =IF(M22="Falta tele",ROUND(I22*G22/E22,1),IF(M22="Falta angular",ROUND(H22*G22/E22,1),"")) | R22: =IF(OR(N22="",J22="",J22=0),"",ROUND((F22*1000)*((N22^2/(J22*E22/1200)+N22)-N22)/((N22^2/(J22*E22/1200)+N22)+(F22*1000)-2*N22)/1000,2)) | S22: =IF(OR(N22="",J22="",J22=0),"",IF((F22*1000)>=(N22^2/(J22*E22/1200)+N22),"infinito",ROUND((F22*1000)*((N22^2/(J22*E22/1200)+N22)-N22)/((N22^2/(J22*E22/1200)+N22)-(F22*1000))/1000,2))) | T22: =IF(M22="","",IF(M22="Falta tele","Aproxime a câmera até a distância indicada, use lente mais longa ou aceite a cena obtida",IF(M22="Falta angular","Afaste a câmera até a distância indicada, use lente mais aberta ou aceite a cena obtida",IF(AND(ISNUMBER(S22),ISNUMBER(R22)),IF(S22-R22<0.5,"A lente alcança. Faixa em foco estreita: feche a íris se a pessoa anda","A lente alcança. Deixe o zoom digital desligado"),"A lente alcança. Deixe o zoom digital desligado"))))
B23: 11 | E23: =IF(D23="","",IFERROR(VLOOKUP(D23,Referência!$B$6:$C$16,2,FALSE()),"")) | K23: =IF(OR(E23="",F23="",G23="",G23=0,E23=0),"",ROUND(F23*E23/G23,1)) | L23: =IF(K23="","",ROUND(K23*36/E23,0)) | M23: =IF(OR(K23="",H23="",I23=""),"",IF(K23>I23,"Falta tele",IF(K23<H23,"Falta angular","OK"))) | N23: =IF(K23="","",IF(OR(H23="",I23=""),K23,MIN(MAX(K23,H23),I23))) | O23: =IF(N23="","",ROUND(F23*E23/N23,2)) | P23: =IF(O23="","",ROUND(O23*9/16,2)) | Q23: =IF(M23="Falta tele",ROUND(I23*G23/E23,1),IF(M23="Falta angular",ROUND(H23*G23/E23,1),"")) | R23: =IF(OR(N23="",J23="",J23=0),"",ROUND((F23*1000)*((N23^2/(J23*E23/1200)+N23)-N23)/((N23^2/(J23*E23/1200)+N23)+(F23*1000)-2*N23)/1000,2)) | S23: =IF(OR(N23="",J23="",J23=0),"",IF((F23*1000)>=(N23^2/(J23*E23/1200)+N23),"infinito",ROUND((F23*1000)*((N23^2/(J23*E23/1200)+N23)-N23)/((N23^2/(J23*E23/1200)+N23)-(F23*1000))/1000,2))) | T23: =IF(M23="","",IF(M23="Falta tele","Aproxime a câmera até a distância indicada, use lente mais longa ou aceite a cena obtida",IF(M23="Falta angular","Afaste a câmera até a distância indicada, use lente mais aberta ou aceite a cena obtida",IF(AND(ISNUMBER(S23),ISNUMBER(R23)),IF(S23-R23<0.5,"A lente alcança. Faixa em foco estreita: feche a íris se a pessoa anda","A lente alcança. Deixe o zoom digital desligado"),"A lente alcança. Deixe o zoom digital desligado"))))
B24: 12 | E24: =IF(D24="","",IFERROR(VLOOKUP(D24,Referência!$B$6:$C$16,2,FALSE()),"")) | K24: =IF(OR(E24="",F24="",G24="",G24=0,E24=0),"",ROUND(F24*E24/G24,1)) | L24: =IF(K24="","",ROUND(K24*36/E24,0)) | M24: =IF(OR(K24="",H24="",I24=""),"",IF(K24>I24,"Falta tele",IF(K24<H24,"Falta angular","OK"))) | N24: =IF(K24="","",IF(OR(H24="",I24=""),K24,MIN(MAX(K24,H24),I24))) | O24: =IF(N24="","",ROUND(F24*E24/N24,2)) | P24: =IF(O24="","",ROUND(O24*9/16,2)) | Q24: =IF(M24="Falta tele",ROUND(I24*G24/E24,1),IF(M24="Falta angular",ROUND(H24*G24/E24,1),"")) | R24: =IF(OR(N24="",J24="",J24=0),"",ROUND((F24*1000)*((N24^2/(J24*E24/1200)+N24)-N24)/((N24^2/(J24*E24/1200)+N24)+(F24*1000)-2*N24)/1000,2)) | S24: =IF(OR(N24="",J24="",J24=0),"",IF((F24*1000)>=(N24^2/(J24*E24/1200)+N24),"infinito",ROUND((F24*1000)*((N24^2/(J24*E24/1200)+N24)-N24)/((N24^2/(J24*E24/1200)+N24)-(F24*1000))/1000,2))) | T24: =IF(M24="","",IF(M24="Falta tele","Aproxime a câmera até a distância indicada, use lente mais longa ou aceite a cena obtida",IF(M24="Falta angular","Afaste a câmera até a distância indicada, use lente mais aberta ou aceite a cena obtida",IF(AND(ISNUMBER(S24),ISNUMBER(R24)),IF(S24-R24<0.5,"A lente alcança. Faixa em foco estreita: feche a íris se a pessoa anda","A lente alcança. Deixe o zoom digital desligado"),"A lente alcança. Deixe o zoom digital desligado"))))
B26: Resumo automático
B27: Câmeras registradas | F27: =COUNTA(C13:C24) -> 0
B28: Lente alcança (OK) | F28: =COUNTIF(M13:M24,"OK") -> 0
B29: Falta tele | F29: =COUNTIF(M13:M24,"Falta tele") -> 0
B30: Falta angular | F30: =COUNTIF(M13:M24,"Falta angular") -> 0
B31: Aviso | F31: =IF(F27=0,"Liste as câmeras",IF(COUNTIF(M13:M24,"OK")+COUNTIF(M13:M24,"Falta tele")+COUNTIF(M13:M24,"Falta angular")<F27,"Há câmera sem sensor, distância, cena ou lente",IF(F29+F30>0,"Há quadro que a lente não alcança: decida antes de montar","OK"))) -> Liste as câmeras

Sheet Balanço de branco
B1: Balanço de branco — ficha de cor por câmera
B2: Depois do balanço com cartão, anote o que cada câmera mostra. As células cinza conferem e apontam o que fazer.
B4: Evento | G4: Luz principal (K) | J4: 3200 | K4: Temperatura de cor da luz que ilumina o rosto. Veja a aba Referência.
B5: Local | G5: Câmera de referência (nº) | J5: 1 | K5: A câmera principal. As outras são comparadas com ela.
B6: Data | G6: Tolerância para a luz (K) | J6: 500 | K6: Diferença aceita entre o kelvin da câmera e a luz principal.
B7: Operador | G7: Tolerância entre câmeras (K) | J7: 200 | K7: Diferença aceita entre cada câmera e a de referência.
G8: O kelvin que a câmera mostra depois do balanço é uma leitura dela. O que decide é a comparação no mesmo monitor.
B9: Kelvin da referência | E9: =IF(OR($J$5="",$J$5<1,$J$5>8),"",IF(INDEX(F14:F21,$J$5)="","",INDEX(F14:F21,$J$5)))
B10: Perfil da referência | E10: =IF(OR($J$5="",$J$5<1,$J$5>8),"",IF(INDEX(H14:H21,$J$5)="","",INDEX(H14:H21,$J$5)))
B11: Ficha de cor, uma linha por câmera
B12: # | C12: Câmera e posição | D12: Tipo de câmera | E12: Modo | F12: Kelvin | G12: Tint | H12: Perfil | I12: Comparada no monitor | J12: Diferença para a luz | K12: Diferença para a ref. | L12: Situação | M12: O que fazer | N12: Observação
B13: nº | E13: lista | F13: K | G13: passos | H13: lista | I13: Sim / Não | J13: K | K13: K
B14: 1 | J14: =IF(OR(F14="",$J$4=""),"",F14-$J$4) | K14: =IF(OR(F14="",$E$9="",$J$5=1),"",F14-$E$9) | L14: =IF(AND(C14="",E14=""),"",IF(E14="Automático","Automático",IF(F14="","Sem kelvin",IF(H14="Log","Perfil log",IF(AND($E$10<>"",H14<>"",H14<>$E$10),"Perfil diferente",IF(IF(J14="",FALSE(),ABS(J14)>$J$6),"Longe da luz",IF(IF(K14="",FALSE(),ABS(K14)>$J$7),"Diferente da referência",IF(I14<>"Sim","Conferir no monitor","OK")))))))) | M14: =IF(L14="","",IF(L14="Automático","Passe para manual e faça o balanço com o cartão branco",IF(L14="Sem kelvin","Anote o kelvin que a câmera mostra",IF(L14="Perfil log","Ponha o perfil padrão, ou aplique a correção na mesa de corte",IF(L14="Perfil diferente","Ponha o mesmo perfil da câmera de referência e refaça o balanço",IF(L14="Longe da luz","Confira o modo e refaça o balanço com o cartão sob a luz do evento",IF(L14="Diferente da referência","Compare no monitor e ajuste alguns passos no kelvin ou no tint",IF(L14="Conferir no monitor","Compare lado a lado com a câmera de referência","Manter"))))))))
B15: 2 | J15: =IF(OR(F15="",$J$4=""),"",F15-$J$4) | K15: =IF(OR(F15="",$E$9="",$J$5=2),"",F15-$E$9) | L15: =IF(AND(C15="",E15=""),"",IF(E15="Automático","Automático",IF(F15="","Sem kelvin",IF(H15="Log","Perfil log",IF(AND($E$10<>"",H15<>"",H15<>$E$10),"Perfil diferente",IF(IF(J15="",FALSE(),ABS(J15)>$J$6),"Longe da luz",IF(IF(K15="",FALSE(),ABS(K15)>$J$7),"Diferente da referência",IF(I15<>"Sim","Conferir no monitor","OK")))))))) | M15: =IF(L15="","",IF(L15="Automático","Passe para manual e faça o balanço com o cartão branco",IF(L15="Sem kelvin","Anote o kelvin que a câmera mostra",IF(L15="Perfil log","Ponha o perfil padrão, ou aplique a correção na mesa de corte",IF(L15="Perfil diferente","Ponha o mesmo perfil da câmera de referência e refaça o balanço",IF(L15="Longe da luz","Confira o modo e refaça o balanço com o cartão sob a luz do evento",IF(L15="Diferente da referência","Compare no monitor e ajuste alguns passos no kelvin ou no tint",IF(L15="Conferir no monitor","Compare lado a lado com a câmera de referência","Manter"))))))))
B16: 3 | J16: =IF(OR(F16="",$J$4=""),"",F16-$J$4) | K16: =IF(OR(F16="",$E$9="",$J$5=3),"",F16-$E$9) | L16: =IF(AND(C16="",E16=""),"",IF(E16="Automático","Automático",IF(F16="","Sem kelvin",IF(H16="Log","Perfil log",IF(AND($E$10<>"",H16<>"",H16<>$E$10),"Perfil diferente",IF(IF(J16="",FALSE(),ABS(J16)>$J$6),"Longe da luz",IF(IF(K16="",FALSE(),ABS(K16)>$J$7),"Diferente da referência",IF(I16<>"Sim","Conferir no monitor","OK")))))))) | M16: =IF(L16="","",IF(L16="Automático","Passe para manual e faça o balanço com o cartão branco",IF(L16="Sem kelvin","Anote o kelvin que a câmera mostra",IF(L16="Perfil log","Ponha o perfil padrão, ou aplique a correção na mesa de corte",IF(L16="Perfil diferente","Ponha o mesmo perfil da câmera de referência e refaça o balanço",IF(L16="Longe da luz","Confira o modo e refaça o balanço com o cartão sob a luz do evento",IF(L16="Diferente da referência","Compare no monitor e ajuste alguns passos no kelvin ou no tint",IF(L16="Conferir no monitor","Compare lado a lado com a câmera de referência","Manter"))))))))
B17: 4 | J17: =IF(OR(F17="",$J$4=""),"",F17-$J$4) | K17: =IF(OR(F17="",$E$9="",$J$5=4),"",F17-$E$9) | L17: =IF(AND(C17="",E17=""),"",IF(E17="Automático","Automático",IF(F17="","Sem kelvin",IF(H17="Log","Perfil log",IF(AND($E$10<>"",H17<>"",H17<>$E$10),"Perfil diferente",IF(IF(J17="",FALSE(),ABS(J17)>$J$6),"Longe da luz",IF(IF(K17="",FALSE(),ABS(K17)>$J$7),"Diferente da referência",IF(I17<>"Sim","Conferir no monitor","OK")))))))) | M17: =IF(L17="","",IF(L17="Automático","Passe para manual e faça o balanço com o cartão branco",IF(L17="Sem kelvin","Anote o kelvin que a câmera mostra",IF(L17="Perfil log","Ponha o perfil padrão, ou aplique a correção na mesa de corte",IF(L17="Perfil diferente","Ponha o mesmo perfil da câmera de referência e refaça o balanço",IF(L17="Longe da luz","Confira o modo e refaça o balanço com o cartão sob a luz do evento",IF(L17="Diferente da referência","Compare no monitor e ajuste alguns passos no kelvin ou no tint",IF(L17="Conferir no monitor","Compare lado a lado com a câmera de referência","Manter"))))))))
B18: 5 | J18: =IF(OR(F18="",$J$4=""),"",F18-$J$4) | K18: =IF(OR(F18="",$E$9="",$J$5=5),"",F18-$E$9) | L18: =IF(AND(C18="",E18=""),"",IF(E18="Automático","Automático",IF(F18="","Sem kelvin",IF(H18="Log","Perfil log",IF(AND($E$10<>"",H18<>"",H18<>$E$10),"Perfil diferente",IF(IF(J18="",FALSE(),ABS(J18)>$J$6),"Longe da luz",IF(IF(K18="",FALSE(),ABS(K18)>$J$7),"Diferente da referência",IF(I18<>"Sim","Conferir no monitor","OK")))))))) | M18: =IF(L18="","",IF(L18="Automático","Passe para manual e faça o balanço com o cartão branco",IF(L18="Sem kelvin","Anote o kelvin que a câmera mostra",IF(L18="Perfil log","Ponha o perfil padrão, ou aplique a correção na mesa de corte",IF(L18="Perfil diferente","Ponha o mesmo perfil da câmera de referência e refaça o balanço",IF(L18="Longe da luz","Confira o modo e refaça o balanço com o cartão sob a luz do evento",IF(L18="Diferente da referência","Compare no monitor e ajuste alguns passos no kelvin ou no tint",IF(L18="Conferir no monitor","Compare lado a lado com a câmera de referência","Manter"))))))))
B19: 6 | J19: =IF(OR(F19="",$J$4=""),"",F19-$J$4) | K19: =IF(OR(F19="",$E$9="",$J$5=6),"",F19-$E$9) | L19: =IF(AND(C19="",E19=""),"",IF(E19="Automático","Automático",IF(F19="","Sem kelvin",IF(H19="Log","Perfil log",IF(AND($E$10<>"",H19<>"",H19<>$E$10),"Perfil diferente",IF(IF(J19="",FALSE(),ABS(J19)>$J$6),"Longe da luz",IF(IF(K19="",FALSE(),ABS(K19)>$J$7),"Diferente da referência",IF(I19<>"Sim","Conferir no monitor","OK")))))))) | M19: =IF(L19="","",IF(L19="Automático","Passe para manual e faça o balanço com o cartão branco",IF(L19="Sem kelvin","Anote o kelvin que a câmera mostra",IF(L19="Perfil log","Ponha o perfil padrão, ou aplique a correção na mesa de corte",IF(L19="Perfil diferente","Ponha o mesmo perfil da câmera de referência e refaça o balanço",IF(L19="Longe da luz","Confira o modo e refaça o balanço com o cartão sob a luz do evento",IF(L19="Diferente da referência","Compare no monitor e ajuste alguns passos no kelvin ou no tint",IF(L19="Conferir no monitor","Compare lado a lado com a câmera de referência","Manter"))))))))
B20: 7 | J20: =IF(OR(F20="",$J$4=""),"",F20-$J$4) | K20: =IF(OR(F20="",$E$9="",$J$5=7),"",F20-$E$9) | L20: =IF(AND(C20="",E20=""),"",IF(E20="Automático","Automático",IF(F20="","Sem kelvin",IF(H20="Log","Perfil log",IF(AND($E$10<>"",H20<>"",H20<>$E$10),"Perfil diferente",IF(IF(J20="",FALSE(),ABS(J20)>$J$6),"Longe da luz",IF(IF(K20="",FALSE(),ABS(K20)>$J$7),"Diferente da referência",IF(I20<>"Sim","Conferir no monitor","OK")))))))) | M20: =IF(L20="","",IF(L20="Automático","Passe para manual e faça o balanço com o cartão branco",IF(L20="Sem kelvin","Anote o kelvin que a câmera mostra",IF(L20="Perfil log","Ponha o perfil padrão, ou aplique a correção na mesa de corte",IF(L20="Perfil diferente","Ponha o mesmo perfil da câmera de referência e refaça o balanço",IF(L20="Longe da luz","Confira o modo e refaça o balanço com o cartão sob a luz do evento",IF(L20="Diferente da referência","Compare no monitor e ajuste alguns passos no kelvin ou no tint",IF(L20="Conferir no monitor","Compare lado a lado com a câmera de referência","Manter"))))))))
B21: 8 | J21: =IF(OR(F21="",$J$4=""),"",F21-$J$4) | K21: =IF(OR(F21="",$E$9="",$J$5=8),"",F21-$E$9) | L21: =IF(AND(C21="",E21=""),"",IF(E21="Automático","Automático",IF(F21="","Sem kelvin",IF(H21="Log","Perfil log",IF(AND($E$10<>"",H21<>"",H21<>$E$10),"Perfil diferente",IF(IF(J21="",FALSE(),ABS(J21)>$J$6),"Longe da luz",IF(IF(K21="",FALSE(),ABS(K21)>$J$7),"Diferente da referência",IF(I21<>"Sim","Conferir no monitor","OK")))))))) | M21: =IF(L21="","",IF(L21="Automático","Passe para manual e faça o balanço com o cartão branco",IF(L21="Sem kelvin","Anote o kelvin que a câmera mostra",IF(L21="Perfil log","Ponha o perfil padrão, ou aplique a correção na mesa de corte",IF(L21="Perfil diferente","Ponha o mesmo perfil da câmera de referência e refaça o balanço",IF(L21="Longe da luz","Confira o modo e refaça o balanço com o cartão sob a luz do evento",IF(L21="Diferente da referência","Compare no monitor e ajuste alguns passos no kelvin ou no tint",IF(L21="Conferir no monitor","Compare lado a lado com a câmera de referência","Manter"))))))))
B23: Resumo automático
B24: Câmeras registradas | F24: =COUNTA(C14:C21) -> 0
B25: Na situação OK | F25: =COUNTIF(L14:L21,"OK") -> 0
B26: Em automático ou em log | F26: =COUNTIF(L14:L21,"Automático")+COUNTIF(L14:L21,"Perfil log") -> 0
B27: Maior diferença entre câmeras (K) | F27: =IF(COUNT(F14:F21)<2,"",MAX(F14:F21)-MIN(F14:F21))
B28: Aviso | F28: =IF(F24=0,"Liste as câmeras",IF($J$4="","Informe a luz principal",IF(F26>0,"Há câmera em automático ou em log: corrija antes do evento",IF(F25<F24,"Há câmera a ajustar ou a conferir","OK")))) -> Liste as câmeras

Sheet Referência
B1: Referência — valores típicos
B2: Valores de referência, para servir de ponto de partida. Confira o manual do seu equipamento.
B4: Sensores (a calculadora de enquadramento usa esta tabela)
B5: Sensor | C5: Largura (mm) | D5: Altura (mm) | E5: Fator de corte (pela largura) | F5: Onde costuma aparecer
B6: Full frame | C6: 36 | D6: 24 | E6: =IF(C6="","",ROUND(36/C6,1)) -> 1 | F6: Câmeras fotográficas e de cinema de sensor grande
B7: Super 35 | C7: 24 | D7: 13.5 | E7: =IF(C7="","",ROUND(36/C7,1)) -> 1.5 | F7: Câmeras de cinema digital (varia de 22 a 25 mm)
B8: APS-C (fator 1,5) | C8: 23.5 | D8: 15.6 | E8: =IF(C8="","",ROUND(36/C8,1)) -> 1.5 | F8: Câmeras fotográficas intermediárias
B9: APS-C (fator 1,6) | C9: 22.3 | D9: 14.9 | E9: =IF(C9="","",ROUND(36/C9,1)) -> 1.6 | F9: Câmeras fotográficas intermediárias de alguns fabricantes
B10: Micro 4/3 | C10: 17.3 | D10: 13 | E10: =IF(C10="","",ROUND(36/C10,1)) -> 2.1 | F10: Câmeras compactas de lente intercambiável
B11: 1 polegada | C11: 13.2 | D11: 8.8 | E11: =IF(C11="","",ROUND(36/C11,1)) -> 2.7 | F11: Filmadoras de mão e PTZ de linha mais alta
B12: 2/3 polegada | C12: 9.6 | D12: 5.4 | E12: =IF(C12="","",ROUND(36/C12,1)) -> 3.8 | F12: Câmeras de estúdio e de ombro de emissoras
B13: 1/2,3 polegada | C13: 6.2 | D13: 4.6 | E13: =IF(C13="","",ROUND(36/C13,1)) -> 5.8 | F13: Filmadoras compactas e algumas PTZ
B14: 1/2,8 polegada | C14: 5.6 | D14: 3.2 | E14: =IF(C14="","",ROUND(36/C14,1)) -> 6.4 | F14: A maioria das câmeras PTZ
B15: 1/3 polegada | C15: 4.8 | D15: 3.6 | E15: =IF(C15="","",ROUND(36/C15,1)) -> 7.5 | F15: PTZ simples e webcams
B16: Outro | E16: =IF(C16="","",ROUND(36/C16,1)) | F16: Digite a largura do sensor da sua câmera (ficha técnica, em mm)
B17: Medidas nominais. O fator publicado costuma ser calculado pela diagonal e pode diferir alguns por cento deste, pela largura, que é o que vale para o enquadramento. Algumas câmeras usam só parte do sensor em certos modos (4K, câmera lenta, estabilização eletrônica): o manual informa o recorte.
B19: Temperatura de cor das fontes
B20: Fonte | C20: Temperatura de cor | E20: Preset mais próximo | F20: Observação
B21: Vela | C21: cerca de 1.900 K | E21: – | F21: Muito alaranjada. Nenhum preset chega lá.
B22: Lâmpada incandescente, LED branco quente | C22: 2.700 a 3.000 K | E22: Tungstênio | F22: O valor do LED vem na embalagem.
B23: Halógena, refletor de tungstênio | C23: 3.000 a 3.200 K | E23: Tungstênio | F23: Fica mais alaranjada com o dimmer abaixo do máximo.
B24: LED branco neutro, fluorescente comum | C24: 4.000 a 4.500 K | E24: – | F24: Fluorescente e LED barato costumam puxar para o verde: use cartão branco ou tint.
B25: Sol direto, flash | C25: 5.000 a 5.600 K | E25: Luz do dia | F25: O sol fica mais quente no começo e no fim do dia.
B26: LED luz do dia, branco frio | C26: 5.600 a 6.500 K | E26: Luz do dia | F26: Refletores de LED de palco costumam ter a temperatura ajustável.
B27: Céu nublado | C27: 6.000 a 7.500 K | E27: Nublado | F27: Varia com a nuvem e a hora.
B28: Telão de LED, monitor, projetor | C28: 6.500 a 9.000 K | E28: – | F28: Com a câmera em 3.200 K, sai azulado. Corrija no telão, se possível.
B29: Sombra sob céu azul | C29: 7.500 a 10.000 K | E29: Sombra | F29: Muito azulada.
B31: Distância focal e ângulo de visão (equivalente a full frame)
B32: Focal equivalente | C32: Ângulo horizontal | E32: Cena a 10 m | F32: Nome usual e uso
B33: 16 mm | C33: 97° | E33: 22,5 m | F33: Grande-angular extrema. Câmera muito perto do palco; distorce as bordas.
B34: 24 mm | C34: 74° | E34: 15 m | F34: Grande-angular. Plano geral do palco e da plateia.
B35: 35 mm | C35: 54° | E35: 10,3 m | F35: Grande-angular moderada. Palco pequeno, banda inteira.
B36: 50 mm | C36: 40° | E36: 7,2 m | F36: Normal. Grupo de pessoas.
B37: 85 mm | C37: 24° | E37: 4,2 m | F37: Teleobjetiva curta. Pessoa de corpo inteiro a 10 m.
B38: 135 mm | C38: 15° | E38: 2,7 m | F38: Teleobjetiva. Pessoa dos joelhos para cima a 10 m.
B39: 200 mm | C39: 10° | E39: 1,8 m | F39: Teleobjetiva. Pessoa da cintura para cima a 10 m.
B40: 400 mm | C40: 5° | E40: 0,9 m | F40: Teleobjetiva longa. Cintura para cima a 20 m; pede tripé firme.
B42: Modo de foco por situação
B43: Situação | C43: Modo indicado | E43: Abertura | F43: Por quê
B44: Pessoa parada no púlpito, tripé | C44: Manual | E44: a da exposição | F44: A distância não muda. Foque com o zoom fechado no rosto.
...

Sheet Checklist
B1: Checklist de lente, foco e cor
B2: Confira antes de o evento começar, com a luz do evento ligada. Escolha a situação de cada item na lista suspensa.
B4: # | C4: Grupo | D4: Item | E4: Situação | F4: Observação
B5: 1 | C5: Lente | D5: A distância de cada câmera até o assunto foi medida, e a distância focal necessária cabe na lente.
B6: 2 | C6: Lente | D6: O zoom digital está desligado em todas as câmeras, ou limitado à faixa sem perda.
B7: 3 | C7: Lente | D7: As lentes estão limpas e com para-sol, e a estabilização está de acordo com o suporte (mão ou tripé).
B8: 4 | C8: Lente | D8: A abertura escolhida vale para toda a faixa de zoom: a imagem não escurece ao fechar o quadro.
B9: 5 | C9: Foco | D9: O modo de foco de cada câmera foi escolhido: manual para quadro fixo, automático com detecção de rosto para quem anda.
B10: 6 | C10: Foco | D10: O foco manual foi feito com o zoom fechado no rosto, com peaking ou ampliação.
B11: 7 | C11: Foco | D11: A faixa em foco cobre o espaço em que a pessoa se move.
B12: 8 | C12: Foco | D12: O foco automático foi testado com a luz do evento e com o fundo real (telão ligado).
B13: 9 | C13: Cor | D13: Nenhuma câmera está com o balanço de branco em automático.
B14: 10 | C14: Cor | D14: O balanço foi feito com cartão branco no lugar do rosto, sob a luz do evento, com as cortinas fechadas.
B15: 11 | C15: Cor | D15: Todas as câmeras usam o mesmo perfil de imagem, e nenhuma está em perfil log sem correção.
B16: 12 | C16: Cor | D16: As câmeras foram comparadas lado a lado no mesmo monitor, e os valores de cada uma estão anotados.
B18: Itens respondidos | E18: =COUNTA(E5:E16) -> 0
B19: Percentual atendido (Parcial vale metade) | E19: =IF(COUNTA(E5:E16)=0,"",(COUNTIF(E5:E16,"Sim")+COUNTIF(E5:E16,"Parcial")/2)/COUNTA(E5:E16))
B20: Situação | E20: =IF(COUNTA(E5:E16)<12,"Incompleto",IF(COUNTIF(E5:E16,"Não")=0,"OK","Há itens a resolver")) -> Incompleto

Sheet Exemplo - Enquadramento
B1: Enquadramento — que lente usar de onde a câmera está
B2: Exemplo preenchido, para consulta. Use a aba Enquadramento para o seu evento.
B4: Evento | D4: Culto de domingo, 19 h | J4: largura da cena = distância × largura do sensor ÷ distância focal
B5: Local | D5: Igreja de 200 lugares | J5: distância focal necessária = distância × largura do sensor ÷ largura desejada
B6: Data | D6: 46299 | J6: A faixa em foco é uma estimativa usual (círculo de confusão = largura do sensor ÷ 1200), para assunto distante.
B7: Operador | D7: Equipe de vídeo da escala | J7: Sensor que não está na lista: escolha Outro e digite a largura na aba Referência.
B9: Calculadora de enquadramento, uma linha por câmera
B10: # | C10: Câmera e quadro pedido | D10: Sensor | E10: Largura do sensor | F10: Distância | G10: Cena desejada | H10: Lente mín. | I10: Lente máx. | J10: Abertura | K10: Focal necessária | L10: Equivalente full frame | M10: Situação | N10: Focal a usar | O10: Cena obtida | P10: Altura (16:9) | Q10: Distância que fecha a cena | R10: Foco de | S10: Foco até | T10: O que fazer | U10: Observação
B11: nº | C11: posição e o que mostra | D11: lista | E11: mm | F11: m | G11: largura, m | H11: mm | I11: mm | J11: f/ | K11: mm | L11: mm | N11: mm | O11: largura, m | P11: m | Q11: m | R11: m | S11: m
B12: As quatro câmeras do exemplo 1, antes da mudança de posição. As colunas cinza são calculadas.
B13: 1 | C13: Fundo, centro: pastor da cintura para cima | D13: Micro 4/3 | E13: =IF(D13="","",IFERROR(VLOOKUP(D13,Referência!$B$6:$C$16,2,FALSE()),"")) -> 17.3 | F13: 18 | G13: 1.6 | H13: 14 | I13: 140 | J13: 5.6 | K13: =IF(OR(E13="",F13="",G13="",G13=0,E13=0),"",ROUND(F13*E13/G13,1)) -> 194.6 | L13: =IF(K13="","",ROUND(K13*36/E13,0)) -> 405 | M13: =IF(OR(K13="",H13="",I13=""),"",IF(K13>I13,"Falta tele",IF(K13<H13,"Falta angular","OK"))) -> Falta tele | N13: =IF(K13="","",IF(OR(H13="",I13=""),K13,MIN(MAX(K13,H13),I13))) -> 140 | O13: =IF(N13="","",ROUND(F13*E13/N13,2)) -> 2.22 | P13: =IF(O13="","",ROUND(O13*9/16,2)) -> 1.25 | Q13: =IF(M13="Falta tele",ROUND(I13*G13/E13,1),IF(M13="Falta angular",ROUND(H13*G13/E13,1),"")) -> 12.9 | R13: =IF(OR(N13="",J13="",J13=0),"",ROUND((F13*1000)*((N13^2/(J13*E13/1200)+N13)-N13)/((N13^2/(J13*E13/1200)+N13)+(F13*1000)-2*N13)/1000,2)) -> 16.77 | S13: =IF(OR(N13="",J13="",J13=0),"",IF((F13*1000)>=(N13^2/(J13*E13/1200)+N13),"infinito",ROUND((F13*1000)*((N13^2/(J13*E13/1200)+N13)-N13)/((N13^2/(J13*E13/1200)+N13)-(F13*1000))/1000,2))) -> 19.43 | T13: =IF(M13="","",IF(M13="Falta tele","Aproxime a câmera até a distância indicada, use lente mais longa ou aceite a cena obtida",IF(M13="Falta angular","Afaste a câmera até a distância indicada, use lente mais aberta ou aceite a cena obtida",IF(AND(ISNUMBER(S13),ISNUMBER(R13)),IF(S13-R13<0.5,"A lente alcança. Faixa em foco estreita: feche a íris se a pessoa anda","A lente alcança. Deixe o zoom digital desligado"),"A lente alcança. Deixe o zoom digital desligado")))) -> Aproxime a câmera até a distância indicada, use lente mais longa ou aceite a cena obtida
B14: 2 | C14: PTZ no fundo: palco inteiro | D14: 1/2,8 polegada | E14: =IF(D14="","",IFERROR(VLOOKUP(D14,Referência!$B$6:$C$16,2,FALSE()),"")) -> 5.6 | F14: 18 | G14: 10 | H14: 4.3 | I14: 129 | J14: 2.8 | K14: =IF(OR(E14="",F14="",G14="",G14=0,E14=0),"",ROUND(F14*E14/G14,1)) -> 10.1 | L14: =IF(K14="","",ROUND(K14*36/E14,0)) -> 65 | M14: =IF(OR(K14="",H14="",I14=""),"",IF(K14>I14,"Falta tele",IF(K14<H14,"Falta angular","OK"))) -> OK | N14: =IF(K14="","",IF(OR(H14="",I14=""),K14,MIN(MAX(K14,H14),I14))) -> 10.1 | O14: =IF(N14="","",ROUND(F14*E14/N14,2)) -> 9.98 | P14: =IF(O14="","",ROUND(O14*9/16,2)) -> 5.61 | Q14: =IF(M14="Falta tele",ROUND(I14*G14/E14,1),IF(M14="Falta angular",ROUND(H14*G14/E14,1),"")) | R14: =IF(OR(N14="",J14="",J14=0),"",ROUND((F14*1000)*((N14^2/(J14*E14/1200)+N14)-N14)/((N14^2/(J14*E14/1200)+N14)+(F14*1000)-2*N14)/1000,2)) -> 5.45 | S14: =IF(OR(N14="",J14="",J14=0),"",IF((F14*1000)>=(N14^2/(J14*E14/1200)+N14),"infinito",ROUND((F14*1000)*((N14^2/(J14*E14/1200)+N14)-N14)/((N14^2/(J14*E14/1200)+N14)-(F14*1000))/1000,2))) -> infinito | T14: =IF(M14="","",IF(M14="Falta tele","Aproxime a câmera até a distância indicada, use lente mais longa ou aceite a cena obtida",IF(M14="Falta angular","Afaste a câmera até a distância indicada, use lente mais aberta ou aceite a cena obtida",IF(AND(ISNUMBER(S14),ISNUMBER(R14)),IF(S14-R14<0.5,"A lente alcança. Faixa em foco estreita: feche a íris se a pessoa anda","A lente alcança. Deixe o zoom digital desligado"),"A lente alcança. Deixe o zoom digital desligado")))) -> A lente alcança. Deixe o zoom digital desligado
B15: 3 | C15: Lateral: close da cantora | D15: APS-C (fator 1,5) | E15: =IF(D15="","",IFERROR(VLOOKUP(D15,Referência!$B$6:$C$16,2,FALSE()),"")) -> 23.5 | F15: 6 | G15: 1 | H15: 18 | I15: 55 | J15: 5.6 | K15: =IF(OR(E15="",F15="",G15="",G15=0,E15=0),"",ROUND(F15*E15/G15,1)) -> 141 | L15: =IF(K15="","",ROUND(K15*36/E15,0)) -> 216 | M15: =IF(OR(K15="",H15="",I15=""),"",IF(K15>I15,"Falta tele",IF(K15<H15,"Falta angular","OK"))) -> Falta tele | N15: =IF(K15="","",IF(OR(H15="",I15=""),K15,MIN(MAX(K15,H15),I15))) -> 55 | O15: =IF(N15="","",ROUND(F15*E15/N15,2)) -> 2.56 | P15: =IF(O15="","",ROUND(O15*9/16,2)) -> 1.44 | Q15: =IF(M15="Falta tele",ROUND(I15*G15/E15,1),IF(M15="Falta angular",ROUND(H15*G15/E15,1),"")) -> 2.3 | R15: =IF(OR(N15="",J15="",J15=0),"",ROUND((F15*1000)*((N15^2/(J15*E15/1200)+N15)-N15)/((N15^2/(J15*E15/1200)+N15)+(F15*1000)-2*N15)/1000,2)) -> 4.94 | S15: =IF(OR(N15="",J15="",J15=0),"",IF((F15*1000)>=(N15^2/(J15*E15/1200)+N15),"infinito",ROUND((F15*1000)*((N15^2/(J15*E15/1200)+N15)-N15)/((N15^2/(J15*E15/1200)+N15)-(F15*1000))/1000,2))) -> 7.65 | T15: =IF(M15="","",IF(M15="Falta tele","Aproxime a câmera até a distância indicada, use lente mais longa ou aceite a cena obtida",IF(M15="Falta angular","Afaste a câmera até a distância indicada, use lente mais aberta ou aceite a cena obtida",IF(AND(ISNUMBER(S15),ISNUMBER(R15)),IF(S15-R15<0.5,"A lente alcança. Faixa em foco estreita: feche a íris se a pessoa anda","A lente alcança. Deixe o zoom digital desligado"),"A lente alcança. Deixe o zoom digital desligado")))) -> Aproxime a câmera até a distância indicada, use lente mais longa ou aceite a cena obtida
B16: 4 | C16: Frente do palco: banda inteira | D16: Full frame | E16: =IF(D16="","",IFERROR(VLOOKUP(D16,Referência!$B$6:$C$16,2,FALSE()),"")) -> 36 | F16: 3 | G16: 8 | H16: 24 | I16: 70 | J16: 4 | K16: =IF(OR(E16="",F16="",G16="",G16=0,E16=0),"",ROUND(F16*E16/G16,1)) -> 13.5 | L16: =IF(K16="","",ROUND(K16*36/E16,0)) -> 14 | M16: =IF(OR(K16="",H16="",I16=""),"",IF(K16>I16,"Falta tele",IF(K16<H16,"Falta angular","OK"))) -> Falta angular | N16: =IF(K16="","",IF(OR(H16="",I16=""),K16,MIN(MAX(K16,H16),I16))) -> 24 | O16: =IF(N16="","",ROUND(F16*E16/N16,2)) -> 4.5 | P16: =IF(O16="","",ROUND(O16*9/16,2)) -> 2.53 | Q16: =IF(M16="Falta tele",ROUND(I16*G16/E16,1),IF(M16="Falta angular",ROUND(H16*G16/E16,1),"")) -> 5.3 | R16: =IF(OR(N16="",J16="",J16=0),"",ROUND((F16*1000)*((N16^2/(J16*E16/1200)+N16)-N16)/((N16^2/(J16*E16/1200)+N16)+(F16*1000)-2*N16)/1000,2)) -> 1.85 | S16: =IF(OR(N16="",J16="",J16=0),"",IF((F16*1000)>=(N16^2/(J16*E16/1200)+N16),"infinito",ROUND((F16*1000)*((N16^2/(J16*E16/1200)+N16)-N16)/((N16^2/(J16*E16/1200)+N16)-(F16*1000))/1000,2))) -> 7.89 | T16: =IF(M16="","",IF(M16="Falta tele","Aproxime a câmera até a distância indicada, use lente mais longa ou aceite a cena obtida",IF(M16="Falta angular","Afaste a câmera até a distância indicada, use lente mais aberta ou aceite a cena obtida",IF(AND(ISNUMBER(S16),ISNUMBER(R16)),IF(S16-R16<0.5,"A lente alcança. Faixa em foco estreita: feche a íris se a pessoa anda","A lente alcança. Deixe o zoom digital desligado"),"A lente alcança. Deixe o zoom digital desligado")))) -> Afaste a câmera até a distância indicada, use lente mais aberta ou aceite a cena obtida
B17: 5 | E17: =IF(D17="","",IFERROR(VLOOKUP(D17,Referência!$B$6:$C$16,2,FALSE()),"")) | K17: =IF(OR(E17="",F17="",G17="",G17=0,E17=0),"",ROUND(F17*E17/G17,1)) | L17: =IF(K17="","",ROUND(K17*36/E17,0)) | M17: =IF(OR(K17="",H17="",I17=""),"",IF(K17>I17,"Falta tele",IF(K17<H17,"Falta angular","OK"))) | N17: =IF(K17="","",IF(OR(H17="",I17=""),K17,MIN(MAX(K17,H17),I17))) | O17: =IF(N17="","",ROUND(F17*E17/N17,2)) | P17: =IF(O17="","",ROUND(O17*9/16,2)) | Q17: =IF(M17="Falta tele",ROUND(I17*G17/E17,1),IF(M17="Falta angular",ROUND(H17*G17/E17,1),"")) | R17: =IF(OR(N17="",J17="",J17=0),"",ROUND((F17*1000)*((N17^2/(J17*E17/1200)+N17)-N17)/((N17^2/(J17*E17/1200)+N17)+(F17*1000)-2*N17)/1000,2)) | S17: =IF(OR(N17="",J17="",J17=0),"",IF((F17*1000)>=(N17^2/(J17*E17/1200)+N17),"infinito",ROUND((F17*1000)*((N17^2/(J17*E17/1200)+N17)-N17)/((N17^2/(J17*E17/1200)+N17)-(F17*1000))/1000,2))) | T17: =IF(M17="","",IF(M17="Falta tele","Aproxime a câmera até a distância indicada, use lente mais longa ou aceite a cena obtida",IF(M17="Falta angular","Afaste a câmera até a distância indicada, use lente mais aberta ou aceite a cena obtida",IF(AND(ISNUMBER(S17),ISNUMBER(R17)),IF(S17-R17<0.5,"A lente alcança. Faixa em foco estreita: feche a íris se a pessoa anda","A lente alcança. Deixe o zoom digital desligado"),"A lente alcança. Deixe o zoom digital desligado"))))
B18: 6 | E18: =IF(D18="","",IFERROR(VLOOKUP(D18,Referência!$B$6:$C$16,2,FALSE()),"")) | K18: =IF(OR(E18="",F18="",G18="",G18=0,E18=0),"",ROUND(F18*E18/G18,1)) | L18: =IF(K18="","",ROUND(K18*36/E18,0)) | M18: =IF(OR(K18="",H18="",I18=""),"",IF(K18>I18,"Falta tele",IF(K18<H18,"Falta angular","OK"))) | N18: =IF(K18="","",IF(OR(H18="",I18=""),K18,MIN(MAX(K18,H18),I18))) | O18: =IF(N18="","",ROUND(F18*E18/N18,2)) | P18: =IF(O18="","",ROUND(O18*9/16,2)) | Q18: =IF(M18="Falta tele",ROUND(I18*G18/E18,1),IF(M18="Falta angular",ROUND(H18*G18/E18,1),"")) | R18: =IF(OR(N18="",J18="",J18=0),"",ROUND((F18*1000)*((N18^2/(J18*E18/1200)+N18)-N18)/((N18^2/(J18*E18/1200)+N18)+(F18*1000)-2*N18)/1000,2)) | S18: =IF(OR(N18="",J18="",J18=0),"",IF((F18*1000)>=(N18^2/(J18*E18/1200)+N18),"infinito",ROUND((F18*1000)*((N18^2/(J18*E18/1200)+N18)-N18)/((N18^2/(J18*E18/1200)+N18)-(F18*1000))/1000,2))) | T18: =IF(M18="","",IF(M18="Falta tele","Aproxime a câmera até a distância indicada, use lente mais longa ou aceite a cena obtida",IF(M18="Falta angular","Afaste a câmera até a distância indicada, use lente mais aberta ou aceite a cena obtida",IF(AND(ISNUMBER(S18),ISNUMBER(R18)),IF(S18-R18<0.5,"A lente alcança. Faixa em foco estreita: feche a íris se a pessoa anda","A lente alcança. Deixe o zoom digital desligado"),"A lente alcança. Deixe o zoom digital desligado"))))
B19: 7 | E19: =IF(D19="","",IFERROR(VLOOKUP(D19,Referência!$B$6:$C$16,2,FALSE()),"")) | K19: =IF(OR(E19="",F19="",G19="",G19=0,E19=0),"",ROUND(F19*E19/G19,1)) | L19: =IF(K19="","",ROUND(K19*36/E19,0)) | M19: =IF(OR(K19="",H19="",I19=""),"",IF(K19>I19,"Falta tele",IF(K19<H19,"Falta angular","OK"))) | N19: =IF(K19="","",IF(OR(H19="",I19=""),K19,MIN(MAX(K19,H19),I19))) | O19: =IF(N19="","",ROUND(F19*E19/N19,2)) | P19: =IF(O19="","",ROUND(O19*9/16,2)) | Q19: =IF(M19="Falta tele",ROUND(I19*G19/E19,1),IF(M19="Falta angular",ROUND(H19*G19/E19,1),"")) | R19: =IF(OR(N19="",J19="",J19=0),"",ROUND((F19*1000)*((N19^2/(J19*E19/1200)+N19)-N19)/((N19^2/(J19*E19/1200)+N19)+(F19*1000)-2*N19)/1000,2)) | S19: =IF(OR(N19="",J19="",J19=0),"",IF((F19*1000)>=(N19^2/(J19*E19/1200)+N19),"infinito",ROUND((F19*1000)*((N19^2/(J19*E19/1200)+N19)-N19)/((N19^2/(J19*E19/1200)+N19)-(F19*1000))/1000,2))) | T19: =IF(M19="","",IF(M19="Falta tele","Aproxime a câmera até a distância indicada, use lente mais longa ou aceite a cena obtida",IF(M19="Falta angular","Afaste a câmera até a distância indicada, use lente mais aberta ou aceite a cena obtida",IF(AND(ISNUMBER(S19),ISNUMBER(R19)),IF(S19-R19<0.5,"A lente alcança. Faixa em foco estreita: feche a íris se a pessoa anda","A lente alcança. Deixe o zoom digital desligado"),"A lente alcança. Deixe o zoom digital desligado"))))
B20: 8 | E20: =IF(D20="","",IFERROR(VLOOKUP(D20,Referência!$B$6:$C$16,2,FALSE()),"")) | K20: =IF(OR(E20="",F20="",G20="",G20=0,E20=0),"",ROUND(F20*E20/G20,1)) | L20: =IF(K20="","",ROUND(K20*36/E20,0)) | M20: =IF(OR(K20="",H20="",I20=""),"",IF(K20>I20,"Falta tele",IF(K20<H20,"Falta angular","OK"))) | N20: =IF(K20="","",IF(OR(H20="",I20=""),K20,MIN(MAX(K20,H20),I20))) | O20: =IF(N20="","",ROUND(F20*E20/N20,2)) | P20: =IF(O20="","",ROUND(O20*9/16,2)) | Q20: =IF(M20="Falta tele",ROUND(I20*G20/E20,1),IF(M20="Falta angular",ROUND(H20*G20/E20,1),"")) | R20: =IF(OR(N20="",J20="",J20=0),"",ROUND((F20*1000)*((N20^2/(J20*E20/1200)+N20)-N20)/((N20^2/(J20*E20/1200)+N20)+(F20*1000)-2*N20)/1000,2)) | S20: =IF(OR(N20="",J20="",J20=0),"",IF((F20*1000)>=(N20^2/(J20*E20/1200)+N20),"infinito",ROUND((F20*1000)*((N20^2/(J20*E20/1200)+N20)-N20)/((N20^2/(J20*E20/1200)+N20)-(F20*1000))/1000,2))) | T20: =IF(M20="","",IF(M20="Falta tele","Aproxime a câmera até a distância indicada, use lente mais longa ou aceite a cena obtida",IF(M20="Falta angular","Afaste a câmera até a distância indicada, use lente mais aberta ou aceite a cena obtida",IF(AND(ISNUMBER(S20),ISNUMBER(R20)),IF(S20-R20<0.5,"A lente alcança. Faixa em foco estreita: feche a íris se a pessoa anda","A lente alcança. Deixe o zoom digital desligado"),"A lente alcança. Deixe o zoom digital desligado"))))
B21: 9 | E21: =IF(D21="","",IFERROR(VLOOKUP(D21,Referência!$B$6:$C$16,2,FALSE()),"")) | K21: =IF(OR(E21="",F21="",G21="",G21=0,E21=0),"",ROUND(F21*E21/G21,1)) | L21: =IF(K21="","",ROUND(K21*36/E21,0)) | M21: =IF(OR(K21="",H21="",I21=""),"",IF(K21>I21,"Falta tele",IF(K21<H21,"Falta angular","OK"))) | N21: =IF(K21="","",IF(OR(H21="",I21=""),K21,MIN(MAX(K21,H21),I21))) | O21: =IF(N21="","",ROUND(F21*E21/N21,2)) | P21: =IF(O21="","",ROUND(O21*9/16,2)) | Q21: =IF(M21="Falta tele",ROUND(I21*G21/E21,1),IF(M21="Falta angular",ROUND(H21*G21/E21,1),"")) | R21: =IF(OR(N21="",J21="",J21=0),"",ROUND((F21*1000)*((N21^2/(J21*E21/1200)+N21)-N21)/((N21^2/(J21*E21/1200)+N21)+(F21*1000)-2*N21)/1000,2)) | S21: =IF(OR(N21="",J21="",J21=0),"",IF((F21*1000)>=(N21^2/(J21*E21/1200)+N21),"infinito",ROUND((F21*1000)*((N21^2/(J21*E21/1200)+N21)-N21)/((N21^2/(J21*E21/1200)+N21)-(F21*1000))/1000,2))) | T21: =IF(M21="","",IF(M21="Falta tele","Aproxime a câmera até a distância indicada, use lente mais longa ou aceite a cena obtida",IF(M21="Falta angular","Afaste a câmera até a distância indicada, use lente mais aberta ou aceite a cena obtida",IF(AND(ISNUMBER(S21),ISNUMBER(R21)),IF(S21-R21<0.5,"A lente alcança. Faixa em foco estreita: feche a íris se a pessoa anda","A lente alcança. Deixe o zoom digital desligado"),"A lente alcança. Deixe o zoom digital desligado"))))
B22: 10 | E22: =IF(D22="","",IFERROR(VLOOKUP(D22,Referência!$B$6:$C$16,2,FALSE()),"")) | K22: =IF(OR(E22="",F22="",G22="",G22=0,E22=0),"",ROUND(F22*E22/G22,1)) | L22: =IF(K22="","",ROUND(K22*36/E22,0)) | M22: =IF(OR(K22="",H22="",I22=""),"",IF(K22>I22,"Falta tele",IF(K22<H22,"Falta angular","OK"))) | N22: =IF(K22="","",IF(OR(H22="",I22=""),K22,MIN(MAX(K22,H22),I22))) | O22: =IF(N22="","",ROUND(F22*E22/N22,2)) | P22: =IF(O22="","",ROUND(O22*9/16,2)) | Q22: =IF(M22="Falta tele",ROUND(I22*G22/E22,1),IF(M22="Falta angular",ROUND(H22*G22/E22,1),"")) | R22: =IF(OR(N22="",J22="",J22=0),"",ROUND((F22*1000)*((N22^2/(J22*E22/1200)+N22)-N22)/((N22^2/(J22*E22/1200)+N22)+(F22*1000)-2*N22)/1000,2)) | S22: =IF(OR(N22="",J22="",J22=0),"",IF((F22*1000)>=(N22^2/(J22*E22/1200)+N22),"infinito",ROUND((F22*1000)*((N22^2/(J22*E22/1200)+N22)-N22)/((N22^2/(J22*E22/1200)+N22)-(F22*1000))/1000,2))) | T22: =IF(M22="","",IF(M22="Falta tele","Aproxime a câmera até a distância indicada, use lente mais longa ou aceite a cena obtida",IF(M22="Falta angular","Afaste a câmera até a distância indicada, use lente mais aberta ou aceite a cena obtida",IF(AND(ISNUMBER(S22),ISNUMBER(R22)),IF(S22-R22<0.5,"A lente alcança. Faixa em foco estreita: feche a íris se a pessoa anda","A lente alcança. Deixe o zoom digital desligado"),"A lente alcança. Deixe o zoom digital desligado"))))
B23: 11 | E23: =IF(D23="","",IFERROR(VLOOKUP(D23,Referência!$B$6:$C$16,2,FALSE()),"")) | K23: =IF(OR(E23="",F23="",G23="",G23=0,E23=0),"",ROUND(F23*E23/G23,1)) | L23: =IF(K23="","",ROUND(K23*36/E23,0)) | M23: =IF(OR(K23="",H23="",I23=""),"",IF(K23>I23,"Falta tele",IF(K23<H23,"Falta angular","OK"))) | N23: =IF(K23="","",IF(OR(H23="",I23=""),K23,MIN(MAX(K23,H23),I23))) | O23: =IF(N23="","",ROUND(F23*E23/N23,2)) | P23: =IF(O23="","",ROUND(O23*9/16,2)) | Q23: =IF(M23="Falta tele",ROUND(I23*G23/E23,1),IF(M23="Falta angular",ROUND(H23*G23/E23,1),"")) | R23: =IF(OR(N23="",J23="",J23=0),"",ROUND((F23*1000)*((N23^2/(J23*E23/1200)+N23)-N23)/((N23^2/(J23*E23/1200)+N23)+(F23*1000)-2*N23)/1000,2)) | S23: =IF(OR(N23="",J23="",J23=0),"",IF((F23*1000)>=(N23^2/(J23*E23/1200)+N23),"infinito",ROUND((F23*1000)*((N23^2/(J23*E23/1200)+N23)-N23)/((N23^2/(J23*E23/1200)+N23)-(F23*1000))/1000,2))) | T23: =IF(M23="","",IF(M23="Falta tele","Aproxime a câmera até a distância indicada, use lente mais longa ou aceite a cena obtida",IF(M23="Falta angular","Afaste a câmera até a distância indicada, use lente mais aberta ou aceite a cena obtida",IF(AND(ISNUMBER(S23),ISNUMBER(R23)),IF(S23-R23<0.5,"A lente alcança. Faixa em foco estreita: feche a íris se a pessoa anda","A lente alcança. Deixe o zoom digital desligado"),"A lente alcança. Deixe o zoom digital desligado"))))
B24: 12 | E24: =IF(D24="","",IFERROR(VLOOKUP(D24,Referência!$B$6:$C$16,2,FALSE()),"")) | K24: =IF(OR(E24="",F24="",G24="",G24=0,E24=0),"",ROUND(F24*E24/G24,1)) | L24: =IF(K24="","",ROUND(K24*36/E24,0)) | M24: =IF(OR(K24="",H24="",I24=""),"",IF(K24>I24,"Falta tele",IF(K24<H24,"Falta angular","OK"))) | N24: =IF(K24="","",IF(OR(H24="",I24=""),K24,MIN(MAX(K24,H24),I24))) | O24: =IF(N24="","",ROUND(F24*E24/N24,2)) | P24: =IF(O24="","",ROUND(O24*9/16,2)) | Q24: =IF(M24="Falta tele",ROUND(I24*G24/E24,1),IF(M24="Falta angular",ROUND(H24*G24/E24,1),"")) | R24: =IF(OR(N24="",J24="",J24=0),"",ROUND((F24*1000)*((N24^2/(J24*E24/1200)+N24)-N24)/((N24^2/(J24*E24/1200)+N24)+(F24*1000)-2*N24)/1000,2)) | S24: =IF(OR(N24="",J24="",J24=0),"",IF((F24*1000)>=(N24^2/(J24*E24/1200)+N24),"infinito",ROUND((F24*1000)*((N24^2/(J24*E24/1200)+N24)-N24)/((N24^2/(J24*E24/1200)+N24)-(F24*1000))/1000,2))) | T24: =IF(M24="","",IF(M24="Falta tele","Aproxime a câmera até a distância indicada, use lente mais longa ou aceite a cena obtida",IF(M24="Falta angular","Afaste a câmera até a distância indicada, use lente mais aberta ou aceite a cena obtida",IF(AND(ISNUMBER(S24),ISNUMBER(R24)),IF(S24-R24<0.5,"A lente alcança. Faixa em foco estreita: feche a íris se a pessoa anda","A lente alcança. Deixe o zoom digital desligado"),"A lente alcança. Deixe o zoom digital desligado"))))
B26: Resumo automático
B27: Câmeras registradas | F27: =COUNTA(C13:C24) -> 4
B28: Lente alcança (OK) | F28: =COUNTIF(M13:M24,"OK") -> 1
B29: Falta tele | F29: =COUNTIF(M13:M24,"Falta tele") -> 2
B30: Falta angular | F30: =COUNTIF(M13:M24,"Falta angular") -> 1
B31: Aviso | F31: =IF(F27=0,"Liste as câmeras",IF(COUNTIF(M13:M24,"OK")+COUNTIF(M13:M24,"Falta tele")+COUNTIF(M13:M24,"Falta angular")<F27,"Há câmera sem sensor, distância, cena ou lente",IF(F29+F30>0,"Há quadro que a lente não alcança: decida antes de montar","OK"))) -> Há quadro que a lente não alcança: decida antes de montar
B33: O que foi ajustado
B34: Câm. | C34: O que foi feito | M34: Resultado
B35: 1 | C35: Levada para um praticável a 12 m do púlpito. | M35: 130 mm, dentro da lente. Em f/5,6, faixa em foco de cerca de 1,4 m.
B36: 2 | C36: Nada a mudar. | M36: 10 mm, dentro da lente.
B37: 3 | C37: O close (1,0 m) só caberia a 2,3 m da cantora. O plano pedido virou plano médio, de 2,6 m. | M37: 55 mm, no fim da lente.
B38: 4 | C38: Recuada para 5,5 m do palco. | M38: 24,8 mm, dentro da lente.
B39: Todas | C39: Zoom digital desligado no menu.

Sheet Exemplo - Balanço
B1: Balanço de branco — ficha de cor por câmera
B2: Exemplo preenchido, para consulta. Use a aba Balanço de branco para o seu evento.
B4: Evento | D4: Formatura no auditório da escola | G4: Luz principal (K) | J4: 3200 | K4: Temperatura de cor da luz que ilumina o rosto. Veja a aba Referência.
B5: Local | D5: Auditório com janelas laterais | G5: Câmera de referência (nº) | J5: 1 | K5: A câmera principal. As outras são comparadas com ela.
B6: Data | D6: 46368 | G6: Tolerância para a luz (K) | J6: 500 | K6: Diferença aceita entre o kelvin da câmera e a luz principal.
B7: Operador | D7: Operador de vídeo do evento | G7: Tolerância entre câmeras (K) | J7: 200 | K7: Diferença aceita entre cada câmera e a de referência.
G8: O kelvin que a câmera mostra depois do balanço é uma leitura dela. O que decide é a comparação no mesmo monitor.
B9: Kelvin da referência | E9: =IF(OR($J$5="",$J$5<1,$J$5>8),"",IF(INDEX(F14:F21,$J$5)="","",INDEX(F14:F21,$J$5))) -> 3300
B10: Perfil da referência | E10: =IF(OR($J$5="",$J$5<1,$J$5>8),"",IF(INDEX(H14:H21,$J$5)="","",INDEX(H14:H21,$J$5))) -> Padrão
B11: Ficha de cor, uma linha por câmera
B12: # | C12: Câmera e posição | D12: Tipo de câmera | E12: Modo | F12: Kelvin | G12: Tint | H12: Perfil | I12: Comparada no monitor | J12: Diferença para a luz | K12: Diferença para a ref. | L12: Situação | M12: O que fazer | N12: Observação
B13: nº | E13: lista | F13: K | G13: passos | H13: lista | I13: Sim / Não | J13: K | K13: K
