Workbook

Sheet Instruções
B1: Equalização — como usar esta planilha
B2: Ficha de EQ de cada canal, consulta de faixas e sintomas e guia de ponto de partida por fonte.
B4: Legenda: onde preencher
B5: Amarelo-claro | C5: Células de entrada. É aqui que você digita.
B6: Cinza | C6: Células calculadas ou fixas (rótulos, contas, avisos). Não altere.
B7: Cinza em itálico | C7: Linha de exemplo (marcada com “Ex.”) e dicas de preenchimento. Não entram nas contas.
B8: Listas suspensas | C8: Tipo de fonte e tipo de banda (Bell ou Shelf) aceitam só as opções da lista.
B9: Números | C9: Frequência em Hz, sem a letra k: 3000, e não 3 k. Ganho em dB, com o sinal de menos no corte: -4.
B10: Comentários | C10: Células com triângulo vermelho no canto trazem uma dica. Passe o mouse sobre elas.
B12: Ordem de preenchimento
B13: 1 | C13: Aba Ficha de EQ: preencha o cabeçalho e confira os dois limites dos avisos, no alto à direita.
B14: 2 | C14: Liste a fonte e o tipo de fonte de cada canal. O tipo traz a faixa de partida do passa-altas.
B15: 3 | C15: Na mesa: ajuste o ganho, ligue o passa-altas, procure o que sobra por varredura, corte e, se faltar, realce pouco.
B16: 4 | C16: Anote o passa-altas e cada banda usada: tipo, frequência, ganho e Q.
B17: 5 | C17: Veja a situação e o que fazer em cada canal. Depois, o mapa de faixas: ele mostra disputa e cortes repetidos.
B18: 6 | C18: Aba Faixas e sintomas: consulte uma frequência, ou calcule a largura de uma banda pelo Q.
B19: 7 | C19: Aba Checklist: confira os doze itens antes de montar os retornos.
B21: Abas da planilha
B22: Ficha de EQ | C22: Até 24 canais, com conferência do passa-altas, maior realce, maior corte, situação e o mapa por faixa.
B23: Faixas e sintomas | C23: Consulta por frequência, calculadora de largura pelo Q, as sete faixas e a tabela de sintomas.
B24: Guia por fonte | C24: Passa-altas de partida e onde cada fonte costuma sobrar ou faltar, para doze tipos de fonte.
B25: Checklist | C25: Os doze itens do treinamento, com percentual atendido.
B26: Exemplo - Ficha de EQ | C26: Os oito canais do exemplo 1 do treinamento, como foram encontrados, e o que foi ajustado.
B28: Regras e premissas do modelo
B29: Passa-altas | C29: OK dentro da faixa de partida do Guia por fonte. Em branco, vale Desligado nas fontes que podem ficar sem ele e Sem HPF nas outras.
B30: Realce alto | C30: Maior realce do canal acima do limite do alto da aba (6 dB, de partida).
B31: Só realces | C31: O canal tem realce e nenhum corte em bell ou shelf. Convite para procurar o que cortar.
B32: Mapa de faixas | C32: Conta, em todos os canais, as bandas que realçam e as que cortam em cada faixa. Muitos realces na mesma faixa indicam disputa; muitos cortes, defeito do sistema ou da sala.
B33: Avisos | C33: São convites para conferir, e não erros. O ouvido decide. Os limites são regra prática deste material, e não norma.
B34: Exemplos | C34: Os dados da aba de exemplo são ilustrativos, criados para este material.

Sheet Ficha de EQ
B1: Ficha de EQ por canal — passa-altas e até quatro bandas
B2: Preencha as células em amarelo-claro com o EQ de cada canal. As células cinza são calculadas.
B4: Evento | K4: Realce máximo (dB) | R4: 6 | S4: Realce acima disto recebe o aviso Realce alto. Ponto de partida: 6 dB.
B5: Local | K5: Aviso de faixa repetida (nº) | R5: 4 | S5: Quantos realces, ou cortes, na mesma faixa disparam o aviso do mapa. Ponto de partida: 4.
B6: Data
B7: Operador | K7: Frequências em Hz (3000, e não 3 k). Ganho em dB, com sinal: −4 para corte. Q só na banda bell.
B8: Mesa | K8: Passa-altas em branco = desligado. A faixa de partida vem da aba Guia por fonte.
B10: Ficha de EQ por canal
B11: Canal | C11: Fonte | D11: Tipo de fonte | E11: HPF | F11: Banda 1 | J11: Banda 2 | N11: Banda 3 | R11: Banda 4 | V11: Partida do HPF | W11: Passa-altas | X11: Maior realce | Y11: Maior corte | Z11: Situação | AA11: O que fazer | AB11: Observação
B12: nº | C12: o que está no canal | D12: da lista | E12: Hz | F12: Tipo | G12: Hz | H12: dB | I12: Q | J12: Tipo | K12: Hz | L12: dB | M12: Q | N12: Tipo | O12: Hz | P12: dB | Q12: Q | R12: Tipo | S12: Hz | T12: dB | U12: Q | V12: do Guia por fonte | W12: conferência | X12: dB | Y12: dB
B13: Ex. | C13: Voz do pastor | D13: Voz masculina | E13: 100 | F13: Bell | G13: 300 | H13: -3 | I13: 1.4 | J13: Bell | K13: 2500 | L13: 3 | M13: 1 | V13: 80 a 120 Hz | W13: OK | X13: 3 | Y13: -3 | Z13: OK | AA13: Manter. Decida na mistura
B14: 1 | V14: =IF(D14="","",IFERROR(VLOOKUP(D14,'Guia por fonte'!$B$5:$I$16,5,0),"–")) | W14: =IF(D14="","",IFERROR(IF(E14="",IF(VLOOKUP(D14,'Guia por fonte'!$B$5:$I$16,4,0)="Sim","Desligado","Sem HPF"),IF(E14<VLOOKUP(D14,'Guia por fonte'!$B$5:$I$16,2,0),"Abaixo da faixa",IF(E14>VLOOKUP(D14,'Guia por fonte'!$B$5:$I$16,3,0),"Acima da faixa","OK"))),"–")) | X14: =IF(COUNT(H14,L14,P14,T14)=0,"",MAX(0,H14,L14,P14,T14)) | Y14: =IF(COUNT(H14,L14,P14,T14)=0,"",MIN(0,H14,L14,P14,T14)) | Z14: =IF(AND(C14="",D14="",COUNT(E14,G14,H14,I14,K14,L14,M14,O14,P14,Q14,S14,T14,U14)=0),"",IF(AND(X14<>"",X14>$R$4),"Realce alto",IF(W14="Sem HPF","Sem HPF",IF(OR(W14="Abaixo da faixa",W14="Acima da faixa"),"HPF fora da faixa",IF(AND((H14>0)+(L14>0)+(P14>0)+(T14>0)>0,(H14<0)+(L14<0)+(P14<0)+(T14<0)=0),"Só realces","OK"))))) | AA14: =IF(Z14="","",IF(Z14="Realce alto","Realce de "&X14&" dB: procure antes o que cortar e confira o microfone",IF(Z14="Sem HPF","Ligue o passa-altas: comece em "&V14,IF(Z14="HPF fora da faixa","Partida sugerida: "&V14&". Confira ouvindo",IF(Z14="Só realces","Procure o que cortar antes de realçar","Manter. Decida na mistura")))))
B15: 2 | V15: =IF(D15="","",IFERROR(VLOOKUP(D15,'Guia por fonte'!$B$5:$I$16,5,0),"–")) | W15: =IF(D15="","",IFERROR(IF(E15="",IF(VLOOKUP(D15,'Guia por fonte'!$B$5:$I$16,4,0)="Sim","Desligado","Sem HPF"),IF(E15<VLOOKUP(D15,'Guia por fonte'!$B$5:$I$16,2,0),"Abaixo da faixa",IF(E15>VLOOKUP(D15,'Guia por fonte'!$B$5:$I$16,3,0),"Acima da faixa","OK"))),"–")) | X15: =IF(COUNT(H15,L15,P15,T15)=0,"",MAX(0,H15,L15,P15,T15)) | Y15: =IF(COUNT(H15,L15,P15,T15)=0,"",MIN(0,H15,L15,P15,T15)) | Z15: =IF(AND(C15="",D15="",COUNT(E15,G15,H15,I15,K15,L15,M15,O15,P15,Q15,S15,T15,U15)=0),"",IF(AND(X15<>"",X15>$R$4),"Realce alto",IF(W15="Sem HPF","Sem HPF",IF(OR(W15="Abaixo da faixa",W15="Acima da faixa"),"HPF fora da faixa",IF(AND((H15>0)+(L15>0)+(P15>0)+(T15>0)>0,(H15<0)+(L15<0)+(P15<0)+(T15<0)=0),"Só realces","OK"))))) | AA15: =IF(Z15="","",IF(Z15="Realce alto","Realce de "&X15&" dB: procure antes o que cortar e confira o microfone",IF(Z15="Sem HPF","Ligue o passa-altas: comece em "&V15,IF(Z15="HPF fora da faixa","Partida sugerida: "&V15&". Confira ouvindo",IF(Z15="Só realces","Procure o que cortar antes de realçar","Manter. Decida na mistura")))))
B16: 3 | V16: =IF(D16="","",IFERROR(VLOOKUP(D16,'Guia por fonte'!$B$5:$I$16,5,0),"–")) | W16: =IF(D16="","",IFERROR(IF(E16="",IF(VLOOKUP(D16,'Guia por fonte'!$B$5:$I$16,4,0)="Sim","Desligado","Sem HPF"),IF(E16<VLOOKUP(D16,'Guia por fonte'!$B$5:$I$16,2,0),"Abaixo da faixa",IF(E16>VLOOKUP(D16,'Guia por fonte'!$B$5:$I$16,3,0),"Acima da faixa","OK"))),"–")) | X16: =IF(COUNT(H16,L16,P16,T16)=0,"",MAX(0,H16,L16,P16,T16)) | Y16: =IF(COUNT(H16,L16,P16,T16)=0,"",MIN(0,H16,L16,P16,T16)) | Z16: =IF(AND(C16="",D16="",COUNT(E16,G16,H16,I16,K16,L16,M16,O16,P16,Q16,S16,T16,U16)=0),"",IF(AND(X16<>"",X16>$R$4),"Realce alto",IF(W16="Sem HPF","Sem HPF",IF(OR(W16="Abaixo da faixa",W16="Acima da faixa"),"HPF fora da faixa",IF(AND((H16>0)+(L16>0)+(P16>0)+(T16>0)>0,(H16<0)+(L16<0)+(P16<0)+(T16<0)=0),"Só realces","OK"))))) | AA16: =IF(Z16="","",IF(Z16="Realce alto","Realce de "&X16&" dB: procure antes o que cortar e confira o microfone",IF(Z16="Sem HPF","Ligue o passa-altas: comece em "&V16,IF(Z16="HPF fora da faixa","Partida sugerida: "&V16&". Confira ouvindo",IF(Z16="Só realces","Procure o que cortar antes de realçar","Manter. Decida na mistura")))))
B17: 4 | V17: =IF(D17="","",IFERROR(VLOOKUP(D17,'Guia por fonte'!$B$5:$I$16,5,0),"–")) | W17: =IF(D17="","",IFERROR(IF(E17="",IF(VLOOKUP(D17,'Guia por fonte'!$B$5:$I$16,4,0)="Sim","Desligado","Sem HPF"),IF(E17<VLOOKUP(D17,'Guia por fonte'!$B$5:$I$16,2,0),"Abaixo da faixa",IF(E17>VLOOKUP(D17,'Guia por fonte'!$B$5:$I$16,3,0),"Acima da faixa","OK"))),"–")) | X17: =IF(COUNT(H17,L17,P17,T17)=0,"",MAX(0,H17,L17,P17,T17)) | Y17: =IF(COUNT(H17,L17,P17,T17)=0,"",MIN(0,H17,L17,P17,T17)) | Z17: =IF(AND(C17="",D17="",COUNT(E17,G17,H17,I17,K17,L17,M17,O17,P17,Q17,S17,T17,U17)=0),"",IF(AND(X17<>"",X17>$R$4),"Realce alto",IF(W17="Sem HPF","Sem HPF",IF(OR(W17="Abaixo da faixa",W17="Acima da faixa"),"HPF fora da faixa",IF(AND((H17>0)+(L17>0)+(P17>0)+(T17>0)>0,(H17<0)+(L17<0)+(P17<0)+(T17<0)=0),"Só realces","OK"))))) | AA17: =IF(Z17="","",IF(Z17="Realce alto","Realce de "&X17&" dB: procure antes o que cortar e confira o microfone",IF(Z17="Sem HPF","Ligue o passa-altas: comece em "&V17,IF(Z17="HPF fora da faixa","Partida sugerida: "&V17&". Confira ouvindo",IF(Z17="Só realces","Procure o que cortar antes de realçar","Manter. Decida na mistura")))))
B18: 5 | V18: =IF(D18="","",IFERROR(VLOOKUP(D18,'Guia por fonte'!$B$5:$I$16,5,0),"–")) | W18: =IF(D18="","",IFERROR(IF(E18="",IF(VLOOKUP(D18,'Guia por fonte'!$B$5:$I$16,4,0)="Sim","Desligado","Sem HPF"),IF(E18<VLOOKUP(D18,'Guia por fonte'!$B$5:$I$16,2,0),"Abaixo da faixa",IF(E18>VLOOKUP(D18,'Guia por fonte'!$B$5:$I$16,3,0),"Acima da faixa","OK"))),"–")) | X18: =IF(COUNT(H18,L18,P18,T18)=0,"",MAX(0,H18,L18,P18,T18)) | Y18: =IF(COUNT(H18,L18,P18,T18)=0,"",MIN(0,H18,L18,P18,T18)) | Z18: =IF(AND(C18="",D18="",COUNT(E18,G18,H18,I18,K18,L18,M18,O18,P18,Q18,S18,T18,U18)=0),"",IF(AND(X18<>"",X18>$R$4),"Realce alto",IF(W18="Sem HPF","Sem HPF",IF(OR(W18="Abaixo da faixa",W18="Acima da faixa"),"HPF fora da faixa",IF(AND((H18>0)+(L18>0)+(P18>0)+(T18>0)>0,(H18<0)+(L18<0)+(P18<0)+(T18<0)=0),"Só realces","OK"))))) | AA18: =IF(Z18="","",IF(Z18="Realce alto","Realce de "&X18&" dB: procure antes o que cortar e confira o microfone",IF(Z18="Sem HPF","Ligue o passa-altas: comece em "&V18,IF(Z18="HPF fora da faixa","Partida sugerida: "&V18&". Confira ouvindo",IF(Z18="Só realces","Procure o que cortar antes de realçar","Manter. Decida na mistura")))))
B19: 6 | V19: =IF(D19="","",IFERROR(VLOOKUP(D19,'Guia por fonte'!$B$5:$I$16,5,0),"–")) | W19: =IF(D19="","",IFERROR(IF(E19="",IF(VLOOKUP(D19,'Guia por fonte'!$B$5:$I$16,4,0)="Sim","Desligado","Sem HPF"),IF(E19<VLOOKUP(D19,'Guia por fonte'!$B$5:$I$16,2,0),"Abaixo da faixa",IF(E19>VLOOKUP(D19,'Guia por fonte'!$B$5:$I$16,3,0),"Acima da faixa","OK"))),"–")) | X19: =IF(COUNT(H19,L19,P19,T19)=0,"",MAX(0,H19,L19,P19,T19)) | Y19: =IF(COUNT(H19,L19,P19,T19)=0,"",MIN(0,H19,L19,P19,T19)) | Z19: =IF(AND(C19="",D19="",COUNT(E19,G19,H19,I19,K19,L19,M19,O19,P19,Q19,S19,T19,U19)=0),"",IF(AND(X19<>"",X19>$R$4),"Realce alto",IF(W19="Sem HPF","Sem HPF",IF(OR(W19="Abaixo da faixa",W19="Acima da faixa"),"HPF fora da faixa",IF(AND((H19>0)+(L19>0)+(P19>0)+(T19>0)>0,(H19<0)+(L19<0)+(P19<0)+(T19<0)=0),"Só realces","OK"))))) | AA19: =IF(Z19="","",IF(Z19="Realce alto","Realce de "&X19&" dB: procure antes o que cortar e confira o microfone",IF(Z19="Sem HPF","Ligue o passa-altas: comece em "&V19,IF(Z19="HPF fora da faixa","Partida sugerida: "&V19&". Confira ouvindo",IF(Z19="Só realces","Procure o que cortar antes de realçar","Manter. Decida na mistura")))))
B20: 7 | V20: =IF(D20="","",IFERROR(VLOOKUP(D20,'Guia por fonte'!$B$5:$I$16,5,0),"–")) | W20: =IF(D20="","",IFERROR(IF(E20="",IF(VLOOKUP(D20,'Guia por fonte'!$B$5:$I$16,4,0)="Sim","Desligado","Sem HPF"),IF(E20<VLOOKUP(D20,'Guia por fonte'!$B$5:$I$16,2,0),"Abaixo da faixa",IF(E20>VLOOKUP(D20,'Guia por fonte'!$B$5:$I$16,3,0),"Acima da faixa","OK"))),"–")) | X20: =IF(COUNT(H20,L20,P20,T20)=0,"",MAX(0,H20,L20,P20,T20)) | Y20: =IF(COUNT(H20,L20,P20,T20)=0,"",MIN(0,H20,L20,P20,T20)) | Z20: =IF(AND(C20="",D20="",COUNT(E20,G20,H20,I20,K20,L20,M20,O20,P20,Q20,S20,T20,U20)=0),"",IF(AND(X20<>"",X20>$R$4),"Realce alto",IF(W20="Sem HPF","Sem HPF",IF(OR(W20="Abaixo da faixa",W20="Acima da faixa"),"HPF fora da faixa",IF(AND((H20>0)+(L20>0)+(P20>0)+(T20>0)>0,(H20<0)+(L20<0)+(P20<0)+(T20<0)=0),"Só realces","OK"))))) | AA20: =IF(Z20="","",IF(Z20="Realce alto","Realce de "&X20&" dB: procure antes o que cortar e confira o microfone",IF(Z20="Sem HPF","Ligue o passa-altas: comece em "&V20,IF(Z20="HPF fora da faixa","Partida sugerida: "&V20&". Confira ouvindo",IF(Z20="Só realces","Procure o que cortar antes de realçar","Manter. Decida na mistura")))))
B21: 8 | V21: =IF(D21="","",IFERROR(VLOOKUP(D21,'Guia por fonte'!$B$5:$I$16,5,0),"–")) | W21: =IF(D21="","",IFERROR(IF(E21="",IF(VLOOKUP(D21,'Guia por fonte'!$B$5:$I$16,4,0)="Sim","Desligado","Sem HPF"),IF(E21<VLOOKUP(D21,'Guia por fonte'!$B$5:$I$16,2,0),"Abaixo da faixa",IF(E21>VLOOKUP(D21,'Guia por fonte'!$B$5:$I$16,3,0),"Acima da faixa","OK"))),"–")) | X21: =IF(COUNT(H21,L21,P21,T21)=0,"",MAX(0,H21,L21,P21,T21)) | Y21: =IF(COUNT(H21,L21,P21,T21)=0,"",MIN(0,H21,L21,P21,T21)) | Z21: =IF(AND(C21="",D21="",COUNT(E21,G21,H21,I21,K21,L21,M21,O21,P21,Q21,S21,T21,U21)=0),"",IF(AND(X21<>"",X21>$R$4),"Realce alto",IF(W21="Sem HPF","Sem HPF",IF(OR(W21="Abaixo da faixa",W21="Acima da faixa"),"HPF fora da faixa",IF(AND((H21>0)+(L21>0)+(P21>0)+(T21>0)>0,(H21<0)+(L21<0)+(P21<0)+(T21<0)=0),"Só realces","OK"))))) | AA21: =IF(Z21="","",IF(Z21="Realce alto","Realce de "&X21&" dB: procure antes o que cortar e confira o microfone",IF(Z21="Sem HPF","Ligue o passa-altas: comece em "&V21,IF(Z21="HPF fora da faixa","Partida sugerida: "&V21&". Confira ouvindo",IF(Z21="Só realces","Procure o que cortar antes de realçar","Manter. Decida na mistura")))))
B22: 9 | V22: =IF(D22="","",IFERROR(VLOOKUP(D22,'Guia por fonte'!$B$5:$I$16,5,0),"–")) | W22: =IF(D22="","",IFERROR(IF(E22="",IF(VLOOKUP(D22,'Guia por fonte'!$B$5:$I$16,4,0)="Sim","Desligado","Sem HPF"),IF(E22<VLOOKUP(D22,'Guia por fonte'!$B$5:$I$16,2,0),"Abaixo da faixa",IF(E22>VLOOKUP(D22,'Guia por fonte'!$B$5:$I$16,3,0),"Acima da faixa","OK"))),"–")) | X22: =IF(COUNT(H22,L22,P22,T22)=0,"",MAX(0,H22,L22,P22,T22)) | Y22: =IF(COUNT(H22,L22,P22,T22)=0,"",MIN(0,H22,L22,P22,T22)) | Z22: =IF(AND(C22="",D22="",COUNT(E22,G22,H22,I22,K22,L22,M22,O22,P22,Q22,S22,T22,U22)=0),"",IF(AND(X22<>"",X22>$R$4),"Realce alto",IF(W22="Sem HPF","Sem HPF",IF(OR(W22="Abaixo da faixa",W22="Acima da faixa"),"HPF fora da faixa",IF(AND((H22>0)+(L22>0)+(P22>0)+(T22>0)>0,(H22<0)+(L22<0)+(P22<0)+(T22<0)=0),"Só realces","OK"))))) | AA22: =IF(Z22="","",IF(Z22="Realce alto","Realce de "&X22&" dB: procure antes o que cortar e confira o microfone",IF(Z22="Sem HPF","Ligue o passa-altas: comece em "&V22,IF(Z22="HPF fora da faixa","Partida sugerida: "&V22&". Confira ouvindo",IF(Z22="Só realces","Procure o que cortar antes de realçar","Manter. Decida na mistura")))))
B23: 10 | V23: =IF(D23="","",IFERROR(VLOOKUP(D23,'Guia por fonte'!$B$5:$I$16,5,0),"–")) | W23: =IF(D23="","",IFERROR(IF(E23="",IF(VLOOKUP(D23,'Guia por fonte'!$B$5:$I$16,4,0)="Sim","Desligado","Sem HPF"),IF(E23<VLOOKUP(D23,'Guia por fonte'!$B$5:$I$16,2,0),"Abaixo da faixa",IF(E23>VLOOKUP(D23,'Guia por fonte'!$B$5:$I$16,3,0),"Acima da faixa","OK"))),"–")) | X23: =IF(COUNT(H23,L23,P23,T23)=0,"",MAX(0,H23,L23,P23,T23)) | Y23: =IF(COUNT(H23,L23,P23,T23)=0,"",MIN(0,H23,L23,P23,T23)) | Z23: =IF(AND(C23="",D23="",COUNT(E23,G23,H23,I23,K23,L23,M23,O23,P23,Q23,S23,T23,U23)=0),"",IF(AND(X23<>"",X23>$R$4),"Realce alto",IF(W23="Sem HPF","Sem HPF",IF(OR(W23="Abaixo da faixa",W23="Acima da faixa"),"HPF fora da faixa",IF(AND((H23>0)+(L23>0)+(P23>0)+(T23>0)>0,(H23<0)+(L23<0)+(P23<0)+(T23<0)=0),"Só realces","OK"))))) | AA23: =IF(Z23="","",IF(Z23="Realce alto","Realce de "&X23&" dB: procure antes o que cortar e confira o microfone",IF(Z23="Sem HPF","Ligue o passa-altas: comece em "&V23,IF(Z23="HPF fora da faixa","Partida sugerida: "&V23&". Confira ouvindo",IF(Z23="Só realces","Procure o que cortar antes de realçar","Manter. Decida na mistura")))))
B24: 11 | V24: =IF(D24="","",IFERROR(VLOOKUP(D24,'Guia por fonte'!$B$5:$I$16,5,0),"–")) | W24: =IF(D24="","",IFERROR(IF(E24="",IF(VLOOKUP(D24,'Guia por fonte'!$B$5:$I$16,4,0)="Sim","Desligado","Sem HPF"),IF(E24<VLOOKUP(D24,'Guia por fonte'!$B$5:$I$16,2,0),"Abaixo da faixa",IF(E24>VLOOKUP(D24,'Guia por fonte'!$B$5:$I$16,3,0),"Acima da faixa","OK"))),"–")) | X24: =IF(COUNT(H24,L24,P24,T24)=0,"",MAX(0,H24,L24,P24,T24)) | Y24: =IF(COUNT(H24,L24,P24,T24)=0,"",MIN(0,H24,L24,P24,T24)) | Z24: =IF(AND(C24="",D24="",COUNT(E24,G24,H24,I24,K24,L24,M24,O24,P24,Q24,S24,T24,U24)=0),"",IF(AND(X24<>"",X24>$R$4),"Realce alto",IF(W24="Sem HPF","Sem HPF",IF(OR(W24="Abaixo da faixa",W24="Acima da faixa"),"HPF fora da faixa",IF(AND((H24>0)+(L24>0)+(P24>0)+(T24>0)>0,(H24<0)+(L24<0)+(P24<0)+(T24<0)=0),"Só realces","OK"))))) | AA24: =IF(Z24="","",IF(Z24="Realce alto","Realce de "&X24&" dB: procure antes o que cortar e confira o microfone",IF(Z24="Sem HPF","Ligue o passa-altas: comece em "&V24,IF(Z24="HPF fora da faixa","Partida sugerida: "&V24&". Confira ouvindo",IF(Z24="Só realces","Procure o que cortar antes de realçar","Manter. Decida na mistura")))))
B25: 12 | V25: =IF(D25="","",IFERROR(VLOOKUP(D25,'Guia por fonte'!$B$5:$I$16,5,0),"–")) | W25: =IF(D25="","",IFERROR(IF(E25="",IF(VLOOKUP(D25,'Guia por fonte'!$B$5:$I$16,4,0)="Sim","Desligado","Sem HPF"),IF(E25<VLOOKUP(D25,'Guia por fonte'!$B$5:$I$16,2,0),"Abaixo da faixa",IF(E25>VLOOKUP(D25,'Guia por fonte'!$B$5:$I$16,3,0),"Acima da faixa","OK"))),"–")) | X25: =IF(COUNT(H25,L25,P25,T25)=0,"",MAX(0,H25,L25,P25,T25)) | Y25: =IF(COUNT(H25,L25,P25,T25)=0,"",MIN(0,H25,L25,P25,T25)) | Z25: =IF(AND(C25="",D25="",COUNT(E25,G25,H25,I25,K25,L25,M25,O25,P25,Q25,S25,T25,U25)=0),"",IF(AND(X25<>"",X25>$R$4),"Realce alto",IF(W25="Sem HPF","Sem HPF",IF(OR(W25="Abaixo da faixa",W25="Acima da faixa"),"HPF fora da faixa",IF(AND((H25>0)+(L25>0)+(P25>0)+(T25>0)>0,(H25<0)+(L25<0)+(P25<0)+(T25<0)=0),"Só realces","OK"))))) | AA25: =IF(Z25="","",IF(Z25="Realce alto","Realce de "&X25&" dB: procure antes o que cortar e confira o microfone",IF(Z25="Sem HPF","Ligue o passa-altas: comece em "&V25,IF(Z25="HPF fora da faixa","Partida sugerida: "&V25&". Confira ouvindo",IF(Z25="Só realces","Procure o que cortar antes de realçar","Manter. Decida na mistura")))))
... B37: 24 | V37: =IF(D37="","",IFERROR(VLOOKUP(D37,'Guia por fonte'!$B$5:$I$16,5,0),"–")) | W37: =IF(D37="","",IFERROR(IF(E37="",IF(VLOOKUP(D37,'Guia por fonte'!$B$5:$I$16,4,0)="Sim","Desligado","Sem HPF"),IF(E37<VLOOKUP(D37,'Guia por fonte'!$B$5:$I$16,2,0),"Abaixo da faixa",IF(E37>VLOOKUP(D37,'Guia por fonte'!$B$5:$I$16,3,0),"Acima da faixa","OK"))),"–")) | X37: =IF(COUNT(H37,L37,P37,T37)=0,"",MAX(0,H37,L37,P37,T37)) | Y37: =IF(COUNT(H37,L37,P37,T37)=0,"",MIN(0,H37,L37,P37,T37)) | Z37: =IF(AND(C37="",D37="",COUNT(E37,G37,H37,I37,K37,L37,M37,O37,P37,Q37,S37,T37,U37)=0),"",IF(AND(X37<>"",X37>$R$4),"Realce alto",IF(W37="Sem HPF","Sem HPF",IF(OR(W37="Abaixo da faixa",W37="Acima da faixa"),"HPF fora da faixa",IF(AND((H37>0)+(L37>0)+(P37>0)+(T37>0)>0,(H37<0)+(L37<0)+(P37<0)+(T37<0)=0),"Só realces","OK"))))) | AA37: =IF(Z37="","",IF(Z37="Realce alto","Realce de "&X37&" dB: procure antes o que cortar e confira o microfone",IF(Z37="Sem HPF","Ligue o passa-altas: comece em "&V37,IF(Z37="HPF fora da faixa","Partida sugerida: "&V37&". Confira ouvindo",IF(Z37="Só realces","Procure o que cortar antes de realçar","Manter. Decida na mistura")))))
B39: Mapa de cortes e realces por faixa, somando todos os canais
B40: Faixa | D40: De (Hz) | E40: Até (Hz) | F40: Realces | J40: Cortes | N40: Aviso
B41: Subgrave | D41: 20 | E41: 60 | F41: =COUNTIFS(G$14:G$37,">="&$D41,G$14:G$37,"<"&$E41,H$14:H$37,">0")+COUNTIFS(K$14:K$37,">="&$D41,K$14:K$37,"<"&$E41,L$14:L$37,">0")+COUNTIFS(O$14:O$37,">="&$D41,O$14:O$37,"<"&$E41,P$14:P$37,">0")+COUNTIFS(S$14:S$37,">="&$D41,S$14:S$37,"<"&$E41,T$14:T$37,">0") -> 0 | J41: =COUNTIFS(G$14:G$37,">="&$D41,G$14:G$37,"<"&$E41,H$14:H$37,"<0")+COUNTIFS(K$14:K$37,">="&$D41,K$14:K$37,"<"&$E41,L$14:L$37,"<0")+COUNTIFS(O$14:O$37,">="&$D41,O$14:O$37,"<"&$E41,P$14:P$37,"<0")+COUNTIFS(S$14:S$37,">="&$D41,S$14:S$37,"<"&$E41,T$14:T$37,"<0") -> 0 | N41: =IF(F41+J41=0,"",IF(F41>=$R$5,"Disputa: muitos realces nesta faixa. Corte nos canais que cobrem a fonte principal",IF(J41>=$R$5,"Mesmo corte em muitos canais: teste o sistema com música gravada","OK")))
B42: Grave | D42: 60 | E42: 250 | F42: =COUNTIFS(G$14:G$37,">="&$D42,G$14:G$37,"<"&$E42,H$14:H$37,">0")+COUNTIFS(K$14:K$37,">="&$D42,K$14:K$37,"<"&$E42,L$14:L$37,">0")+COUNTIFS(O$14:O$37,">="&$D42,O$14:O$37,"<"&$E42,P$14:P$37,">0")+COUNTIFS(S$14:S$37,">="&$D42,S$14:S$37,"<"&$E42,T$14:T$37,">0") -> 0 | J42: =COUNTIFS(G$14:G$37,">="&$D42,G$14:G$37,"<"&$E42,H$14:H$37,"<0")+COUNTIFS(K$14:K$37,">="&$D42,K$14:K$37,"<"&$E42,L$14:L$37,"<0")+COUNTIFS(O$14:O$37,">="&$D42,O$14:O$37,"<"&$E42,P$14:P$37,"<0")+COUNTIFS(S$14:S$37,">="&$D42,S$14:S$37,"<"&$E42,T$14:T$37,"<0") -> 0 | N42: =IF(F42+J42=0,"",IF(F42>=$R$5,"Disputa: muitos realces nesta faixa. Corte nos canais que cobrem a fonte principal",IF(J42>=$R$5,"Mesmo corte em muitos canais: teste o sistema com música gravada","OK")))
B43: Médio-grave | D43: 250 | E43: 500 | F43: =COUNTIFS(G$14:G$37,">="&$D43,G$14:G$37,"<"&$E43,H$14:H$37,">0")+COUNTIFS(K$14:K$37,">="&$D43,K$14:K$37,"<"&$E43,L$14:L$37,">0")+COUNTIFS(O$14:O$37,">="&$D43,O$14:O$37,"<"&$E43,P$14:P$37,">0")+COUNTIFS(S$14:S$37,">="&$D43,S$14:S$37,"<"&$E43,T$14:T$37,">0") -> 0 | J43: =COUNTIFS(G$14:G$37,">="&$D43,G$14:G$37,"<"&$E43,H$14:H$37,"<0")+COUNTIFS(K$14:K$37,">="&$D43,K$14:K$37,"<"&$E43,L$14:L$37,"<0")+COUNTIFS(O$14:O$37,">="&$D43,O$14:O$37,"<"&$E43,P$14:P$37,"<0")+COUNTIFS(S$14:S$37,">="&$D43,S$14:S$37,"<"&$E43,T$14:T$37,"<0") -> 0 | N43: =IF(F43+J43=0,"",IF(F43>=$R$5,"Disputa: muitos realces nesta faixa. Corte nos canais que cobrem a fonte principal",IF(J43>=$R$5,"Mesmo corte em muitos canais: teste o sistema com música gravada","OK")))
B44: Médio | D44: 500 | E44: 2000 | F44: =COUNTIFS(G$14:G$37,">="&$D44,G$14:G$37,"<"&$E44,H$14:H$37,">0")+COUNTIFS(K$14:K$37,">="&$D44,K$14:K$37,"<"&$E44,L$14:L$37,">0")+COUNTIFS(O$14:O$37,">="&$D44,O$14:O$37,"<"&$E44,P$14:P$37,">0")+COUNTIFS(S$14:S$37,">="&$D44,S$14:S$37,"<"&$E44,T$14:T$37,">0") -> 0 | J44: =COUNTIFS(G$14:G$37,">="&$D44,G$14:G$37,"<"&$E44,H$14:H$37,"<0")+COUNTIFS(K$14:K$37,">="&$D44,K$14:K$37,"<"&$E44,L$14:L$37,"<0")+COUNTIFS(O$14:O$37,">="&$D44,O$14:O$37,"<"&$E44,P$14:P$37,"<0")+COUNTIFS(S$14:S$37,">="&$D44,S$14:S$37,"<"&$E44,T$14:T$37,"<0") -> 0 | N44: =IF(F44+J44=0,"",IF(F44>=$R$5,"Disputa: muitos realces nesta faixa. Corte nos canais que cobrem a fonte principal",IF(J44>=$R$5,"Mesmo corte em muitos canais: teste o sistema com música gravada","OK")))
B45: Médio-agudo | D45: 2000 | E45: 4000 | F45: =COUNTIFS(G$14:G$37,">="&$D45,G$14:G$37,"<"&$E45,H$14:H$37,">0")+COUNTIFS(K$14:K$37,">="&$D45,K$14:K$37,"<"&$E45,L$14:L$37,">0")+COUNTIFS(O$14:O$37,">="&$D45,O$14:O$37,"<"&$E45,P$14:P$37,">0")+COUNTIFS(S$14:S$37,">="&$D45,S$14:S$37,"<"&$E45,T$14:T$37,">0") -> 0 | J45: =COUNTIFS(G$14:G$37,">="&$D45,G$14:G$37,"<"&$E45,H$14:H$37,"<0")+COUNTIFS(K$14:K$37,">="&$D45,K$14:K$37,"<"&$E45,L$14:L$37,"<0")+COUNTIFS(O$14:O$37,">="&$D45,O$14:O$37,"<"&$E45,P$14:P$37,"<0")+COUNTIFS(S$14:S$37,">="&$D45,S$14:S$37,"<"&$E45,T$14:T$37,"<0") -> 0 | N45: =IF(F45+J45=0,"",IF(F45>=$R$5,"Disputa: muitos realces nesta faixa. Corte nos canais que cobrem a fonte principal",IF(J45>=$R$5,"Mesmo corte em muitos canais: teste o sistema com música gravada","OK")))
B46: Agudo | D46: 4000 | E46: 8000 | F46: =COUNTIFS(G$14:G$37,">="&$D46,G$14:G$37,"<"&$E46,H$14:H$37,">0")+COUNTIFS(K$14:K$37,">="&$D46,K$14:K$37,"<"&$E46,L$14:L$37,">0")+COUNTIFS(O$14:O$37,">="&$D46,O$14:O$37,"<"&$E46,P$14:P$37,">0")+COUNTIFS(S$14:S$37,">="&$D46,S$14:S$37,"<"&$E46,T$14:T$37,">0") -> 0 | J46: =COUNTIFS(G$14:G$37,">="&$D46,G$14:G$37,"<"&$E46,H$14:H$37,"<0")+COUNTIFS(K$14:K$37,">="&$D46,K$14:K$37,"<"&$E46,L$14:L$37,"<0")+COUNTIFS(O$14:O$37,">="&$D46,O$14:O$37,"<"&$E46,P$14:P$37,"<0")+COUNTIFS(S$14:S$37,">="&$D46,S$14:S$37,"<"&$E46,T$14:T$37,"<0") -> 0 | N46: =IF(F46+J46=0,"",IF(F46>=$R$5,"Disputa: muitos realces nesta faixa. Corte nos canais que cobrem a fonte principal",IF(J46>=$R$5,"Mesmo corte em muitos canais: teste o sistema com música gravada","OK")))
B47: Brilho | D47: 8000 | E47: 20000 | F47: =COUNTIFS(G$14:G$37,">="&$D47,G$14:G$37,"<="&$E47,H$14:H$37,">0")+COUNTIFS(K$14:K$37,">="&$D47,K$14:K$37,"<="&$E47,L$14:L$37,">0")+COUNTIFS(O$14:O$37,">="&$D47,O$14:O$37,"<="&$E47,P$14:P$37,">0")+COUNTIFS(S$14:S$37,">="&$D47,S$14:S$37,"<="&$E47,T$14:T$37,">0") -> 0 | J47: =COUNTIFS(G$14:G$37,">="&$D47,G$14:G$37,"<="&$E47,H$14:H$37,"<0")+COUNTIFS(K$14:K$37,">="&$D47,K$14:K$37,"<="&$E47,L$14:L$37,"<0")+COUNTIFS(O$14:O$37,">="&$D47,O$14:O$37,"<="&$E47,P$14:P$37,"<0")+COUNTIFS(S$14:S$37,">="&$D47,S$14:S$37,"<="&$E47,T$14:T$37,"<0") -> 0 | N47: =IF(F47+J47=0,"",IF(F47>=$R$5,"Disputa: muitos realces nesta faixa. Corte nos canais que cobrem a fonte principal",IF(J47>=$R$5,"Mesmo corte em muitos canais: teste o sistema com música gravada","OK")))
B48: Conta as bandas com ganho diferente de zero pela frequência. O shelf entra pela frequência do ponto. O passa-altas não entra na conta.
B50: Resumo automático
B51: Canais registrados | F51: =COUNTA(C14:C37) -> 0
B52: Na situação OK | F52: =COUNTIF(Z14:Z37,"OK") -> 0
B53: Realce alto | F53: =COUNTIF(Z14:Z37,"Realce alto") -> 0
B54: Sem passa-altas | F54: =COUNTIF(Z14:Z37,"Sem HPF") -> 0
B55: Passa-altas fora da faixa | F55: =COUNTIF(Z14:Z37,"HPF fora da faixa") -> 0
...

Sheet Faixas e sintomas
B1: Faixas e sintomas — consulta e calculadora
B2: Digite uma frequência para ver a faixa e como ela soa. Digite a frequência e o Q para ver de onde até onde a banda age.
B4: Consulta por frequência (exercício 2: o que você ouviu na varredura)
B5: Defeito ouvido | C5: Frequência | D5: Faixa | E5: Em excesso, soa | F5: Região típica do defeito | G5: Conferência | H5: Observação
C6: Hz
B7: Retumbante | D7: =IF(C7="","",IF(OR(C7<20,C7>20000),"Fora de 20 Hz a 20 kHz",INDEX($B$27:$B$33,MATCH(C7,$C$27:$C$33,1)))) | E7: =IF(C7="","",IF(OR(C7<20,C7>20000),"",INDEX($F$27:$F$33,MATCH(C7,$C$27:$C$33,1)))) | F7: 100 a 250 Hz | G7: =IF(C7="","",IF(AND(C7>=100,C7<=250),"Dentro da região típica","Fora da região típica: confira"))
B8: Embolado | D8: =IF(C8="","",IF(OR(C8<20,C8>20000),"Fora de 20 Hz a 20 kHz",INDEX($B$27:$B$33,MATCH(C8,$C$27:$C$33,1)))) | E8: =IF(C8="","",IF(OR(C8<20,C8>20000),"",INDEX($F$27:$F$33,MATCH(C8,$C$27:$C$33,1)))) | F8: 200 a 400 Hz | G8: =IF(C8="","",IF(AND(C8>=200,C8<=400),"Dentro da região típica","Fora da região típica: confira"))
B9: Anasalado | D9: =IF(C9="","",IF(OR(C9<20,C9>20000),"Fora de 20 Hz a 20 kHz",INDEX($B$27:$B$33,MATCH(C9,$C$27:$C$33,1)))) | E9: =IF(C9="","",IF(OR(C9<20,C9>20000),"",INDEX($F$27:$F$33,MATCH(C9,$C$27:$C$33,1)))) | F9: 800 Hz a 1,5 kHz | G9: =IF(C9="","",IF(AND(C9>=800,C9<=1500),"Dentro da região típica","Fora da região típica: confira"))
B10: Áspero | D10: =IF(C10="","",IF(OR(C10<20,C10>20000),"Fora de 20 Hz a 20 kHz",INDEX($B$27:$B$33,MATCH(C10,$C$27:$C$33,1)))) | E10: =IF(C10="","",IF(OR(C10<20,C10>20000),"",INDEX($F$27:$F$33,MATCH(C10,$C$27:$C$33,1)))) | F10: 2 a 5 kHz | G10: =IF(C10="","",IF(AND(C10>=2000,C10<=5000),"Dentro da região típica","Fora da região típica: confira"))
B11: Sibilante | D11: =IF(C11="","",IF(OR(C11<20,C11>20000),"Fora de 20 Hz a 20 kHz",INDEX($B$27:$B$33,MATCH(C11,$C$27:$C$33,1)))) | E11: =IF(C11="","",IF(OR(C11<20,C11>20000),"",INDEX($F$27:$F$33,MATCH(C11,$C$27:$C$33,1)))) | F11: 5 a 8 kHz | G11: =IF(C11="","",IF(AND(C11>=5000,C11<=8000),"Dentro da região típica","Fora da região típica: confira"))
D12: =IF(C12="","",IF(OR(C12<20,C12>20000),"Fora de 20 Hz a 20 kHz",INDEX($B$27:$B$33,MATCH(C12,$C$27:$C$33,1)))) | E12: =IF(C12="","",IF(OR(C12<20,C12>20000),"",INDEX($F$27:$F$33,MATCH(C12,$C$27:$C$33,1)))) | F12: –
D13: =IF(C13="","",IF(OR(C13<20,C13>20000),"Fora de 20 Hz a 20 kHz",INDEX($B$27:$B$33,MATCH(C13,$C$27:$C$33,1)))) | E13: =IF(C13="","",IF(OR(C13<20,C13>20000),"",INDEX($F$27:$F$33,MATCH(C13,$C$27:$C$33,1)))) | F13: –
D14: =IF(C14="","",IF(OR(C14<20,C14>20000),"Fora de 20 Hz a 20 kHz",INDEX($B$27:$B$33,MATCH(C14,$C$27:$C$33,1)))) | E14: =IF(C14="","",IF(OR(C14<20,C14>20000),"",INDEX($F$27:$F$33,MATCH(C14,$C$27:$C$33,1)))) | F14: –
B15: A frequência de um defeito muda com a voz, o microfone e a sala. Fora da região típica não é erro: é a sua voz. As três últimas linhas são para consulta livre.
B17: Calculadora de largura de uma banda bell
B18: Uso | C18: Frequência | D18: Q | E18: Largura (oitavas) | F18: De (Hz) | G18: Até (Hz) | H18: Observação
B19: Banda larga (realce) | D19: 0.7 | E19: =IF(OR(D19="",D19<=0),"",ROUND(2*LOG10((1/(2*D19)+(1/(4*D19^2)+1)^0.5))/LOG10(2),2)) -> 1.92 | F19: =IF(OR(C19="",E19=""),"",ROUND(C19/2^(E19/2),0)) | G19: =IF(OR(C19="",E19=""),"",ROUND(C19*2^(E19/2),0))
B20: Corte comum | D20: 2 | E20: =IF(OR(D20="",D20<=0),"",ROUND(2*LOG10((1/(2*D20)+(1/(4*D20^2)+1)^0.5))/LOG10(2),2)) -> 0.71 | F20: =IF(OR(C20="",E20=""),"",ROUND(C20/2^(E20/2),0)) | G20: =IF(OR(C20="",E20=""),"",ROUND(C20*2^(E20/2),0))
B21: Corte estreito (microfonia) | D21: 8 | E21: =IF(OR(D21="",D21<=0),"",ROUND(2*LOG10((1/(2*D21)+(1/(4*D21^2)+1)^0.5))/LOG10(2),2)) -> 0.18 | F21: =IF(OR(C21="",E21=""),"",ROUND(C21/2^(E21/2),0)) | G21: =IF(OR(C21="",E21=""),"",ROUND(C21*2^(E21/2),0))
B22: Livre | E22: =IF(OR(D22="",D22<=0),"",ROUND(2*LOG10((1/(2*D22)+(1/(4*D22^2)+1)^0.5))/LOG10(2),2)) | F22: =IF(OR(C22="",E22=""),"",ROUND(C22/2^(E22/2),0)) | G22: =IF(OR(C22="",E22=""),"",ROUND(C22*2^(E22/2),0))
B23: Conta usual do Q (pontos de meia intensidade em torno da frequência central). Alguns fabricantes usam outra definição: trate o resultado como ordem de grandeza.
B25: As sete faixas
B26: Faixa | C26: De (Hz) | D26: Até (Hz) | E26: O que mora ali | F26: Em excesso, soa | G26: Em falta, soa
B27: Subgrave | C27: 20 | D27: 60 | E27: Peso do bumbo, notas mais graves do baixo e do teclado. | F27: Ronco, vibração no palco. | G27: Bumbo e baixo sem peso.
B28: Grave | C28: 60 | D28: 250 | E28: Corpo do baixo, do bumbo e do violão; fundamental das vozes. | F28: Retumbante, pesado. | G28: Magro, sem corpo.
B29: Médio-grave | C29: 250 | D29: 500 | E29: Calor das vozes e dos instrumentos. Onde tudo se acumula. | F29: Embolado, caixa de papelão. | G29: Oco, sem calor.
B30: Médio | C30: 500 | D30: 2000 | E30: Miolo das vozes, do violão, do teclado e da guitarra. | F30: Anasalado, som de telefone. | G30: Distante, vazio.
B31: Médio-agudo | C31: 2000 | D31: 4000 | E31: Consoantes e clareza da fala. O ouvido é mais sensível aqui. | F31: Áspero, estridente. | G31: Sem clareza nas palavras.
B32: Agudo | C32: 4000 | D32: 8000 | E32: Definição, ataque, o s e o ch das vozes. | F32: Sibilante, cortante. | G32: Opaco, sem ataque.
B33: Brilho | C33: 8000 | D33: 20000 | E33: Brilho dos pratos e das cordas, ar nas vozes. | F33: Chiado, agudo que cansa. | G33: Abafado, sem ar.
B35: Do que se ouve para onde procurar
B36: Como soa | C36: Onde procurar | E36: Primeira medida
B37: Ronco, vento, pof nas letras P e B, batida de mão | C37: abaixo de 100 Hz | E37: Ligar ou subir o passa-altas.
B38: Retumbante, pesado | C38: 100 a 250 Hz | E38: Subir um pouco o passa-altas, ou cortar com o shelving de graves.
B39: Embolado, turvo | C39: 200 a 400 Hz | E39: Corte de 2 a 4 dB com uma banda bell.
B40: Caixa de papelão, som oco de tambor | C40: 300 a 600 Hz | E40: Corte com uma banda bell. No bumbo, o corte costuma ser maior.
B41: Anasalado, corneta, telefone | C41: 800 Hz a 1,5 kHz | E41: Corte de 2 a 4 dB com uma banda bell.
B42: Áspero, estridente, cansa o ouvido | C42: 2 a 5 kHz | E42: Corte suave e largo. Confira antes se há realce demais nessa região.
B43: Sibilante: s e ch que espetam | C43: 5 a 8 kHz | E43: Corte leve, ou o de-esser (estudo Dinâmica e efeitos).
B44: Abafado, ou sem clareza nas palavras | C44: 2 kHz para cima | E44: Conferir microfone e posição. Cortar o que embola (200 a 400 Hz). Só então, realce largo de 2 a 3 dB.
...

Sheet Guia por fonte
B1: Guia por fonte — ponto de partida
B2: Onde procurar primeiro, e não receita. As colunas C a F alimentam a conferência do passa-altas na Ficha de EQ.
B4: Fonte | C4: HPF mín. (Hz) | D4: HPF máx. (Hz) | E4: Pode ficar desligado | F4: Passa-altas para começar | G4: Onde costuma sobrar (cortar) | H4: Onde pode faltar (realçar com cuidado) | I4: Observação
B5: Voz masculina | C5: 80 | D5: 120 | E5: Não | F5: 80 a 120 Hz | G5: 200 a 350 Hz: embolado. 800 Hz a 1,5 kHz: anasalado. 5 a 8 kHz: sibilância. | H5: 2 a 4 kHz: clareza das palavras (2 a 3 dB, banda larga). | I5: Fala: entender cada palavra do fundo da sala. Canto: equalize com a voz forte.
B6: Voz feminina | C6: 100 | D6: 180 | E6: Não | F6: 100 a 180 Hz | G6: 200 a 400 Hz: embolado. 2,5 a 4 kHz: áspero nas notas fortes. 5 a 8 kHz: sibilância. | H6: 3 a 5 kHz: presença. Shelving em 10 a 12 kHz: ar (2 a 3 dB). | I6: Vale também para voz infantil, lapela e headset. Lapela no peito costuma soar abafada.
B7: Coral | C7: 100 | D7: 180 | E7: Não | F7: 100 a 180 Hz | G7: 200 a 400 Hz: embolado com o som da sala. | H7: 3 a 5 kHz: presença, com cuidado: microfone distante apita antes. | I7: O microfone distante capta muita sala. Aproxime antes de equalizar.
B8: Violão | C8: 80 | D8: 150 | E8: Não | F8: 80 a 150 Hz | G8: 100 a 250 Hz: ressonância do corpo, onde apita. 1 a 3 kHz: som duro de captador. | H8: Shelving em 8 a 10 kHz: brilho das cordas. | I8: Sozinho, passa-altas perto de 80 Hz. Com banda, mais alto: o baixo cuida do grave.
B9: Guitarra | C9: 80 | D9: 120 | E9: Não | F9: 80 a 120 Hz | G9: 200 a 400 Hz: embolado. 2 a 4 kHz: se disputar com a voz. | H9: Raramente precisa. | I9: O timbre se acerta no amplificador, antes da mesa.
B10: Caixa da bateria | C10: 80 | D10: 120 | E10: Não | F10: 80 a 120 Hz | G10: 400 a 800 Hz: som oco, de papelão. | H10: 150 a 250 Hz: corpo. 3 a 5 kHz: estalo da esteira. | I10: O passa-altas reduz o bumbo que entra no microfone da caixa.
B11: Tons e surdo | C11: 40 | D11: 100 | E11: Não | F11: 40 a 100 Hz | G11: 300 a 600 Hz: som oco, de papelão. | H11: 80 a 150 Hz: corpo. 3 a 5 kHz: ataque. | I11: Quanto maior o tambor, mais baixo o filtro.
B12: Pratos e chimbal | C12: 200 | D12: 400 | E12: Não | F12: 200 a 400 Hz | G12: 1 a 3 kHz: som de lata, áspero. | H12: Shelving em 10 kHz: brilho, com cuidado. | I12: O passa-altas deixa passar só os pratos, e não o resto da bateria.
B13: Teclado | C13: 40 | D13: 120 | E13: Sim | F13: desligado, ou 40 a 120 Hz | G13: 200 a 400 Hz: embolado com a banda. 2 a 4 kHz: se disputar com a voz. | H13: Raramente precisa. | I13: Filtro baixo quando o teclado faz o grave; mais alto quando há baixista. Ajuste o timbre no teclado.
B14: Baixo | C14: 30 | D14: 40 | E14: Sim | F14: desligado, ou 30 a 40 Hz | G14: 200 a 300 Hz: embolado. 40 a 60 Hz: se a sala retumbar. | H14: 60 a 100 Hz: peso. 700 Hz a 1 kHz: definição. 2 a 3 kHz: ataque. | I14: É a definição, e não o peso, que faz o baixo ser ouvido em caixas pequenas.
B15: Bumbo | C15: 30 | D15: 40 | E15: Sim | F15: desligado, ou 30 a 40 Hz | G15: 300 a 500 Hz: caixa de papelão (cortes de 4 a 8 dB são comuns). | H15: 50 a 80 Hz: peso. 2 a 5 kHz: ataque do batedor. | I15: Decida com o baixo quem fica mais embaixo. Não realce os dois no mesmo ponto.
B16: Computador e mídia | C16: 30 | D16: 40 | E16: Sim | F16: desligado, ou 30 a 40 Hz | G16: Raramente: o material já vem equalizado. | H16: Raramente. | I16: Se a mídia soa mal no sistema, o defeito pode ser da sala ou das caixas.
B17: Valores típicos. Mudam com a voz, o instrumento, o microfone, a distância e a sala. Se mudar os números das colunas C e D, a conferência da ficha acompanha.

Sheet Checklist
B1: Checklist da equalização
B2: Confira na passagem de som, depois de equalizar os canais. Escolha a situação de cada item na lista suspensa.
B4: # | C4: Grupo | D4: Item | E4: Situação | F4: Observação
B5: 1 | C5: Antes | D5: O ganho de cada canal foi ajustado antes do EQ, e o EQ começou plano.
B6: 2 | C6: Antes | D6: A fonte, o microfone e a posição foram conferidos antes de equalizar.
B7: 3 | C7: Canal | D7: O passa-altas está ligado em tudo o que não faz o grave da música, na faixa de partida de cada fonte.
B8: 4 | C8: Canal | D8: Cada ajuste responde a um defeito que foi ouvido e tem nome.
B9: 5 | C9: Canal | D9: Os cortes vieram antes dos realces, e o ponto de cada corte foi achado por varredura.
B10: 6 | C10: Canal | D10: Os realces são poucos, largos e de até cerca de 6 dB. Nenhum canal tem só realces.
B11: 7 | C11: Canal | D11: Cada canal foi comparado com o EQ desligado, no mesmo volume, e ficou melhor com ele ligado.
B12: 8 | C12: Canal | D12: O nível de cada canal foi conferido no medidor depois do EQ.
B13: 9 | C13: Mistura | D13: O EQ foi decidido na mistura: a voz principal está clara por cima da banda, e o bumbo e o baixo se distinguem.
B14: 10 | C14: Sistema | D14: O mesmo corte não se repete em quase todos os canais. Se repete, o sistema foi testado com música gravada.
B15: 11 | C15: Retorno | D15: O EQ de cada retorno tem só cortes, poucos e moderados, e foi comparado com o equalizador desligado.
B16: 12 | C16: Registro | D16: O EQ de cada canal e de cada saída está anotado, e qualquer mudança no EQ de sistema foi registrada.
B18: Itens respondidos | E18: =COUNTA(E5:E16) -> 0
B19: Percentual atendido (Parcial vale metade) | E19: =IF(COUNTA(E5:E16)=0,"",(COUNTIF(E5:E16,"Sim")+COUNTIF(E5:E16,"Parcial")/2)/COUNTA(E5:E16))
B20: Situação | E20: =IF(COUNTA(E5:E16)<12,"Incompleto",IF(COUNTIF(E5:E16,"Não")=0,"OK","Há itens a resolver")) -> Incompleto

Sheet Exemplo - Ficha de EQ
B1: Ficha de EQ por canal — passa-altas e até quatro bandas
B2: Exemplo preenchido, para consulta. Use a aba Ficha de EQ para o seu evento.
B4: Evento | D4: Culto de domingo, 19 h | K4: Realce máximo (dB) | R4: 6 | S4: Realce acima disto recebe o aviso Realce alto. Ponto de partida: 6 dB.
B5: Local | D5: Igreja de 200 lugares | K5: Aviso de faixa repetida (nº) | R5: 4 | S5: Quantos realces, ou cortes, na mesma faixa disparam o aviso do mapa. Ponto de partida: 4.
B6: Data | D6: 46299
B7: Operador | D7: Operador de som da escala | K7: Frequências em Hz (3000, e não 3 k). Ganho em dB, com sinal: −4 para corte. Q só na banda bell.
B8: Mesa | D8: Mesa digital, passa-altas e quatro bandas por canal | K8: Passa-altas em branco = desligado. A faixa de partida vem da aba Guia por fonte.
B10: Ficha de EQ por canal
B11: Canal | C11: Fonte | D11: Tipo de fonte | E11: HPF | F11: Banda 1 | J11: Banda 2 | N11: Banda 3 | R11: Banda 4 | V11: Partida do HPF | W11: Passa-altas | X11: Maior realce | Y11: Maior corte | Z11: Situação | AA11: O que fazer | AB11: Observação
B12: nº | C12: o que está no canal | D12: da lista | E12: Hz | F12: Tipo | G12: Hz | H12: dB | I12: Q | J12: Tipo | K12: Hz | L12: dB | M12: Q | N12: Tipo | O12: Hz | P12: dB | Q12: Q | R12: Tipo | S12: Hz | T12: dB | U12: Q | V12: do Guia por fonte | W12: conferência | X12: dB | Y12: dB
B13: O EQ como foi encontrado na passagem de som, antes da correção. As colunas de V a AA são calculadas.
B14: 1 | C14: Voz da cantora | D14: Voz feminina | F14: Bell | G14: 3000 | H14: 8 | I14: 1.4 | J14: Shelf | K14: 10000 | L14: 9 | V14: =IF(D14="","",IFERROR(VLOOKUP(D14,'Guia por fonte'!$B$5:$I$16,5,0),"–")) -> 100 a 180 Hz | W14: =IF(D14="","",IFERROR(IF(E14="",IF(VLOOKUP(D14,'Guia por fonte'!$B$5:$I$16,4,0)="Sim","Desligado","Sem HPF"),IF(E14<VLOOKUP(D14,'Guia por fonte'!$B$5:$I$16,2,0),"Abaixo da faixa",IF(E14>VLOOKUP(D14,'Guia por fonte'!$B$5:$I$16,3,0),"Acima da faixa","OK"))),"–")) -> Sem HPF | X14: =IF(COUNT(H14,L14,P14,T14)=0,"",MAX(0,H14,L14,P14,T14)) -> 9 | Y14: =IF(COUNT(H14,L14,P14,T14)=0,"",MIN(0,H14,L14,P14,T14)) -> 0 | Z14: =IF(AND(C14="",D14="",COUNT(E14,G14,H14,I14,K14,L14,M14,O14,P14,Q14,S14,T14,U14)=0),"",IF(AND(X14<>"",X14>$R$4),"Realce alto",IF(W14="Sem HPF","Sem HPF",IF(OR(W14="Abaixo da faixa",W14="Acima da faixa"),"HPF fora da faixa",IF(AND((H14>0)+(L14>0)+(P14>0)+(T14>0)>0,(H14<0)+(L14<0)+(P14<0)+(T14<0)=0),"Só realces","OK"))))) -> Realce alto | AA14: =IF(Z14="","",IF(Z14="Realce alto","Realce de "&X14&" dB: procure antes o que cortar e confira o microfone",IF(Z14="Sem HPF","Ligue o passa-altas: comece em "&V14,IF(Z14="HPF fora da faixa","Partida sugerida: "&V14&". Confira ouvindo",IF(Z14="Só realces","Procure o que cortar antes de realçar","Manter. Decida na mistura"))))) -> Realce de 9 dB: procure antes o que cortar e confira o microfone
B15: 2 | C15: Voz de apoio | D15: Voz feminina | E15: 100 | F15: Bell | G15: 3150 | H15: 6 | I15: 1.4 | J15: Shelf | K15: 10000 | L15: 4 | V15: =IF(D15="","",IFERROR(VLOOKUP(D15,'Guia por fonte'!$B$5:$I$16,5,0),"–")) -> 100 a 180 Hz | W15: =IF(D15="","",IFERROR(IF(E15="",IF(VLOOKUP(D15,'Guia por fonte'!$B$5:$I$16,4,0)="Sim","Desligado","Sem HPF"),IF(E15<VLOOKUP(D15,'Guia por fonte'!$B$5:$I$16,2,0),"Abaixo da faixa",IF(E15>VLOOKUP(D15,'Guia por fonte'!$B$5:$I$16,3,0),"Acima da faixa","OK"))),"–")) -> OK | X15: =IF(COUNT(H15,L15,P15,T15)=0,"",MAX(0,H15,L15,P15,T15)) -> 6 | Y15: =IF(COUNT(H15,L15,P15,T15)=0,"",MIN(0,H15,L15,P15,T15)) -> 0 | Z15: =IF(AND(C15="",D15="",COUNT(E15,G15,H15,I15,K15,L15,M15,O15,P15,Q15,S15,T15,U15)=0),"",IF(AND(X15<>"",X15>$R$4),"Realce alto",IF(W15="Sem HPF","Sem HPF",IF(OR(W15="Abaixo da faixa",W15="Acima da faixa"),"HPF fora da faixa",IF(AND((H15>0)+(L15>0)+(P15>0)+(T15>0)>0,(H15<0)+(L15<0)+(P15<0)+(T15<0)=0),"Só realces","OK"))))) -> Só realces | AA15: =IF(Z15="","",IF(Z15="Realce alto","Realce de "&X15&" dB: procure antes o que cortar e confira o microfone",IF(Z15="Sem HPF","Ligue o passa-altas: comece em "&V15,IF(Z15="HPF fora da faixa","Partida sugerida: "&V15&". Confira ouvindo",IF(Z15="Só realces","Procure o que cortar antes de realçar","Manter. Decida na mistura"))))) -> Procure o que cortar antes de realçar
B16: 3 | C16: Voz do pastor | D16: Voz masculina | E16: 100 | F16: Bell | G16: 300 | H16: -3 | I16: 1.4 | J16: Bell | K16: 2500 | L16: 3 | M16: 1 | V16: =IF(D16="","",IFERROR(VLOOKUP(D16,'Guia por fonte'!$B$5:$I$16,5,0),"–")) -> 80 a 120 Hz | W16: =IF(D16="","",IFERROR(IF(E16="",IF(VLOOKUP(D16,'Guia por fonte'!$B$5:$I$16,4,0)="Sim","Desligado","Sem HPF"),IF(E16<VLOOKUP(D16,'Guia por fonte'!$B$5:$I$16,2,0),"Abaixo da faixa",IF(E16>VLOOKUP(D16,'Guia por fonte'!$B$5:$I$16,3,0),"Acima da faixa","OK"))),"–")) -> OK | X16: =IF(COUNT(H16,L16,P16,T16)=0,"",MAX(0,H16,L16,P16,T16)) -> 3 | Y16: =IF(COUNT(H16,L16,P16,T16)=0,"",MIN(0,H16,L16,P16,T16)) -> -3 | Z16: =IF(AND(C16="",D16="",COUNT(E16,G16,H16,I16,K16,L16,M16,O16,P16,Q16,S16,T16,U16)=0),"",IF(AND(X16<>"",X16>$R$4),"Realce alto",IF(W16="Sem HPF","Sem HPF",IF(OR(W16="Abaixo da faixa",W16="Acima da faixa"),"HPF fora da faixa",IF(AND((H16>0)+(L16>0)+(P16>0)+(T16>0)>0,(H16<0)+(L16<0)+(P16<0)+(T16<0)=0),"Só realces","OK"))))) -> OK | AA16: =IF(Z16="","",IF(Z16="Realce alto","Realce de "&X16&" dB: procure antes o que cortar e confira o microfone",IF(Z16="Sem HPF","Ligue o passa-altas: comece em "&V16,IF(Z16="HPF fora da faixa","Partida sugerida: "&V16&". Confira ouvindo",IF(Z16="Só realces","Procure o que cortar antes de realçar","Manter. Decida na mistura"))))) -> Manter. Decida na mistura
B17: 4 | C17: Violão | D17: Violão | E17: 80 | F17: Bell | G17: 200 | H17: -4 | I17: 1.4 | J17: Bell | K17: 3000 | L17: 5 | M17: 1.4 | V17: =IF(D17="","",IFERROR(VLOOKUP(D17,'Guia por fonte'!$B$5:$I$16,5,0),"–")) -> 80 a 150 Hz | W17: =IF(D17="","",IFERROR(IF(E17="",IF(VLOOKUP(D17,'Guia por fonte'!$B$5:$I$16,4,0)="Sim","Desligado","Sem HPF"),IF(E17<VLOOKUP(D17,'Guia por fonte'!$B$5:$I$16,2,0),"Abaixo da faixa",IF(E17>VLOOKUP(D17,'Guia por fonte'!$B$5:$I$16,3,0),"Acima da faixa","OK"))),"–")) -> OK | X17: =IF(COUNT(H17,L17,P17,T17)=0,"",MAX(0,H17,L17,P17,T17)) -> 5 | Y17: =IF(COUNT(H17,L17,P17,T17)=0,"",MIN(0,H17,L17,P17,T17)) -> -4 | Z17: =IF(AND(C17="",D17="",COUNT(E17,G17,H17,I17,K17,L17,M17,O17,P17,Q17,S17,T17,U17)=0),"",IF(AND(X17<>"",X17>$R$4),"Realce alto",IF(W17="Sem HPF","Sem HPF",IF(OR(W17="Abaixo da faixa",W17="Acima da faixa"),"HPF fora da faixa",IF(AND((H17>0)+(L17>0)+(P17>0)+(T17>0)>0,(H17<0)+(L17<0)+(P17<0)+(T17<0)=0),"Só realces","OK"))))) -> OK | AA17: =IF(Z17="","",IF(Z17="Realce alto","Realce de "&X17&" dB: procure antes o que cortar e confira o microfone",IF(Z17="Sem HPF","Ligue o passa-altas: comece em "&V17,IF(Z17="HPF fora da faixa","Partida sugerida: "&V17&". Confira ouvindo",IF(Z17="Só realces","Procure o que cortar antes de realçar","Manter. Decida na mistura"))))) -> Manter. Decida na mistura
B18: 5 | C18: Baixo | D18: Baixo | F18: Bell | G18: 250 | H18: -3 | I18: 1.4 | J18: Bell | K18: 800 | L18: 3 | M18: 1.4 | V18: =IF(D18="","",IFERROR(VLOOKUP(D18,'Guia por fonte'!$B$5:$I$16,5,0),"–")) -> desligado, ou 30 a 40 Hz | W18: =IF(D18="","",IFERROR(IF(E18="",IF(VLOOKUP(D18,'Guia por fonte'!$B$5:$I$16,4,0)="Sim","Desligado","Sem HPF"),IF(E18<VLOOKUP(D18,'Guia por fonte'!$B$5:$I$16,2,0),"Abaixo da faixa",IF(E18>VLOOKUP(D18,'Guia por fonte'!$B$5:$I$16,3,0),"Acima da faixa","OK"))),"–")) -> Desligado | X18: =IF(COUNT(H18,L18,P18,T18)=0,"",MAX(0,H18,L18,P18,T18)) -> 3 | Y18: =IF(COUNT(H18,L18,P18,T18)=0,"",MIN(0,H18,L18,P18,T18)) -> -3 | Z18: =IF(AND(C18="",D18="",COUNT(E18,G18,H18,I18,K18,L18,M18,O18,P18,Q18,S18,T18,U18)=0),"",IF(AND(X18<>"",X18>$R$4),"Realce alto",IF(W18="Sem HPF","Sem HPF",IF(OR(W18="Abaixo da faixa",W18="Acima da faixa"),"HPF fora da faixa",IF(AND((H18>0)+(L18>0)+(P18>0)+(T18>0)>0,(H18<0)+(L18<0)+(P18<0)+(T18<0)=0),"Só realces","OK"))))) -> OK | AA18: =IF(Z18="","",IF(Z18="Realce alto","Realce de "&X18&" dB: procure antes o que cortar e confira o microfone",IF(Z18="Sem HPF","Ligue o passa-altas: comece em "&V18,IF(Z18="HPF fora da faixa","Partida sugerida: "&V18&". Confira ouvindo",IF(Z18="Só realces","Procure o que cortar antes de realçar","Manter. Decida na mistura"))))) -> Manter. Decida na mistura
B19: 6 | C19: Bumbo | D19: Bumbo | F19: Bell | G19: 60 | H19: 3 | I19: 1.4 | J19: Bell | K19: 400 | L19: -6 | M19: 2.9 | N19: Bell | O19: 3500 | P19: 4 | Q19: 1.4 | V19: =IF(D19="","",IFERROR(VLOOKUP(D19,'Guia por fonte'!$B$5:$I$16,5,0),"–")) -> desligado, ou 30 a 40 Hz | W19: =IF(D19="","",IFERROR(IF(E19="",IF(VLOOKUP(D19,'Guia por fonte'!$B$5:$I$16,4,0)="Sim","Desligado","Sem HPF"),IF(E19<VLOOKUP(D19,'Guia por fonte'!$B$5:$I$16,2,0),"Abaixo da faixa",IF(E19>VLOOKUP(D19,'Guia por fonte'!$B$5:$I$16,3,0),"Acima da faixa","OK"))),"–")) -> Desligado | X19: =IF(COUNT(H19,L19,P19,T19)=0,"",MAX(0,H19,L19,P19,T19)) -> 4 | Y19: =IF(COUNT(H19,L19,P19,T19)=0,"",MIN(0,H19,L19,P19,T19)) -> -6 | Z19: =IF(AND(C19="",D19="",COUNT(E19,G19,H19,I19,K19,L19,M19,O19,P19,Q19,S19,T19,U19)=0),"",IF(AND(X19<>"",X19>$R$4),"Realce alto",IF(W19="Sem HPF","Sem HPF",IF(OR(W19="Abaixo da faixa",W19="Acima da faixa"),"HPF fora da faixa",IF(AND((H19>0)+(L19>0)+(P19>0)+(T19>0)>0,(H19<0)+(L19<0)+(P19<0)+(T19<0)=0),"Só realces","OK"))))) -> OK | AA19: =IF(Z19="","",IF(Z19="Realce alto","Realce de "&X19&" dB: procure antes o que cortar e confira o microfone",IF(Z19="Sem HPF","Ligue o passa-altas: comece em "&V19,IF(Z19="HPF fora da faixa","Partida sugerida: "&V19&". Confira ouvindo",IF(Z19="Só realces","Procure o que cortar antes de realçar","Manter. Decida na mistura"))))) -> Manter. Decida na mistura
B20: 7 | C20: Teclado | D20: Teclado | F20: Bell | G20: 2500 | H20: 6 | I20: 1.4 | J20: Shelf | K20: 8000 | L20: 3 | V20: =IF(D20="","",IFERROR(VLOOKUP(D20,'Guia por fonte'!$B$5:$I$16,5,0),"–")) -> desligado, ou 40 a 120 Hz | W20: =IF(D20="","",IFERROR(IF(E20="",IF(VLOOKUP(D20,'Guia por fonte'!$B$5:$I$16,4,0)="Sim","Desligado","Sem HPF"),IF(E20<VLOOKUP(D20,'Guia por fonte'!$B$5:$I$16,2,0),"Abaixo da faixa",IF(E20>VLOOKUP(D20,'Guia por fonte'!$B$5:$I$16,3,0),"Acima da faixa","OK"))),"–")) -> Desligado | X20: =IF(COUNT(H20,L20,P20,T20)=0,"",MAX(0,H20,L20,P20,T20)) -> 6 | Y20: =IF(COUNT(H20,L20,P20,T20)=0,"",MIN(0,H20,L20,P20,T20)) -> 0 | Z20: =IF(AND(C20="",D20="",COUNT(E20,G20,H20,I20,K20,L20,M20,O20,P20,Q20,S20,T20,U20)=0),"",IF(AND(X20<>"",X20>$R$4),"Realce alto",IF(W20="Sem HPF","Sem HPF",IF(OR(W20="Abaixo da faixa",W20="Acima da faixa"),"HPF fora da faixa",IF(AND((H20>0)+(L20>0)+(P20>0)+(T20>0)>0,(H20<0)+(L20<0)+(P20<0)+(T20<0)=0),"Só realces","OK"))))) -> Só realces | AA20: =IF(Z20="","",IF(Z20="Realce alto","Realce de "&X20&" dB: procure antes o que cortar e confira o microfone",IF(Z20="Sem HPF","Ligue o passa-altas: comece em "&V20,IF(Z20="HPF fora da faixa","Partida sugerida: "&V20&". Confira ouvindo",IF(Z20="Só realces","Procure o que cortar antes de realçar","Manter. Decida na mistura"))))) -> Procure o que cortar antes de realçar
B21: 8 | C21: Computador (som dos vídeos) | D21: Computador e mídia | V21: =IF(D21="","",IFERROR(VLOOKUP(D21,'Guia por fonte'!$B$5:$I$16,5,0),"–")) -> desligado, ou 30 a 40 Hz | W21: =IF(D21="","",IFERROR(IF(E21="",IF(VLOOKUP(D21,'Guia por fonte'!$B$5:$I$16,4,0)="Sim","Desligado","Sem HPF"),IF(E21<VLOOKUP(D21,'Guia por fonte'!$B$5:$I$16,2,0),"Abaixo da faixa",IF(E21>VLOOKUP(D21,'Guia por fonte'!$B$5:$I$16,3,0),"Acima da faixa","OK"))),"–")) -> Desligado | X21: =IF(COUNT(H21,L21,P21,T21)=0,"",MAX(0,H21,L21,P21,T21)) | Y21: =IF(COUNT(H21,L21,P21,T21)=0,"",MIN(0,H21,L21,P21,T21)) | Z21: =IF(AND(C21="",D21="",COUNT(E21,G21,H21,I21,K21,L21,M21,O21,P21,Q21,S21,T21,U21)=0),"",IF(AND(X21<>"",X21>$R$4),"Realce alto",IF(W21="Sem HPF","Sem HPF",IF(OR(W21="Abaixo da faixa",W21="Acima da faixa"),"HPF fora da faixa",IF(AND((H21>0)+(L21>0)+(P21>0)+(T21>0)>0,(H21<0)+(L21<0)+(P21<0)+(T21<0)=0),"Só realces","OK"))))) -> OK | AA21: =IF(Z21="","",IF(Z21="Realce alto","Realce de "&X21&" dB: procure antes o que cortar e confira o microfone",IF(Z21="Sem HPF","Ligue o passa-altas: comece em "&V21,IF(Z21="HPF fora da faixa","Partida sugerida: "&V21&". Confira ouvindo",IF(Z21="Só realces","Procure o que cortar antes de realçar","Manter. Decida na mistura"))))) -> Manter. Decida na mistura
B22: 9 | V22: =IF(D22="","",IFERROR(VLOOKUP(D22,'Guia por fonte'!$B$5:$I$16,5,0),"–")) | W22: =IF(D22="","",IFERROR(IF(E22="",IF(VLOOKUP(D22,'Guia por fonte'!$B$5:$I$16,4,0)="Sim","Desligado","Sem HPF"),IF(E22<VLOOKUP(D22,'Guia por fonte'!$B$5:$I$16,2,0),"Abaixo da faixa",IF(E22>VLOOKUP(D22,'Guia por fonte'!$B$5:$I$16,3,0),"Acima da faixa","OK"))),"–")) | X22: =IF(COUNT(H22,L22,P22,T22)=0,"",MAX(0,H22,L22,P22,T22)) | Y22: =IF(COUNT(H22,L22,P22,T22)=0,"",MIN(0,H22,L22,P22,T22)) | Z22: =IF(AND(C22="",D22="",COUNT(E22,G22,H22,I22,K22,L22,M22,O22,P22,Q22,S22,T22,U22)=0),"",IF(AND(X22<>"",X22>$R$4),"Realce alto",IF(W22="Sem HPF","Sem HPF",IF(OR(W22="Abaixo da faixa",W22="Acima da faixa"),"HPF fora da faixa",IF(AND((H22>0)+(L22>0)+(P22>0)+(T22>0)>0,(H22<0)+(L22<0)+(P22<0)+(T22<0)=0),"Só realces","OK"))))) | AA22: =IF(Z22="","",IF(Z22="Realce alto","Realce de "&X22&" dB: procure antes o que cortar e confira o microfone",IF(Z22="Sem HPF","Ligue o passa-altas: comece em "&V22,IF(Z22="HPF fora da faixa","Partida sugerida: "&V22&". Confira ouvindo",IF(Z22="Só realces","Procure o que cortar antes de realçar","Manter. Decida na mistura")))))
B23: 10 | V23: =IF(D23="","",IFERROR(VLOOKUP(D23,'Guia por fonte'!$B$5:$I$16,5,0),"–")) | W23: =IF(D23="","",IFERROR(IF(E23="",IF(VLOOKUP(D23,'Guia por fonte'!$B$5:$I$16,4,0)="Sim","Desligado","Sem HPF"),IF(E23<VLOOKUP(D23,'Guia por fonte'!$B$5:$I$16,2,0),"Abaixo da faixa",IF(E23>VLOOKUP(D23,'Guia por fonte'!$B$5:$I$16,3,0),"Acima da faixa","OK"))),"–")) | X23: =IF(COUNT(H23,L23,P23,T23)=0,"",MAX(0,H23,L23,P23,T23)) | Y23: =IF(COUNT(H23,L23,P23,T23)=0,"",MIN(0,H23,L23,P23,T23)) | Z23: =IF(AND(C23="",D23="",COUNT(E23,G23,H23,I23,K23,L23,M23,O23,P23,Q23,S23,T23,U23)=0),"",IF(AND(X23<>"",X23>$R$4),"Realce alto",IF(W23="Sem HPF","Sem HPF",IF(OR(W23="Abaixo da faixa",W23="Acima da faixa"),"HPF fora da faixa",IF(AND((H23>0)+(L23>0)+(P23>0)+(T23>0)>0,(H23<0)+(L23<0)+(P23<0)+(T23<0)=0),"Só realces","OK"))))) | AA23: =IF(Z23="","",IF(Z23="Realce alto","Realce de "&X23&" dB: procure antes o que cortar e confira o microfone",IF(Z23="Sem HPF","Ligue o passa-altas: comece em "&V23,IF(Z23="HPF fora da faixa","Partida sugerida: "&V23&". Confira ouvindo",IF(Z23="Só realces","Procure o que cortar antes de realçar","Manter. Decida na mistura")))))
B24: 11 | V24: =IF(D24="","",IFERROR(VLOOKUP(D24,'Guia por fonte'!$B$5:$I$16,5,0),"–")) | W24: =IF(D24="","",IFERROR(IF(E24="",IF(VLOOKUP(D24,'Guia por fonte'!$B$5:$I$16,4,0)="Sim","Desligado","Sem HPF"),IF(E24<VLOOKUP(D24,'Guia por fonte'!$B$5:$I$16,2,0),"Abaixo da faixa",IF(E24>VLOOKUP(D24,'Guia por fonte'!$B$5:$I$16,3,0),"Acima da faixa","OK"))),"–")) | X24: =IF(COUNT(H24,L24,P24,T24)=0,"",MAX(0,H24,L24,P24,T24)) | Y24: =IF(COUNT(H24,L24,P24,T24)=0,"",MIN(0,H24,L24,P24,T24)) | Z24: =IF(AND(C24="",D24="",COUNT(E24,G24,H24,I24,K24,L24,M24,O24,P24,Q24,S24,T24,U24)=0),"",IF(AND(X24<>"",X24>$R$4),"Realce alto",IF(W24="Sem HPF","Sem HPF",IF(OR(W24="Abaixo da faixa",W24="Acima da faixa"),"HPF fora da faixa",IF(AND((H24>0)+(L24>0)+(P24>0)+(T24>0)>0,(H24<0)+(L24<0)+(P24<0)+(T24<0)=0),"Só realces","OK"))))) | AA24: =IF(Z24="","",IF(Z24="Realce alto","Realce de "&X24&" dB: procure antes o que cortar e confira o microfone",IF(Z24="Sem HPF","Ligue o passa-altas: comece em "&V24,IF(Z24="HPF fora da faixa","Partida sugerida: "&V24&". Confira ouvindo",IF(Z24="Só realces","Procure o que cortar antes de realçar","Manter. Decida na mistura")))))
B25: 12 | V25: =IF(D25="","",IFERROR(VLOOKUP(D25,'Guia por fonte'!$B$5:$I$16,5,0),"–")) | W25: =IF(D25="","",IFERROR(IF(E25="",IF(VLOOKUP(D25,'Guia por fonte'!$B$5:$I$16,4,0)="Sim","Desligado","Sem HPF"),IF(E25<VLOOKUP(D25,'Guia por fonte'!$B$5:$I$16,2,0),"Abaixo da faixa",IF(E25>VLOOKUP(D25,'Guia por fonte'!$B$5:$I$16,3,0),"Acima da faixa","OK"))),"–")) | X25: =IF(COUNT(H25,L25,P25,T25)=0,"",MAX(0,H25,L25,P25,T25)) | Y25: =IF(COUNT(H25,L25,P25,T25)=0,"",MIN(0,H25,L25,P25,T25)) | Z25: =IF(AND(C25="",D25="",COUNT(E25,G25,H25,I25,K25,L25,M25,O25,P25,Q25,S25,T25,U25)=0),"",IF(AND(X25<>"",X25>$R$4),"Realce alto",IF(W25="Sem HPF","Sem HPF",IF(OR(W25="Abaixo da faixa",W25="Acima da faixa"),"HPF fora da faixa",IF(AND((H25>0)+(L25>0)+(P25>0)+(T25>0)>0,(H25<0)+(L25<0)+(P25<0)+(T25<0)=0),"Só realces","OK"))))) | AA25: =IF(Z25="","",IF(Z25="Realce alto","Realce de "&X25&" dB: procure antes o que cortar e confira o microfone",IF(Z25="Sem HPF","Ligue o passa-altas: comece em "&V25,IF(Z25="HPF fora da faixa","Partida sugerida: "&V25&". Confira ouvindo",IF(Z25="Só realces","Procure o que cortar antes de realçar","Manter. Decida na mistura")))))
B26: 13 | V26: =IF(D26="","",IFERROR(VLOOKUP(D26,'Guia por fonte'!$B$5:$I$16,5,0),"–")) | W26: =IF(D26="","",IFERROR(IF(E26="",IF(VLOOKUP(D26,'Guia por fonte'!$B$5:$I$16,4,0)="Sim","Desligado","Sem HPF"),IF(E26<VLOOKUP(D26,'Guia por fonte'!$B$5:$I$16,2,0),"Abaixo da faixa",IF(E26>VLOOKUP(D26,'Guia por fonte'!$B$5:$I$16,3,0),"Acima da faixa","OK"))),"–")) | X26: =IF(COUNT(H26,L26,P26,T26)=0,"",MAX(0,H26,L26,P26,T26)) | Y26: =IF(COUNT(H26,L26,P26,T26)=0,"",MIN(0,H26,L26,P26,T26)) | Z26: =IF(AND(C26="",D26="",COUNT(E26,G26,H26,I26,K26,L26,M26,O26,P26,Q26,S26,T26,U26)=0),"",IF(AND(X26<>"",X26>$R$4),"Realce alto",IF(W26="Sem HPF","Sem HPF",IF(OR(W26="Abaixo da faixa",W26="Acima da faixa"),"HPF fora da faixa",IF(AND((H26>0)+(L26>0)+(P26>0)+(T26>0)>0,(H26<0)+(L26<0)+(P26<0)+(T26<0)=0),"Só realces","OK"))))) | AA26: =IF(Z26="","",IF(Z26="Realce alto","Realce de "&X26&" dB: procure antes o que cortar e confira o microfone",IF(Z26="Sem HPF","Ligue o passa-altas: comece em "&V26,IF(Z26="HPF fora da faixa","Partida sugerida: "&V26&". Confira ouvindo",IF(Z26="Só realces","Procure o que cortar antes de realçar","Manter. Decida na mistura")))))
B27: 14 | V27: =IF(D27="","",IFERROR(VLOOKUP(D27,'Guia por fonte'!$B$5:$I$16,5,0),"–")) | W27: =IF(D27="","",IFERROR(IF(E27="",IF(VLOOKUP(D27,'Guia por fonte'!$B$5:$I$16,4,0)="Sim","Desligado","Sem HPF"),IF(E27<VLOOKUP(D27,'Guia por fonte'!$B$5:$I$16,2,0),"Abaixo da faixa",IF(E27>VLOOKUP(D27,'Guia por fonte'!$B$5:$I$16,3,0),"Acima da faixa","OK"))),"–")) | X27: =IF(COUNT(H27,L27,P27,T27)=0,"",MAX(0,H27,L27,P27,T27)) | Y27: =IF(COUNT(H27,L27,P27,T27)=0,"",MIN(0,H27,L27,P27,T27)) | Z27: =IF(AND(C27="",D27="",COUNT(E27,G27,H27,I27,K27,L27,M27,O27,P27,Q27,S27,T27,U27)=0),"",IF(AND(X27<>"",X27>$R$4),"Realce alto",IF(W27="Sem HPF","Sem HPF",IF(OR(W27="Abaixo da faixa",W27="Acima da faixa"),"HPF fora da faixa",IF(AND((H27>0)+(L27>0)+(P27>0)+(T27>0)>0,(H27<0)+(L27<0)+(P27<0)+(T27<0)=0),"Só realces","OK"))))) | AA27: =IF(Z27="","",IF(Z27="Realce alto","Realce de "&X27&" dB: procure antes o que cortar e confira o microfone",IF(Z27="Sem HPF","Ligue o passa-altas: comece em "&V27,IF(Z27="HPF fora da faixa","Partida sugerida: "&V27&". Confira ouvindo",IF(Z27="Só realces","Procure o que cortar antes de realçar","Manter. Decida na mistura")))))
B28: 15 | V28: =IF(D28="","",IFERROR(VLOOKUP(D28,'Guia por fonte'!$B$5:$I$16,5,0),"–")) | W28: =IF(D28="","",IFERROR(IF(E28="",IF(VLOOKUP(D28,'Guia por fonte'!$B$5:$I$16,4,0)="Sim","Desligado","Sem HPF"),IF(E28<VLOOKUP(D28,'Guia por fonte'!$B$5:$I$16,2,0),"Abaixo da faixa",IF(E28>VLOOKUP(D28,'Guia por fonte'!$B$5:$I$16,3,0),"Acima da faixa","OK"))),"–")) | X28: =IF(COUNT(H28,L28,P28,T28)=0,"",MAX(0,H28,L28,P28,T28)) | Y28: =IF(COUNT(H28,L28,P28,T28)=0,"",MIN(0,H28,L28,P28,T28)) | Z28: =IF(AND(C28="",D28="",COUNT(E28,G28,H28,I28,K28,L28,M28,O28,P28,Q28,S28,T28,U28)=0),"",IF(AND(X28<>"",X28>$R$4),"Realce alto",IF(W28="Sem HPF","Sem HPF",IF(OR(W28="Abaixo da faixa",W28="Acima da faixa"),"HPF fora da faixa",IF(AND((H28>0)+(L28>0)+(P28>0)+(T28>0)>0,(H28<0)+(L28<0)+(P28<0)+(T28<0)=0),"Só realces","OK"))))) | AA28: =IF(Z28="","",IF(Z28="Realce alto","Realce de "&X28&" dB: procure antes o que cortar e confira o microfone",IF(Z28="Sem HPF","Ligue o passa-altas: comece em "&V28,IF(Z28="HPF fora da faixa","Partida sugerida: "&V28&". Confira ouvindo",IF(Z28="Só realces","Procure o que cortar antes de realçar","Manter. Decida na mistura")))))
B29: 16 | V29: =IF(D29="","",IFERROR(VLOOKUP(D29,'Guia por fonte'!$B$5:$I$16,5,0),"–")) | W29: =IF(D29="","",IFERROR(IF(E29="",IF(VLOOKUP(D29,'Guia por fonte'!$B$5:$I$16,4,0)="Sim","Desligado","Sem HPF"),IF(E29<VLOOKUP(D29,'Guia por fonte'!$B$5:$I$16,2,0),"Abaixo da faixa",IF(E29>VLOOKUP(D29,'Guia por fonte'!$B$5:$I$16,3,0),"Acima da faixa","OK"))),"–")) | X29: =IF(COUNT(H29,L29,P29,T29)=0,"",MAX(0,H29,L29,P29,T29)) | Y29: =IF(COUNT(H29,L29,P29,T29)=0,"",MIN(0,H29,L29,P29,T29)) | Z29: =IF(AND(C29="",D29="",COUNT(E29,G29,H29,I29,K29,L29,M29,O29,P29,Q29,S29,T29,U29)=0),"",IF(AND(X29<>"",X29>$R$4),"Realce alto",IF(W29="Sem HPF","Sem HPF",IF(OR(W29="Abaixo da faixa",W29="Acima da faixa"),"HPF fora da faixa",IF(AND((H29>0)+(L29>0)+(P29>0)+(T29>0)>0,(H29<0)+(L29<0)+(P29<0)+(T29<0)=0),"Só realces","OK"))))) | AA29: =IF(Z29="","",IF(Z29="Realce alto","Realce de "&X29&" dB: procure antes o que cortar e confira o microfone",IF(Z29="Sem HPF","Ligue o passa-altas: comece em "&V29,IF(Z29="HPF fora da faixa","Partida sugerida: "&V29&". Confira ouvindo",IF(Z29="Só realces","Procure o que cortar antes de realçar","Manter. Decida na mistura")))))
